Workbook

Sheet TỔNG HỢP
A1: BẢNG TỔNG HỢP DỰ TOÁN
A2: Dự án: Nhà Máy Sản Xuất Công Ty ….
A3: Gói thầu: Thi Công Xây Dựng & Hệ Thống Cơ Điện, PCCC
A5: STT | B5: HẠNG MỤC THI CÔNG | C5: ĐVT | D5: KHỐI LƯỢNG | E5: ĐƠN GIÁ ( VNĐ) | F5: THÀNH TIỀN (VNĐ) | G5: GHI CHÚ
A7: A | B7: CÔNG TÁC CHUẨN BỊ | F7: =+SUBTOTAL(9,F8:F13) -> 0
A8: =MAX($A$5:$A7)+1 -> 1 | B8: Chi phí thiết lập công trường | C8: set | D8: 1 | F8: =D8*E8 -> 0
A9: =MAX($A$5:$A8)+1 -> 2 | B9: Chi phí quản lý và duy trì hoạt động công trường | C9: set | D9: 1 | F9: =D9*E9 -> 0
A10: =MAX($A$5:$A9)+1 -> 3 | B10: Chi phí an toàn lao động và hệ thống an ninh | C10: set | D10: 1 | F10: =D10*E10 -> 0
A11: =MAX($A$5:$A10)+1 -> 4 | B11: Chi phí mẫu vật liệu và thí nghiệm | C11: set | D11: 1 | F11: =D11*E11 -> 0 | G11: Đã bao gồm
A12: =MAX($A$5:$A11)+1 -> 5 | B12: Điều kiện hợp đồng | C12: set | D12: 1 | F12: =D12*E12 -> 0 | G12: Đã bao gồm
A13: =MAX($A$5:$A12)+1 -> 6 | B13: Chi phí phục vụ thi công | C13: set | D13: 1 | F13: =D13*E13 -> 0
A14: B | B14: CHI PHÍ XÂY DỰNG CÔNG TRÌNH | F14: =+SUBTOTAL(9,F15:F31) -> 0
A15: =MAX($A$5:$A14)+1 -> 7 | B15: Hạng mục: San lấp | C15: set | D15: 1 | F15: =D15*E15 -> 0
A16: =MAX($A$5:$A15)+1 -> 8 | B16: Hạng mục: cọc | C16: set | D16: 1 | F16: =D16*E16 -> 0 | G16: Xác định giá trị HM thực tế sau khi có kết quả thi công cọc thử
A17: =MAX($A$5:$A16)+1 -> 9 | B17: Hạng mục: Nhà xưởng | C17: set | D17: 1 | F17: =D17*E17 -> 0
A18: =MAX($A$5:$A17)+1 -> 10 | B18: Hạng mục: Nhà văn phòng | C18: set | D18: 1 | F18: =D18*E18 -> 0
A19: =MAX($A$5:$A18)+1 -> 11 | B19: Hạng mục: Nhà lò hơi - kho hóa chất - nhà rác | C19: set | D19: 1 | F19: =D19*E19 -> 0
A20: =MAX($A$5:$A19)+1 -> 12 | B20: Hạng mục: Nhà trạm điện | C20: set | D20: 1 | F20: =D20*E20 -> 0
A21: =MAX($A$5:$A20)+1 -> 13 | B21: Hạng mục: Nhà bảo vệ | C21: set | D21: 1 | F21: =D21*E21 -> 0
A22: =MAX($A$5:$A21)+1 -> 14 | B22: Hạng mục: Cổng và hàng rào | C22: set | D22: 1 | F22: =D22*E22 -> 0
A23: =MAX($A$5:$A22)+1 -> 15 | B23: Hạng mục: Bể nước PCCC | C23: set | D23: 1 | F23: =D23*E23 -> 0
A24: =MAX($A$5:$A23)+1 -> 16 | B24: Hạng mục: Bể XLNT | C24: set | D24: 1 | F24: =D24*E24 -> 0
A25: =MAX($A$5:$A24)+1 -> 17 | B25: Hạng mục: Hạ Tầng | C25: set | D25: 1 | F25: =D25*E25 -> 0
A26: =MAX($A$5:$A25)+1 -> 18 | B26: Hạng mục: Thoát nước mưa | C26: set | D26: 1 | F26: =D26*E26 -> 0
A27: =MAX($A$5:$A26)+1 -> 19 | B27: Hạng mục: Thoát nước thải | C27: set | D27: 1 | F27: =D27*E27 -> 0
A28: =MAX($A$5:$A27)+1 -> 20 | B28: Hạng mục: Điện + nước | C28: set | D28: 1 | F28: =D28*E28 -> 0
... A30: =MAX($A$5:$A29)+1 -> 22 | B30: Hạng mục: Thang tải hàng | C30: set | D30: 1 | F30: =D30*E30 -> 0
A32: TỔNG GIÁ TRỊ TRƯỚC THUẾ | F32: =+SUBTOTAL(9,F7:F31) -> 0 | G32: =F32/11000 -> 0
A33: THUẾ VAT 8% | F33: =8%*F32 -> 0
A34: TỔNG GIÁ TRỊ SAU THUẾ | F34: =F32+F33 -> 0
A36: Ghi chú:

Sheet CP chuẩn bị
A2: BẢNG CHI TIẾT KHỐI LƯỢNG CÔNG VIỆC
A3: ='TỔNG HỢP'!A2 -> Dự án: Nhà Máy Sản Xuất Công Ty ….
A4: ='[69]San lấp'!A3 -> Gói thầu: Thi Công Xây Dựng & Hệ Thống Cơ Điện, PCCC
A5: HẠNG MỤC : CÔNG TÁC CHUẨN BỊ
A7: Stt | B7: HẠNG MỤC THI CÔNG | C7: ĐVT | D7: KHỐI LƯỢNG | E7: ĐƠN GIÁ ( VNĐ) | F7: THÀNH TIỀN (VNĐ) | G7: GHI CHÚ
A9: I | B9: CHI PHÍ THIẾT LẬP CÔNG TRƯỜNG | F9: =+SUBTOTAL(9,F10:F23) -> 0
A10: 1 | B10: Đường tạm thi công | C10: m2 | D10: 250 | F10: =D10*E10 -> 0
A11: 2 | B11: Cầu rửa xe | C11: gói | D11: 1 | F11: =D11*E11 -> 0
A12: 3 | B12: Văn phòng (bao gồm nhà vệ sinh) | C12: tháng | D12: 6 | F12: =D12*E12 -> 0
A13: 5 | B13: Phòng họp (01 phòng) | C13: m2 | D13: 25 | F13: =D13*E13 -> 0
A14: 6 | B14: Thiết bị văn phòng | C14: gói | D14: 1 | F14: =D14*E14 -> 0
A15: 7 | B15: Nhà vệ sinh cho công nhân | C15: m2 | D15: 6 | F15: =D15*E15 -> 0
A16: 8 | B16: Hệ thống chống sét tạm thời | C16: gói | D16: 1 | F16: =D16*E16 -> 0
A17: 9 | B17: Hệ thống thoát nước mưa tạm thời | C17: gói | D17: 1 | F17: =D17*E17 -> 0
A18: 10 | B18: Hệ thống thoát nước thải tạm thời | C18: gói | D18: 1 | F18: =D18*E18 -> 0
A19: 11 | B19: Nhà bảo vệ tạm thời | C19: gói | D19: 1 | F19: =D19*E19 -> 0
A20: 12 | B20: Hàng rào tạm thời cao 2m | C20: m2 | D20: =(180+80)*2 -> 520 | F20: =D20*E20 -> 0 | G20: làm 2 mặt giáp đường
A21: 13 | B21: Bảng hiệu + khung cổng công trường | C21: gói | D21: 1 | F21: =D21*E21 -> 0
A22: 14 | B22: Lán trại công nhân và kho vật tư | C22: m2 | D22: 55 | F22: =D22*E22 -> 0
A23: 15 | B23: Lễ khởi công | C23: gói | D23: 1 | F23: =D23*E23 -> 0
A24: II | B24: CHI PHÍ QUẢN LÝ VÀ DUY TRÌ HOẠT ĐỘNG CÔNG TRƯỜNG | F24: =+SUBTOTAL(9,F25:F33) -> 0
A25: 1 | B25: Chi phí điện thi công | C25: tháng | D25: 7 | F25: =D25*E25 -> 0
A26: 2 | B26: Chi phí nước thi công | C26: tháng | D26: 7 | F26: =D26*E26 -> 0
A27: 3 | B27: Chiếu sáng cho công trình | C27: tháng | D27: 7 | F27: =D27*E27 -> 0
A28: 4 | B28: Chi phí kết nối điện thoại, internet cho văn phòng của Chủ đầu tư và Nhà thầu | C28: tháng | D28: 7 | F28: =D28*E28 -> 0
A29: 5 | B29: Chi phí phòng phẩm | C29: tháng | D29: 7 | F29: =D29*E29 -> 0
A30: 6 | B30: Chi phi quản lý tại công trường | C30: tháng | F30: =D30*E30 -> 0 | G30: Đã bao gồm
A31: 7 | B31: Chi phí bản vẽ hoàn công | C31: gói | F31: =D31*E31 -> 0 | G31: Đã bao gồm
A32: 8 | B32: Công tác khảo sát trắc đạc toàn Nhà máy | C32: gói | D32: 1 | F32: =D32*E32 -> 0
A33: 9 | B33: Chi phí khác thuộc công trường | C33: gói | D33: 1 | F33: =D33*E33 -> 0
A34: III | B34: CHI PHÍ AN TOÀN LAO ĐỘNG VÀ HỆ THỐNG AN NINH | F34: =+SUBTOTAL(9,F35:F41) -> 0
A35: 1 | B35: Chi phí Tiện ích sơ cấp cứu | C35: gói | D35: 1 | F35: =D35*E35 -> 0
A36: 2 | B36: Chi phí thiết bị an toàn, lưới và biển báo cho tất cả các hoạt động thi công, huấn luyện an toàn định kỳ, giám sát an toàn độc lập | C36: gói | F36: =D36*E36 -> 0 | G36: Đã bao gồm
A37: 3 | B37: Chi phí đồ bảo hộ cho công nhân, nhân viên quản lý của Nhà thầu | C37: gói | D37: 1 | F37: =D37*E37 -> 0
A38: 4 | B38: Chi phí các dịch vụ an ninh trong công trường | C38: gói | D38: 1 | F38: =D38*E38 -> 0
A39: 5 | B39: Chi phí các thiết bị phòng hộ và chống cháy | C39: gói | D39: 1 | F39: =D39*E39 -> 0
A40: 6 | B40: Chi phí vệ sinh công trường và bảo vệ môi trường bao gồm chi phí xả thải trong thời gian thi công | C40: gói | D40: 1 | F40: =D40*E40 -> 0
A41: 7 | B41: Vệ sinh bàn giao dự án | C41: gói | D41: 1 | G41: Đã bao gồm
A42: IV | B42: CHI PHÍ MẪU VẬT LIỆU VÀ THÍ NGHIỆM | F42: =+SUBTOTAL(9,F43:F45) -> 0
A43: 1 | B43: Chi phí lấy mẫu vật liệu bê tông để đệ trình và chi phí để thử nghiệm và đệ trình chứng nhận thử nghiệm | C43: gói | F43: =D43*E43 -> 0 | G43: Đã bao gồm
...

Sheet San lấp
A1: BẢNG KHỐI LƯỢNG MỜI THẦU
A2: ='TỔNG HỢP'!A2 -> Dự án: Nhà Máy Sản Xuất Công Ty ….
A3: Gói thầu: Thi Công Xây Dựng & Hệ Thống Cơ Điện, PCCC
A4: Hạng mục: SAN LẤP VÀ CHUẨN BỊ MẶT BẰNG
A8: STT | B8: NỘI DUNG CÔNG VIỆC | C8: ĐVT | D8: KHỐI LƯỢNG | E8: ĐƠN GIÁ | G8: THÀNH TIỀN | J8: GHI CHÚ
E9: Vật Tư | F9: NC&MTC | G9: =+E9 -> Vật Tư | H9: =+F9 -> NC&MTC | I9: Tổng
B10: SAN LẤP
A11: 1 | B11: Cắt cây, ủi cỏ, ban gạt mặt bằng và vận chuyển ra khỏi công trình | C11: m² | D11: 11000 | G11: =+D11*E11 -> 0 | H11: =+D11*F11 -> 0 | I11: =+SUM(G11:H11) -> 0 | J11: Bao gồm xử lí gốc rễ cây (nếu có)
A12: 2 | B12: San lấp đất độ chặt k =0.9 | C12: m³ | D12: =D11*0.4*1.35 -> 5940 | G12: =+D12*E12 -> 0 | H12: =+D12*F12 -> 0 | I12: =+SUM(G12:H12) -> 0 | J12: Dự kiến Nâng nền lên 400mm
B14: CỘNG GIÁ TRỊ TRƯỚC THUẾ | G14: =+SUBTOTAL(9,G10:G13) -> 0 | H14: =+SUBTOTAL(9,H10:H13) -> 0 | I14: =+SUBTOTAL(9,I10:I13) -> 0

Sheet Cọc
A1: BẢNG KHỐI LƯỢNG MỜI THẦU
A2: ='San lấp'!A2 -> Dự án: Nhà Máy Sản Xuất Công Ty ….
A3: Gói thầu: Thi Công Xây Dựng & Hệ Thống Cơ Điện, PCCC
A4: HẠNG MỤC : CỌC BÊ TÔNG LY TÂM PHC & THỬ TĨNH
A6: STT | B6: NỘI DUNG CÔNG VIỆC | C6: ĐVT | D6: SL | E6: DÀI | F6: KHỐI LƯỢNG | G6: ĐƠN GIÁ | I6: THÀNH TIỀN | L6: GHI CHÚ
D7: SL | E7: Dài | G7: Vật tư | H7: NC&MTC | I7: =G7 -> Vật tư | J7: =H7 -> NC&MTC | K7: Tổng
B8: THI CÔNG CỌC THỬ
A9: =MAX($A$7:A8)+1 -> 1 | B9: Cung cấp và thi công cọc thử D300 | C9: tim | F9: 2 | I9: =+F9*G9 -> 0 | J9: =+F9*H9 -> 0 | K9: =+SUM(I9:J9) -> 0
A10: =MAX($A$7:A9)+1 -> 2 | B10: Cung cấp và thi công cọc thử D400 | C10: tim | F10: 2 | I10: =+F10*G10 -> 0 | J10: =+F10*H10 -> 0 | K10: =+SUM(I10:J10) -> 0
A11: =MAX($A$7:A10)+1 -> 3 | B11: Thử tĩnh cọc D300 Pmax=120 tấn và báo cáo kết quả | C11: tim | F11: =F9 -> 2 | I11: =+F11*G11 -> 0 | J11: =+F11*H11 -> 0 | K11: =+SUM(I11:J11) -> 0
A12: =MAX($A$7:A11)+1 -> 4 | B12: Thử tĩnh cọc D400 Pmax=240 tấn và báo cáo kết quả | C12: tim | F12: =F10 -> 2 | I12: =+F12*G12 -> 0 | J12: =+F12*H12 -> 0 | K12: =+SUM(I12:J12) -> 0
B14: THI CÔNG CỌC ĐẠI TRÀ
A15: 1 | B15: Cung cấp và thi công cọc đại trà D300 | C15: md | F15: =SUBTOTAL(9,F16:F17) -> 1254 | I15: =+F15*G15 -> 0 | J15: =+F15*H15 -> 0 | K15: =+SUM(I15:J15) -> 0
B16: Xưởng | D16: =27-2 -> 25 | E16: 22 | F16: =PRODUCT(D16:E16) -> 550
B17: Lò hơi | D17: 32 | E17: 22 | F17: =PRODUCT(D17:E17) -> 704
A18: =MAX($A$14:A15)+1 -> 2 | B18: Cung cấp và thi công cọc đại trà D400 | C18: md | F18: =SUBTOTAL(9,F19:F21) -> 5850 | I18: =+F18*G18 -> 0 | J18: =+F18*H18 -> 0 | K18: =+SUM(I18:J18) -> 0
B19: Xưởng | D19: =183-2 -> 181 | E19: 26 | F19: =PRODUCT(D19:E19) -> 4706
B20: NVP | D20: 34 | E20: 26 | F20: =PRODUCT(D20:E20) -> 884
B21: Lò hơi | D21: 10 | E21: 26 | F21: =PRODUCT(D21:E21) -> 260
A22: =MAX($A$14:A18)+1 -> 3 | B22: Cẩu hạ cọc, trắc đạc | C22: md | F22: =F15+F18 -> 7104 | I22: =+F22*G22 -> 0 | J22: =+F22*H22 -> 0 | K22: =+SUM(I22:J22) -> 0
A23: =MAX($A$14:A22)+1 -> 4 | B23: Nối cọc D300 | C23: Mối nối | F23: =(F9+D16+D17)*2 -> 118 | I23: =+F23*G23 -> 0 | J23: =+F23*H23 -> 0 | K23: =+SUM(I23:J23) -> 0 | L23: bao gồm
A24: =MAX($A$14:A23)+1 -> 5 | B24: Nối cọc D400 | C24: Mối nối | F24: =(F10+D19+D20+D21)*2 -> 454 | I24: =+F24*G24 -> 0 | J24: =+F24*H24 -> 0 | K24: =+SUM(I24:J24) -> 0 | L24: bao gồm
A25: =MAX($A$14:A24)+1 -> 6 | B25: Máy phát (phục vụ thi công) | C25: md | F25: =F22 -> 7104 | I25: =+F25*G25 -> 0 | J25: =+F25*H25 -> 0 | K25: =+SUM(I25:J25) -> 0
A26: =MAX($A$14:A25)+1 -> 7 | B26: Huy động và giải thể thiết bị ép cọc | C26: lot | F26: 1 | I26: =+F26*G26 -> 0 | J26: =+F26*H26 -> 0 | K26: =+SUM(I26:J26) -> 0
B28: CỘNG GIÁ TRỊ TRƯỚC THUẾ | I28: =+SUBTOTAL(9,I8:I27) -> 0 | J28: =+SUBTOTAL(9,J8:J27) -> 0 | K28: =+SUBTOTAL(9,K8:K27) -> 0

Sheet Xưởng
A1: BẢNG KHỐI LƯỢNG MỜI THẦU
A2: =Cọc!A2 -> Dự án: Nhà Máy Sản Xuất Công Ty ….
A3: Gói thầu: Thi Công Xây Dựng & Hệ Thống Cơ Điện, PCCC
A4: HẠNG MỤC: NHÀ XƯỞNG
A6: STT | B6: NỘI DUNG CÔNG VIỆC | C6: ĐVT | D6: SL | E6: Dài | F6: Rộng | G6: Cao | H6: K. lượng | I6: Đơn giá (VNĐ) | K6: Thành tiền (VNĐ) | M6: Tổng cộng (VNĐ) | N6: Ghi chú
I7: Vật tư | J7: NC&MTC | K7: Vật tư | L7: NC&MTC
B9: Công tác đất và xử lí đầu cọc | K9: =+SUBTOTAL(9,K10:K78) -> 0 | L9: =+SUBTOTAL(9,L10:L78) -> 0 | M9: =+SUBTOTAL(9,M10:M78) -> 0
A10: 1 | B10: Đào đất | C10: m³ | H10: =SUM(H11:H38) -> 1311.518 | K10: =H10*I10 -> 0 | L10: =+H10*J10 -> 0 | M10: =+SUM(K10:L10) -> 0
B11: F1 | D11: 3 | E11: 2.1 | F11: 0.9 | G11: 2.35 | H11: =G11*(F11+0.3)*(E11+0.3)*D11*1.3 -> 26.3952 | K11: =H11*I11 -> 0 | L11: =+H11*J11 -> 0 | M11: =+SUM(K11:L11) -> 0
B12: F1A | D12: 1 | E12: 2.1 | F12: 1.15 | G12: 2.35 | H12: =G12*(F12+0.3)*(E12+0.3)*D12*1.3 -> 10.6314 | K12: =H12*I12 -> 0 | L12: =+H12*J12 -> 0 | M12: =+SUM(K12:L12) -> 0
B13: F2,F2A,F3,F3A | D13: =2+1+8+8 -> 19 | E13: 2.1 | F13: 0.9 | G13: 2.35 | H13: =G13*(F13+0.3)*(E13+0.3)*D13*1.3 -> 167.1696 | K13: =H13*I13 -> 0 | L13: =+H13*J13 -> 0 | M13: =+SUM(K13:L13) -> 0
B14: F4,F4A,F5 | D14: =16+6+6 -> 28 | E14: 2.1 | F14: 2.1 | G14: 2.35 | H14: =G14*(F14+0.3)*(E14+0.3)*D14*1.3 -> 492.7104 | K14: =H14*I14 -> 0 | L14: =+H14*J14 -> 0 | M14: =+SUM(K14:L14) -> 0
B15: F6A,F6B | D15: 3 | E15: 2.1 | F15: 1.95 | G15: 2.35 | H15: =G15*(F15+0.3)*(E15+0.3)*D15*1.3 -> 49.491 | K15: =H15*I15 -> 0 | L15: =+H15*J15 -> 0 | M15: =+SUM(K15:L15) -> 0
B16: F7 | D16: 2 | E16: 0.8 | F16: 0.8 | G16: 2.35 | H16: =G16*(F16+0.3)*(E16+0.3)*D16*1.3 -> 7.3931 | K16: =H16*I16 -> 0 | L16: =+H16*J16 -> 0 | M16: =+SUM(K16:L16) -> 0
B17: FTM-1 | D17: 1 | E17: 5.55 | F17: 4.65 | G17: 2.9 | H17: =G17*(F17+0.3)*(E17+0.3)*D17*1.3 -> 109.16978 | K17: =H17*I17 -> 0 | L17: =+H17*J17 -> 0 | M17: =+SUM(K17:L17) -> 0
B18: FTM-2 | D18: 1 | E18: 4.15 | F18: 5.55 | G18: 2.9 | H18: =G18*(F18+0.3)*(E18+0.3)*D18*1.3 -> 98.142525 | K18: =H18*I18 -> 0 | L18: =+H18*J18 -> 0 | M18: =+SUM(K18:L18) -> 0
B19: FTM-3 | D19: 1 | E19: 3.8 | F19: 4.8 | G19: 2.9 | H19: =G19*(F19+0.3)*(E19+0.3)*D19*1.3 -> 78.8307 | K19: =H19*I19 -> 0 | L19: =+H19*J19 -> 0 | M19: =+SUM(K19:L19) -> 0
B20: 1X1B1,2 | D20: 1 | E20: =67+32+66.8 -> 165.8 | F20: 0.2 | G20: 0.9 | H20: =G20*(F20+0.3)*(E20+0.3)*D20*1.3 -> 97.1685 | K20: =H20*I20 -> 0 | L20: =+H20*J20 -> 0 | M20: =+SUM(K20:L20) -> 0
B21: 1X1B3 | D21: 1 | E21: 1.4 | F21: 0.2 | G21: 0.4 | H21: =G21*(F21+0.3)*(E21+0.3)*D21*1.3 -> 0.442 | K21: =H21*I21 -> 0 | L21: =+H21*J21 -> 0 | M21: =+SUM(K21:L21) -> 0
B22: 1XB4 | D22: 1 | E22: =9.4*2 -> 18.8 | F22: 0.2 | G22: 0.9 | H22: =G22*(F22+0.3)*(E22+0.3)*D22*1.3 -> 11.1735 | K22: =H22*I22 -> 0 | L22: =+H22*J22 -> 0 | M22: =+SUM(K22:L22) -> 0
B23: 1XB5 | D23: 1 | E23: =3.4*2 -> 6.8 | F23: 0.2 | G23: 0.4 | H23: =G23*(F23+0.3)*(E23+0.3)*D23*1.3 -> 1.846 | K23: =H23*I23 -> 0 | L23: =+H23*J23 -> 0 | M23: =+SUM(K23:L23) -> 0
B24: 1XB6 | D24: 1 | E24: 1.8 | F24: 0.2 | G24: 0.4 | H24: =G24*(F24+0.3)*(E24+0.3)*D24*1.3 -> 0.546 | K24: =H24*I24 -> 0 | L24: =+H24*J24 -> 0 | M24: =+SUM(K24:L24) -> 0
B25: 1XB7 | D25: 1 | E25: 14 | F25: 0.2 | G25: 0.6 | H25: =G25*(F25+0.3)*(E25+0.3)*D25*1.3 -> 5.577 | K25: =H25*I25 -> 0 | L25: =+H25*J25 -> 0 | M25: =+SUM(K25:L25) -> 0
B26: 1XB8 | D26: 1 | E26: 3 | F26: 0.1 | G26: 0.4 | H26: =G26*(F26+0.3)*(E26+0.3)*D26*1.3 -> 0.6864 | K26: =H26*I26 -> 0 | L26: =+H26*J26 -> 0 | M26: =+SUM(K26:L26) -> 0
B27: 1XB9 | D27: 1 | E27: 3 | F27: 0.1 | G27: 0.4 | H27: =G27*(F27+0.3)*(E27+0.3)*D27*1.3 -> 0.6864 | K27: =H27*I27 -> 0 | L27: =+H27*J27 -> 0 | M27: =+SUM(K27:L27) -> 0
B28: 1XB10 | D28: 1 | E28: 3 | F28: 0.1 | G28: 0.4 | H28: =G28*(F28+0.3)*(E28+0.3)*D28*1.3 -> 0.6864 | K28: =H28*I28 -> 0 | L28: =+H28*J28 -> 0 | M28: =+SUM(K28:L28) -> 0
B29: 1XB11 | D29: 1 | E29: 1.4 | F29: 0.2 | G29: 0.4 | H29: =G29*(F29+0.3)*(E29+0.3)*D29*1.3 -> 0.442 | K29: =H29*I29 -> 0 | L29: =+H29*J29 -> 0 | M29: =+SUM(K29:L29) -> 0
B30: 1XB12 | D30: 1 | E30: 9.4 | F30: 0.2 | G30: 0.6 | H30: =G30*(F30+0.3)*(E30+0.3)*D30*1.3 -> 3.783 | K30: =H30*I30 -> 0 | L30: =+H30*J30 -> 0 | M30: =+SUM(K30:L30) -> 0
B31: 1YB1,B2,B3 | D31: 1 | E31: =80*2+6 -> 166 | F31: 0.2 | G31: 0.9 | H31: =G31*(F31+0.3)*(E31+0.3)*D31*1.3 -> 97.2855 | K31: =H31*I31 -> 0 | L31: =+H31*J31 -> 0 | M31: =+SUM(K31:L31) -> 0
B32: 1YB4 | D32: 1 | E32: 5 | F32: 0.1 | G32: 0.6 | H32: =G32*(F32+0.3)*(E32+0.3)*D32*1.3 -> 1.6536 | K32: =H32*I32 -> 0 | L32: =+H32*J32 -> 0 | M32: =+SUM(K32:L32) -> 0
B33: 1YB5 | D33: 1 | E33: 20 | F33: 0.2 | G33: 0.9 | H33: =G33*(F33+0.3)*(E33+0.3)*D33*1.3 -> 11.8755 | K33: =H33*I33 -> 0 | L33: =+H33*J33 -> 0 | M33: =+SUM(K33:L33) -> 0
B34: 1YB6 | D34: 1 | E34: 5 | F34: 0.2 | G34: 0.6 | H34: =G34*(F34+0.3)*(E34+0.3)*D34*1.3 -> 2.067 | K34: =H34*I34 -> 0 | L34: =+H34*J34 -> 0 | M34: =+SUM(K34:L34) -> 0
B35: 1YB7 | D35: 1 | E35: 14 | F35: 0.2 | G35: 0.9 | H35: =G35*(F35+0.3)*(E35+0.3)*D35*1.3 -> 8.3655 | K35: =H35*I35 -> 0 | L35: =+H35*J35 -> 0 | M35: =+SUM(K35:L35) -> 0
B36: 1YB8,8A | D36: 2 | E36: 12 | F36: 0.2 | G36: 0.9 | H36: =G36*(F36+0.3)*(E36+0.3)*D36*1.3 -> 14.391 | K36: =H36*I36 -> 0 | L36: =+H36*J36 -> 0 | M36: =+SUM(K36:L36) -> 0
B37: 1B19,10 | D37: 3 | E37: 5 | F37: 0.2 | G37: 0.6 | H37: =G37*(F37+0.3)*(E37+0.3)*D37*1.3 -> 6.201 | K37: =H37*I37 -> 0 | L37: =+H37*J37 -> 0 | M37: =+SUM(K37:L37) -> 0
B38: 1B12,1314 | D38: 4 | E38: 4 | F38: 0.2 | G38: 0.6 | H38: =G38*(F38+0.3)*(E38+0.3)*D38*1.3 -> 6.708 | K38: =H38*I38 -> 0 | L38: =+H38*J38 -> 0 | M38: =+SUM(K38:L38) -> 0
K39: =H39*I39 -> 0 | L39: =+H39*J39 -> 0 | M39: =+SUM(K39:L39) -> 0
A40: 2 | B40: Chỉnh sửa, ban gạt và đầm nền đất trước khi thi công công tác bê tông lót (hố móng, đà kiềng, hố pit) | C40: m2 | H40: =SUM(H41:H69) -> 5971.57 | K40: =H40*I40 -> 0 | L40: =+H40*J40 -> 0 | M40: =+SUM(K40:L40) -> 0
B41: F1 | D41: 3 | E41: 2.1 | F41: 0.9 | H41: =D41*(F41+0.3)*(E41+0.3) -> 8.64 | K41: =H41*I41 -> 0 | L41: =+H41*J41 -> 0 | M41: =+SUM(K41:L41) -> 0
B42: F1A | D42: 1 | E42: 2.1 | F42: 1.15 | H42: =D42*(F42+0.3)*(E42+0.3) -> 3.48 | K42: =H42*I42 -> 0 | L42: =+H42*J42 -> 0 | M42: =+SUM(K42:L42) -> 0
...

Sheet VP
A1: =Cọc!A1 -> BẢNG KHỐI LƯỢNG MỜI THẦU
A2: =Cọc!A2 -> Dự án: Nhà Máy Sản Xuất Công Ty ….
A3: =Cọc!A3 -> Gói thầu: Thi Công Xây Dựng & Hệ Thống Cơ Điện, PCCC
A4: HẠNG MỤC: NHÀ VĂN PHÒNG (Giai đoạn 1)
A6: STT | B6: NỘI DUNG CÔNG VIỆC | C6: ĐVT | D6: K. lượng | E6: Đơn giá (VNĐ) | G6: Thành tiền (VNĐ) | I6: Tổng cộng (VNĐ) | J6: Ghi chú
E7: Vật tư | F7: NC&NTC | G7: Vật tư | H7: =F7 -> NC&NTC
B9: Công tác đất và xử lí đầu cọc | G9: =+SUBTOTAL(9,G10:G18) -> 0 | H9: =+SUBTOTAL(9,H10:H18) -> 0 | I9: =+SUBTOTAL(9,I10:I18) -> 0
A10: =MAX($A$6:$A8)+1 -> 1 | B10: Đào đất | C10: m³ | D10: 157.6718 | G10: =D10*E10 -> 0 | H10: =+D10*F10 -> 0 | I10: =+SUM(G10:H10) -> 0
A11: =MAX($A$6:$A10)+1 -> 2 | B11: Chỉnh sửa, ban gạt và đầm nền đất trước khi thi công công tác bê tông lót (hố móng, đà kiềng, hố pit) | C11: m2 | D11: 126.91 | G11: =D11*E11 -> 0 | H11: =+D11*F11 -> 0 | I11: =+SUM(G11:H11) -> 0
A12: =MAX($A$6:$A11)+1 -> 3 | B12: Cắt đầu cọc D400 | C12: đầu cọc | D12: 34 | G12: =D12*E12 -> 0 | H12: =+D12*F12 -> 0 | I12: =+SUM(G12:H12) -> 0
A13: =MAX($A$6:$A12)+1 -> 4 | B13: Vận chuyển đầu cọc | C13: đầu cọc | D13: 34 | G13: =D13*E13 -> 0 | H13: =+D13*F13 -> 0 | I13: =+SUM(G13:H13) -> 0
A14: =MAX($A$6:$A13)+1 -> 5 | B14: Gia công lắp đặt kết nối đầu cọc D400 (bao gồm thép tấm, cốt thép và bê tông đầu cọc) | C14: đầu cọc | D14: 34 | G14: =D14*E14 -> 0 | H14: =+D14*F14 -> 0 | I14: =+SUM(G14:H14) -> 0
A15: =MAX($A$6:$A14)+1 -> 6 | B15: Đắp đất hố móng | C15: m³ | D15: 37.296365 | G15: =D15*E15 -> 0 | H15: =+D15*F15 -> 0 | I15: =+SUM(G15:H15) -> 0
A16: =MAX($A$6:$A15)+1 -> 7 | B16: Cân bằng đào đắp và vận chuyển đất dư | C16: m³ | D16: 120.37544 | G16: =D16*E16 -> 0 | H16: =+D16*F16 -> 0 | I16: =+SUM(G16:H16) -> 0
A17: =MAX($A$6:$A16)+1 -> 8 | B17: Công tác chống mối | C17: m² | D17: 400 | G17: =D17*E17 -> 0 | H17: =+D17*F17 -> 0 | I17: =+SUM(G17:H17) -> 0
B19: Công tác ván khuôn | G19: =+SUBTOTAL(9,G20:G31) -> 0 | H19: =+SUBTOTAL(9,H20:H31) -> 0 | I19: =+SUBTOTAL(9,I20:I31) -> 0
A20: =MAX($A$6:$A19)+1 -> 9 | B20: Công tác ván khuôn lót móng, đà kiềng | C20: m² | D20: 24.3625 | G20: =D20*E20 -> 0 | H20: =+D20*F20 -> 0 | I20: =+SUM(G20:H20) -> 0
A21: =MAX($A$6:$A20)+1 -> 10 | B21: Công tác ván khuôn móng | C21: m² | D21: 90 | G21: =D21*E21 -> 0 | H21: =+D21*F21 -> 0 | I21: =+SUM(G21:H21) -> 0
A22: =MAX($A$6:$A21)+1 -> 11 | B22: Công tác ván khuôn cổ cột | C22: m² | D22: 22.65 | G22: =D22*E22 -> 0 | H22: =+D22*F22 -> 0 | I22: =+SUM(G22:H22) -> 0
A23: =MAX($A$6:$A22)+1 -> 12 | B23: Công tác ván khuôn đà kiềng | C23: m² | D23: 212.76 | G23: =D23*E23 -> 0 | H23: =+D23*F23 -> 0 | I23: =+SUM(G23:H23) -> 0
A24: =MAX($A$6:$A23)+1 -> 13 | B24: Công tác ván khuôn cột (đến cote +8.1m) | C24: m² | D24: 244.62 | G24: =D24*E24 -> 0 | H24: =+D24*F24 -> 0 | I24: =+SUM(G24:H24) -> 0
A25: =MAX($A$6:$A24)+1 -> 14 | B25: Công tác ván khuôn dầm sàn cote +4.1m | C25: m² | D25: 669.338 | G25: =D25*E25 -> 0 | H25: =+D25*F25 -> 0 | I25: =+SUM(G25:H25) -> 0
A26: =MAX($A$6:$A25)+1 -> 15 | B26: Công tác ván khuôn dầm sàn cote +8.1m | C26: m² | D26: 669.338 | G26: =D26*E26 -> 0 | H26: =+D26*F26 -> 0 | I26: =+SUM(G26:H26) -> 0
A27: =MAX($A$6:$A26)+1 -> 16 | B27: Công tác ván khuôn hố pit thang máy | C27: m² | D27: 28.48 | G27: =D27*E27 -> 0 | H27: =+D27*F27 -> 0 | I27: =+SUM(G27:H27) -> 0
A28: =MAX($A$6:$A27)+1 -> 17 | B28: Công tác ván khuôn cầu thang | C28: m² | D28: 24.46 | G28: =D28*E28 -> 0 | H28: =+D28*F28 -> 0 | I28: =+SUM(G28:H28) -> 0
A29: =MAX($A$6:$A28)+1 -> 18 | B29: Công tác ván khuôn lanh tô, bổ trụ, giằng tường, ô văng | C29: m² | D29: 149.77 | G29: =D29*E29 -> 0 | H29: =+D29*F29 -> 0 | I29: =+SUM(G29:H29) -> 0
A30: =MAX($A$6:$A29)+1 -> 19 | B30: Công tác ván khuôn cho sê nô, máng nước rửa tay | C30: m² | D30: 7.2 | G30: =D30*E30 -> 0 | H30: =+D30*F30 -> 0 | I30: =+SUM(G30:H30) -> 0
B32: Công tác cốt thép | G32: =+SUBTOTAL(9,G33:G43) -> 0 | H32: =+SUBTOTAL(9,H33:H43) -> 0 | I32: =+SUBTOTAL(9,I33:I43) -> 0
A33: =MAX($A$6:$A32)+1 -> 20 | B33: Công tác cốt thép móng | C33: tấn | D33: 3.7999084 | G33: =D33*E33 -> 0 | H33: =+D33*F33 -> 0 | I33: =+SUM(G33:H33) -> 0
A34: =MAX($A$6:$A33)+1 -> 21 | B34: Công tác cốt thép cột (đến cote +8.1m) | C34: tấn | D34: 7.3198182 | G34: =D34*E34 -> 0 | H34: =+D34*F34 -> 0 | I34: =+SUM(G34:H34) -> 0
A35: =MAX($A$6:$A34)+1 -> 22 | B35: Thép chờ cột cho giai đoạn 2 (đoạn trên cote 8.1m) | C35: tấn | D35: 2.0995962 | G35: =D35*E35 -> 0 | H35: =+D35*F35 -> 0 | I35: =+SUM(G35:H35) -> 0
A36: =MAX($A$6:$A35)+1 -> 23 | B36: Công tác cốt thép đà kiềng | C36: tấn | D36: 2.7152102 | G36: =D36*E36 -> 0 | H36: =+D36*F36 -> 0 | I36: =+SUM(G36:H36) -> 0
A37: =MAX($A$6:$A36)+1 -> 24 | B37: Công tác cốt thép dầm sàn cote +4.1 | C37: tấn | D37: 11.389151 | G37: =D37*E37 -> 0 | H37: =+D37*F37 -> 0 | I37: =+SUM(G37:H37) -> 0
A38: =MAX($A$6:$A37)+1 -> 25 | B38: Công tác cốt thép dầm sàn cote +8.1 | C38: tấn | D38: 11.389151 | G38: =D38*E38 -> 0 | H38: =+D38*F38 -> 0 | I38: =+SUM(G38:H38) -> 0
A39: =MAX($A$6:$A38)+1 -> 26 | B39: Công tác cốt thép lanh tô, bổ trụ, giằng tường, ô văng | C39: tấn | D39: 1.2652 | G39: =D39*E39 -> 0 | H39: =+D39*F39 -> 0 | I39: =+SUM(G39:H39) -> 0
A40: =MAX($A$6:$A39)+1 -> 27 | B40: Công tác cốt thép nền (01 lớp lưới thép hàn Þ6a200) | C40: tấn | D40: 0.902097 | G40: =D40*E40 -> 0 | H40: =+D40*F40 -> 0 | I40: =+SUM(G40:H40) -> 0
A41: =MAX($A$6:$A40)+1 -> 28 | B41: Cốt thép cầu thang, hố pit | C41: tấn | D41: 2.05595 | G41: =D41*E41 -> 0 | H41: =+D41*F41 -> 0 | I41: =+SUM(G41:H41) -> 0
A42: =MAX($A$6:$A41)+1 -> 29 | B42: Cốt thép sê nô, máng nước rửa tay | C42: tấn | D42: 0.0711 | G42: =D42*E42 -> 0 | H42: =+D42*F42 -> 0 | I42: =+SUM(G42:H42) -> 0
B44: Công tác bê tông | G44: =+SUBTOTAL(9,G45:G55) -> 0 | H44: =+SUBTOTAL(9,H45:H55) -> 0 | I44: =+SUBTOTAL(9,I45:I55) -> 0
A45: =MAX($A$6:$A44)+1 -> 30 | B45: Công tác BT lót đá 1x2, mác M100 | C45: m³ | D45: 9.54375 | G45: =D45*E45 -> 0 | H45: =+D45*F45 -> 0 | I45: =+SUM(G45:H45) -> 0 | K45: TGN báo
...

Sheet Lò Hơi
A1: =Cọc!A1 -> BẢNG KHỐI LƯỢNG MỜI THẦU
A2: =Cọc!A2 -> Dự án: Nhà Máy Sản Xuất Công Ty ….
A3: =Cọc!A3 -> Gói thầu: Thi Công Xây Dựng & Hệ Thống Cơ Điện, PCCC | P3: =46*22 -> 1012
A4: HẠNG MỤC: NHÀ LÒ HƠI-KHO HÓA CHẤT - NHÀ RÁC
A6: STT | B6: NỘI DUNG CÔNG VIỆC | C6: ĐVT | E6: Kích thước | I6: K. lượng | J6: Đơn giá (VNĐ) | L6: Thành tiền (VNĐ) | N6: Tổng cộng (VNĐ) | O6: Ghi chú
D7: SL | E7: Dài | F7: Rộng | G7: Cao | H7: Hệ số | J7: Vật tư | K7: NC&MTC | L7: Vật tư | M7: =K7 -> NC&MTC
B9: Công tác đất và xử lí đầu cọc | L9: =+SUBTOTAL(9,L10:L38) -> 0 | M9: =+SUBTOTAL(9,M10:M38) -> 0 | N9: =+SUBTOTAL(9,N10:N38) -> 0
A10: =MAX($A$6:$A8)+1 -> 1 | B10: Đào đất | C10: m³ | I10: =SUBTOTAL(9,I11:I24) -> 92.593436 | L10: =I10*J10 -> 0 | M10: =+I10*K10 -> 0 | N10: =+SUM(L10:M10) -> 0
B11: PC1-30 | D11: 11 | E11: 0.8 | F11: 0.8 | G11: =0.9+0.05+0.7 -> 1.65 | H11: 1.3 | I11: =PRODUCT(D11:H11) -> 15.1008
B12: PC2-30 | D12: 11 | E12: 0.8 | F12: 1.7 | G12: =0.9+0.05+0.7 -> 1.65 | H12: 1.3 | I12: =PRODUCT(D12:H12) -> 32.0892
B13: PC3-30 | D13: 3 | E13: 1.36 | F13: =1.17/2 -> 0.585 | G13: =0.9+0.05+0.7 -> 1.65 | H13: 1.3 | I13: =PRODUCT(D13:H13) -> 5.119686
B14: DG (200*500) | E14: =+(8.8*3+7.3*3)*2-7.3+11.8 -> 101.1 | F14: 0.2 | G14: =0.5+0.05 -> 0.55 | H14: 1.3 | I14: =PRODUCT(D14:H14) -> 14.4573
B15: CG (200*200) | E15: =(6.2*2+7.4*2+4.1*2+5.8*2) -> 47 | F15: 0.2 | G15: =0.2+0.05 -> 0.25 | H15: 1.3 | I15: =PRODUCT(D15:H15) -> 3.055
B16: DM4 (400*600) | E16: =7.25*2 -> 14.5 | F16: 0.4 | G16: =0.6+0.05 -> 0.65 | H16: 1.3 | I16: =PRODUCT(D16:H16) -> 4.901
B17: DM5 (400*600) | E17: 7.25 | F17: 0.4 | G17: =0.6+0.05 -> 0.65 | H17: 1.3 | I17: =PRODUCT(D17:H17) -> 2.4505
B18: D0.A (200*600) | E18: =6*3 -> 18 | F18: 0.2 | G18: =0.6+0.05 -> 0.65 | H18: 1.3 | I18: =PRODUCT(D18:H18) -> 3.042
B19: D0.B (200*500) | E19: =6*5 -> 30 | F19: 0.2 | G19: =0.5+0.05 -> 0.55 | H19: 1.3 | I19: =PRODUCT(D19:H19) -> 4.29
B20: D0.5 (200*600) | E20: =7.3*2 -> 14.6 | F20: 0.2 | G20: =0.6+0.05 -> 0.65 | H20: 1.3 | I20: =PRODUCT(D20:H20) -> 2.4674
B21: D0.5A (200*600) | E21: =7.3*2 -> 14.6 | F21: 0.2 | G21: =0.6+0.05 -> 0.65 | H21: 1.3 | I21: =PRODUCT(D21:H21) -> 2.4674
B22: D0.5B (200*600) | I22: =PRODUCT(D22:H22) -> 0
B23: D0.6 (200*500) | E23: =7.4*2+7.25 -> 22.05 | F23: 0.2 | G23: =0.5+0.05 -> 0.55 | H23: 1.3 | I23: =PRODUCT(D23:H23) -> 3.15315
A25: =MAX($A$6:$A10)+1 -> 2 | B25: Chỉnh sửa, ban gạt và đầm nền đất trước khi thi công công tác bê tông lót (hố móng, đà kiềng, hố pit) | C25: m2 | I25: =SUBTOTAL(9,I26:I29) -> 1147.77 | L25: =I25*J25 -> 0 | M25: =+I25*K25 -> 0 | N25: =+SUM(L25:M25) -> 0
B26: Nền nhà phụ | E26: =8.8*3+11.8+6*2 -> 50.2 | F26: =7.3+7.4+7.25 -> 21.95 | I26: =PRODUCT(D26:H26) -> 1101.89
B27: Nền nhà rác | E27: 6.2 | F27: 7.4 | I27: =PRODUCT(D27:H27) -> 45.88
A30: =MAX($A$6:$A25)+1 -> 3 | B30: Cắt đầu cọc D300 | C30: đầu cọc | I30: 32 | L30: =I30*J30 -> 0 | M30: =+I30*K30 -> 0 | N30: =+SUM(L30:M30) -> 0
A31: =MAX($A$6:$A30)+1 -> 4 | B31: Cắt đầu cọc D400 | C31: đầu cọc | I31: 10 | L31: =I31*J31 -> 0 | M31: =+I31*K31 -> 0 | N31: =+SUM(L31:M31) -> 0
A32: =MAX($A$6:$A31)+1 -> 5 | B32: Vận chuyển đầu cọc | C32: đầu cọc | I32: =I30+I31 -> 42 | L32: =I32*J32 -> 0 | M32: =+I32*K32 -> 0 | N32: =+SUM(L32:M32) -> 0
A33: =MAX($A$6:$A32)+1 -> 6 | B33: Gia công lắp đặt kết nối đầu cọc D300 (bao gồm thép tấm, cốt thép và bê tông đầu cọc) | C33: đầu cọc | I33: =I30 -> 32 | L33: =I33*J33 -> 0 | M33: =+I33*K33 -> 0 | N33: =+SUM(L33:M33) -> 0
A34: =MAX($A$6:$A33)+1 -> 7 | B34: Gia công lắp đặt kết nối đầu cọc D400 (bao gồm thép tấm, cốt thép và bê tông đầu cọc) | C34: đầu cọc | I34: =I31 -> 10 | L34: =I34*J34 -> 0 | M34: =+I34*K34 -> 0 | N34: =+SUM(L34:M34) -> 0
A35: =MAX($A$6:$A34)+1 -> 8 | B35: Đắp đất hố móng | C35: m³ | I35: =I10-I213-I218-I229 -> 43.226306 | L35: =I35*J35 -> 0 | M35: =+I35*K35 -> 0 | N35: =+SUM(L35:M35) -> 0
A36: =MAX($A$6:$A35)+1 -> 9 | B36: Cân bằng đào đắp và vận chuyển đất dư | C36: m³ | I36: =I10-I35 -> 49.36713 | L36: =I36*J36 -> 0 | M36: =+I36*K36 -> 0 | N36: =+SUM(L36:M36) -> 0
A37: =MAX($A$6:$A36)+1 -> 10 | B37: Công tác chống mối | C37: m² | I37: =I25 -> 1147.77 | L37: =I37*J37 -> 0 | M37: =+I37*K37 -> 0 | N37: =+SUM(L37:M37) -> 0
B39: Công tác ván khuôn | L39: =+SUBTOTAL(9,L40:L91) -> 0 | M39: =+SUBTOTAL(9,M40:M91) -> 0 | N39: =+SUBTOTAL(9,N40:N91) -> 0
A40: =MAX($A$6:$A39)+1 -> 11 | B40: Công tác ván khuôn lót móng, đà kiềng | C40: m² | I40: =SUBTOTAL(9,I41:I44) -> 6.092 | L40: =I40*J40 -> 0 | M40: =+I40*K40 -> 0 | N40: =+SUM(L40:M40) -> 0
B41: =B11 -> PC1-30 | D41: =D11 -> 11 | E41: =E11+0.2 -> 1 | F41: =F11+0.2 -> 1 | G41: 0.05 | I41: =D41*(E41+F41)*2*G41 -> 2.2
B42: =B12 -> PC2-30 | D42: =D12 -> 11 | E42: =E12+0.2 -> 1 | F42: =F12+0.2 -> 1.9 | G42: 0.05 | I42: =D42*(E42+F42)*2*G42 -> 3.19
B43: =B13 -> PC3-30 | D43: =D13 -> 3 | E43: =E13+0.2 -> 1.56 | F43: =F13+0.2 -> 0.785 | G43: 0.05 | I43: =D43*E43*3*G43 -> 0.702
A45: =MAX($A$6:$A40)+1 -> 12 | B45: Công tác ván khuôn móng | C45: m² | I45: =SUBTOTAL(9,I46:I49) -> 81.496 | L45: =I45*J45 -> 0 | M45: =+I45*K45 -> 0 | N45: =+SUM(L45:M45) -> 0
B46: =B41 -> PC1-30 | D46: =D11 -> 11 | E46: =E11 -> 0.8 | F46: =F11 -> 0.8 | G46: 0.8 | I46: =D46*(E46+F46)*2*G46 -> 28.16
B47: =B42 -> PC2-30 | D47: =D12 -> 11 | E47: =E12 -> 0.8 | F47: =F12 -> 1.7 | G47: 0.8 | I47: =D47*(E47+F47)*2*G47 -> 44
...

Sheet Trạm điện
A1: =+VP!A1 -> BẢNG KHỐI LƯỢNG MỜI THẦU
A2: =+VP!A2 -> Dự án: Nhà Máy Sản Xuất Công Ty ….
A3: =+VP!A3 -> Gói thầu: Thi Công Xây Dựng & Hệ Thống Cơ Điện, PCCC
A4: HẠNG MỤC: TRẠM ĐIỆN
A6: STT | B6: NỘI DUNG CÔNG VIỆC | C6: ĐVT | E6: Kích thước | I6: K. lượng | J6: Đơn giá (VNĐ) | L6: Thành tiền (VNĐ) | N6: Tổng cộng (VNĐ) | O6: Ghi chú
D7: SL | E7: Dài | F7: Rộng | G7: Cao | H7: Hệ số | J7: Vật tư | K7: NC | L7: Vật tư | M7: NC
B9: Công tác đất đá | L9: =+SUBTOTAL(9,L10:L20) -> 0 | M9: =+SUBTOTAL(9,M10:M20) -> 0 | N9: =+SUBTOTAL(9,N10:N20) -> 0
A10: =MAX($A$6:$A8)+1 -> 1 | B10: Đào đất | C10: m3 | I10: =SUBTOTAL(9,I11:I12) -> 38.61 | L10: =+I10*J10 -> 0 | M10: =+I10*K10 -> 0 | N10: =+SUM(L10:M10) -> 0
B11: M1 | D11: 8 | E11: =1.4+0.1 -> 1.5 | F11: =1.4+0.1 -> 1.5 | G11: 1.65 | H11: 1.3 | I11: =PRODUCT(D11:H11) -> 38.61
A13: =MAX($A$6:$A10)+1 -> 2 | B13: Chỉnh sửa, ban gạt và đầm nền đất trước khi thi công công tác bê tông lót (đáy hố móng, đà kiềng) | C13: m2 | E13: 16.3 | F13: 4.25 | I13: =PRODUCT(D13:H13) -> 69.275 | L13: =+I13*J13 -> 0 | M13: =+I13*K13 -> 0 | N13: =+SUM(L13:M13) -> 0
A14: =MAX($A$6:$A13)+1 -> 3 | B14: Lấp đất hố móng | C14: =+C10 -> m3 | I14: =I10-I68-I65 -> 33.006 | L14: =+I14*J14 -> 0 | M14: =+I14*K14 -> 0 | N14: =+SUM(L14:M14) -> 0
A15: =MAX($A$6:$A14)+1 -> 4 | B15: Cân bằng đào đắp và vận chuyển đất dư | C15: =+C14 -> m3 | I15: =I10-I14 -> 5.604 | L15: =+I15*J15 -> 0 | M15: =+I15*K15 -> 0 | N15: =+SUM(L15:M15) -> 0
A16: =MAX($A$6:$A15)+1 -> 5 | B16: Đầm nền đất, K=0.95 | C16: m2 | I16: =I13 -> 69.275 | L16: =+I16*J16 -> 0 | M16: =+I16*K16 -> 0 | N16: =+SUM(L16:M16) -> 0
A17: =MAX($A$6:$A16)+1 -> 6 | B17: Nền đá 04 dày 200, đầm chặt K=0.95 | C17: m3 | E17: =E13 -> 16.3 | F17: =F13 -> 4.25 | G17: 0.2 | I17: =PRODUCT(D17:H17) -> 13.855 | L17: =+I17*J17 -> 0 | M17: =+I17*K17 -> 0 | N17: =+SUM(L17:M17) -> 0
A18: =MAX($A$6:$A17)+1 -> 7 | B18: Lớp màng PE dày 0.15mm, nền trệt | C18: m2 | I18: =I16 -> 69.275 | L18: =+I18*J18 -> 0 | M18: =+I18*K18 -> 0 | N18: =+SUM(L18:M18) -> 0
A19: =MAX($A$6:$A18)+1 -> 8 | B19: Công tác chống mối | C19: m2 | I19: =I18 -> 69.275 | L19: =+I19*J19 -> 0 | M19: =+I19*K19 -> 0 | N19: =+SUM(L19:M19) -> 0
B21: Công tác ván khuôn | L21: =+SUBTOTAL(9,L22:L39) -> 0 | M21: =+SUBTOTAL(9,M22:M39) -> 0 | N21: =+SUBTOTAL(9,N22:N39) -> 0
A22: =MAX($A$6:$A21)+1 -> 9 | B22: Ván khuôn bê tông lót | C22: m2 | I22: =SUBTOTAL(9,I23:I24) -> 2.4 | L22: =+I22*J22 -> 0 | M22: =+I22*K22 -> 0 | N22: =+SUM(L22:M22) -> 0
B23: M1 | D23: =D11 -> 8 | E23: =E11 -> 1.5 | F23: =F11 -> 1.5 | G23: 0.05 | I23: =D23*(E23+F23)*2*G23 -> 2.4
A25: =MAX($A$6:$A22)+1 -> 10 | B25: Ván khuôn móng | C25: m2 | I25: =SUBTOTAL(9,I26:I27) -> 13.44 | L25: =+I25*J25 -> 0 | M25: =+I25*K25 -> 0 | N25: =+SUM(L25:M25) -> 0
B26: M1 | D26: =D23 -> 8 | E26: =E23-0.1 -> 1.4 | F26: =F23-0.1 -> 1.4 | G26: 0.3 | I26: =D26*(E26+F26)*2*G26 -> 13.44
A28: =MAX($A$6:$A25)+1 -> 11 | B28: Ván khuôn đà kiềng | C28: m2 | I28: =SUBTOTAL(9,I29:I29) -> 39.68 | L28: =+I28*J28 -> 0 | M28: =+I28*K28 -> 0 | N28: =+SUM(L28:M28) -> 0
B29: DK. 200*400 | E29: =16.3*2+4.25*4 -> 49.6 | F29: 0.2 | G29: 0.4 | I29: =E29*G29*2 -> 39.68
A31: =MAX($A$6:$A28)+1 -> 12 | B31: Ván khuôn nền | C31: m2 | I31: =SUBTOTAL(9,I32:I33) -> 6.165 | L31: =+I31*J31 -> 0 | M31: =+I31*K31 -> 0 | N31: =+SUM(L31:M31) -> 0
B32: nền 150 | D32: 1 | E32: 16.3 | F32: 4.25 | G32: 0.15 | I32: =D32*(E32+F32)*2*G32 -> 6.165
A34: =MAX($A$6:$A31)+1 -> 13 | B34: Ván khuôn cột, dầm giằng | C34: m2 | I34: =SUBTOTAL(9,I35:I37) -> 53.075 | L34: =+I34*J34 -> 0 | M34: =+I34*K34 -> 0 | N34: =+SUM(L34:M34) -> 0
B35: C. 200*200 | D35: 8 | E35: 0.2 | F35: 0.2 | G35: 4.6 | I35: =D35*(E35+F35)*2*G35 -> 29.44
B36: Seno 550*450 | E36: 16.3 | F36: 0.55 | G36: 0.45 | I36: =E36*(F36+G36*2) -> 23.635
A38: =MAX($A$6:$A34)+1 -> 14 | B38: Ván khuôn lanh tô, bổ trụ, giằng tường | C38: m2 | I38: 14.4 | L38: =+I38*J38 -> 0 | M38: =+I38*K38 -> 0 | N38: =+SUM(L38:M38) -> 0
B40: Công tác cốt thép | L40: =+SUBTOTAL(9,L41:L63) -> 0 | M40: =+SUBTOTAL(9,M41:M63) -> 0 | N40: =+SUBTOTAL(9,N41:N63) -> 0
A41: =MAX($A$6:$A40)+1 -> 15 | B41: GCLD cốt thép móng | C41: tấn | I41: =SUBTOTAL(9,I42:I44)/1000 -> 0.10259185 | L41: =+I41*J41 -> 0 | M41: =+I41*K41 -> 0 | N41: =+SUM(L41:M41) -> 0
B42: M1 | D42: =D26 -> 8 | E42: =E26 -> 1.4 | F42: =F26 -> 1.4 | G42: =G26 -> 0.3 | H42: 0 | I42: =PRODUCT(D42:H42) -> 0
B43: Phi10a200 | D43: =D42 -> 8 | E43: =E42-0.1 -> 1.3 | G43: 16 | H43: =PI()*(10)^2/4*7.85/1000 -> 0.61653756 | I43: =PRODUCT(D43:H43) -> 102.59185
A45: =MAX($A$6:$A41)+1 -> 16 | B45: GCLD cốt thép đà kiềng | C45: tấn | I45: =SUBTOTAL(9,I46:I48)/1000 -> 0.40130183 | L45: =+I45*J45 -> 0 | M45: =+I45*K45 -> 0 | N45: =+SUM(L45:M45) -> 0
B46: DK. 200*400 | E46: =E29 -> 49.6 | F46: =F29 -> 0.2 | G46: =G29 -> 0.4 | H46: 0 | I46: =PRODUCT(D46:H46) -> 0
B47: 4phi16 | E47: =E46 -> 49.6 | F47: 4 | H47: =PI()*(16)^2/4*7.85/1000 -> 1.5783361 | I47: =PRODUCT(D47:H47) -> 313.14189
B48: phi6a150 | E48: =ROUNDUP(E47/0.15,0) -> 331 | F48: =(F46+G46-0.05)*2+0.1 -> 1.2 | H48: =PI()*(6)^2/4*7.85/1000 -> 0.22195352 | I48: =PRODUCT(D48:H48) -> 88.159939
A49: =MAX($A$6:$A45)+1 -> 17 | B49: Cốt thép cột, dầm giằng | C49: =+C41 -> tấn | I49: =SUBTOTAL(9,I50:I57)/1000 -> 0.28910679 | L49: =+I49*J49 -> 0 | M49: =+I49*K49 -> 0 | N49: =+SUM(L49:M49) -> 0
B50: =B35 -> C. 200*200 | D50: =D35 -> 8 | E50: =E35 -> 0.2 | F50: =F35 -> 0.2 | G50: =G35 -> 4.6 | H50: 0 | I50: =PRODUCT(D50:H50) -> 0
B51: 4phi16 | D51: =D50 -> 8 | E51: 4 | F51: =0.25+1.075 -> 1.325 | H51: =PI()*(16)^2/4*7.85/1000 -> 1.5783361 | I51: =PRODUCT(D51:H51) -> 66.921453
...

Sheet Nhà Bảo Vệ
A1: =Cọc!A1 -> BẢNG KHỐI LƯỢNG MỜI THẦU
A2: =Cọc!A2 -> Dự án: Nhà Máy Sản Xuất Công Ty ….
A3: =Cọc!A3 -> Gói thầu: Thi Công Xây Dựng & Hệ Thống Cơ Điện, PCCC
A4: HẠNG MỤC: NHÀ BẢO VỆ
A6: STT | B6: NỘI DUNG CÔNG VIỆC | C6: ĐVT | D6: K. lượng | E6: Đơn giá (VNĐ) | G6: Thành tiền (VNĐ) | I6: Tổng cộng (VNĐ) | J6: Ghi chú
E7: Vật tư | F7: NC&NTC | G7: Vật tư | H7: =F7 -> NC&NTC
B9: Nhà bảo vệ | C9: m2 | D9: =(2.3+3.9)*4 -> 24.8 | G9: =E9*D9 -> 0 | H9: =F9*D9 -> 0 | I9: =H9+G9 -> 0
B10: Công tác đất | G10: =+SUBTOTAL(9,G11:G16) -> 0 | H10: =+SUBTOTAL(9,H11:H16) -> 0 | I10: =+SUBTOTAL(9,I11:I16) -> 0
A11: =MAX($A$6:$A8)+1 -> 1 | B11: Đào đất | C11: m³ | G11: =D11*E11 -> 0 | H11: =+D11*F11 -> 0 | I11: =+SUM(G11:H11) -> 0
A12: =MAX($A$6:$A11)+1 -> 2 | B12: Chỉnh sửa, ban gạt và đầm nền đất trước khi thi công công tác bê tông lót (hố móng, đà kiềng, hố pit) | C12: m2 | G12: =D12*E12 -> 0 | H12: =+D12*F12 -> 0 | I12: =+SUM(G12:H12) -> 0
A13: =MAX($A$6:$A12)+1 -> 3 | B13: Đắp đất hố móng | C13: m³ | G13: =D13*E13 -> 0 | H13: =+D13*F13 -> 0 | I13: =+SUM(G13:H13) -> 0
A14: =MAX($A$6:$A13)+1 -> 4 | B14: Cân bằng đào đắp và vận chuyển đất dư | C14: m³ | G14: =D14*E14 -> 0 | H14: =+D14*F14 -> 0 | I14: =+SUM(G14:H14) -> 0
A15: =MAX($A$6:$A14)+1 -> 5 | B15: Công tác chống mối | C15: m² | G15: =D15*E15 -> 0 | H15: =+D15*F15 -> 0 | I15: =+SUM(G15:H15) -> 0
B17: Công tác ván khuôn | G17: =+SUBTOTAL(9,G18:G25) -> 0 | H17: =+SUBTOTAL(9,H18:H25) -> 0 | I17: =+SUBTOTAL(9,I18:I25) -> 0
A18: =MAX($A$6:$A17)+1 -> 6 | B18: Công tác ván khuôn lót móng, đà kiềng | C18: m² | G18: =D18*E18 -> 0 | H18: =+D18*F18 -> 0 | I18: =+SUM(G18:H18) -> 0
A19: =MAX($A$6:$A18)+1 -> 7 | B19: Công tác ván khuôn móng | C19: m² | G19: =D19*E19 -> 0 | H19: =+D19*F19 -> 0 | I19: =+SUM(G19:H19) -> 0
A20: =MAX($A$6:$A19)+1 -> 8 | B20: Công tác ván khuôn cổ cột | C20: m² | G20: =D20*E20 -> 0 | H20: =+D20*F20 -> 0 | I20: =+SUM(G20:H20) -> 0
A21: =MAX($A$6:$A20)+1 -> 9 | B21: Công tác ván khuôn đà kiềng | C21: m² | G21: =D21*E21 -> 0 | H21: =+D21*F21 -> 0 | I21: =+SUM(G21:H21) -> 0
A22: =MAX($A$6:$A21)+1 -> 10 | B22: Công tác ván khuôn cột | C22: m² | G22: =D22*E22 -> 0 | H22: =+D22*F22 -> 0 | I22: =+SUM(G22:H22) -> 0
A23: =MAX($A$6:$A22)+1 -> 11 | B23: Công tác ván khuôn dầm sàn, sê nô | C23: m² | G23: =D23*E23 -> 0 | H23: =+D23*F23 -> 0 | I23: =+SUM(G23:H23) -> 0
A24: =MAX($A$6:$A23)+1 -> 12 | B24: Công tác ván khuôn lanh tô, bổ trụ, giằng tường, ô văng | C24: m² | G24: =D24*E24 -> 0 | H24: =+D24*F24 -> 0 | I24: =+SUM(G24:H24) -> 0
B26: Công tác cốt thép | G26: =+SUBTOTAL(9,G27:G33) -> 0 | H26: =+SUBTOTAL(9,H27:H33) -> 0 | I26: =+SUBTOTAL(9,I27:I33) -> 0
A27: =MAX($A$6:$A26)+1 -> 13 | B27: Công tác cốt thép móng | C27: tấn | G27: =D27*E27 -> 0 | H27: =+D27*F27 -> 0 | I27: =+SUM(G27:H27) -> 0
A28: =MAX($A$6:$A27)+1 -> 14 | B28: Công tác cốt thép cột | C28: tấn | G28: =D28*E28 -> 0 | H28: =+D28*F28 -> 0 | I28: =+SUM(G28:H28) -> 0
A29: =MAX($A$6:$A28)+1 -> 15 | B29: Công tác cốt thép đà kiềng | C29: tấn | G29: =D29*E29 -> 0 | H29: =+D29*F29 -> 0 | I29: =+SUM(G29:H29) -> 0
A30: =MAX($A$6:$A29)+1 -> 16 | B30: Công tác cốt thép dầm sàn, sê nô | C30: tấn | G30: =D30*E30 -> 0 | H30: =+D30*F30 -> 0 | I30: =+SUM(G30:H30) -> 0
A31: =MAX($A$6:$A30)+1 -> 17 | B31: Công tác cốt thép lanh tô, bổ trụ, giằng tường, ô văng | C31: tấn | G31: =D31*E31 -> 0 | H31: =+D31*F31 -> 0 | I31: =+SUM(G31:H31) -> 0
A32: =MAX($A$6:$A31)+1 -> 18 | B32: Công tác cốt thép nền (01 lớp lưới thép hàn Þ6a200) | C32: tấn | G32: =D32*E32 -> 0 | H32: =+D32*F32 -> 0 | I32: =+SUM(G32:H32) -> 0
B34: Công tác bê tông | G34: =+SUBTOTAL(9,G35:G41) -> 0 | H34: =+SUBTOTAL(9,H35:H41) -> 0 | I34: =+SUBTOTAL(9,I35:I41) -> 0
A35: =MAX($A$6:$A34)+1 -> 19 | B35: Công tác BT lót đá 1x2, mác M100 | C35: m³ | G35: =D35*E35 -> 0 | H35: =+D35*F35 -> 0 | I35: =+SUM(G35:H35) -> 0
A36: =MAX($A$6:$A35)+1 -> 20 | B36: Công tác BT móng, đá 1x2, mác M300 | C36: m³ | G36: =D36*E36 -> 0 | H36: =+D36*F36 -> 0 | I36: =+SUM(G36:H36) -> 0
A37: =MAX($A$6:$A36)+1 -> 21 | B37: Công tác BT cột, đá 1x2. mác M300 | C37: m³ | G37: =D37*E37 -> 0 | H37: =+D37*F37 -> 0 | I37: =+SUM(G37:H37) -> 0
A38: =MAX($A$6:$A37)+1 -> 22 | B38: Công tác BT đà kiềng, đá 1x2, mác M300 | C38: m³ | G38: =D38*E38 -> 0 | H38: =+D38*F38 -> 0 | I38: =+SUM(G38:H38) -> 0
A39: =MAX($A$6:$A38)+1 -> 23 | B39: Công tác BT dầm sàn, sê nô. Đá 1x2 mác 300 | C39: m³ | G39: =D39*E39 -> 0 | H39: =+D39*F39 -> 0 | I39: =+SUM(G39:H39) -> 0
A40: =MAX($A$6:$A39)+1 -> 24 | B40: Công tác BT lanh tô, bổ trụ, giằng tường, ô văng, bệ đỡ, đá 1x2, mác M200 | C40: m³ | G40: =D40*E40 -> 0 | H40: =+D40*F40 -> 0 | I40: =+SUM(G40:H40) -> 0
A41: =MAX($A$6:$A40)+1 -> 25 | B41: Công tác BT nền, đá 1x2, mác M300 | C41: m³ | G41: =D41*E41 -> 0 | H41: =+D41*F41 -> 0 | I41: =+SUM(G41:H41) -> 0
B43: Công tác xây tô | G43: =+SUBTOTAL(9,G44:G50) -> 0 | H43: =+SUBTOTAL(9,H44:H50) -> 0 | I43: =+SUBTOTAL(9,I44:I50) -> 0
A44: =MAX($A$6:$A43)+1 -> 26 | B44: Công tác xây tường gạch ống câu gạch thẻ, dày 200mm, vữa xm mác 75 | C44: m² | G44: =D44*E44 -> 0 | H44: =+D44*F44 -> 0 | I44: =+SUM(G44:H44) -> 0
A45: =MAX($A$6:$A44)+1 -> 27 | B45: Công tác xây tường gạch ống, dày 100mm, vữa xm mác 75 | C45: m² | G45: =D45*E45 -> 0 | H45: =+D45*F45 -> 0 | I45: =+SUM(G45:H45) -> 0
A46: =MAX($A$6:$A45)+1 -> 28 | B46: Công tác tô tường ngoài nhà, vữa xm mác 75, dày 15mm | C46: m² | G46: =D46*E46 -> 0 | H46: =+D46*F46 -> 0 | I46: =+SUM(G46:H46) -> 0
...

Sheet Cổng+HR
A1: =Cọc!A1 -> BẢNG KHỐI LƯỢNG MỜI THẦU
A2: =Cọc!A2 -> Dự án: Nhà Máy Sản Xuất Công Ty ….
A3: =Cọc!A3 -> Gói thầu: Thi Công Xây Dựng & Hệ Thống Cơ Điện, PCCC
A4: HẠNG MỤC: CỔNG + HÀNG RÀO
A6: STT | B6: NỘI DUNG CÔNG VIỆC | C6: ĐVT | E6: Kích thước | I6: K. lượng | J6: Đơn giá (VNĐ) | L6: Thành tiền (VNĐ) | N6: Tổng cộng (VNĐ) | O6: Ghi chú
D7: SL | E7: Dài | F7: Rộng | G7: Cao | H7: Hệ số | J7: Vật tư | K7: NC&NTC | L7: Vật tư | M7: =K7 -> NC&NTC
A8: A | B8: CỔNG + BẢNG TÊN
B9: Công tác đất | L9: =+SUBTOTAL(9,L10:L19) -> 0 | M9: =+SUBTOTAL(9,M10:M19) -> 0 | N9: =+SUBTOTAL(9,N10:N19) -> 0
A10: =MAX($A$6:$A7)+1 -> 1 | B10: Đào đất | C10: m³ | I10: =SUBTOTAL(9,I11:I13) -> 20.7636 | L10: =I10*J10 -> 0 | M10: =+I10*K10 -> 0 | N10: =+SUM(L10:M10) -> 0
B11: Cổng chính | D11: 4 | E11: =1+0.1 -> 1.1 | F11: =1+0.1 -> 1.1 | G11: 1.65 | H11: 1.3 | I11: =PRODUCT(D11:H11) -> 10.3818
B12: Cổng phụ | D12: 4 | E12: =1+0.1 -> 1.1 | F12: =1+0.1 -> 1.1 | G12: 1.65 | H12: 1.3 | I12: =PRODUCT(D12:H12) -> 10.3818
A14: =MAX($A$6:$A10)+1 -> 2 | B14: Chỉnh sửa, ban gạt và đầm nền đất trước khi thi công công tác bê tông lót (hố móng, đà kiềng) | C14: m2 | I14: =SUBTOTAL(9,I15:I16) -> 135.52 | L14: =I14*J14 -> 0 | M14: =+I14*K14 -> 0 | N14: =+SUM(L14:M14) -> 0
B15: M1, M2 (1000*1000) | D15: =ROUNDUP((132.8*2+82.87*2)/4,0)+4 -> 112 | E15: =1+0.1 -> 1.1 | F15: =1+0.1 -> 1.1 | I15: =PRODUCT(D15:H15) -> 135.52
A17: =MAX($A$6:$A14)+1 -> 3 | B17: Đắp đất hố móng | C17: m³ | I17: =I10-I64-I60 -> 17.8796 | L17: =I17*J17 -> 0 | M17: =+I17*K17 -> 0 | N17: =+SUM(L17:M17) -> 0
A18: =MAX($A$6:$A17)+1 -> 4 | B18: Cân bằng đào đắp và vận chuyển đất dư | C18: m³ | I18: =I10-I17 -> 2.884 | L18: =I18*J18 -> 0 | M18: =+I18*K18 -> 0 | N18: =+SUM(L18:M18) -> 0
B20: Công tác ván khuôn | L20: =+SUBTOTAL(9,L21:L37) -> 0 | M20: =+SUBTOTAL(9,M21:M37) -> 0 | N20: =+SUBTOTAL(9,N21:N37) -> 0
A21: =MAX($A$6:$A20)+1 -> 5 | B21: Công tác ván khuôn lót móng, đà kiềng | C21: m² | I21: =SUBTOTAL(9,I22:I24) -> 1.122 | L21: =I21*J21 -> 0 | M21: =+I21*K21 -> 0 | N21: =+SUM(L21:M21) -> 0
B22: =B11 -> Cổng chính | D22: =D11 -> 4 | E22: =E11 -> 1.1 | F22: =F11 -> 1.1 | G22: 0.05 | I22: =D22*(E22+F22)*2*G22 -> 0.88
B23: Cổng phụ | D23: =D12 -> 4 | E23: =E12 -> 1.1 | F23: =F12 -> 1.1 | G23: 0.05 | I23: =PRODUCT(D23:H23) -> 0.242
A25: =MAX($A$6:$A21)+1 -> 6 | B25: Công tác ván khuôn móng | C25: m² | I25: =SUBTOTAL(9,I26:I28) -> 9.6 | L25: =I25*J25 -> 0 | M25: =+I25*K25 -> 0 | N25: =+SUM(L25:M25) -> 0
B26: =B22 -> Cổng chính | D26: =D22 -> 4 | E26: =E22-0.1 -> 1 | F26: =F22-0.1 -> 1 | G26: 0.3 | I26: =D26*(E26+F26)*2*G26 -> 4.8
B27: =B23 -> Cổng phụ | D27: =D23 -> 4 | E27: =E23-0.1 -> 1 | F27: =F23-0.1 -> 1 | G27: 0.3 | I27: =D27*(E27+F27)*2*G27 -> 4.8
A29: =MAX($A$6:$A25)+1 -> 7 | B29: Công tác ván khuôn đà kiềng | C29: m² | I29: =SUBTOTAL(9,I30:I31) -> 46.8 | L29: =I29*J29 -> 0 | M29: =+I29*K29 -> 0 | N29: =+SUM(L29:M29) -> 0
B30: DK(200*400) | E30: =31.59+26.91 -> 58.5 | F30: 0.2 | G30: 0.4 | I30: =E30*G30*2 -> 46.8
A32: =MAX($A$6:$A29)+1 -> 8 | B32: Công tác ván khuôn cột | C32: m² | I32: =SUBTOTAL(9,I33:I34) -> 28.8 | L32: =I32*J32 -> 0 | M32: =+I32*K32 -> 0 | N32: =+SUM(L32:M32) -> 0
B33: C1. 200*200 | D33: =6+6 -> 12 | E33: 0.2 | F33: 0.2 | G33: 3 | I33: =D33*(E33+F33)*2*G33 -> 28.8
A35: =MAX($A$6:$A32)+1 -> 9 | B35: Công tác ván khuôn dầm sàn | C35: m² | I35: =SUBTOTAL(9,I36:I37) -> 46.8 | L35: =I35*J35 -> 0 | M35: =+I35*K35 -> 0 | N35: =+SUM(L35:M35) -> 0
B36: GT(100*200) | E36: =E30*2 -> 117 | F36: 0.1 | G36: 0.2 | I36: =E36*G36*2 -> 46.8
B39: Công tác cốt thép | L39: =+SUBTOTAL(9,L40:L55) -> 0 | M39: =+SUBTOTAL(9,M40:M55) -> 0 | N39: =+SUBTOTAL(9,N40:N55) -> 0
A40: =MAX($A$6:$A39)+1 -> 10 | B40: Công tác cốt thép móng | C40: tấn | I40: =SUBTOTAL(9,I41:I42)/1000 -> 0.071912941 | L40: =I40*J40 -> 0 | M40: =+I40*K40 -> 0 | N40: =+SUM(L40:M40) -> 0
B41: =B26 -> Cổng chính | D41: =D26 -> 4 | E41: =E26 -> 1 | F41: =F26 -> 1 | G41: =G26 -> 0.3 | H41: 0 | I41: =PRODUCT(D41:H41) -> 0
B42: phi 18 | D42: =D41 -> 4 | E42: 0.9 | G42: 10 | H42: =PI()*(18)^2/4*7.85/1000 -> 1.9975817 | I42: =PRODUCT(D42:H42) -> 71.912941
B43: =B27 -> Cổng phụ | D43: =D27 -> 4 | E43: =E27 -> 1 | F43: =F27 -> 1 | G43: =G27 -> 0.3 | H43: 0 | I43: =PRODUCT(D43:H43) -> 0
B44: phi 18 | D44: =D43 -> 4 | E44: 0.9 | G44: 10 | H44: =PI()*(18)^2/4*7.85/1000 -> 1.9975817 | I44: =PRODUCT(D44:H44) -> 71.912941
A45: =MAX($A$6:$A40)+1 -> 11 | B45: Công tác cốt thép cột | C45: tấn | I45: =SUBTOTAL(9,I46:I49)/1000 -> 0.095870234 | L45: =I45*J45 -> 0 | M45: =+I45*K45 -> 0 | N45: =+SUM(L45:M45) -> 0
B46: =B33 -> C1. 200*200 | D46: =D33 -> 12 | E46: =E33 -> 0.2 | F46: =F33 -> 0.2 | G46: =G33 -> 3 | H46: 0 | I46: =PRODUCT(D46:H46) -> 0
B47: 4phi14 | D47: =D46 -> 12 | E47: =2.2+1.5+0.25 -> 3.95 | F47: =0.25+1.075 -> 1.325 | H47: =PI()*(14)^2/4*7.85/1000 -> 1.2084136 | I47: =PRODUCT(D47:H47) -> 75.894417
B48: đai6a200 | D48: =D47 -> 12 | E48: =ROUNDUP(G46/0.2,0) -> 15 | F48: =(E46-0.1+F46-0.1)*2+0.1 -> 0.5 | H48: =PI()*(6)^2/4*7.85/1000 -> 0.22195352 | I48: =PRODUCT(D48:H48) -> 19.975817
A50: =MAX($A$6:$A45)+1 -> 12 | B50: Công tác cốt thép đà kiềng | C50: tấn | I50: =SUBTOTAL(9,I51:I53)/1000 -> 0.56553757 | L50: =I50*J50 -> 0 | M50: =+I50*K50 -> 0 | N50: =+SUM(L50:M50) -> 0
B51: =B30 -> DK(200*400) | E51: =E30 -> 58.5 | F51: =F30 -> 0.2 | G51: =G30 -> 0.4 | H51: 0
...

Sheet Bể PCCC
A1: =Cọc!A1 -> BẢNG KHỐI LƯỢNG MỜI THẦU
A2: =Cọc!A2 -> Dự án: Nhà Máy Sản Xuất Công Ty ….
A3: =Cọc!A3 -> Gói thầu: Thi Công Xây Dựng & Hệ Thống Cơ Điện, PCCC
A4: HẠNG MỤC: BỂ PCCC
A6: STT | B6: NỘI DUNG CÔNG VIỆC | C6: ĐVT | E6: Kích thước | I6: K. lượng | J6: Đơn giá (VNĐ) | L6: Thành tiền (VNĐ) | N6: Tổng cộng (VNĐ) | O6: Ghi chú
D7: SL | E7: Dài | F7: Rộng | G7: Cao | H7: Hệ số | J7: Vật tư | K7: NC&NTC | L7: Vật tư | M7: =K7 -> NC&NTC
B9: Công tác đất | L9: =+SUBTOTAL(9,L10:L16) -> 0 | M9: =+SUBTOTAL(9,M10:M16) -> 0 | N9: =+SUBTOTAL(9,N10:N16) -> 0
A10: =MAX($A$6:$A8)+1 -> 1 | B10: Đào đất | C10: m³ | I10: =SUBTOTAL(9,I11:I12) -> 1341.78 | L10: =I10*J10 -> 0 | M10: =+I10*K10 -> 0 | N10: =+SUM(L10:M10) -> 0
B11: Đáy | E11: =31.5+0.6 -> 32.1 | F11: =7+0.6 -> 7.6 | G11: =5.4+0.1 -> 5.5 | I11: =PRODUCT(D11:H11) -> 1341.78
A13: =MAX($A$6:$A10)+1 -> 2 | B13: Chỉnh sửa, ban gạt và đầm nền đất trước khi thi công công tác bê tông lót | C13: m2 | I13: =E11*F11 -> 243.96 | L13: =I13*J13 -> 0 | M13: =+I13*K13 -> 0 | N13: =+SUM(L13:M13) -> 0
A14: =MAX($A$6:$A13)+1 -> 3 | B14: Đắp đất hố móng | C14: m³ | I14: =I10*0.3 -> 402.534 | L14: =I14*J14 -> 0 | M14: =+I14*K14 -> 0 | N14: =+SUM(L14:M14) -> 0
A15: =MAX($A$6:$A14)+1 -> 4 | B15: Cân bằng đào đắp và vận chuyển đất dư | C15: m³ | I15: =I10-I14 -> 939.246 | L15: =I15*J15 -> 0 | M15: =+I15*K15 -> 0 | N15: =+SUM(L15:M15) -> 0
B17: Công tác ván khuôn | L17: =+SUBTOTAL(9,L18:L32) -> 0 | M17: =+SUBTOTAL(9,M18:M32) -> 0 | N17: =+SUBTOTAL(9,N18:N32) -> 0
A18: =MAX($A$6:$A17)+1 -> 5 | B18: Công tác ván khuôn lót | C18: m² | I18: =SUBTOTAL(9,I19:I20) -> 7.94 | L18: =I18*J18 -> 0 | M18: =+I18*K18 -> 0 | N18: =+SUM(L18:M18) -> 0
B19: =B11 -> Đáy | E19: =E11 -> 32.1 | F19: =F11 -> 7.6 | G19: 0.1 | I19: =(E19+F19)*2*G19 -> 7.94
A21: =MAX($A$6:$A18)+1 -> 6 | B21: Công tác ván khuôn đáy bể nước | C21: m² | I21: =SUBTOTAL(9,I22:I23) -> 38.5 | L21: =I21*J21 -> 0 | M21: =+I21*K21 -> 0 | N21: =+SUM(L21:M21) -> 0
B22: =B11 -> Đáy | E22: =E19-0.6 -> 31.5 | F22: =F19-0.6 -> 7 | G22: 0.5 | I22: =(E22+F22)*2*G22 -> 38.5
A24: =MAX($A$6:$A21)+1 -> 7 | B24: Công tác ván khuôn vách | C24: m² | I24: =SUBTOTAL(9,I25:I27) -> 823.2 | L24: =I24*J24 -> 0 | M24: =+I24*K24 -> 0 | N24: =+SUM(L24:M24) -> 0
B25: vách trục A-B | D25: 2 | E25: =E22 -> 31.5 | F25: 0.25 | G25: 4.9 | I25: =D25*E25*G25*2 -> 617.4
B26: vách trục 1,2,7 | D26: 3 | E26: =F22 -> 7 | F26: 0.25 | G26: 4.9 | I26: =D26*E26*G26*2 -> 205.8
A28: =MAX($A$6:$A24)+1 -> 8 | B28: Công tác ván khuôn cột | C28: m² | I28: =SUBTOTAL(9,I29:I30) -> 54.88 | L28: =I28*J28 -> 0 | M28: =+I28*K28 -> 0 | N28: =+SUM(L28:M28) -> 0
B29: C1 (300*400) | D29: 8 | E29: 0.3 | F29: 0.4 | G29: =5.3-0.4 -> 4.9 | I29: =D29*(E29+F29)*2*G29 -> 54.88
A31: =MAX($A$6:$A28)+1 -> 9 | B31: Công tác ván khuôn dầm sàn nắp bể nước | C31: m² | I31: =SUBTOTAL(9,I32:I36) -> 325.5 | L31: =I31*J31 -> 0 | M31: =+I31*K31 -> 0 | N31: =+SUM(L31:M31) -> 0
B32: Nắp | E32: =E22 -> 31.5 | F32: =F22 -> 7 | G32: 0.2 | I32: =(E32+F32)*2*G32 -> 15.4
E33: =E32 -> 31.5 | F33: =F32 -> 7 | I33: =E33*F33 -> 220.5
B34: D. 300*400 | E34: =F32*5 -> 35 | F34: 0.3 | G34: 0.4 | I34: =E34*G34*2 -> 28
B35: D. 250*400 | E35: =(E32+F32)*2 -> 77 | F35: 0.25 | G35: 0.4 | I35: =E35*G35*2 -> 61.6
B38: Công tác cốt thép | L38: =+SUBTOTAL(9,L39:L58) -> 0 | M38: =+SUBTOTAL(9,M39:M58) -> 0 | N38: =+SUBTOTAL(9,N39:N58) -> 0
A39: =MAX($A$6:$A38)+1 -> 10 | B39: Công tác cốt thép đáy bể nước | C39: tấn | I39: =SUBTOTAL(9,I40:I45)/1000*1.2 -> 7.6394182 | L39: =I39*J39 -> 0 | M39: =+I39*K39 -> 0 | N39: =+SUM(L39:M39) -> 0
B40: =B22 -> Đáy | E40: =E22 -> 31.5 | F40: =F22 -> 7 | G40: =G22 -> 0.5 | H40: 0 | I40: =PRODUCT(D40:H40) -> 0
B41: phi 14a200 | D41: 2 | E41: =E40 -> 31.5 | F41: 39 | H41: =PI()*(14)^2/4*7.85/1000 -> 1.2084136 | I41: =PRODUCT(D41:H41) -> 2969.0723
B42: phi 14a200 | D42: 2 | E42: =F40 -> 7 | F42: 161 | H42: =PI()*(14)^2/4*7.85/1000 -> 1.2084136 | I42: =PRODUCT(D42:H42) -> 2723.7643
B43: Chân chó phi 10 | E43: =0.25+0.3+0.25-0.1 -> 0.7 | F43: =ROUNDUP(E40*F40/1,0) -> 221 | H43: =PI()*(10)^2/4*7.85/1000 -> 0.61653756 | I43: =PRODUCT(D43:H43) -> 95.37836
B44: tăng cường phi12 | E44: 1.5 | F44: =38*3+160*2 -> 434 | H44: =PI()*(12)^2/4*7.85/1000 -> 0.88781408 | I44: =PRODUCT(D44:H44) -> 577.96697
A46: =MAX($A$6:$A39)+1 -> 11 | B46: Công tác cốt thép cột | C46: tấn | I46: =SUBTOTAL(9,I47:I48)/1000*1.2 -> 0.64384277 | L46: =I46*J46 -> 0 | M46: =+I46*K46 -> 0 | N46: =+SUM(L46:M46) -> 0
B47: 10phi18 | D47: =D29 -> 8 | E47: 10 | F47: =5.3+0.25 -> 5.55 | H47: =PI()*(14)^2/4*7.85/1000 -> 1.2084136 | I47: =PRODUCT(D47:H47) -> 536.53564
A49: =MAX($A$6:$A46)+1 -> 12 | B49: Công tác cốt thép vách | C49: tấn | I49: =SUBTOTAL(9,I50:I56)/1000*1.2 -> 13.999526 | L49: =I49*J49 -> 0 | M49: =+I49*K49 -> 0 | N49: =+SUM(L49:M49) -> 0
B50: =B25 -> vách trục A-B | D50: =D25 -> 2 | E50: =E25 -> 31.5 | F50: =F25 -> 0.25 | G50: =G25 -> 4.9 | H50: 0 | I50: =PRODUCT(D50:H50) -> 0
B51: phi16a200 | D51: =D50 -> 2 | E51: =5.5+0.25 -> 5.75 | F51: =158*2 -> 316 | H51: =PI()*(16)^2/4*7.85/1000 -> 1.5783361 | I51: =PRODUCT(D51:H51) -> 5735.6736
B52: phi12a200 | D52: =D51 -> 2 | E52: =31.5+0.4 -> 31.9 | F52: =26*2 -> 52 | H52: =PI()*(12)^2/4*7.85/1000 -> 0.88781408 | I52: =PRODUCT(D52:H52) -> 2945.412
...

Sheet Bể XLNT
A1: =[70]Cọc!A1 -> BẢNG KHỐI LƯỢNG MỜI THẦU
A2: ='TỔNG HỢP'!A2 -> Dự án: Nhà Máy Sản Xuất Công Ty ….
A3: =[70]Cọc!A3 -> Gói thầu: Thi Công Xây Dựng & Hệ Thống Cơ Điện, PCCC
A4: HẠNG MỤC: BỂ XỬ LÍ NƯỚC THẢI
A6: STT | B6: NỘI DUNG CÔNG VIỆC | C6: ĐVT | E6: Kích thước | I6: K. lượng | J6: Đơn giá (VNĐ) | L6: Thành tiền (VNĐ) | N6: Tổng cộng (VNĐ) | O6: Ghi chú
D7: SL | E7: Dài | F7: Rộng | G7: Cao | H7: Hệ số | J7: Vật tư | K7: NC&NTC | L7: Vật tư | M7: =K7 -> NC&NTC
B9: Công tác đất | L9: =+SUBTOTAL(9,L10:L17) -> #REF! | M9: =+SUBTOTAL(9,M10:M17) -> #REF! | N9: =+SUBTOTAL(9,N10:N17) -> #REF!
A10: =MAX($A$6:$A8)+1 -> 1 | B10: Đào đất | C10: m³ | I10: =SUBTOTAL(9,I11:I13) -> 3811.5792 | J10: =#REF!*#REF! -> #REF! | K10: =#REF!*#REF! -> #REF! | L10: =I10*J10 -> #REF! | M10: =+I10*K10 -> #REF! | N10: =+SUM(L10:M10) -> #REF!
B11: Đáy Bể XLNT | E11: =52.5+0.2 -> 52.7 | F11: =8.6+0.2 -> 8.8 | G11: 5.4 | H11: 1.3 | I11: =PRODUCT(D11:H11) -> 3255.5952
B12: Đáy Bể XLNT dệt | E12: =8.8+0.2 -> 9 | F12: =8.6+0.2 -> 8.8 | G12: 5.4 | H12: 1.3 | I12: =PRODUCT(D12:H12) -> 555.984
A14: =MAX($A$6:$A10)+1 -> 2 | B14: Chỉnh sửa, ban gạt và đầm nền đất trước khi thi công công tác bê tông lót | C14: m2 | I14: =E11*F11 -> 463.76 | J14: =#REF!*#REF! -> #REF! | K14: =#REF!*#REF! -> #REF! | L14: =I14*J14 -> #REF! | M14: =+I14*K14 -> #REF! | N14: =+SUM(L14:M14) -> #REF!
A15: =MAX($A$6:$A14)+1 -> 3 | B15: Đắp đất hố móng | C15: m³ | I15: =I10*0.3 -> 1143.4738 | J15: =#REF!*#REF! -> #REF! | K15: =#REF!*#REF! -> #REF! | L15: =I15*J15 -> #REF! | M15: =+I15*K15 -> #REF! | N15: =+SUM(L15:M15) -> #REF!
A16: =MAX($A$6:$A15)+1 -> 4 | B16: Cân bằng đào đắp và vận chuyển đất dư | C16: m³ | I16: =I10-I15 -> 2668.1054 | J16: =#REF!*#REF! -> #REF! | K16: =#REF!*#REF! -> #REF! | L16: =I16*J16 -> #REF! | M16: =+I16*K16 -> #REF! | N16: =+SUM(L16:M16) -> #REF!
B18: Công tác ván khuôn | L18: =+SUBTOTAL(9,L19:L43) -> #REF! | M18: =+SUBTOTAL(9,M19:M43) -> #REF! | N18: =+SUBTOTAL(9,N19:N43) -> #REF!
A19: =MAX($A$6:$A18)+1 -> 5 | B19: Công tác ván khuôn lót | C19: m² | I19: =SUBTOTAL(9,I20:I22) -> 15.86 | J19: =#REF!*#REF! -> #REF! | K19: =#REF!*#REF! -> #REF! | L19: =I19*J19 -> #REF! | M19: =+I19*K19 -> #REF! | N19: =+SUM(L19:M19) -> #REF!
B20: =B11 -> Đáy Bể XLNT | E20: =E11 -> 52.7 | F20: =F11 -> 8.8 | G20: 0.1 | I20: =(E20+F20)*2*G20 -> 12.3
B21: =B12 -> Đáy Bể XLNT dệt | E21: =E12 -> 9 | F21: =F12 -> 8.8 | G21: 0.1 | I21: =(E21+F21)*2*G21 -> 3.56
A23: =MAX($A$6:$A19)+1 -> 6 | B23: Công tác ván khuôn đáy bể nước | C23: m² | I23: =SUBTOTAL(9,I24:I26)*1.3 -> 61.23 | J23: =#REF!*#REF! -> #REF! | K23: =#REF!*#REF! -> #REF! | L23: =I23*J23 -> #REF! | M23: =+I23*K23 -> #REF! | N23: =+SUM(L23:M23) -> #REF!
B24: =B20 -> Đáy Bể XLNT | E24: =E20-0.2 -> 52.5 | F24: =F20-0.2 -> 8.6 | G24: 0.3 | I24: =(E24+F24)*2*G24 -> 36.66
B25: =B21 -> Đáy Bể XLNT dệt | E25: =E21-0.2 -> 8.8 | F25: =F21-0.2 -> 8.6 | G25: 0.3 | I25: =(E25+F25)*2*G25 -> 10.44
A27: =MAX($A$6:$A23)+1 -> 7 | B27: Công tác ván khuôn vách | C27: m² | I27: =SUBTOTAL(9,I28:I34) -> 2322.24 | J27: =#REF!*#REF! -> #REF! | K27: =#REF!*#REF! -> #REF! | L27: =I27*J27 -> #REF! | M27: =+I27*K27 -> #REF! | N27: =+SUM(L27:M27) -> #REF!
B28: Bể XLNT
B29: vách bao | D29: 1 | E29: =(E20+F20)*2 -> 123 | F29: 0.3 | G29: 4.8 | I29: =D29*E29*G29*2 -> 1180.8
B30: vách ngăn | D30: 8 | E30: =F20 -> 8.8 | F30: 0.2 | G30: 4.8 | I30: =D30*E30*G30*2 -> 675.84
B31: Bể XLNT dệt
B32: vách bao | D32: 1 | E32: =(E21+F21)*2 -> 35.6 | F32: 0.3 | G32: 4.8 | I32: =D32*E32*G32*2 -> 341.76
B33: vách ngăn | D33: 1 | E33: =8.6+4.3 -> 12.9 | F33: 0.2 | G33: 4.8 | I33: =D33*E33*G33*2 -> 123.84
A35: =MAX($A$6:$A27)+1 -> 8 | B35: Công tác ván khuôn cột | C35: m² | I35: 0 | J35: =#REF!*#REF! -> #REF! | K35: =#REF!*#REF! -> #REF! | L35: =I35*J35 -> #REF! | M35: =+I35*K35 -> #REF! | N35: =+SUM(L35:M35) -> #REF!
A36: =MAX($A$6:$A35)+1 -> 9 | B36: Công tác ván khuôn dầm sàn nắp bể nước | C36: m² | I36: =SUBTOTAL(9,I38:I43) -> 558.58 | J36: =#REF!*#REF! -> #REF! | K36: =#REF!*#REF! -> #REF! | L36: =I36*J36 -> #REF! | M36: =+I36*K36 -> #REF! | N36: =+SUM(L36:M36) -> #REF!
B37: Bể XLNT
B38: Nắp | E38: =E24 -> 52.5 | F38: =F24 -> 8.6 | G38: 0.2 | I38: =(E38+F38)*2*G38 -> 24.44
E39: =E38 -> 52.5 | F39: =F38 -> 8.6 | I39: =E39*F39 -> 451.5
B40: Bể XLNT dệt
B41: Nắp | E41: =E25 -> 8.8 | F41: =F25 -> 8.6 | G41: 0.2 | I41: =(E41+F41)*2*G41 -> 6.96
E42: =E41 -> 8.8 | F42: =F41 -> 8.6 | I42: =E42*F42 -> 75.68
B44: Công tác cốt thép | L44: =+SUBTOTAL(9,L45:L81) -> #REF! | M44: =+SUBTOTAL(9,M45:M81) -> #REF! | N44: =+SUBTOTAL(9,N45:N81) -> #REF!
A45: =MAX($A$6:$A44)+1 -> 10 | B45: Công tác cốt thép đáy bể nước | C45: tấn | I45: =SUBTOTAL(9,I46:I54)/1000*1.2 -> 15.343842 | J45: =#REF!*#REF! -> #REF! | K45: =#REF!*#REF! -> #REF! | L45: =I45*J45 -> #REF! | M45: =+I45*K45 -> #REF! | N45: =+SUM(L45:M45) -> #REF!
B46: =B20 -> Đáy Bể XLNT | E46: =E24 -> 52.5 | F46: =F24 -> 8.6 | G46: =G24 -> 0.3 | H46: 0 | I46: =PRODUCT(D46:H46) -> 0
B47: phi 12a150 | D47: 2 | E47: =E46 -> 52.5 | F47: =ROUNDUP(F46/0.15,0) -> 58 | H47: =PI()*(12)^2/4*7.85/1000 -> 0.88781408 | I47: =PRODUCT(D47:H47) -> 5406.7878
B48: phi 12a150 | D48: 2 | E48: =F46 -> 8.6 | F48: =ROUNDUP(E46/0.15,0) -> 350 | H48: =PI()*(12)^2/4*7.85/1000 -> 0.88781408 | I48: =PRODUCT(D48:H48) -> 5344.6408
...

Sheet Hạ tầng
A1: =Cọc!A1 -> BẢNG KHỐI LƯỢNG MỜI THẦU
A2: =Cọc!A2 -> Dự án: Nhà Máy Sản Xuất Công Ty ….
A3: =Cọc!A3 -> Gói thầu: Thi Công Xây Dựng & Hệ Thống Cơ Điện, PCCC
A4: HẠNG MỤC: HẠ TẦNG GIAO THÔNG VÀ CẢNH QUAN
A6: STT | B6: NỘI DUNG CÔNG VIỆC | C6: ĐVT | E6: Kích thước | I6: K. lượng | J6: Đơn giá (VNĐ) | L6: Thành tiền (VNĐ) | N6: Tổng cộng (VNĐ) | O6: Ghi chú
D7: SL | E7: Dài | F7: Rộng | G7: Cao | H7: Hệ số | J7: Vật tư | K7: NC&NTC | L7: Vật tư | M7: =K7 -> NC&NTC
A9: A | B9: Đưởng Tải Nặng | L9: =+SUBTOTAL(9,L10:L17) -> #REF! | M9: =+SUBTOTAL(9,M10:M17) -> #REF! | N9: =+SUBTOTAL(9,N10:N17) -> #REF!
A10: =MAX($A$6:$A8)+1 -> 1 | B10: Lu nền đất K=0.95 | C10: m2 | E10: =612.87+455.68 -> 1068.55 | I10: =PRODUCT(D10:H10) -> 1068.55 | J10: =#REF!*#REF! -> #REF! | K10: =#REF!*#REF! -> #REF! | L10: =I10*J10 -> #REF! | M10: =+I10*K10 -> #REF! | N10: =+SUM(L10:M10) -> #REF!
A11: =MAX($A$6:$A10)+1 -> 2 | B11: Cấp phối đá 4x6 dày 12cm, K=0.95 | C11: m3 | E11: =E10 -> 1068.55 | G11: 0.12 | I11: =PRODUCT(D11:H11) -> 128.226 | J11: =#REF!*#REF! -> #REF! | K11: =#REF!*#REF! -> #REF! | L11: =I11*J11 -> #REF! | M11: =+I11*K11 -> #REF! | N11: =+SUM(L11:M11) -> #REF!
A12: =MAX($A$6:$A11)+1 -> 3 | B12: Cấp phối đá 0x4 dày 30cm, K=0.95 | C12: m3 | E12: =E11 -> 1068.55 | G12: 0.3 | I12: =PRODUCT(D12:H12) -> 320.565 | J12: =#REF!*#REF! -> #REF! | K12: =#REF!*#REF! -> #REF! | L12: =I12*J12 -> #REF! | M12: =+I12*K12 -> #REF! | N12: =+SUM(L12:M12) -> #REF!
A13: =MAX($A$6:$A12)+1 -> 4 | B13: Tưới nhựa bám dính tiêu chuẩn 1kg/m2 | C13: m2 | I13: =I10 -> 1068.55 | J13: =#REF!*#REF! -> #REF! | K13: =#REF!*#REF! -> #REF! | L13: =I13*J13 -> #REF! | M13: =+I13*K13 -> #REF! | N13: =+SUM(L13:M13) -> #REF!
A14: =MAX($A$6:$A13)+1 -> 5 | B14: Bê tông nhựa nóng C12.5 dày 6cm (lớp 1) | C14: m2 | I14: =I13 -> 1068.55 | J14: =#REF!*#REF! -> #REF! | K14: =#REF!*#REF! -> #REF! | L14: =I14*J14 -> #REF! | M14: =+I14*K14 -> #REF! | N14: =+SUM(L14:M14) -> #REF!
A15: =MAX($A$6:$A14)+1 -> 6 | B15: Tưới nhựa bám dính tiêu chuẩn 0.5kg/m2 | C15: m2 | I15: =I10 -> 1068.55 | J15: =#REF!*#REF! -> #REF! | K15: =#REF!*#REF! -> #REF! | L15: =I15*J15 -> #REF! | M15: =+I15*K15 -> #REF! | N15: =+SUM(L15:M15) -> #REF!
A16: =MAX($A$6:$A15)+1 -> 7 | B16: Bê tông nhựa nóng C9.5 dày 4cm (lớp 2) | C16: m2 | I16: =I10 -> 1068.55 | J16: =#REF!*#REF! -> #REF! | K16: =#REF!*#REF! -> #REF! | L16: =I16*J16 -> #REF! | M16: =+I16*K16 -> #REF! | N16: =+SUM(L16:M16) -> #REF!
A18: B | B18: Đưởng Tải Nhẹ | L18: =+SUBTOTAL(9,L19:L23) -> #REF! | M18: =+SUBTOTAL(9,M19:M23) -> #REF! | N18: =+SUBTOTAL(9,N19:N23) -> #REF!
A19: =MAX($A$6:$A17)+1 -> 8 | B19: Lu nền đất K=0.95 | C19: m2 | E19: =800.62+288.28+29.52*2 -> 1147.94 | I19: =PRODUCT(D19:H19) -> 1147.94 | J19: =#REF!*#REF! -> #REF! | K19: =#REF!*#REF! -> #REF! | L19: =I19*J19 -> #REF! | M19: =+I19*K19 -> #REF! | N19: =+SUM(L19:M19) -> #REF!
A20: =MAX($A$6:$A19)+1 -> 9 | B20: Cấp phối đá dăm loại I dày 20cm, K=0.95 | C20: m3 | E20: =E19 -> 1147.94 | G20: 0.2 | I20: =PRODUCT(D20:H20) -> 229.588 | J20: =#REF!*#REF! -> #REF! | K20: =#REF!*#REF! -> #REF! | L20: =I20*J20 -> #REF! | M20: =+I20*K20 -> #REF! | N20: =+SUM(L20:M20) -> #REF!
A21: =MAX($A$6:$A20)+1 -> 10 | B21: Tưới nhựa bám dính tiêu chuẩn 1kg/m2 | C21: m2 | I21: =I19 -> 1147.94 | J21: =#REF!*#REF! -> #REF! | K21: =#REF!*#REF! -> #REF! | L21: =I21*J21 -> #REF! | M21: =+I21*K21 -> #REF! | N21: =+SUM(L21:M21) -> #REF!
A22: =MAX($A$6:$A21)+1 -> 11 | B22: Bê tông nhựa nóng C12.5 dày 5cm | C22: m2 | I22: =I21 -> 1147.94 | J22: =#REF!*#REF! -> #REF! | K22: =#REF!*#REF! -> #REF! | L22: =I22*J22 -> #REF! | M22: =+I22*K22 -> #REF! | N22: =+SUM(L22:M22) -> #REF!
A24: C | B24: Đưởng Lát Gạch Trồng Cỏ | L24: =+SUBTOTAL(9,L25:L28) -> #REF! | M24: =+SUBTOTAL(9,M25:M28) -> #REF! | N24: =+SUBTOTAL(9,N25:N28) -> #REF!
A25: =MAX($A$6:$A23)+1 -> 12 | B25: Lu nền đất K=0.9 | C25: m2 | E25: =327.64+96 -> 423.64 | I25: =PRODUCT(D25:H25) -> 423.64 | J25: =#REF!*#REF! -> #REF! | K25: =#REF!*#REF! -> #REF! | L25: =I25*J25 -> #REF! | M25: =+I25*K25 -> #REF! | N25: =+SUM(L25:M25) -> #REF!
A26: =MAX($A$6:$A25)+1 -> 13 | B26: Lớp cát đệm dày 3cm | C26: m3 | I26: =I25*0.03 -> 12.7092 | J26: =#REF!*#REF! -> #REF! | K26: =#REF!*#REF! -> #REF! | L26: =I26*J26 -> #REF! | M26: =+I26*K26 -> #REF! | N26: =+SUM(L26:M26) -> #REF!
A27: =MAX($A$6:$A26)+1 -> 14 | B27: Gạch trồng cỏ KT 200x400 | C27: m2 | I27: =I25 -> 423.64 | J27: =#REF!*#REF! -> #REF! | K27: =#REF!*#REF! -> #REF! | L27: =I27*J27 -> #REF! | M27: =+I27*K27 -> #REF! | N27: =+SUM(L27:M27) -> #REF!
A29: D | B29: Ram dốc BTCT | L29: =+SUBTOTAL(9,L30:L48) -> #REF! | M29: =+SUBTOTAL(9,M30:M48) -> #REF! | N29: =+SUBTOTAL(9,N30:N48) -> #REF!
A30: =MAX($A$6:$A28)+1 -> 15 | B30: Lu nền đất K=0.95 | C30: m2 | I30: =SUBTOTAL(9,I31:I33) -> 1313.73 | J30: =#REF!*#REF! -> #REF! | K30: =#REF!*#REF! -> #REF! | L30: =I30*J30 -> #REF! | M30: =+I30*K30 -> #REF! | N30: =+SUM(L30:M30) -> #REF!
B31: Ram cổng chính | E31: 559.72 | I31: =PRODUCT(D31:H31) -> 559.72 | J31: =#REF!*#REF! -> #REF! | K31: =#REF!*#REF! -> #REF!
B32: Ram cổng phụ | E32: 614.18 | I32: =PRODUCT(D32:H32) -> 614.18 | J32: =#REF!*#REF! -> #REF! | K32: =#REF!*#REF! -> #REF!
