Workbook
Name ________________P3: #REF!
Name ________________P3: #REF!
Name ________________PPP3: #REF!
Name ________________PPP3: #REF!
Name ________________PPP33: #REF!
Name ________________PPP33: #REF!
Name ________________ppp34: #REF!
Name ________________ppp34: #REF!
Name ________________ppp3444: #REF!
Name ________________ppp3444: #REF!
Name _______________P3: #REF!
Name _______________P3: #REF!
Name _______________PPP3: #REF!
Name _______________PPP3: #REF!
Name _______________PPP33: #REF!
Name _______________PPP33: #REF!
Name _______________ppp34: #REF!
Name _______________ppp34: #REF!
Name _______________ppp3444: #REF!
Name _______________ppp3444: #REF!
Name ______________P3: #REF!
Name ______________P3: #REF!
Name ______________PPP3: #REF!
Name ______________PPP3: #REF!
Name ______________PPP33: #REF!
Name ______________PPP33: #REF!
Name ______________ppp34: #REF!
Name ______________ppp34: #REF!
Name ______________ppp3444: #REF!
Name ______________ppp3444: #REF!
Name _____________P3: #REF!
Name _____________P3: #REF!
Name _____________PPP3: #REF!
Name _____________PPP3: #REF!
Name _____________PPP33: #REF!
Name _____________PPP33: #REF!
Name _____________ppp34: #REF!
Name _____________ppp34: #REF!
Name _____________ppp3444: #REF!
Name _____________ppp3444: #REF!
Name ____________P3: #REF!
Name ____________P3: #REF!
Name ____________PPP3: #REF!
Name ____________PPP3: #REF!
Name ____________PPP33: #REF!
Name ____________PPP33: #REF!
Name ____________ppp34: #REF!
Name ____________ppp34: #REF!
Name ____________ppp3444: #REF!
Name ____________ppp3444: #REF!
Name ___________dam24: [1]GIAVLIEU!$M$51
Name ___________TVL1: #REF!
Name ___________TVL1: #REF!
Name ___________TVL1: #REF!
Name ___________TVL1: #REF!
Name __________dam24: [1]GIAVLIEU!$M$51
Name __________P3: #REF!
Name __________P3: #REF!
Name __________PPP3: #REF!
Name __________PPP3: #REF!

Sheet 01.BÌA
C5: BẢNG DỰ TOÁN/BILL OF QUANTITY
C8: DỰ ÁN/PROJECT | D8: : | E8: NEW WAREHOUSE/NHÀ KHO
C9: HẠNG MỤC/ITEM | D9: : | E9: CSA WORKS
C10: ĐỊA ĐIỂM/LOCATION | D10: : | E10: VSIP 3, BINH DUONG, VIETNAM
C11: CHỦ ĐẦU TƯ/OWNER | D11: :
C12: NHÀ THẦU/CONTRACTOR | D12: :
C14: NGÀY/DATE: | E14: =TODAY() -> 46301

Sheet Total Amount 
A8: No: 01-2024.NICON
A10: BẢNG DỰ TOÁN/ BILL OF QUANTITY
A12: Project / Dự án : NEW WAREHOUSE/NHÀ KHO
A13: Owner/ Chủ đầu tư :
A14: Location / Địa điểm :
A15: Items / Hạng mục : CIVIL CONSTRUCTION / XÂY DỰNG
A16: Kindly to /Kính gửi :
A17: TỔNG HỢP CHI PHÍ
F19: Currency: VND
A20: PART | B20: NO | C20: DESCRIPTION | E20: AMOUNT | G20: REMARK
A22: CONSTRUCTION | C22: CONSTRUCTION WORKS COST/ CHI PHÍ THI CÔNG XÂY DỰNG | E22: =' COST SUMMARY'!D12 -> 0 | G22: Detail next page
C23: GRAND-TOTAL/ TỔNG CỘNG | E23: =SUM(E22) -> 0
C24: VAT 8%/ THUẾ VAT 8% | E24: =E23*0.08 -> 0
C25: GRAND-TOTAL AFTER TAX VAT/ TỔNG CỘNG VAT | E25: =E23+E24 -> 0
A27: NIPPON ENGINEERING PROCUREMENT AND CONSTRUCTION JSC | E27: NEW INVESTMENT CONSTRUCTION CONSULTANT JOINT STOCK COMPANY
A28: General Director | E28: General Director
E32: VO TRI NGUYEN

Sheet  COST SUMMARY
A1: TỔNG HỢP CHI PHÍ/COST SUMMARY
A2: PROJECT/ DỰ ÁN : NEW WAREHOUSE/NHÀ KHO
A3: ITEM/HẠNG MỤC : CIVIL CONSTRUCTION / XÂY DỰNG
A4: DATE/NGÀY : | C4: =TODAY() -> 46301
D5: Currency: VND
A6: SECTION | B6: No. | C6: DESCRIPTION | E6: REMARK
D7: TOTAL
A8: CHI PHÍ TRỰC TIẾP/DIRECT COST | B8: 1 | C8: BILL No.1: PRELIMINARY & GENERAL REQUIREMENTS/ TIỆN ÍCH VÀ YÊU CẦU CHUNG | D8: ='Bill 1- Premilinary & General'!F5 -> 0 | E8: Detail next page
B9: 2 | C9: BILL No.2: MAIN BUILDING WORKS | D9: ='Bill 2-Main building works'!Q6 -> 0 | E9: Detail next page
B10: 3 | C10: BILL No.3: EXTERNAL WORKS | D10: ='Bill 3-External works'!Q6 -> 0 | E10: Detail next page
C12: TỔNG CỘNG/SUB-TOTAL | D12: =SUBTOTAL(109,D8:D11) -> 0
A13: TỔNG CỘNG CHI PHÍ/GRAND-TOTAL | D13: =D12 -> 0
A14: NOTE: | B14: - | C14: 'V.A.T IS EXCLUDED

Sheet Bill 1- Premilinary & General
A1: PROJECT/ DỰ ÁN : NEW WAREHOUSE/NHÀ KHO
A2: ADDRESS/ĐỊA CHỈ : VSIP 3, BINH DUONG, VIETNAM
A3: BILL No.01 : PRELIMINARY & GENERAL REQUIREMENTS/ CÔNG TÁC TẠM VÀ CÁC YÊU CẦU CHUNG
A4: No. | B4: DESCRIPTION | C4: UNIT | D4: Q'TY | E4: PRICE | F4: AMOUNT | G4: REMARK
A5: No.01 | B5: TOTAL OF BILL No.1: PRELIMINARY & GENERAL REQUIREMENTS/ TIỆN ÍCH VÀ YÊU CẦU CHUNG | F5: =SUBTOTAL(9,F6:F69) -> 0
B6: The Contractor shall refer to the General Requirements and other tender documents and he is to include all items that he considers necessary for completion of the Works and complying with all the requirements contained therein, whether or not they are specifically mentioned in this Bill of Quantities./Nhà thầu phải tham khảo các Yêu cầu chung và các tài liệu đấu thầu khác và Nhà thầu phải đưa vào tất cả các hạng mục mà Nhà thầu cho là cần thiết để hoàn thành Công trình và tuân thủ tất cả các yêu cầu có trong đó, cho dù chúng có được đề cập cụ thể trong Bảng khối lượng này hay không.
A7: I | B7: PERMANENT VALUE
A8: 1.1 | B8: Groundbreaking | C8: item
A9: 1.2 | B9: Insurance
A10: 1.2.1 | B10: Workmen's compensation insurance for all workers and sub-contractors with minium coverage, USD3,000/person | C10: item
A11: 1.2.2 | B11: Third Party Insurance(USD300,000) | C11: item
A12: 1.3 | B12: Performance bond
A13: 1.3.1 | B13: Advance payment bond fee | C13: item
A14: 1.3.2 | B14: Performance bond fee | C14: item
A15: 1.3.3 | B15: Warranty guarantee | C15: item
A16: 1.4 | B16: Site Safety Measures
A17: 1.4.1 | B17: Signs | C17: item
A18: 1.4.2 | B18: Flagman | C18: item
A19: 1.4.3 | B19: Safety Barriers | C19: item
A20: 1.4.4 | B20: PPE to Workers & Visitors | C20: item
A21: 1.5 | B21: Temporary Fecility
A22: 1.5.1 | B22: Site Office for Constructor | C22: item
A23: 1.5.2 | B23: Site Office for Client(20ft, including desks and chairs, shelves, air conditioners) | C23: item
A24: 1.5.3 | B24: Site Office for Consultant(20ft, including desks and chairs, shelves, air conditioners, printers, essential stationery…) | C24: item
A25: 1.5.4 | B25: Meeting room | C25: item
A26: 1.5.5 | B26: Safety training area | C26: item
A27: 1.5.6 | B27: Storehouse & Workshop | C27: item
A28: 1.5.7 | B28: Bike parking | C28: item
A29: 1.5.8 | B29: Toilet for contractor | C29: item
A30: 1.5.9 | B30: Toilet for Client & Consultant | C30: item
A31: 1.5.10 | B31: Toilet for worker | C31: item
A32: 1.5.11 | B32: Temporary road | C32: item
A33: 1.6 | B33: Temporary service
A34: 1.6.1 | B34: Power supply sysem | C34: item
A35: 1.6.2 | B35: Lightings system | C35: item
A36: 1.6.3 | B36: Water Supply system | C36: item
A37: 1.6.4 | B37: Telephone & Internet | C37: item
A38: 1.6.5 | B38: Waste water Sewerage | C38: item
A39: 1.7 | B39: Survey & Setting Out | C39: item
A40: 1.8 | B40: Temporary fence (1.50m to 2.10m high) & Gates | C40: item
...

Sheet Bill 2-Main building works
A1: PROJECT/ DỰ ÁN : NEW WAREHOUSE/NHÀ KHO
A2: ADDRESS/ĐỊA CHỈ : VSIP 3, BINH DUONG, VIETNAM
A3: BILL No.02 : MAIN BUILDING WORKS
A4: No. | B4: DESCRIPTION | C4: STANDARD | D4: Unit | E4: DIMENSION | J4: QUANTITY | K4: Q'TY | L4: MATERIAL | N4: LABOUR & EQUIPMENT | P4: TOTAL COST(VND) | R4: REMARK
E5: No | F5: L | G5: W | H5: H | I5: HS | J5: COMPONENT | L5: MATERIAL | M5: AMOUNT | N5: UNIT | O5: AMOUNT | P5: UNIT | Q5: AMOUNT
A6: No.02 | B6: TOTAL OF BILL No.2: MAIN BUILDING WORKS
A7: =A13 -> C.01 | B7: =B13 -> WAREHOUSE / NHÀ KHO
A8: =A261 -> C.02 | B8: =B261 -> OFFICE/ VĂN PHÒNG
A9: =A449 -> C.03 | B9: =B449 -> WATER TANK/ BỂ NƯỚC
A10: =A515 -> C.04 | B10: =B515 -> PUPM ROOM+ELECTRIC+TRANFORMER/NHÀ BƠM +NHÀ ĐIỆN, MÁY PHÁT
A11: =A573 -> C.05 | B11: =B573 -> GUARD HOUSE/NHÀ BẢO VỆ
A12: =A641 -> C.06 | B12: =B641 -> MOTOBIKE HOUSE / NHÀ XE MÁY
A13: C.01 | B13: WAREHOUSE / NHÀ KHO
A14: I | B14: EARTH WORK/ CÔNG TÁC ĐẤT
A15: 1 | B15: Excavation of Soil/ Công tác đào đất | C15: Soil grade 3 | D15: m3
B16: M1 | E16: 8 | F16: 2 | G16: 3.5 | H16: 2.55 | I16: 1.3 | J16: =PRODUCT(E16:I16) -> 185.64
B17: M2 | E17: 7 | F17: 2.8 | G17: 4 | H17: 2.55 | I17: 1.3 | J17: =PRODUCT(E17:I17) -> 259.896
B18: M3 | E18: 20 | F18: 3 | G18: 4.5 | H18: 2.55 | I18: 1.3 | J18: =PRODUCT(E18:I18) -> 895.05
B19: M4 | E19: 32 | F19: 2.4 | G19: 3 | H19: 2.55 | I19: 1.3 | J19: =PRODUCT(E19:I19) -> 763.776
B20: M4a | E20: 2 | F20: 2.5 | G20: 3 | H20: 2.55 | I20: 1.3 | J20: =PRODUCT(E20:I20) -> 49.725
B21: M5 | E21: =42-13 -> 29 | F21: 2.2 | G21: 2.2 | H21: 2.55 | I21: 1.3 | J21: =PRODUCT(E21:I21) -> 465.2934
B22: M6 | E22: 24 | F22: 2.2 | G22: 2.2 | H22: 2.55 | I22: 1.3 | J22: =PRODUCT(E22:I22) -> 385.0704
B23: M7 | E23: 12 | F23: 2.5 | G23: 2.5 | H23: 2.55 | I23: 1.3 | J23: =PRODUCT(E23:I23) -> 248.625
B24: M8 | E24: 1 | F24: 2.8 | G24: 2.8 | H24: 2.55 | I24: 1.3 | J24: =PRODUCT(E24:I24) -> 25.9896
B25: M9 | E25: 16 | F25: 2 | G25: 2 | H25: 2.55 | I25: 1.3 | J25: =PRODUCT(E25:I25) -> 212.16
B26: DK 200x800 | E26: 1 | F26: =14.05+40+30+15.7 -> 99.75 | G26: 0.2 | H26: 0.85 | I26: 1.3 | J26: =PRODUCT(E26:I26) -> 22.04475
B27: DK 200x1000 | E27: 1 | F27: =(110+112.5)*2 -> 445 | G27: 0.2 | H27: 1.05 | I27: 1.3 | J27: =PRODUCT(E27:I27) -> 121.485
A28: 2 | B28: Backfilling soil for foundation/ Lấp đất móng | C28: Compact layer by layer, each layer 0.3m | D28: m3
A29: 3 | B29: Remove surplus soil/ Vận chuyển đất dư | C29: Distance D<=1Km | D29: m3
A30: 4 | B30: Natural soil well compacted, k = 0.95/ Đầm chặt nền đất | D30: m2
B31: Nền xưởng 2T | E31: 1 | F31: 70 | G31: 28.05 | J31: =G31*F31 -> 1963.5
B32: Nền xưởng 5T | E32: 1 | I32: =(110*112.5)-(70*28.05)-(15.7*29.4) -> 9949.92 | J32: =I32 -> 9949.92
A33: 5 | B33: Foundation, ground beam soil well compacted, k = 0.95/ Đầm chặt đất móng, đà kiềng | D33: m2
B34: M1 | E34: 8 | F34: 2 | G34: 3.5 | J34: =E34*(F34+0.2)*(G34+0.2) -> 65.12
B35: M2 | E35: 7 | F35: 2.8 | G35: 4 | J35: =E35*(F35+0.2)*(G35+0.2) -> 88.2
B36: M3 | E36: 20 | F36: 3 | G36: 4.5 | J36: =E36*(F36+0.2)*(G36+0.2) -> 300.8
B37: M4 | E37: 32 | F37: 2.4 | G37: 3 | J37: =E37*(F37+0.2)*(G37+0.2) -> 266.24
B38: M4a | E38: 2 | F38: 2.5 | G38: 3 | J38: =E38*(F38+0.2)*(G38+0.2) -> 17.28
B39: M5 | E39: =42-13 -> 29 | F39: 2.2 | G39: 2.2 | J39: =E39*(F39+0.2)*(G39+0.2) -> 167.04
B40: M6 | E40: 24 | F40: 2.2 | G40: 2.2 | J40: =E40*(F40+0.2)*(G40+0.2) -> 138.24
...

Sheet C02.CSA_OFFICE
A1: ESTIMATE DETAIL TABLE
A2: ='Bill 3-External works'!#REF! -> #REF!
A3: ITEM/HẠNG MỤC : COMPLETE CONSTRUCTION /XÂY DỰNG HOÀN THIỆN
R4: VND
A5: No. | B5: DESCRIPTION | C5: STANDARD | D5: Unit | E5: DIMENSION | J5: QUANTITY | K5: Q'TY | L5: MATERIAL | N5: LABOUR & EQUIPMENT | P5: TOTAL COST(VND) | R5: REMARK | S5: Profit | T5: ='Bill 2-Main building works'!#REF! -> #REF!
E6: No | F6: L | G6: W | H6: H | I6: HS | J6: COMPONENT | L6: UNIT | M6: AMOUNT | N6: UNIT | O6: AMOUNT | P6: UNIT | Q6: AMOUNT | T6: Vật tư | U6: Nhân công
A7: C02 | B7: OFFICE/ VĂN PHÒNG | K7: =I288+I322*0.5+264.2 -> 679.68 | M7: =SUBTOTAL(9,M8:M17) -> #REF! | O7: =SUBTOTAL(9,O8:O17) -> #REF! | Q7: =SUBTOTAL(9,Q8:Q17) -> #REF!
A8: I | B8: EARTH WORK/ CÔNG TÁC ĐẤT | M8: =M18 -> #REF! | N8: =N18 -> 0 | O8: =O18 -> #REF! | Q8: =O8+M8 -> #REF!
A9: II | B9: ANTI TERMITE TREATMENT/ CHỐNG MỐI | M9: =M128 -> #REF! | O9: =O128 -> #REF! | Q9: =O9+M9 -> #REF!
A10: III | B10: REINFORCED CONCRETE WORK/ BÊ TÔNG CỐT THÉP | M10: =M131 -> #REF! | O10: =O131 -> #REF! | Q10: =O10+M10 -> #REF!
A11: IV | B11: FLOOR FINISHING WORKS/ HOÀN THIỆN NỀN | M11: =M690 -> #REF! | O11: =O690 -> #REF! | Q11: =O11+M11 -> #REF!
A12: V | B12: WALL FINISHING WORKS/ CÔNG TÁC HOÀN THIỆN TƯỜNG | M12: =M766 -> #REF! | O12: =O766 -> #REF! | Q12: =O12+M12 -> #REF!
A13: VI | B13: CEILING FINISHING WORKS/ CÔNG TÁC HOÀN THIỆN TRẦN | M13: =M1307 -> #REF! | O13: =O1307 -> #REF! | Q13: =Q1307 -> #REF!
A14: VII | B14: DOORS AND WINDOWS/ CỬA ĐI. CỬA SỔ | M14: =M1316 -> #REF! | O14: =O1316 -> #REF! | Q14: =O14+M14 -> #REF!
A15: VIII | B15: METAL WORKS/ CÔNG TÁC KIM LOẠI | M15: =M1359 -> #REF! | O15: =O1359 -> #REF! | Q15: =Q1359 -> #REF!
A16: IX | B16: OTHERS WORKS/ CÔNG TÁC KHÁC | M16: =M1364 -> #REF! | O16: =O1364 -> #REF! | Q16: =O16+M16 -> #REF!
A18: I | B18: EARTH WORK/ CÔNG TÁC ĐẤT | M18: =SUBTOTAL(109,M19:M127) -> #REF! | O18: =SUM(O19:O126) -> #REF! | Q18: =O18+M18 -> #REF!
A19: 1 | B19: Excavation of Soil/ Công tác đào đất | C19: Soil grade 3 | D19: m3 | K19: =+SUBTOTAL(9,J21:J63) -> 349.2135 | L19: =T19*$T$5 -> #REF! | M19: =ROUND(L19*K19,0) -> #REF! | N19: =U19*$T$5 -> #REF! | O19: =ROUND(N19*K19,0) -> #REF! | P19: =N19+L19 -> #REF! | Q19: =O19+M19 -> #REF! | U19: 35000
B20: Foudation | L20: =T20*$T$5 -> #REF! | M20: =ROUND(L20*K20,0) -> #REF! | N20: =U20*$T$5 -> #REF! | O20: =ROUND(N20*K20,0) -> #REF! | Q20: =O20+M20 -> #REF!
B21: M1 | E21: 1 | F21: 1 | G21: 1 | H21: 2.25 | I21: 1.3 | J21: =PRODUCT(E21:I21) -> 2.925 | L21: =T21*$T$5 -> #REF! | M21: =ROUND(L21*K21,0) -> #REF! | N21: =U21*$T$5 -> #REF! | O21: =ROUND(N21*K21,0) -> #REF! | Q21: =O21+M21 -> #REF!
B22: M2 | E22: 1 | F22: 1.6 | G22: 1.6 | H22: 2.25 | I22: 1.3 | J22: =PRODUCT(E22:I22) -> 7.488 | L22: =T22*$T$5 -> #REF! | M22: =ROUND(L22*K22,0) -> #REF! | N22: =U22*$T$5 -> #REF! | O22: =ROUND(N22*K22,0) -> #REF! | Q22: =O22+M22 -> #REF!
B23: M3 | E23: 2 | F23: 1.8 | G23: 1.8 | H23: 2.25 | I23: 1.3 | J23: =PRODUCT(E23:I23) -> 18.954 | L23: =T23*$T$5 -> #REF! | M23: =ROUND(L23*K23,0) -> #REF! | N23: =U23*$T$5 -> #REF! | O23: =ROUND(N23*K23,0) -> #REF! | Q23: =O23+M23 -> #REF! | T23: =7/13 -> 0.53846154
B24: M4 | E24: 2 | F24: 2 | G24: 2 | H24: 2.25 | I24: 1.3 | J24: =PRODUCT(E24:I24) -> 23.4 | L24: =T24*$T$5 -> #REF! | M24: =ROUND(L24*K24,0) -> #REF! | N24: =U24*$T$5 -> #REF! | O24: =ROUND(N24*K24,0) -> #REF! | Q24: =O24+M24 -> #REF!
B25: M5 | E25: 3 | F25: 2.2 | G25: 2.2 | H25: 2.25 | I25: 1.3 | J25: =PRODUCT(E25:I25) -> 42.471 | L25: =T25*$T$5 -> #REF! | M25: =ROUND(L25*K25,0) -> #REF! | N25: =U25*$T$5 -> #REF! | O25: =ROUND(N25*K25,0) -> #REF! | Q25: =O25+M25 -> #REF!
B26: M6 | E26: 5 | F26: 2.4 | G26: 2.4 | H26: 2.25 | I26: 1.3 | J26: =PRODUCT(E26:I26) -> 84.24 | L26: =T26*$T$5 -> #REF! | M26: =ROUND(L26*K26,0) -> #REF! | N26: =U26*$T$5 -> #REF! | O26: =ROUND(N26*K26,0) -> #REF! | Q26: =O26+M26 -> #REF!
B27: M7 | E27: 3 | F27: 2.6 | G27: 2.6 | H27: 2.25 | I27: 1.3 | J27: =PRODUCT(E27:I27) -> 59.319 | L27: =T27*$T$5 -> #REF! | M27: =ROUND(L27*K27,0) -> #REF! | N27: =U27*$T$5 -> #REF! | O27: =ROUND(N27*K27,0) -> #REF! | Q27: =O27+M27 -> #REF!
B28: M8 | E28: 2 | F28: 2.8 | G28: 2.8 | H28: 2.25 | I28: 1.3 | J28: =PRODUCT(E28:I28) -> 45.864 | L28: =T28*$T$5 -> #REF! | M28: =ROUND(L28*K28,0) -> #REF! | N28: =U28*$T$5 -> #REF! | O28: =ROUND(N28*K28,0) -> #REF! | Q28: =O28+M28 -> #REF!
B29: M9 | E29: 1 | F29: 2.6 | G29: 4.2 | H29: 2.25 | I29: 1.3 | J29: =PRODUCT(E29:I29) -> 31.941 | L29: =T29*$T$5 -> #REF! | M29: =ROUND(L29*K29,0) -> #REF! | N29: =U29*$T$5 -> #REF! | O29: =ROUND(N29*K29,0) -> #REF! | Q29: =O29+M29 -> #REF!
B30: M10 | E30: 1 | F30: 2.4 | G30: 3.2 | H30: 2.25 | I30: 1.3 | J30: =PRODUCT(E30:I30) -> 22.464 | L30: =T30*$T$5 -> #REF! | M30: =ROUND(L30*K30,0) -> #REF! | N30: =U30*$T$5 -> #REF! | O30: =ROUND(N30*K30,0) -> #REF! | Q30: =O30+M30 -> #REF!
B31: Ground beam | L31: =T31*$T$5 -> #REF! | M31: =ROUND(L31*K31,0) -> #REF! | N31: =U31*$T$5 -> #REF! | O31: =ROUND(N31*K31,0) -> #REF! | Q31: =O31+M31 -> #REF!
B32: D1-1 | C32: 200x400 | E32: 1 | F32: 15.4 | G32: 0.4 | H32: 0.15 | J32: =PRODUCT(E32:I32) -> 0.924 | L32: =T32*$T$5 -> #REF! | M32: =ROUND(L32*K32,0) -> #REF! | N32: =U32*$T$5 -> #REF! | O32: =ROUND(N32*K32,0) -> #REF! | Q32: =O32+M32 -> #REF!
B33: D1-1a | C33: 200x400(-0.150) | E33: 1 | F33: 3.8 | G33: 0.4 | H33: 0.45 | J33: =PRODUCT(E33:I33) -> 0.684 | L33: =T33*$T$5 -> #REF! | M33: =ROUND(L33*K33,0) -> #REF! | N33: =U33*$T$5 -> #REF! | O33: =ROUND(N33*K33,0) -> #REF! | Q33: =O33+M33 -> #REF!
B34: D1-2 | C34: 200x300 | E34: 1 | F34: 8.75 | G34: 0.4 | H34: 0.05 | J34: =PRODUCT(E34:I34) -> 0.175 | L34: =T34*$T$5 -> #REF! | M34: =ROUND(L34*K34,0) -> #REF! | N34: =U34*$T$5 -> #REF! | O34: =ROUND(N34*K34,0) -> #REF! | Q34: =O34+M34 -> #REF!
B35: D1-2a | C35: 200x300(-0.150) | E35: 1 | F35: 3.8 | G35: 0.4 | H35: 0.35 | J35: =PRODUCT(E35:I35) -> 0.532 | L35: =T35*$T$5 -> #REF! | M35: =ROUND(L35*K35,0) -> #REF! | N35: =U35*$T$5 -> #REF! | O35: =ROUND(N35*K35,0) -> #REF! | Q35: =O35+M35 -> #REF!
B36: D1-3 | C36: 200x300 | E36: 1 | F36: 5.8 | G36: 0.4 | H36: 0.05 | J36: =PRODUCT(E36:I36) -> 0.116 | L36: =T36*$T$5 -> #REF! | M36: =ROUND(L36*K36,0) -> #REF! | N36: =U36*$T$5 -> #REF! | O36: =ROUND(N36*K36,0) -> #REF! | Q36: =O36+M36 -> #REF!
B37: D1-4 | C37: 200x400 | E37: 1 | F37: 5.9 | G37: 0.4 | H37: 0.15 | J37: =PRODUCT(E37:I37) -> 0.354 | L37: =T37*$T$5 -> #REF! | M37: =ROUND(L37*K37,0) -> #REF! | N37: =U37*$T$5 -> #REF! | O37: =ROUND(N37*K37,0) -> #REF! | Q37: =O37+M37 -> #REF!
C38: 200x300 | E38: 1 | F38: 4.4 | G38: 0.4 | H38: 0.05 | J38: =PRODUCT(E38:I38) -> 0.088 | L38: =T38*$T$5 -> #REF! | M38: =ROUND(L38*K38,0) -> #REF! | N38: =U38*$T$5 -> #REF! | O38: =ROUND(N38*K38,0) -> #REF! | Q38: =O38+M38 -> #REF!
B39: D1-4a | C39: 200x300(-0.150) | E39: 1 | F39: 3.8 | G39: 0.4 | H39: 0.35 | J39: =PRODUCT(E39:I39) -> 0.532 | L39: =T39*$T$5 -> #REF! | M39: =ROUND(L39*K39,0) -> #REF! | N39: =U39*$T$5 -> #REF! | O39: =ROUND(N39*K39,0) -> #REF! | Q39: =O39+M39 -> #REF!
B40: D1-5 | C40: 200x400 | E40: 1 | F40: 19 | G40: 0.4 | H40: 0.15 | J40: =PRODUCT(E40:I40) -> 1.14 | L40: =T40*$T$5 -> #REF! | M40: =ROUND(L40*K40,0) -> #REF! | N40: =U40*$T$5 -> #REF! | O40: =ROUND(N40*K40,0) -> #REF! | Q40: =O40+M40 -> #REF!
B41: D1-6 | C41: 200x400 | E41: 1 | F41: 2.5 | G41: 0.4 | H41: 0.15 | J41: =PRODUCT(E41:I41) -> 0.15 | L41: =T41*$T$5 -> #REF! | M41: =ROUND(L41*K41,0) -> #REF! | N41: =U41*$T$5 -> #REF! | O41: =ROUND(N41*K41,0) -> #REF! | Q41: =O41+M41 -> #REF!
...

Sheet C03.CSA_ANCILLARAY
A1: ESTIMATE DETAIL TABLE
A2: PROJECT/ DỰ ÁN : WAREHOUSE/NHÀ KHO
A3: ITEM/HẠNG MỤC : ANCILLARY ITEMS /HẠNG MỤC PHỤ
R4: VND
A5: No. | B5: DESCRIPTION | C5: STANDARD | D5: Unit | E5: DIMENSION | J5: QUANTITY | K5: Q'TY | L5: MATERIAL | N5: LABOUR & EQUIPMENT | P5: TOTAL COST(VND) | R5: REMARK | S5: ='C02.CSA_OFFICE'!S5 -> Profit | T5: ='C02.CSA_OFFICE'!T5 -> #REF!
E6: No | F6: L | G6: W | H6: H | I6: HS | J6: COMPONENT | L6: UNIT | M6: AMOUNT | N6: UNIT | O6: AMOUNT | P6: UNIT | Q6: AMOUNT | T6: ='C02.CSA_OFFICE'!T6 -> Vật tư | U6: ='C02.CSA_OFFICE'!U6 -> Nhân công
A7: C03 | B7: ANCILLARY ITEMS/ HẠNG MỤC PHỤ | M7: =SUBTOTAL(9,M8:M12) -> #REF! | O7: =SUBTOTAL(9,O8:O12) -> #REF! | P7: =SUBTOTAL(9,P8:P12) -> 0 | Q7: =SUBTOTAL(9,Q8:Q12) -> #REF!
A8: =A14 -> I | B8: WATER TANK/ BỂ NƯỚC | M8: =M14 -> #REF! | O8: =O14 -> #REF! | Q8: =O8+M8 -> #REF!
A9: =A110 -> II | B9: GUARD HOUSE/NHÀ BẢO VỆ | M9: =M110 -> #REF! | O9: =O110 -> #REF! | Q9: =O9+M9 -> #REF!
A10: =A341 -> III | B10: PUPM ROOM+TRASH ROOM/NHÀ BƠM +NHÀ RÁC | K10: =9000*6000 -> 54000000 | M10: =M341 -> #REF! | O10: =O341 -> #REF! | Q10: =O10+M10 -> #REF!
A11: =A495 -> IV | B11: FENCE/ HÀNG RÀO | M11: =M495 -> #REF! | O11: =O495 -> #REF! | Q11: =O11+M11 -> #REF!
A12: =A604 -> V | B12: MOTOBIKE HOUSE / NHÀ XE MÁY | M12: =M604 -> #REF! | N12: =N604 -> 0 | O12: =O604 -> #REF! | Q12: =O12+M12 -> #REF!
A14: I | B14: WATER TANK/ BỂ NƯỚC | M14: =SUBTOTAL(109,M15:M109) -> #REF! | O14: =SUBTOTAL(109,O15:O109) -> #REF! | Q14: =O14+M14 -> #REF! | S14: m3 | T14: =234*2.8 -> 655.2
B15: EARTH WORK/ CÔNG TÁC ĐẤT
A16: 1 | B16: Excavation of Soil/ Công tác đào đất | C16: Soil grade 3 | D16: m3 | K16: =+SUBTOTAL(9,J17:J18) -> 870.455 | L16: =T16*$T$5 -> #REF! | M16: =ROUND(L16*K16,0) -> #REF! | N16: =U16*$T$5 -> #REF! | O16: =ROUND(N16*K16,0) -> #REF! | P16: =N16+L16 -> #REF! | Q16: =P16*K16 -> #REF! | T16: ='Bill 2-Main building works'!#REF! -> #REF! | U16: ='Bill 2-Main building works'!#REF! -> #REF!
B17: Dđào đất bể nước | E17: 1 | G17: 249.5 | H17: =3.45 -> 3.45 | J17: =PRODUCT(G17:I17) -> 860.775 | L17: =T17*$T$5 -> #REF! | M17: =ROUND(L17*K17,0) -> #REF! | N17: =U17*$T$5 -> #REF! | O17: =ROUND(N17*K17,0) -> #REF! | P17: =N17+L17 -> #REF! | Q17: =P17*K17 -> #REF!
B18: Móng đáy bể | E18: 8 | F18: 2.2 | G18: 2.2 | H18: 0.25 | J18: =PRODUCT(E18:I18) -> 9.68 | L18: =T18*$T$5 -> #REF! | M18: =ROUND(L18*K18,0) -> #REF! | N18: =U18*$T$5 -> #REF! | O18: =ROUND(N18*K18,0) -> #REF! | P18: =N18+L18 -> #REF! | Q18: =P18*K18 -> #REF!
A19: 2 | B19: Backfilling soil for foundation/ Lấp đất móng | D19: m3 | K19: =(K16-J20-J21) -> 42.78 | L19: =T19*$T$5 -> #REF! | M19: =ROUND(L19*K19,0) -> #REF! | N19: =U19*$T$5 -> #REF! | O19: =ROUND(N19*K19,0) -> #REF! | P19: =N19+L19 -> #REF! | Q19: =P19*K19 -> #REF! | T19: ='Bill 2-Main building works'!#REF! -> #REF! | U19: ='Bill 2-Main building works'!#REF! -> #REF!
B20: bê tông lót | E20: 1 | G20: =K31 -> 24.95 | J20: =PRODUCT(E20:I20) -> 24.95 | L20: =T20*$T$5 -> #REF! | M20: =ROUND(L20*K20,0) -> #REF! | N20: =U20*$T$5 -> #REF! | O20: =ROUND(N20*K20,0) -> #REF! | P20: =N20+L20 -> #REF! | Q20: =P20*K20 -> #REF!
B21: bêể nước | E21: 1 | G21: 243.25 | H21: 3.3 | J21: =PRODUCT(E21:I21) -> 802.725 | L21: =T21*$T$5 -> #REF! | M21: =ROUND(L21*K21,0) -> #REF! | N21: =U21*$T$5 -> #REF! | O21: =ROUND(N21*K21,0) -> #REF! | P21: =N21+L21 -> #REF! | Q21: =P21*K21 -> #REF!
A22: 3 | B22: Remove surplus soil/ Vận chuyển đất dư | C22: Distance D<=1Km | D22: m3 | K22: =K16-K19 -> 827.675 | L22: =T22*$T$5 -> #REF! | M22: =ROUND(L22*K22,0) -> #REF! | N22: =U22*$T$5 -> #REF! | O22: =ROUND(N22*K22,0) -> #REF! | P22: =N22+L22 -> #REF! | Q22: =P22*K22 -> #REF! | T22: ='Bill 2-Main building works'!#REF! -> #REF! | U22: ='Bill 2-Main building works'!#REF! -> #REF!
A23: 4 | B23: Natural soil well compacted, k = 0.95/ Đầm chặt nền đất | D23: m2 | K23: =+SUBTOTAL(9,J24:J25) -> 249.5 | L23: =T23*$T$5 -> #REF! | M23: =ROUND(L23*K23,0) -> #REF! | N23: =U23*$T$5 -> #REF! | O23: =ROUND(N23*K23,0) -> #REF! | P23: =N23+L23 -> #REF! | Q23: =P23*K23 -> #REF! | T23: ='Bill 2-Main building works'!#REF! -> #REF! | U23: ='Bill 2-Main building works'!#REF! -> #REF!
B24: đáy bể | E24: 1 | J24: =G17 -> 249.5 | L24: =T24*$T$5 -> #REF! | M24: =ROUND(L24*K24,0) -> #REF! | N24: =U24*$T$5 -> #REF! | O24: =ROUND(N24*K24,0) -> #REF! | P24: =N24+L24 -> #REF! | Q24: =P24*K24 -> #REF!
L25: =T25*$T$5 -> #REF! | M25: =ROUND(L25*K25,0) -> #REF! | N25: =U25*$T$5 -> #REF! | O25: =ROUND(N25*K25,0) -> #REF! | P25: =N25+L25 -> #REF! | Q25: =P25*K25 -> #REF!
A26: 6 | B26: PVC sheet/ Lớp PVC | C26: PVC 0.3mm | D26: m2 | K26: =G17 -> 249.5 | L26: =T26*$T$5 -> #REF! | M26: =ROUND(L26*K26,0) -> #REF! | N26: =U26*$T$5 -> #REF! | O26: =ROUND(N26*K26,0) -> #REF! | P26: =N26+L26 -> #REF! | Q26: =P26*K26 -> #REF! | T26: ='Bill 2-Main building works'!#REF! -> #REF! | U26: ='Bill 2-Main building works'!#REF! -> #REF!
B27: ANTI TERMITE TREATMENT/ CHỐNG MỐI | M27: =SUM(M28) -> 0 | O27: =SUM(O28) -> 0 | Q27: =O27+M27 -> 0
A28: 1 | B28: Pre-treatment of basement ground surface/ Chống mối cho nền | C28: ='C02.CSA_OFFICE'!C129 -> Termize 200sc solution 0.25%, 5 liters/m2 | D28: m2 | M28: =L28*K28 -> 0 | O28: =N28*K28 -> 0 | P28: =N28+L28 -> 0 | Q28: =O28+M28 -> 0 | R28: Exclude
B29: REINFORCED CONCRETE WORK/ BÊ TÔNG CỐT THÉP
A30: * | B30: Concrete work/ Công tác bê tông
A31: 1 | B31: Lean concrete/ Bê tông lót | C31: Grade B7.5 | D31: m3 | K31: =+SUBTOTAL(9,J32) -> 24.95 | L31: =T31*$T$5 -> #REF! | M31: =ROUND(L31*K31,0) -> #REF! | N31: =U31*$T$5 -> #REF! | O31: =ROUND(N31*K31,0) -> #REF! | P31: =N31+L31 -> #REF! | Q31: =P31*K31 -> #REF! | T31: ='Bill 2-Main building works'!#REF! -> #REF! | U31: ='Bill 2-Main building works'!#REF! -> #REF!
G32: =G17 -> 249.5 | H32: 0.1 | I32: 1 | J32: =PRODUCT(E32:I32) -> 24.95 | L32: =T32*$T$5 -> #REF! | M32: =ROUND(L32*K32,0) -> #REF! | N32: =U32*$T$5 -> #REF! | O32: =ROUND(N32*K32,0) -> #REF! | P32: =N32+L32 -> #REF! | Q32: =P32*K32 -> #REF!
A33: 2 | B33: Bottom slab/ Bê tông bản đáy | C33: Grade B25 | D33: m3 | K33: =+SUBTOTAL(9,J34:J35) -> 81 | L33: =T33*$T$5 -> #REF! | M33: =ROUND(L33*K33,0) -> #REF! | N33: =U33*$T$5 -> #REF! | O33: =ROUND(N33*K33,0) -> #REF! | P33: =N33+L33 -> #REF! | Q33: =P33*K33 -> #REF! | T33: ='Bill 2-Main building works'!#REF! -> #REF! | U33: ='Bill 2-Main building works'!#REF! -> #REF!
E34: 1 | G34: 243 | H34: 0.25 | I34: 1 | J34: =PRODUCT(E34:I34) -> 60.75 | L34: =T34*$T$5 -> #REF! | M34: =ROUND(L34*K34,0) -> #REF! | N34: =U34*$T$5 -> #REF! | O34: =ROUND(N34*K34,0) -> #REF! | P34: =N34+L34 -> #REF! | Q34: =P34*K34 -> #REF!
B35: 0 | E35: 8 | F35: =(2.5+2)/2 -> 2.25 | G35: =(2.5+2)/2 -> 2.25 | H35: 0.5 | I35: 1 | J35: =PRODUCT(E35:I35) -> 20.25 | L35: =T35*$T$5 -> #REF! | M35: =ROUND(L35*K35,0) -> #REF! | N35: =U35*$T$5 -> #REF! | O35: =ROUND(N35*K35,0) -> #REF! | P35: =N35+L35 -> #REF! | Q35: =P35*K35 -> #REF!
A36: 3 | B36: Wall/ Bê tông tường bể | C36: Grade B25 | D36: m3 | K36: =+SUBTOTAL(9,J37) -> 46.871875 | L36: =T36*$T$5 -> #REF! | M36: =ROUND(L36*K36,0) -> #REF! | N36: =U36*$T$5 -> #REF! | O36: =ROUND(N36*K36,0) -> #REF! | P36: =N36+L36 -> #REF! | Q36: =P36*K36 -> #REF! | T36: =T33 -> #REF! | U36: =U33 -> #REF!
B37: Tbn1 | E37: 1 | F37: =18.7+8.5+15.6+4.7+21.85+1.4 -> 70.75 | G37: 0.25 | H37: 2.65 | I37: 1 | J37: =PRODUCT(E37:I37) -> 46.871875 | L37: =T37*$T$5 -> #REF! | M37: =ROUND(L37*K37,0) -> #REF! | N37: =U37*$T$5 -> #REF! | O37: =ROUND(N37*K37,0) -> #REF! | P37: =N37+L37 -> #REF! | Q37: =P37*K37 -> #REF!
B38: Tbn2 | E38: 1 | F38: 12 | G38: 0.25 | H38: 2.95 | I38: 1 | J38: =PRODUCT(E38:I38) -> 8.85 | L38: =T38*$T$5 -> #REF! | M38: =ROUND(L38*K38,0) -> #REF! | N38: =U38*$T$5 -> #REF! | O38: =ROUND(N38*K38,0) -> #REF! | P38: =N38+L38 -> #REF! | Q38: =P38*K38 -> #REF!
B39: Góc vát chân | E39: 1 | F39: =F38+F37 -> 82.75 | G39: 0.25 | H39: 0.25 | I39: 1 | J39: =PRODUCT(E39:I39)/2 -> 2.5859375 | L39: =T39*$T$5 -> #REF! | M39: =ROUND(L39*K39,0) -> #REF! | N39: =U39*$T$5 -> #REF! | O39: =ROUND(N39*K39,0) -> #REF! | P39: =N39+L39 -> #REF! | Q39: =P39*K39 -> #REF!
B40: góc vát đứng | E40: 3 | F40: 0.25 | G40: 0.25 | H40: 2.65 | I40: 1 | J40: =PRODUCT(E40:I40)/2 -> 0.2484375 | L40: =T40*$T$5 -> #REF! | M40: =ROUND(L40*K40,0) -> #REF! | N40: =U40*$T$5 -> #REF! | O40: =ROUND(N40*K40,0) -> #REF! | P40: =N40+L40 -> #REF! | Q40: =P40*K40 -> #REF!
A41: 4 | B41: Column/ Bê tông cho cột | C41: Grade B25 | D41: m3 | K41: =+SUBTOTAL(9,J42:J44) -> 2.421875 | L41: =T41*$T$5 -> #REF! | M41: =ROUND(L41*K41,0) -> #REF! | N41: =U41*$T$5 -> #REF! | O41: =ROUND(N41*K41,0) -> #REF! | P41: =N41+L41 -> #REF! | Q41: =P41*K41 -> #REF! | T41: =T36 -> #REF! | U41: =U36 -> #REF!
...

Sheet Bill 3-External works
A1: PROJECT/ DỰ ÁN : NEW WAREHOUSE/NHÀ KHO
A2: ADDRESS/ĐỊA CHỈ : VSIP 3, BINH DUONG, VIETNAM
A3: BILL No.04 : EXTERNAL WORKS
A4: No. | B4: DESCRIPTION | C4: STANDARD | D4: Unit | E4: DIMENSION | J4: QUANTITY | K4: Q'TY | L4: MATERIAL | N4: LABOUR & EQUIPMENT | P4: TOTAL COST(VND) | R4: REMARK
E5: No | F5: L | G5: W | H5: H | I5: HS | J5: COMPONENT | L5: UNIT | M5: AMOUNT | N5: UNIT | O5: AMOUNT | P5: UNIT | Q5: AMOUNT
A6: No.04 | B6: TOTAL OF BILL No.4: EXTERNAL WORKS
A7: =A14 -> IN.01 | B7: =B14 -> CLEARING AND LEVELING / DỌN DẸP VÀ SAN LẤP MẶT BẰNG
A8: =A19 -> IN.02 | B8: =B19 -> STORM DRAINAGE SYSTEM
A9: =A42 -> IN.03 | B9: =B42 -> ROAD WORKS / CÔNG TÁC ĐƯỜNG
A10: =A66 -> IN.04 | B10: =B66 -> FENCCING & GATES/ HÀNG RÀO VÀ CỔNG
A11: =A139 -> IN.05 | B11: =B139 -> LANDSCAPING WORKS/ CÔNG TÁC CẢNH QUAN
A12: =A142 -> IN.06 | B12: =B142 -> FLAG POLE/ CÔNG TÁC CỘT CỜ
A13: =A144 -> IN.07 | B13: =B144 -> OTHERS WORKS / CÔNG TÁC KHÁC
A14: IN.01 | B14: CLEARING AND LEVELING / DỌN DẸP VÀ SAN LẤP MẶT BẰNG
A15: 1 | B15: All trees, grass, roots, rubbish have to be removed out the site before the execution of cutting & filling work/Toàn bộ cây cối, cỏ, rễ cây, rác thải phải được dọn sạch khỏi công trường trước khi thực hiện công tác san lấp | D15: m2
A16: 2 | B16: Cutting soil/ Cắt lớp đất nền đến cao độ thiết kế | C16: Using soil from excavation and Levelling for elevation 0.3m , to ensure water drainage to VSIP | D16: m3
A17: 3 | B17: Remove surplus soil to to the land consolidation yard of VSIP1 industrial park/ Vận chuyển đất dư đến bải đổ đất của KCN VSIP | D17: m3
A19: IN.02 | B19: STORM DRAINAGE SYSTEM
A20: I | B20: MANHOLE/ HỐ GA
B21: R.C Manhole (including excavation, backfill. Compaction, formwork, rebars, concrete,bricks, concrete cover,edge steel etc.)
A22: 1 | B22: RC Manhole M1 | C22: 900x900xH1250-1500 | D22: pcs
A23: 2 | B23: RC Manhole M2 | C23: 1100x1100xH1550-1900 | D23: pcs
A24: 4 | B24: RC Manhole M3 | C24: 1300x1300xH1900-2400 | D24: pcs
A25: 5 | B25: RC Manhole M3a | C25: 1300x1300xH1900-2400 | D25: pcs
A26: 7 | B26: Waste water Manhole | C26: 800x800xH1200-2400 | D26: pcs
A27: II | B27: PIPING & FITTINGS/ ỐNG VÀ PHỤ KIỆN
B28: Male/female type with shaped concr. Supports, including excavation, backfill, compaction, etc. Combine with TCXDVN 372-2006
A29: 9 | B29: R.C pipe H30 DN300 | C29: ACC, Hung Vuong or equal | D29: m
A30: 11 | B30: R.C pipe H30 DN400 | C30: ACC, Hung Vuong or equal | D30: m
A31: 13 | B31: R.C pipe H30 DN500 | C31: ACC, Hung Vuong or equal | D31: m
A32: 15 | B32: R.C pipe H30 DN800 | C32: ACC, Hung Vuong or equal | D32: m
B33: uPVC storm pipe (PN10) - Underground pipe (including, hanger,support, accessories, excavation, backfill, compaction, etc, ...)
A34: 16 | B34: uPVC pipe D90 | C34: Bình Minh,Tien Phong | D34: m
A35: 16 | B35: uPVC pipe D140 | C35: Bình Minh,Tien Phong | D35: m
A36: 17 | B36: uPVC pipe D220 | C36: Bình Minh,Tien Phong | D36: m
A37: III | B37: OTHER WORKS/CÔNG TÁC KHÁC
A38: 1 | B38: Permit to connect storm drainage water system to the industrial waste water system/ Xin phép đầu nối nước mưa vào hệ thống nước mưa KCN | D38: lot
A39: 2 | B39: Return to their original state/ Hoàn trả lại hiện trạng sau khi kết nối nước mưa vào khu công nghiệp | D39: lot
A40: 3 | B40: Permit to connect industrial road system/ Xin phép đầu nối đường giao thông | D40: lot
A42: IN.03 | B42: ROAD WORKS / CÔNG TÁC ĐƯỜNG
...

Sheet SCHEDULE OF RATES 
A1: #REF!
A2: #REF!
A4: SCHEDULE OF RATES
A6: ITEM | B6: DESCRIPTION | C6: BASE SUPPLIER BRAND (BY NICON) | D6: BIDDER'S QTY | E6: UNIT | F6: MATERIAL RATE (VND) | G6: INSTALLATION RATE (VND) | H6: UNIT RATE (VND) | I6: AMOUNT (BIDDER QTY, VND) | J6: NICON REMARKS
B7: CSA
A8: 1 | B8: Earth works
B9: Non-woven geotextile layer | D9: 1 | E9: m2 | H9: =F9+G9 -> 0 | I9: =H9*D9 -> 0
B10: Woven geotextile layer | D10: 1 | E10: m2 | H10: =F10+G10 -> 0 | I10: =H10*D10 -> 0
B11: PE sheet 0.15mm | D11: 1 | E11: m2 | H11: =F11+G11 -> 0 | I11: =H11*D11 -> 0
B12: PE sheet 0.20mm | D12: 1 | E12: m2 | H12: =F12+G12 -> 0 | I12: =H12*D12 -> 0
B13: PE sheet 0.25mm | D13: 1 | E13: m2 | H13: =F13+G13 -> 0 | I13: =H13*D13 -> 0
B14: Polyolefin vaporbarrier-Perminator 15mil, 0.381mm thk. | D14: 1 | E14: m2 | H14: =F14+G14 -> 0 | I14: =H14*D14 -> 0
B15: Crushed stone, compacted | D15: 1 | E15: m3 | H15: =F15+G15 -> 0 | I15: =H15*D15 -> 0
B16: Laterite soil, compacted | D16: 1 | E16: m3 | H16: =F16+G16 -> 0 | I16: =H16*D16 -> 0
B17: Sand filling, compacted | D17: 1 | E17: m3 | H17: =F17+G17 -> 0 | I17: =H17*D17 -> 0
B18: Soil filling, compacted | D18: 1 | E18: m3 | H18: =F18+G18 -> 0 | I18: =H18*D18 -> 0
A19: 2 | B19: Piling works
B20: Supply PHC spun pile D300mm | D20: 1 | E20: m | H20: =F20+G20 -> 0 | I20: =H20*D20 -> 0
B21: Supply PHC spun pile D350mm | D21: 1 | E21: m | H21: =F21+G21 -> 0 | I21: =H21*D21 -> 0
B22: Supply PHC spun pile D400mm | D22: 1 | E22: m | H22: =F22+G22 -> 0 | I22: =H22*D22 -> 0
B23: Pressing PHC spun pile D300mm | D23: 1 | E23: m | H23: =F23+G23 -> 0 | I23: =H23*D23 -> 0
B24: Pressing PHC spun pile D350mm | D24: 1 | E24: m | H24: =F24+G24 -> 0 | I24: =H24*D24 -> 0
B25: Pressing PHC spun pile D400mm | D25: 1 | E25: m | H25: =F25+G25 -> 0 | I25: =H25*D25 -> 0
B26: Pre-drill PHC spun pile D300mm | D26: 1 | E26: m | H26: =F26+G26 -> 0 | I26: =H26*D26 -> 0
B27: Pre-drill PHC spun pile D350mm | D27: 1 | E27: m | H27: =F27+G27 -> 0 | I27: =H27*D27 -> 0
B28: Pre-drill PHC spun pile D400mm | D28: 1 | E28: m | H28: =F28+G28 -> 0 | I28: =H28*D28 -> 0
B29: Pile heads cut off and disposal surplus debris to assigned location, spun pile D300mm | D29: 1 | E29: nr | H29: =F29+G29 -> 0 | I29: =H29*D29 -> 0
B30: Pile heads cut off and disposal surplus debris to assigned location, spun pile D350mm | D30: 1 | E30: nr | H30: =F30+G30 -> 0 | I30: =H30*D30 -> 0
B31: Pile heads cut off and disposal surplus debris to assigned location, spun pile D400mm | D31: 1 | E31: nr | H31: =F31+G31 -> 0 | I31: =H31*D31 -> 0
A32: 3 | B32: Concrete works
B33: Structure concrete, type B, grade B20 | D33: 1 | E33: m3 | H33: =F33+G33 -> 0 | I33: =H33*D33 -> 0
B34: Structure concrete, type C, grade B22.5 | D34: 1 | E34: m3 | H34: =F34+G34 -> 0 | I34: =H34*D34 -> 0
B35: Structure concrete, type D, grade B30 | D35: 1 | E35: m3 | H35: =F35+G35 -> 0 | I35: =H35*D35 -> 0
B36: Steel fair-face formworks | D36: 1 | E36: m2 | H36: =F36+G36 -> 0 | I36: =H36*D36 -> 0
B37: Plywood fair-face formworks | D37: 1 | E37: m2 | H37: =F37+G37 -> 0 | I37: =H37*D37 -> 0
B38: Steel weldmesh Ø12-150 | D38: 1 | E38: m2 | H38: =F38+G38 -> 0 | I38: =H38*D38 -> 0
B39: Steel weldmesh Ø12-200 | D39: 1 | E39: m2 | H39: =F39+G39 -> 0 | I39: =H39*D39 -> 0
B40: Steel weldmesh Ø10-150 | D40: 1 | E40: m2 | H40: =F40+G40 -> 0 | I40: =H40*D40 -> 0
B41: Steel weldmesh Ø10-200 | D41: 1 | E41: m2 | H41: =F41+G41 -> 0 | I41: =H41*D41 -> 0
B42: Steel weldmesh Ø8-150 | D42: 1 | E42: m2 | H42: =F42+G42 -> 0 | I42: =H42*D42 -> 0
...

Sheet E02.ELV SYSTEM 
A1: ESTIMATE DETAIL TABLE
A2: ='Bill 3-External works'!#REF! -> #REF!
A3: ITEM/HẠNG MỤC : ELV SYSTEM/ HỆ THỐNG ĐIỆN NHẸ
A5: No. | B5: DESCRIPTION | C5: STANDARD | D5: Unit | E5: DIMENSION | J5: QUANTITY | K5: Q'TY | L5: MATERIAL | N5: LABOUR & EQUIPMENT | P5: TOTAL COST | R5: REMARK | S5: =#REF! -> #REF! | T5: =#REF! -> #REF!
E6: No | F6: L | G6: W | H6: H | I6: HS | J6: COMPONENT | L6: UNIT | M6: AMOUNT | N6: UNIT | O6: AMOUNT | P6: UNIT | Q6: AMOUNT | T6: =#REF! -> #REF! | U6: =#REF! -> #REF!
A7: E02 | B7: ELV SYSTEM/ HỆ THỐNG ĐIỆN NHẸ | M7: =SUBTOTAL(109,M8:M13) -> #REF! | O7: =SUBTOTAL(109,O8:O13) -> #REF! | Q7: =O7+M7 -> #REF!
A8: =A14 -> I | B8: =B14 -> DATA AND TEL SYSTEM/ HỆ THỐNG MẠNG, ĐIỆN THOẠI | M8: =M14 -> #REF! | O8: =O14 -> #REF! | Q8: =O8+M8 -> #REF!
A9: =A38 -> II | B9: =B38 -> CAMERA SYSTEM / HỆ THỐNG CAMERA | M9: =M38 -> #REF! | O9: =O38 -> #REF! | Q9: =O9+M9 -> #REF!
A10: =A62 -> III | B10: =B62 -> PA SYSTEM/ HỆ THỐNG ÂM THANH | M10: =M62 -> #REF! | O10: =O62 -> #REF! | Q10: =O10+M10 -> #REF!
A11: =A80 -> IV | B11: =B80 -> DOOR ACCESS CONTROL SYSTEM / HỆ THỐNG KIỂM SOÁT RA / VÀO | M11: =M80 -> #REF! | O11: =O80 -> #REF! | Q11: =O11+M11 -> #REF!
A12: =A95 -> V | B12: =B95 -> ELV EARTHING SYSTEM / HỆ THỐNG NỐI ĐẤT ELV | M12: =M95 -> #REF! | O12: =O95 -> #REF! | Q12: =O12+M12 -> #REF!
A14: I | B14: DATA AND TEL SYSTEM/ HỆ THỐNG MẠNG, ĐIỆN THOẠI | M14: =SUBTOTAL(109,M15:M37) -> #REF! | O14: =SUBTOTAL(109,O15:O37) -> #REF! | Q14: =O14+M14 -> #REF!
A15: 1 | B15: Cabinet 19" - 27U Rack Power Distribution Unit, 6 Universal Outlets, 16A, 250V, MCB/ Tủ rack điện nhẹ 19" - 27U, 6 Universal Outlets, 16A, 250V, MCB | C15: VN | D15: set | K15: 1 | L15: =T15*$T$5 -> #REF! | M15: =ROUND(L15*K15,0) -> #REF! | N15: =U15*$T$5 -> #REF! | O15: =ROUND(N15*K15,0) -> #REF! | P15: =N15+L15 -> #REF! | Q15: =P15*K15 -> #REF! | T15: 7285000 | U15: 420000
A16: 2 | B16: MDF 200pairs/ Hộp điện thoại 200 đôi | C16: Krone VN | D16: set | K16: 1 | L16: =T16*$T$5 -> #REF! | M16: =ROUND(L16*K16,0) -> #REF! | N16: =U16*$T$5 -> #REF! | O16: =ROUND(N16*K16,0) -> #REF! | P16: =N16+L16 -> #REF! | Q16: =P16*K16 -> #REF! | T16: 1635000 | U16: 490500
A17: 3 | B17: Patch panel 24 ports - CAT6/ Thanh đấu nối cáp | C17: COMMSCOPE | D17: set | K17: 5 | L17: =T17*$T$5 -> #REF! | M17: =ROUND(L17*K17,0) -> #REF! | N17: =U17*$T$5 -> #REF! | O17: =ROUND(N17*K17,0) -> #REF! | P17: =N17+L17 -> #REF! | Q17: =P17*K17 -> #REF! | T17: 4224000 | U17: 397400
A18: 4 | B18: ODF 24 cores - Singlemode/ Hộp đấu nối sợi quang 24 cores | C18: VN | D18: set | K18: 1 | L18: =T18*$T$5 -> #REF! | M18: =ROUND(L18*K18,0) -> #REF! | N18: =U18*$T$5 -> #REF! | O18: =ROUND(N18*K18,0) -> #REF! | P18: =N18+L18 -> #REF! | Q18: =P18*K18 -> #REF! | T18: 1750000 | U18: 525000
A19: 5 | B19: ODF 6 cores - Singlemode/ Hộp đấu nối sợi quang 6 cores | C19: VN | D19: set | K19: 3 | L19: =T19*$T$5 -> #REF! | M19: =ROUND(L19*K19,0) -> #REF! | N19: =U19*$T$5 -> #REF! | O19: =ROUND(N19*K19,0) -> #REF! | P19: =N19+L19 -> #REF! | Q19: =P19*K19 -> #REF! | T19: 605000 | U19: 181500
A20: 6 | B20: Fiber optic cable assembly/ Cáp đấu nối sợi quang | C20: VN | D20: pcs | K20: =24 -> 24 | L20: =T20*$T$5 -> #REF! | M20: =ROUND(L20*K20,0) -> #REF! | N20: =U20*$T$5 -> #REF! | O20: =ROUND(N20*K20,0) -> #REF! | P20: =N20+L20 -> #REF! | Q20: =P20*K20 -> #REF! | T20: 125000 | U20: 136000
A21: 7 | B21: Converter/ Bộ chuyển đổi quang | C21: TPLINK | D21: set | K21: 6 | L21: =T21*$T$5 -> #REF! | M21: =ROUND(L21*K21,0) -> #REF! | N21: =U21*$T$5 -> #REF! | O21: =ROUND(N21*K21,0) -> #REF! | P21: =N21+L21 -> #REF! | Q21: =P21*K21 -> #REF! | T21: 2600000 | U21: 520000
A22: 8 | B22: Tray power Media converter 6 modules/ Khay nguồn bộ chuyển đổi 6 modules | C22: VN | D22: set | K22: 1 | L22: =T22*$T$5 -> #REF! | M22: =ROUND(L22*K22,0) -> #REF! | N22: =U22*$T$5 -> #REF! | O22: =ROUND(N22*K22,0) -> #REF! | P22: =N22+L22 -> #REF! | Q22: =P22*K22 -> #REF! | T22: 2300000 | U22: 150000
A23: 9 | B23: Core Switch - 24port/ Thiết bị chuyển mạch 24 cổng | C23: RUIJIE | D23: pcs | K23: 1 | L23: =T23*$T$5 -> #REF! | M23: =ROUND(L23*K23,0) -> #REF! | N23: =U23*$T$5 -> #REF! | O23: =ROUND(N23*K23,0) -> #REF! | P23: =N23+L23 -> #REF! | Q23: =P23*K23 -> #REF! | T23: 7144800 | U23: 580000
A24: 10 | B24: UPS 3KVA, backup 30mins / Bộ lưu điện 3KVA , lưu điện 30 phút | C24: SANTAK | D24: pcs | K24: 1 | L24: =T24*$T$5 -> #REF! | M24: =ROUND(L24*K24,0) -> #REF! | N24: =U24*$T$5 -> #REF! | O24: =ROUND(N24*K24,0) -> #REF! | P24: =N24+L24 -> #REF! | Q24: =P24*K24 -> #REF! | T24: 27370000 | U24: 350000
A25: 11 | B25: PABX 3CO/64EX/ Tổng đài điện thoại | C25: NEC | D25: pcs | K25: 1 | L25: =T25*$T$5 -> #REF! | M25: =ROUND(L25*K25,0) -> #REF! | N25: =U25*$T$5 -> #REF! | O25: =ROUND(N25*K25,0) -> #REF! | P25: =N25+L25 -> #REF! | Q25: =P25*K25 -> #REF! | T25: 52000000 | U25: 1800000
A26: 12 | B26: Telephone/data socket, floor outlet/ Ổ cắm điện thoại, mạng, lắp âm sàn | C26: SINO | D26: pcs | K26: =6+12 -> 18 | L26: =T26*$T$5 -> #REF! | M26: =ROUND(L26*K26,0) -> #REF! | N26: =U26*$T$5 -> #REF! | O26: =ROUND(N26*K26,0) -> #REF! | P26: =N26+L26 -> #REF! | Q26: =P26*K26 -> #REF! | T26: 858000 | U26: 257400
A27: 13 | B27: Telephone socket/ Data socket outlet (CAT6), wall mounted/ Ổ cắm điện thoại/ mạng gắn tường | C27: SINO | D27: pcs | K27: =1+6+4+1 -> 12 | L27: =T27*$T$5 -> #REF! | M27: =ROUND(L27*K27,0) -> #REF! | N27: =U27*$T$5 -> #REF! | O27: =ROUND(N27*K27,0) -> #REF! | P27: =N27+L27 -> #REF! | Q27: =P27*K27 -> #REF! | T27: 27000 | U27: 8100
A28: 14 | B28: Data socket outlet (CAT6), wall mounted/ Ổ cắm mạng gắn tường | C28: SINO | D28: pcs | K28: =3+3 -> 6 | L28: =T28*$T$5 -> #REF! | M28: =ROUND(L28*K28,0) -> #REF! | N28: =U28*$T$5 -> #REF! | O28: =ROUND(N28*K28,0) -> #REF! | P28: =N28+L28 -> #REF! | Q28: =P28*K28 -> #REF! | T28: 27000 | U28: 8100
A29: 15 | B29: Telephone socket outlet (CAT6), wall mounted/ Ổ cắm điện thoại gắn tường | C29: SINO | D29: pcs | K29: 1 | L29: =T29*$T$5 -> #REF! | M29: =ROUND(L29*K29,0) -> #REF! | N29: =U29*$T$5 -> #REF! | O29: =ROUND(N29*K29,0) -> #REF! | P29: =N29+L29 -> #REF! | Q29: =P29*K29 -> #REF! | T29: 27000 | U29: 8100
A30: 16 | B30: Patch cord FTP, CAT6, 4pair/ Dây nhảy | C30: SINO | D30: pcs | K30: =K26*2+K27*2+K28+K29+15 -> 82 | L30: =T30*$T$5 -> #REF! | M30: =ROUND(L30*K30,0) -> #REF! | N30: =U30*$T$5 -> #REF! | O30: =ROUND(N30*K30,0) -> #REF! | P30: =N30+L30 -> #REF! | Q30: =P30*K30 -> #REF! | T30: 32000 | U30: 136000
A31: 17 | B31: Telephone cable 10P - 0.5mm/ Cáp điện thoại 10 đôi, 0.5mm | C31: SINO | D31: m | K31: 121 | L31: =T31*$T$5 -> #REF! | M31: =ROUND(L31*K31,0) -> #REF! | N31: =U31*$T$5 -> #REF! | O31: =ROUND(N31*K31,0) -> #REF! | P31: =N31+L31 -> #REF! | Q31: =P31*K31 -> #REF! | T31: 25920 | U31: 7776
A32: 18 | B32: Cable UTP CAT5e/ Cáp UTP CAT5e | C32: COMMSCOPE | D32: m | K32: 690 | L32: =T32*$T$5 -> #REF! | M32: =ROUND(L32*K32,0) -> #REF! | N32: =U32*$T$5 -> #REF! | O32: =ROUND(N32*K32,0) -> #REF! | P32: =N32+L32 -> #REF! | Q32: =P32*K32 -> #REF! | T32: 7300 | U32: 2190
A33: 19 | B33: Cable FTP, CAT6, 4pair/ Cáp FTP, CAT6, 4pair | D33: m | K33: 1955 | L33: =T33*$T$5 -> #REF! | M33: =ROUND(L33*K33,0) -> #REF! | N33: =U33*$T$5 -> #REF! | O33: =ROUND(N33*K33,0) -> #REF! | P33: =N33+L33 -> #REF! | Q33: =P33*K33 -> #REF! | T33: 19500 | U33: 6200
A34: 20 | B34: PVC conduit D20/ Ống điện D20 | D34: m | K34: 1150 | L34: =T34*$T$5 -> #REF! | M34: =ROUND(L34*K34,0) -> #REF! | N34: =U34*$T$5 -> #REF! | O34: =ROUND(N34*K34,0) -> #REF! | P34: =N34+L34 -> #REF! | Q34: =P34*K34 -> #REF! | U34: 22000
A35: 21 | B35: Testing and comisioning/ Kiểm tra và vận hành thử | D35: lot | K35: 1 | L35: =T35*$T$5 -> #REF! | M35: =ROUND(L35*K35,0) -> #REF! | N35: =U35*$T$5 -> #REF! | O35: =ROUND(N35*K35,0) -> #REF! | P35: =N35+L35 -> #REF! | Q35: =P35*K35 -> #REF! | U35: 25000000
A36: 22 | B36: Accessories / Vật tư phụ | D36: lot | K36: 1 | L36: =T36*$T$5 -> #REF! | M36: =ROUND(L36*K36,0) -> #REF! | N36: =U36*$T$5 -> #REF! | O36: =ROUND(N36*K36,0) -> #REF! | P36: =N36+L36 -> #REF! | Q36: =P36*K36 -> #REF! | T36: 13745000
A38: II | B38: CAMERA SYSTEM / HỆ THỐNG CAMERA | M38: =SUBTOTAL(9,M39:M60) -> #REF! | O38: =SUBTOTAL(9,O39:O60) -> #REF! | Q38: =O38+M38 -> #REF!
A39: 1 | B39: Cabinet 19" - 9U Rack Power Distribution Unit, 6 Universal Outlets, 16A, 250V, MCB/ Tủ rack điện nhẹ 19" - 9U, 6 Universal Outlets, 16A, 250V, MCB | D39: set | K39: 3 | L39: =T39*$T$5 -> #REF! | M39: =ROUND(L39*K39,0) -> #REF! | N39: =U39*$T$5 -> #REF! | O39: =ROUND(N39*K39,0) -> #REF! | P39: =N39+L39 -> #REF! | Q39: =P39*K39 -> #REF! | T39: 7285000 | U39: 420000
A40: 2 | B40: Camera dome IP Dome colors IP camera - 24/7 Colorful imaging - High quality imaging with 2 MP resolution - Efficient H.265+ compression technology - Maximum IR beam distance : 15m | C40: HIKVISION | D40: pcs | K40: 5 | L40: =T40*$T$5 -> #REF! | M40: =ROUND(L40*K40,0) -> #REF! | N40: =U40*$T$5 -> #REF! | O40: =ROUND(N40*K40,0) -> #REF! | P40: =N40+L40 -> #REF! | Q40: =P40*K40 -> #REF! | T40: 1701000 | U40: 180000
A41: 3 | B41: Camera IP thân dài Colors IP camera - 24/7 Colorful imaging - High quality imaging with 2 MP resolution - Efficient H.265+ compression technology - Water and dust resistant (IP66) - Maximum IR beam distance : 30m | C41: HIKVISION | D41: pcs | K41: 23 | L41: =T41*$T$5 -> #REF! | M41: =ROUND(L41*K41,0) -> #REF! | N41: =U41*$T$5 -> #REF! | O41: =ROUND(N41*K41,0) -> #REF! | P41: =N41+L41 -> #REF! | Q41: =P41*K41 -> #REF! | T41: 1701000 | U41: 180000
A42: 4 | B42: Camera IP thân dài Colors IP camera - 24/7 Colorful imaging - High quality imaging with 2 MP resolution - Efficient H.265+ compression technology - Water and dust resistant (IP66) - Maximum IR beam distance : 50m | C42: HIKVISION | D42: pcs | K42: 4 | L42: =T42*$T$5 -> #REF! | M42: =ROUND(L42*K42,0) -> #REF! | N42: =U42*$T$5 -> #REF! | O42: =ROUND(N42*K42,0) -> #REF! | P42: =N42+L42 -> #REF! | Q42: =P42*K42 -> #REF! | T42: 2025000 | U42: 180000
A43: 5 | B43: NVR 32chance - H.265+/H.265/H.264+/H.264 video formats - Intelligent analytics based on deep learning algorithm - Up to 4 SATA interfaces for HDD connection - 2 self-adaptive 10/100/1000 Mbps Ethernet interfaces | C43: COMMSCOPE | D43: set | K43: 1 | L43: =T43*$T$5 -> #REF! | M43: =ROUND(L43*K43,0) -> #REF! | N43: =U43*$T$5 -> #REF! | O43: =ROUND(N43*K43,0) -> #REF! | P43: =N43+L43 -> #REF! | Q43: =P43*K43 -> #REF! | T43: 10560000 | U43: 320000
...

Sheet PL01.PLUMPING
A1: ESTIMATE DETAIL TABLE | N1: hd
A2: ='Bill 3-External works'!#REF! -> #REF!
A3: ITEM/HẠNG MỤC : PLUMPING SYSTEM/HỆ THỐNG NƯỚC
A5: No. | B5: DESCRIPTION | C5: STANDARD | D5: Unit | E5: DIMENSION | J5: QUANTITY | K5: Q'TY | L5: MATERIAL | N5: LABOUR & EQUIPMENT | P5: TOTAL COST | R5: REMARK | S5: ='E02.ELV SYSTEM '!S5 -> #REF! | T5: ='E02.ELV SYSTEM '!T5 -> #REF!
E6: No | F6: L | G6: W | H6: H | I6: HS | J6: COMPONENT | L6: UNIT | M6: AMOUNT | N6: UNIT | O6: AMOUNT | P6: UNIT | Q6: AMOUNT | T6: ='E02.ELV SYSTEM '!T6 -> #REF! | U6: ='E02.ELV SYSTEM '!U6 -> #REF!
A7: P01 | B7: PLUMPING SYSTEM/HỆ THỐNG CẤP THOÁT NƯỚC | M7: =SUM(M8:M11) -> #REF! | O7: =SUM(O8:O11) -> #REF! | Q7: =M7+O7 -> #REF!
A8: =A12 -> I | B8: =B12 -> WATER SUPPLY SYSTEM/ HỆ THỐNG CẤP NƯỚC | M8: =M12 -> #REF! | O8: =O12 -> #REF! | Q8: =Q12 -> #REF!
A9: =A61 -> II | B9: =B61 -> WATER DRAINAGE SYSTEM/ HỆ THỐNG THOÁT NƯỚC | M9: =M61 -> #REF! | O9: =O61 -> #REF! | Q9: =Q61 -> #REF!
A10: =A114 -> III | B10: =B114 -> OTHER WORKS/CÔNG TÁC KHÁC | M10: =M114 -> #REF! | O10: =O114 -> #REF! | Q10: =O10+M10 -> #REF!
A12: I | B12: WATER SUPPLY SYSTEM/ HỆ THỐNG CẤP NƯỚC | M12: =SUBTOTAL(109,M13:M60) -> #REF! | O12: =SUBTOTAL(109,O13:O60) -> #REF! | Q12: =O12+M12 -> #REF!
B13: PIPING WORKS/ ĐƯỜNG ỐNG
A14: 1 | B14: PP-R pipe DN65/ Ống PP-R DN65 | D14: m | K14: 90 | L14: =T14*$T$5 -> #REF! | M14: =ROUND(L14*K14,0) -> #REF! | N14: =U14*$T$5 -> #REF! | O14: =ROUND(N14*K14,0) -> #REF! | P14: =N14+L14 -> #REF! | Q14: =P14*K14 -> #REF! | T14: 134657.14 | U14: 54000
A15: 2 | B15: Galvanized steel pipe DN80/Ống tráng kẽm lồng DN80 | D15: m | K15: 36 | L15: =T15*$T$5 -> #REF! | M15: =ROUND(L15*K15,0) -> #REF! | N15: =U15*$T$5 -> #REF! | O15: =ROUND(N15*K15,0) -> #REF! | P15: =N15+L15 -> #REF! | Q15: =P15*K15 -> #REF! | T15: 158571.43 | U15: 160000
A16: 3 | B16: PP-R pipe DN50/ Ống PP-R DB50 | D16: m | K16: 23 | L16: =T16*$T$5 -> #REF! | M16: =ROUND(L16*K16,0) -> #REF! | N16: =U16*$T$5 -> #REF! | O16: =ROUND(N16*K16,0) -> #REF! | P16: =N16+L16 -> #REF! | Q16: =P16*K16 -> #REF! | T16: 84428.571 | U16: 44000
A17: 4 | B17: PP-R pipe DN40/ Ống PP-R DN40 | D17: m | K17: 132 | L17: =T17*$T$5 -> #REF! | M17: =ROUND(L17*K17,0) -> #REF! | N17: =U17*$T$5 -> #REF! | O17: =ROUND(N17*K17,0) -> #REF! | P17: =N17+L17 -> #REF! | Q17: =P17*K17 -> #REF! | T17: 57600 | U17: 36000
A18: 5 | B18: PP-R pipe DN32/ Ống PP-R DN32 | D18: m | K18: 160 | L18: =T18*$T$5 -> #REF! | M18: =ROUND(L18*K18,0) -> #REF! | N18: =U18*$T$5 -> #REF! | O18: =ROUND(N18*K18,0) -> #REF! | P18: =N18+L18 -> #REF! | Q18: =P18*K18 -> #REF! | T18: 42942.857 | U18: 32000
A19: 6 | B19: PP-R pipe DN25/ Ống PP-R DN25 | D19: m | K19: 149 | L19: =T19*$T$5 -> #REF! | M19: =ROUND(L19*K19,0) -> #REF! | N19: =U19*$T$5 -> #REF! | O19: =ROUND(N19*K19,0) -> #REF! | P19: =N19+L19 -> #REF! | Q19: =P19*K19 -> #REF! | T19: 23571.429 | U19: 25000
A20: 7 | B20: PP-R pipe DN20/ Ống PP-R DN20 | D20: m | K20: 172 | L20: =T20*$T$5 -> #REF! | M20: =ROUND(L20*K20,0) -> #REF! | N20: =U20*$T$5 -> #REF! | O20: =ROUND(N20*K20,0) -> #REF! | P20: =N20+L20 -> #REF! | Q20: =P20*K20 -> #REF! | T20: 15514.286 | U20: 20000
A21: 8 | B21: Fitting for pipe/ Phụ kiện đường ống | D21: lot | K21: 1 | L21: =T21*$T$5 -> #REF! | M21: =ROUND(L21*K21,0) -> #REF! | N21: =U21*$T$5 -> #REF! | O21: =ROUND(N21*K21,0) -> #REF! | P21: =N21+L21 -> #REF! | Q21: =P21*K21 -> #REF! | T21: 20727969 | U21: 6218390.6
A22: 9 | B22: Excavation and backfilling for underground pipe/ Đào và lắp đất cho đường ống ngầm | D22: lot | K22: 1 | L22: =T22*$T$5 -> #REF! | M22: =ROUND(L22*K22,0) -> #REF! | N22: =U22*$T$5 -> #REF! | O22: =ROUND(N22*K22,0) -> #REF! | P22: =N22+L22 -> #REF! | Q22: =P22*K22 -> #REF! | U22: 16800000
A23: 10 | B23: Hanger, support/ Giá đỡ, ty treo | D23: lot | K23: 1 | L23: =T23*$T$5 -> #REF! | M23: =ROUND(L23*K23,0) -> #REF! | N23: =U23*$T$5 -> #REF! | O23: =ROUND(N23*K23,0) -> #REF! | P23: =N23+L23 -> #REF! | Q23: =P23*K23 -> #REF! | T23: 6909322.9 | U23: 2072796.9
A24: 11 | B24: Accessories/Vật tư phụ | D24: lot | K24: 1 | L24: =T24*$T$5 -> #REF! | M24: =ROUND(L24*K24,0) -> #REF! | N24: =U24*$T$5 -> #REF! | O24: =ROUND(N24*K24,0) -> #REF! | P24: =N24+L24 -> #REF! | Q24: =P24*K24 -> #REF! | T24: 1750000 | U24: 350000
B25: VALVE/ VAN
A26: 8 | B26: Gate valve D63/ Van cổng D63 | D26: pcs | K26: 2 | L26: =T26*$T$5 -> #REF! | M26: =ROUND(L26*K26,0) -> #REF! | N26: =U26*$T$5 -> #REF! | O26: =ROUND(N26*K26,0) -> #REF! | P26: =N26+L26 -> #REF! | Q26: =P26*K26 -> #REF! | T26: 1057114.3 | U26: 80000
A27: 9 | B27: Gate valve D50/ Van cổng D50 | D27: pcs | K27: 2 | L27: =T27*$T$5 -> #REF! | M27: =ROUND(L27*K27,0) -> #REF! | N27: =U27*$T$5 -> #REF! | O27: =ROUND(N27*K27,0) -> #REF! | P27: =N27+L27 -> #REF! | Q27: =P27*K27 -> #REF! | T27: 679714.29 | U27: 60000
A28: 10 | B28: Gate valve D40/ Van cổng D40 | D28: pcs | K28: 1 | L28: =T28*$T$5 -> #REF! | M28: =ROUND(L28*K28,0) -> #REF! | N28: =U28*$T$5 -> #REF! | O28: =ROUND(N28*K28,0) -> #REF! | P28: =N28+L28 -> #REF! | Q28: =P28*K28 -> #REF! | T28: 441171.43 | U28: 50000
A29: 11 | B29: Gate valve D32/ Van cổng D32 | D29: pcs | K29: 9 | L29: =T29*$T$5 -> #REF! | M29: =ROUND(L29*K29,0) -> #REF! | N29: =U29*$T$5 -> #REF! | O29: =ROUND(N29*K29,0) -> #REF! | P29: =N29+L29 -> #REF! | Q29: =P29*K29 -> #REF! | T29: 262971.43 | U29: 45000
A30: 12 | B30: Gate valve D25/ Van cổng D25 | D30: pcs | K30: 7 | L30: =T30*$T$5 -> #REF! | M30: =ROUND(L30*K30,0) -> #REF! | N30: =U30*$T$5 -> #REF! | O30: =ROUND(N30*K30,0) -> #REF! | P30: =N30+L30 -> #REF! | Q30: =P30*K30 -> #REF! | T30: 185314.29 | U30: 40000
A31: 13 | B31: Gate valve D20/ Van cổng D20 | D31: pcs | K31: 6 | L31: =T31*$T$5 -> #REF! | M31: =ROUND(L31*K31,0) -> #REF! | N31: =U31*$T$5 -> #REF! | O31: =ROUND(N31*K31,0) -> #REF! | P31: =N31+L31 -> #REF! | Q31: =P31*K31 -> #REF! | T31: 158571.43 | U31: 35000
A32: 14 | B32: Faucet for watering plants/ Vòi nước tưới cây | D32: pcs | K32: 14 | L32: =T32*$T$5 -> #REF! | M32: =ROUND(L32*K32,0) -> #REF! | N32: =U32*$T$5 -> #REF! | O32: =ROUND(N32*K32,0) -> #REF! | P32: =N32+L32 -> #REF! | Q32: =P32*K32 -> #REF! | T32: 135000 | U32: 30000
B33: METER ASSEMBLY/ CỤM ĐỒNG HỒ
A34: 19 | B34: Gate valve DN50/ Van cổng DN50 | K34: 2 | L34: =T34*$T$5 -> #REF! | M34: =ROUND(L34*K34,0) -> #REF! | N34: =U34*$T$5 -> #REF! | O34: =ROUND(N34*K34,0) -> #REF! | P34: =N34+L34 -> #REF! | Q34: =P34*K34 -> #REF! | T34: 679714.29 | U34: 60000
A35: 20 | B35: Male socke DN65/ Đầu nối răng DN65 | K35: 4 | L35: =T35*$T$5 -> #REF! | M35: =ROUND(L35*K35,0) -> #REF! | N35: =U35*$T$5 -> #REF! | O35: =ROUND(N35*K35,0) -> #REF! | P35: =N35+L35 -> #REF! | Q35: =P35*K35 -> #REF! | T35: 276000 | U35: 60000
A36: 21 | B36: Adaptor DN65/ Rắc co DN65 | K36: 2 | L36: =T36*$T$5 -> #REF! | M36: =ROUND(L36*K36,0) -> #REF! | N36: =U36*$T$5 -> #REF! | O36: =ROUND(N36*K36,0) -> #REF! | P36: =N36+L36 -> #REF! | Q36: =P36*K36 -> #REF! | T36: 445000 | U36: 60000
A37: 22 | B37: Water meter DN50/ Đồng hồ nước DN50 | K37: 1 | L37: =T37*$T$5 -> #REF! | M37: =ROUND(L37*K37,0) -> #REF! | N37: =U37*$T$5 -> #REF! | O37: =ROUND(N37*K37,0) -> #REF! | P37: =N37+L37 -> #REF! | Q37: =P37*K37 -> #REF! | T37: 6500000 | U37: 2500000
A38: 23 | B38: Cover box water clock/Hộp chứa đồng hồ | K38: 1 | L38: =T38*$T$5 -> #REF! | M38: =ROUND(L38*K38,0) -> #REF! | N38: =U38*$T$5 -> #REF! | O38: =ROUND(N38*K38,0) -> #REF! | P38: =N38+L38 -> #REF! | Q38: =P38*K38 -> #REF! | T38: 555000 | U38: 125000
A39: 24 | B39: Accessories / Vật tư phụ | K39: 1 | L39: =T39*$T$5 -> #REF! | M39: =ROUND(L39*K39,0) -> #REF! | N39: =U39*$T$5 -> #REF! | O39: =ROUND(N39*K39,0) -> #REF! | P39: =N39+L39 -> #REF! | Q39: =P39*K39 -> #REF! | T39: 12833429 | U39: 3850028.6
B40: COMPLETED SET BOOSTER PUMP 1ST FLOOR/CỤM BỒN NƯỚC MÁY BƠM TẦNG TRỆT
A41: 25 | B41: 2000L SS304 water tank/Bồn nước đứng INOX 2000l | D41: pcs | K41: 1 | L41: =T41*$T$5 -> #REF! | M41: =ROUND(L41*K41,0) -> #REF! | N41: =U41*$T$5 -> #REF! | O41: =ROUND(N41*K41,0) -> #REF! | P41: =N41+L41 -> #REF! | Q41: =P41*K41 -> #REF! | T41: 8150000 | U41: 825000
A42: 26 | B42: Float vale/ Van phao cơ | D42: pcs | K42: 2 | L42: =T42*$T$5 -> #REF! | M42: =ROUND(L42*K42,0) -> #REF! | N42: =U42*$T$5 -> #REF! | O42: =ROUND(N42*K42,0) -> #REF! | P42: =N42+L42 -> #REF! | Q42: =P42*K42 -> #REF! | T42: 1850000 | U42: 115000
...

Sheet AC01.HVAC 
A1: ESTIMATE DETAIL TABLE | N1: hd
A2: ='Bill 3-External works'!#REF! -> #REF!
A3: ITEM/HẠNG MỤC : HVAC SYSTEM/ HỆ THỐNG HVAC
A5: No. | B5: DESCRIPTION | C5: STANDARD | D5: Unit | E5: DIMENSION | J5: QUANTITY | K5: Q'TY | L5: MATERIAL | N5: LABOUR & EQUIPMENT | P5: TOTAL COST(VND) | R5: REMARK | S5: ='C03.CSA_ANCILLARAY'!S5 -> Profit | T5: ='C03.CSA_ANCILLARAY'!T5 -> #REF!
E6: No | F6: L | G6: W | H6: H | I6: HS | J6: COMPONENT | L6: UNIT | M6: AMOUNT | N6: UNIT | O6: AMOUNT | P6: UNIT | Q6: AMOUNT | T6: ='C03.CSA_ANCILLARAY'!T6 -> Vật tư | U6: ='C03.CSA_ANCILLARAY'!U6 -> Nhân công
A7: AC01 | B7: HVAC SYSTEM/ HỆ THỐNG HVAC | M7: =SUBTOTAL(109,M8:M10) -> #REF! | O7: =SUBTOTAL(109,O8:O10) -> #REF! | Q7: =O7+M7 -> #REF!
A8: =A11 -> I | B8: =B11 -> AIR CONDITIONING SYSTEM /HỆ THỐNG ĐIỀU HÒA KHÔNG KHÍ | L8: =L11 -> 0 | M8: =M11 -> #REF! | N8: =N11 -> 0 | O8: =O11 -> #REF! | P8: =P11 -> 0 | Q8: =Q11 -> #REF!
A9: =A33 -> II | B9: =B33 -> VENTILATION SYSTEM/ HỆ THỐNG THÔNG GIÓ | L9: =L33 -> 0 | M9: =M33 -> #REF! | N9: =N33 -> 0 | O9: =O33 -> #REF! | P9: =P33 -> 0 | Q9: =Q33 -> #REF!
A11: I | B11: AIR CONDITIONING SYSTEM /HỆ THỐNG ĐIỀU HÒA KHÔNG KHÍ | M11: =SUBTOTAL(109,M12:M32) -> #REF! | O11: =SUBTOTAL(109,O12:O32) -> #REF! | Q11: =O11+M11 -> #REF!
A12: A | B12: Equipment / Thiết bị
A13: 1 | B13: Ceiling air conditioner,Cooling capacity: 24.000Btu/h / Máy lạnh âm trần,công suất lạnh: 24.000Btu/h | C13: Daikin-Inverter | D13: set | K13: 5 | L13: =T13*$T$5 -> #REF! | M13: =ROUND(L13*K13,0) -> #REF! | N13: =U13*$T$5 -> #REF! | O13: =ROUND(N13*K13,0) -> #REF! | P13: =N13+L13 -> #REF! | Q13: =P13*K13 -> #REF! | T13: 35687270 | U13: 1826000
A14: 2 | B14: Ceiling air conditioner,Cooling capacity: 36.000Btu/h/ Máy lạnh âm trần,công suất lạnh: 36.000Btu/h | C14: Daikin-Inverter | D14: set | K14: 2 | L14: =T14*$T$5 -> #REF! | M14: =ROUND(L14*K14,0) -> #REF! | N14: =U14*$T$5 -> #REF! | O14: =ROUND(N14*K14,0) -> #REF! | P14: =N14+L14 -> #REF! | Q14: =P14*K14 -> #REF! | T14: 46490000 | U14: 2310000
A15: 3 | B15: Wall mounted indoor unit,Capacity: 9.000Btu/h /Dàn lạnh gắn tường,công suất lạnh: 9.000Btu/h | C15: Daikin-Inverter | D15: set | K15: 4 | L15: =T15*$T$5 -> #REF! | M15: =ROUND(L15*K15,0) -> #REF! | N15: =U15*$T$5 -> #REF! | O15: =ROUND(N15*K15,0) -> #REF! | P15: =N15+L15 -> #REF! | Q15: =P15*K15 -> #REF! | T15: 10538182 | U15: 495000
A16: 4 | B16: Split air conditioner, Cooling Capacity: 12.000Btu/h / Máy lạnh gắn tường,công suất lạnh: 12.000Btu/h | C16: Daikin-Inverter | D16: set | K16: 2 | L16: =T16*$T$5 -> #REF! | M16: =ROUND(L16*K16,0) -> #REF! | N16: =U16*$T$5 -> #REF! | O16: =ROUND(N16*K16,0) -> #REF! | P16: =N16+L16 -> #REF! | Q16: =P16*K16 -> #REF! | T16: 12727273 | U16: 495000
A17: B | B17: Material/ Vật tư | L17: =T17*$T$5 -> #REF! | M17: =ROUND(L17*K17,0) -> #REF! | N17: =U17*$T$5 -> #REF! | O17: =ROUND(N17*K17,0) -> #REF! | P17: =N17+L17 -> #REF! | Q17: =P17*K17 -> #REF!
A18: 1 | B18: Copper pipe Ø6,35x0.81 C/w 13mm insulation/ Ống đồng Ø6,35x0.81 kèm cách nhiệt dầy 13mm | D18: m | K18: 97.9 | L18: =T18*$T$5 -> #REF! | M18: =ROUND(L18*K18,0) -> #REF! | N18: =U18*$T$5 -> #REF! | O18: =ROUND(N18*K18,0) -> #REF! | P18: =N18+L18 -> #REF! | Q18: =P18*K18 -> #REF! | T18: 75000 | U18: 60500
A19: 2 | B19: Copper pipe Ø12,7x0.81 C/w 13mm insulation/ Ống đồng Ø12,7x0.81 kèm cách nhiệt dầy 13mm | D19: m | K19: 11 | L19: =T19*$T$5 -> #REF! | M19: =ROUND(L19*K19,0) -> #REF! | N19: =U19*$T$5 -> #REF! | O19: =ROUND(N19*K19,0) -> #REF! | P19: =N19+L19 -> #REF! | Q19: =P19*K19 -> #REF! | T19: 115000 | U19: 70000
A20: 3 | B20: Copper pipe Ø9,52x0.81 C/w 13mm insulation/ Ống đồng Ø9,52x0.81 kèm cách nhiệt dầy 13mm | D20: m | K20: 248.82 | L20: =T20*$T$5 -> #REF! | M20: =ROUND(L20*K20,0) -> #REF! | N20: =U20*$T$5 -> #REF! | O20: =ROUND(N20*K20,0) -> #REF! | P20: =N20+L20 -> #REF! | Q20: =P20*K20 -> #REF! | T20: 95000 | U20: 64900
A21: 4 | B21: Copper pipe Ø15,9x0.81 C/w 13mm insulation/ Ống đồng Ø15,9x0.81kèm cách nhiệt dầy 13mm | D21: m | K21: 161.92 | L21: =T21*$T$5 -> #REF! | M21: =ROUND(L21*K21,0) -> #REF! | N21: =U21*$T$5 -> #REF! | O21: =ROUND(N21*K21,0) -> #REF! | P21: =N21+L21 -> #REF! | Q21: =P21*K21 -> #REF! | T21: 128000 | U21: 75000
A22: 5 | B22: Condensate pipe uPVC DN20 c/w insulation 13mm/ Ống uPVC DN20 bao gồm cách nhiệt dầy 13mm | D22: m | K22: 88 | L22: =T22*$T$5 -> #REF! | M22: =ROUND(L22*K22,0) -> #REF! | N22: =U22*$T$5 -> #REF! | O22: =ROUND(N22*K22,0) -> #REF! | P22: =N22+L22 -> #REF! | Q22: =P22*K22 -> #REF! | T22: 31000 | U22: 33000
A23: 6 | B23: Condensate pipe uPVC DN25 c/w insulation 13mm/ Ống uPVC DN25 bao gồm cách nhiệt dầy 13mm | D23: m | K23: 38.5 | L23: =T23*$T$5 -> #REF! | M23: =ROUND(L23*K23,0) -> #REF! | N23: =U23*$T$5 -> #REF! | O23: =ROUND(N23*K23,0) -> #REF! | P23: =N23+L23 -> #REF! | Q23: =P23*K23 -> #REF! | T23: 41000 | U23: 38000
A24: 7 | B24: Condensate pipe uPVC DN40 c/w insulation 13mm/Ống uPVC DN40 bao gồm cách nhiệt dầy 13mm | D24: m | K24: 38.5 | L24: =T24*$T$5 -> #REF! | M24: =ROUND(L24*K24,0) -> #REF! | N24: =U24*$T$5 -> #REF! | O24: =ROUND(N24*K24,0) -> #REF! | P24: =N24+L24 -> #REF! | Q24: =P24*K24 -> #REF! | T24: 61000 | U24: 57000
A25: 8 | B25: Condensate pipe uPVC DN50 c/w insulation 13mm/ Ống uPVC DN50 bao gồm cách nhiệt dầy 13mm | D25: m | K25: 33 | L25: =T25*$T$5 -> #REF! | M25: =ROUND(L25*K25,0) -> #REF! | N25: =U25*$T$5 -> #REF! | O25: =ROUND(N25*K25,0) -> #REF! | P25: =N25+L25 -> #REF! | Q25: =P25*K25 -> #REF! | T25: 70000 | U25: 55000
A26: 9 | B26: N2, Simily/ N2, xi quấn | D26: lot | K26: 1 | L26: =T26*$T$5 -> #REF! | M26: =ROUND(L26*K26,0) -> #REF! | N26: =U26*$T$5 -> #REF! | O26: =ROUND(N26*K26,0) -> #REF! | P26: =N26+L26 -> #REF! | Q26: =P26*K26 -> #REF! | T26: 3500000 | U26: 500000
A27: 10 | B27: Cable 3cx1.5mm2 + E1.5mm2 Cu/PVC from indoor unit to outdoor unit/ Cáp 3cx1.5mm2 + E1.5mm2 Cu/PVC từ giàn lạnh tới giàn nóng | D27: m | K27: 88 | L27: =T27*$T$5 -> #REF! | M27: =ROUND(L27*K27,0) -> #REF! | N27: =U27*$T$5 -> #REF! | O27: =ROUND(N27*K27,0) -> #REF! | P27: =N27+L27 -> #REF! | Q27: =P27*K27 -> #REF! | T27: =7750*4 -> 31000 | U27: 12000
A28: 10 | B28: Cable 3cx2.5mm2 + E2.5mm2 Cu/PVC from indoor unit to outdoor unit/ Cáp 3cx2.5mm2 + E1.5mm2 Cu/PVC từ giàn lạnh tới giàn nóng | D28: m | K28: 159.5 | L28: =T28*$T$5 -> #REF! | M28: =ROUND(L28*K28,0) -> #REF! | N28: =U28*$T$5 -> #REF! | O28: =ROUND(N28*K28,0) -> #REF! | P28: =N28+L28 -> #REF! | Q28: =P28*K28 -> #REF! | T28: =8750*4 -> 35000 | U28: 13500
A29: 12 | B29: Fittings/ Phụ kiện đường ống: Co, tê, bít… | D29: lot | E29: lot | K29: 1 | L29: =T29*$T$5 -> #REF! | M29: =ROUND(L29*K29,0) -> #REF! | N29: =U29*$T$5 -> #REF! | O29: =ROUND(N29*K29,0) -> #REF! | P29: =N29+L29 -> #REF! | Q29: =P29*K29 -> #REF! | T29: 6500000 | U29: 1750000
A30: 13 | B30: Hangers, support / Giá đỡ, ty treo, phụ kiện | D30: lot | K30: 1 | L30: =T30*$T$5 -> #REF! | M30: =ROUND(L30*K30,0) -> #REF! | N30: =U30*$T$5 -> #REF! | O30: =ROUND(N30*K30,0) -> #REF! | P30: =N30+L30 -> #REF! | Q30: =P30*K30 -> #REF! | T30: 7500000 | U30: 3000000
A31: 11 | B31: Accessories / Vật tư phụ | D31: lot | K31: 1 | L31: =T31*$T$5 -> #REF! | M31: =ROUND(L31*K31,0) -> #REF! | N31: =U31*$T$5 -> #REF! | O31: =ROUND(N31*K31,0) -> #REF! | P31: =N31+L31 -> #REF! | Q31: =P31*K31 -> #REF! | T31: 4500000 | U31: 550000
A33: II | B33: VENTILATION SYSTEM/ HỆ THỐNG THÔNG GIÓ | M33: =SUBTOTAL(109,M35:M66) -> #REF! | O33: =SUBTOTAL(109,O35:O66) -> #REF! | Q33: =O33+M33 -> #REF!
A34: A | B34: Equipment/ Thiết bị
A35: 1 | B35: Wall mounted exhaust fan 255CMH/Quạt hút gắn tường lưu lượng 255m3/h | D35: pcs | K35: 2 | L35: =T35*$T$5 -> #REF! | M35: =ROUND(L35*K35,0) -> #REF! | N35: =U35*$T$5 -> #REF! | O35: =ROUND(N35*K35,0) -> #REF! | P35: =N35+L35 -> #REF! | Q35: =P35*K35 -> #REF! | T35: 1230500 | U35: 319000
