Workbook
Name \0: #REF!
Name \A: #REF!
Name \b: #REF!
Name \c: #REF!
Name \d: #REF!
Name \e: #REF!
Name \f: #REF!
Name \g: #REF!
Name \h: #REF!
Name \i: #REF!
Name \j: #REF!
Name \k: #REF!
Name \l: #REF!
Name \N: #REF!
Name \o: #REF!
Name \p: #REF!
Name \P1: #REF!
Name \q: #REF!
Name \r: #N/A
Name \s: #REF!
Name \t: #REF!
Name \u: #N/A
Name \v: #REF!
Name \VND: #REF!
Name \X: #REF!
Name \z: #REF!
Name _: #N/A
Name _??: NA()
Name _??_1: NA()
Name _??_1_1: NA()
Name _??_1_2: NA()
Name _??_1_3: NA()
Name _??_1_4: NA()
Name _??_1_5: NA()
Name _??_6: NA()
Name _??_7: NA()
Name _??_9: NA()
Name _?1: NA()
Name _?1_1: NA()
Name _?1_1_1: NA()
Name _?1_1_2: NA()
Name _?1_1_3: NA()
Name _?1_1_4: NA()
Name _?1_1_5: NA()
Name _?1_6: NA()
Name _?1_7: NA()
Name _?1_9: NA()
Name _?271: NA()
Name _?271_1: NA()
Name _?271_1_1: NA()
Name _?271_1_2: NA()
Name _?271_1_3: NA()
Name _?271_1_4: NA()
Name _?271_1_5: NA()
Name _?271_6: NA()
Name _?271_7: NA()
Name _?271_9: NA()
Name _?쾴?: #REF!
Name _?쾴?_?: #REF!
Name _?쾴?___P: #REF!

Sheet Cover
A2: BILL OF QUANTITIES BẢNG BÁO GIÁ
C7: PROJECT NAME / TÊN DỰ ÁN :
C8: LOCATION / ĐỊA ĐIỂM : GIANG DIEN INDUSTRIAL PARK - DONG NAI PROVINCE
C9: OWNER / CHỦ ĐẦU TƯ :
C10: CONSTRACTOR / NHÀ THẦU : CÔNG TY CỔ PHẦN TƯ VẤN ĐẦU TƯ XÂY DỰNG MỚI ( NICON)

Sheet Cover 1
A2: BILL OF QUANTITIES BẢNG BÁO GIÁ
C10: CONSTRUCTION COMPANY CÔNG TY DỰ THẦU
C11: GRAND TOTAL TỔNG GIÁ TRỊ | G11: ='00.Tổng Hợp'!E45 -> 0 | H11: VND | I11: excluded V.A.T
G12: =+G11/J12 -> 0 | H12: USD | I12: USD/VND | J12: ='00.Tổng Hợp'!G5 -> 26099
C16: =TODAY() -> 46301

Sheet 00.Tổng Hợp
A2: SUMMARY COST/ TỔNG HỢP CHI PHÍ
A3: =Cover!C7 -> PROJECT NAME / TÊN DỰ ÁN : | I3: =+A3 -> PROJECT NAME / TÊN DỰ ÁN :
F4: CURRENCY : USD/VND
F5: 1 USD/ | G5: 26099
A6: NO. STT | B6: DESCRIPTION DIỄN GIẢI | C6: UNIT / ĐƠN VỊ | D6: Q'TY/ KHỐI LƯỢNG | E6: TOTAL AMOUNT TỔNG GIÁ TRỊ (VND) | F6: TOTAL AMOUNT/ TỔNG GIÁ TRỊ (USD) | G6: REMARK GHI CHÚ
A8: (1) | B8: (2) | C8: (3) | D8: (4) | E8: (5) | F8: (6)
A9: I | B9: DIRECT COST/ CHI PHÍ TRỰC TIẾP | E9: =+E10+E26+E32 -> 0 | F9: =+E9/$G$5 -> 0
A10: A | B10: CONSTRUCTION WORK / CÔNG TÁC XÂY DỰNG | E10: =+SUM(E11:E25) -> 0 | F10: =+E10/$G$5 -> 0
A11: 1 | B11: TEMPORARY WORK/ CÔNG TÁC TẠM | C11: Lot | D11: 1 | E11: ='1.Công Tác Tạm'!J6 -> 0 | F11: =+E11/$G$5 -> 0
A12: 2 | B12: WORKSHOP & OFFICE / NHÀ XƯỞNG & VĂN PHÒNG | C12: Lot | D12: 1 | E12: ='2.Nhà Xưởng & Văn Phòng'!J6 -> 0 | F12: =+E12/$G$5 -> 0
A13: 3 | B13: MAINTENANCE HOUSE, BEAN ROASTING, PACKAGING / NHÀ BẢO TRÌ, RANG ĐẬU, BAO BÌ | C13: Lot | D13: 1 | E13: ='3.Nhà Bảo Trì, Rang Đậu, BB'!J6 -> 0 | F13: =+E13/$G$5 -> 0
A14: 4 | B14: GLASS AND CARTON PACKAGING HOUSE/ NHÀ BAO BÌ THUỶ TINH, CARTON | C14: Lot | D14: 1 | E14: ='4.Nhà BB Thuỷ Tinh, Carton'!J6 -> 0 | F14: =+E14/$G$5 -> 0
A15: 5 | B15: BOILER, AIR COMPRESSOR HOUSE/ NHÀ LÒ HƠI, NÉN KHÍ | C15: Lot | D15: 1 | E15: ='5.Nhà Lò Hơi & Nén Khí'!J6 -> 0 | F15: =+E15/$G$5 -> 0
A16: 6 | B16: BIKE PARKING/ NHÀ ĐỂ XE MÁY | C16: Lot | D16: 1 | E16: ='6.Nhà Để Xe Máy'!J6 -> 0 | F16: =+E16/$G$5 -> 0
A17: 7 | B17: DORMITORY HOUSE/ NHÀ NGHỈ GIỮA CA | C17: Lot | D17: 1 | E17: ='7.Nhà Nghỉ Giữa Ca'!J6 -> 0 | F17: =+E17/$G$5 -> 0
A18: 8 | B18: GUARD HOUSE 1/ NHÀ BẢO VỆ 1 | C18: Lot | D18: 1 | E18: ='8.Nhà Bảo Vệ 1'!J6 -> 0 | F18: =+E18/$G$5 -> 0
A19: 9 | B19: GUARD HOUSE 2/ NHÀ BẢO VỆ 2 | C19: Lot | D19: 1 | E19: ='9.Nhà Bảo Vệ 2'!J6 -> 0 | F19: =+E19/$G$5 -> 0
A20: 10 | B20: GARBAGE, TRANSFORMER HOUSE/ NHÀ RÁC, PHÒNG ĐIỆN | C20: Lot | D20: 1 | E20: ='7.Nhà Nghỉ Giữa Ca'!J9 -> 0 | F20: =+E20/$G$5 -> 0
A21: 11 | B21: WATER TANK FF/ BỂ NƯỚC NGẦM PCCC | C21: Lot | D21: 1 | E21: ='11.Bể Nước Ngầm PCCC'!J6 -> 0 | F21: =+E21/$G$5 -> 0
A22: 12 | B22: COLD WATER TANK/ BỂ NƯỚC XẢ NGUỘI 200M3 | C22: Lot | D22: 1 | E22: ='12.Bể Nước Ngầm Xả Nguội'!J6 -> 0 | F22: =+E22/$G$5 -> 0
A23: 13 | B23: WATER TANK RO/ BỂ NƯỚC NGẦM RO 200M3 | C23: Lot | D23: 1 | E23: ='13.Bể Nước Ngầm RO '!J6 -> 0 | F23: =+E23/$G$5 -> 0
A24: 14 | B24: WWS TANK/ BỂ XLNT | C24: Lot | D24: 1 | E24: ='14.Bể XLNT'!J6 -> 0 | F24: =+E24/$G$5 -> 0
A25: 15 | B25: FENCE & GATE/ HÀNG RÀO & CỔNG | C25: Lot | D25: 1 | E25: ='15.Hàng Rào & Cổng'!J6 -> 0 | F25: =+E25/$G$5 -> 0
A26: B | B26: CIVIL WORKS / CÔNG TÁC HẠ TẦNG | E26: =+SUM(E27:E31) -> 0 | F26: =+E26/$G$5 -> 0
A27: 1 | B27: ROAD/ ĐƯỜNG | C27: Lot | D27: 1 | E27: ='B.Hạ Tầng Kỹ Thuật'!J7 -> 0 | F27: =+E27/$G$5 -> 0
A28: =+A27+1 -> 2 | B28: STORM WATER DRAINAGE SYSTEM/ HỆ THỐNG THOÁT NƯỚC MƯA | C28: Lot | D28: 1 | E28: ='B.Hạ Tầng Kỹ Thuật'!J8 -> 0 | F28: =+E28/$G$5 -> 0
A29: 3 | B29: WASTE WATER DRAINAGE SYSTEM/ HỆ THỐNG THOÁT NƯỚC THẢI NGOÀI NHÀ | C29: Lot | D29: 1 | E29: ='B.Hạ Tầng Kỹ Thuật'!J9 -> 0 | F29: =+E29/$G$5 -> 0
A30: 4 | B30: LANDSCAPE/ CẢNH QUAN | C30: Lot | D30: 1 | E30: ='B.Hạ Tầng Kỹ Thuật'!J10 -> 0 | F30: =+E30/$G$5 -> 0 | J30: Xưởng bậc IV, Hạng sản xuất hạng D (đúc kim loại, ko có vật liệu dễ cháy)
A31: 5 | B31: SETPTIC TANK/ BỂ PHỐT | C31: Lot | D31: 1 | E31: ='B.Hạ Tầng Kỹ Thuật'!J11 -> 0 | F31: =+E31/$G$5 -> 0 | J31: Xưởng bậc IV, Hạng sản xuất hạng D (đúc kim loại, ko có vật liệu dễ cháy)
A32: C | B32: M&E WORKS & EQUIPMENT WORK / CÔNG TÁC CƠ ĐIỆN | E32: =+SUM(E33:E37) -> 0 | F32: =+E32/$G$5 -> 0
A33: 1 | B33: PLUMBING SYSTEM/ HỆ THỐNG CẤP THOÁT NƯỚC | C33: Lot | D33: 1 | E33: ='C1. Hệ Thống Plumbing'!J6 -> 0 | F33: =+E33/$G$5 -> 0 | J33: Báo giá tới thiết bị và lắp đặt trong phòng máy
A34: 2 | B34: WWS EQUIPMNT/ HỆ THỐNG THIẾT BỊ XLNT | C34: Lot | D34: 1 | E34: ='C2.Hệ Thống XLNT'!J6 -> 0 | F34: =+E34/$G$5 -> 0
A35: 3 | B35: FIRE FIGHTING SYSTEM/ HỆ THỐNG PCCC | C35: Lot | D35: 1 | E35: ='C3.Hệ Thống PCCC '!J7 -> 0 | F35: =+E35/$G$5 -> 0
A36: 4 | B36: ELECTRICAL SYSTEM/ HỆ THỐNG ĐIỆN | C36: Lot | D36: 1 | E36: ='C4.Hệ Thống Điện & Điện Nhẹ '!J7 -> 0 | F36: =+E36/$G$5 -> 0
A38: II | B38: INDIRECT COST/ CHI PHÍ GIÁN TIẾP | D38: =SUM(D39:D41) -> 0.06 | E38: =+SUM(E39:E41) -> 0 | F38: =+E38/$G$5 -> 0
A39: 1 | B39: INSURANCE FEE & ISSUE BOND/ BẢO HIỂM & BẢO LÃNH | C39: % | D39: 0.01 | E39: =E9*0.01 -> 0 | F39: =+E39/$G$5 -> 0
A40: 2 | B40: SITE EXPENSE & SITE MANAGEMENT/ CHI PHÍ CÔNG TRƯỜNG & CHI PHÍ QUẢN LÝ | C40: % | D40: 0.03 | E40: =E9*0.03 -> 0 | F40: =+E40/$G$5 -> 0
A41: 3 | B41: OVERHEAD/ QUẢN LÝ PHÍ | C41: % | D41: 0.02 | E41: =E9*0.02 -> 0 | F41: =+E41/$G$5 -> 0
B42: TOTAL AMOUNT (I + II) | E42: =+E9+E38 -> 0 | F42: =+E42/$G$5 -> 0
B43: DISCOUNT , ROUND OFF/ GIẢM GIÁ, LÀM TRÒN | E43: =-MOD(E42,1000000) -> 0
...

Sheet 1.Công Tác Tạm
A1: BILL OF QUANTITIES
A2: ='C4.Hệ Thống Điện & Điện Nhẹ '!A2:K2 -> PROJECT NAME / TÊN DỰ ÁN :
A3: B1.TEMPORARY WORK/ CÔNG TÁC TẠM
A4: NO / STT | B4: WORK SCOPE / CÔNG VIỆC | C4: SPECIFICATION / ĐẶC ĐIỂM KỸ THUẬT | D4: UNIT/ ĐƠN VỊ | E4: QUANTITY / KHỐI LƯỢNG | F4: UNIT PRICE / ĐƠN GIÁ (VNĐ) | J4: AMOUNT / THÀNH TIỀN (VNĐ) | K4: REMARK / GHI CHÚ
F5: MATERIAL / VẬT LIỆU | G5: LABOUR / NHÂN CÔNG | H5: EQUIPMENT / THIẾT BỊ | I5: UNIT PRICE / TỔNG ĐƠN GIÁ
A6: B1 | B6: TEMPORARY WORK/ CÔNG TÁC TẠM | J6: =SUM(J7:J21) -> 0
A7: 1 | B7: Temporary electronic setting Connection & Authority Fee (EVN, etc) | D7: Lot | E7: 1 | G7: 0 | H7: 0 | I7: =+F7+G7+H7 -> 0 | J7: =+E7*I7 -> 0
A8: 2 | B8: Temporary Electronic Charge Cost Chi phí điện thi công | D8: Month | E8: 8 | G8: 0 | H8: 0 | I8: =+F8+G8+H8 -> 0 | J8: =+E8*I8 -> 0
A9: 3 | B9: Temporary water ,Supply & Charge Cost Chi phí nước thi công | D9: Month | E9: =E8 -> 8 | G9: 0 | H9: 0 | I9: =+F9+G9+H9 -> 0 | J9: =+E9*I9 -> 0
A10: 4 | B10: Temporary water connection costs Chi phí đấu nối nước tạm thi công | D10: Lot | E10: 1 | G10: 0 | H10: 0 | I10: =+F10+G10+H10 -> 0 | J10: =+E10*I10 -> 0
A11: 5 | B11: Temporary office -Contractor & Client (Container 3-SET) Văn phòng tạm (Container 2-SET) | D11: Month | E11: =E9 -> 8 | G11: 0 | H11: 0 | I11: =+F11+G11+H11 -> 0 | J11: =+E11*I11 -> 0 | K11: 3 set
A12: 6 | B12: Temporary-Toilet for worker Nhà vệ sinh tạm công nhân | D12: Month | E12: =E11 -> 8 | G12: 0 | H12: 0 | I12: =+F12+G12+H12 -> 0 | J12: =+E12*I12 -> 0
A13: 7 | B13: Warehouse Nhà kho | D13: Month | E13: =E12 -> 8 | G13: 0 | H13: 0 | I13: =+F13+G13+H13 -> 0 | J13: =+E13*I13 -> 0
A14: 8 | B14: Temporary Fence, Hàng rào tạm, | C14: Include steel frame, gate, color steel sheet | D14: m2 | E14: =(270+12+183)*2 -> 930 | H14: 0 | I14: =+F14+G14+H14 -> 0 | J14: =+E14*I14 -> 0
A15: 9 | B15: Security Fee 2-Person Phí bảo vệ (2 người) | D15: Month | E15: 8 | G15: 0 | H15: 0 | I15: =+F15+G15+H15 -> 0 | J15: =+E15*I15 -> 0
A16: 10 | B16: Temporary Guard house 3m x 3m Nhà bảo vệ tạm (3mx3m) | C16: 1 set | D16: Month | E16: =E15 -> 8 | G16: 0 | H16: 0 | I16: =+F16+G16+H16 -> 0 | J16: =+E16*I16 -> 0
A17: 11 | B17: Temporary lighting system Hệ thống chiếu sáng tạm | D17: Lot | E17: 1 | G17: 0 | H17: 0 | I17: =+F17+G17+H17 -> 0 | J17: =+E17*I17 -> 0
A18: 12 | B18: Project board Biển dự án | D18: Lot | E18: 1 | G18: 0 | H18: 0 | I18: =+F18+G18+H18 -> 0 | J18: =+E18*I18 -> 0
A19: 13 | B19: Chi phí làm lễ khởi công dự án Costs for project groundbreaking ceremony | D19: Lot | E19: 1 | G19: 0 | H19: 0 | I19: =+F19+G19+H19 -> 0 | J19: =+E19*I19 -> 0
A20: 14 | B20: Site clean up Vệ sinh công trường | D20: Month | E20: =E8 -> 8 | G20: 0 | H20: 0 | I20: =+F20+G20+H20 -> 0 | J20: =+E20*I20 -> 0
A21: 15 | B21: Final clean up Vệ sinh trước khi bàn giao | D21: Lot | E21: 1 | G21: 0 | H21: 0 | I21: =+F21+G21+H21 -> 0 | J21: =+E21*I21 -> 0

Sheet 2.Nhà Xưởng & Văn Phòng
A1: BILL OF QUANTITIES
A2: =Cover!C7 -> PROJECT NAME / TÊN DỰ ÁN :
A3: 2.WORKSHOP & OFFICE/ NHÀ XƯỞNG & VĂN PHÒNG
A4: NO / STT | B4: WORK SCOPE / CÔNG VIỆC | C4: SPECIFICATION / ĐẶC ĐIỂM KỸ THUẬT | D4: UNIT/ ĐƠN VỊ | E4: QUANTITY / KHỐI LƯỢNG | F4: UNIT PRICE / ĐƠN GIÁ (VNĐ) | J4: AMOUNT / THÀNH TIỀN (VNĐ) | K4: REMARK / GHI CHÚ
F5: MATERIAL / VẬT LIỆU | G5: LABOUR / NHÂN CÔNG | H5: EQUIPMENT / THIẾT BỊ | I5: UNIT PRICE / TỔNG ĐƠN GIÁ
A6: 2 | B6: WORKSHOP & OFFICE/ NHÀ XƯỞNG & VĂN PHÒNG | J6: =+J7+J14 -> 0
A7: A | B7: =B28 -> STRUCTURE WORK / CÔNG TÁC KẾT CẤU | J7: =SUM(J8:J12) -> 0
A8: 1 | B8: =+B29 -> EARTH WORK / CÔNG TÁC ĐẤT | D8: lot | E8: 1 | J8: =+J29 -> 0
A9: =+A8+1 -> 2 | B9: =+B38 -> CONCRETE WORK / CÔNG TÁC BÊ TÔNG | D9: lot | E9: 1 | J9: =+J38 -> 0
A10: =+A9+1 -> 3 | B10: =+B47 -> FORM WORK / CÔNG TÁC VÁN KHUÔN | D10: lot | E10: 1 | J10: =+J47 -> 0
A11: =+A10+1 -> 4 | B11: =+B52 -> REINFORCEMENT WORK / CÔNG TÁC CỐT THÉP | D11: lot | E11: 1 | J11: =+J52 -> 0
A12: =+A11+1 -> 5 | B12: =+B57 -> STEEL STRUCTURE WORK / CÔNG TÁC KẾT CẤU THÉP TIỀN CHẾ | D12: lot | E12: 1 | J12: =+J57 -> 0
A14: B | B14: =B90 -> FINISING WORK / CÔNG TÁC HOÀN THIỆN | J14: =SUM(J15:J25) -> 0
A15: 1 | B15: =B91 -> BRICK WORK / CÔNG TÁC XÂY | D15: lot | E15: 1 | J15: =J91 -> 0
A16: =+A15+1 -> 2 | B16: =B95 -> PLASTERING WORK / CÔNG TÁC TRÁT | D16: lot | E16: 1 | J16: =J95 -> 0
A17: =+A16+1 -> 3 | B17: =B99 -> PAINTING WORK / CÔNG TÁC SƠN | D17: lot | E17: 1 | J17: =J99 -> 0
A18: =+A17+1 -> 4 | B18: =B102 -> TILING & FLOOR FINISHING WORK / ỐP LÁT VÀ HOÀN THIỆN SÀN | D18: lot | E18: 1 | J18: =J102 -> 0
A19: =+A18+1 -> 5 | B19: =B117 -> CEILLING WORK / CÔNG TÁC TRẦN | D19: lot | E19: 1 | J19: =J117 -> 0
A20: =+A19+1 -> 6 | B20: =B129 -> OUTSIDE & INSIDE WALL PANEL WORK / CÔNG TÁC VÁCH PANEL | D20: lot | E20: 1
A21: =+A20+1 -> 7 | B21: =B166 -> ROOF WORK/ CÔNG TÁC MÁI | D21: lot | E21: 1 | J21: =J166 -> 0
A22: =+A21+1 -> 8 | B22: =B193 -> WATERPROOFING WORK/ CÔNG TÁC CHỐNG THẤM | D22: lot | E22: 1 | J22: =J193 -> 0
A23: =+A22+1 -> 9 | B23: =B202 -> DOOR AND WINDOW / CỬA ĐI VÀ CỬA SỔ | D23: lot | E23: 1 | J23: =J202 -> 0
A24: =+A23+1 -> 10 | B24: =B222 -> METAL WORK/ CÔNG TÁC KIM LOẠI | D24: lot | E24: 1 | J24: =J222 -> 0
A25: =+A24+1 -> 11 | B25: =B230 -> OTHERS WORK / CÔNG VIỆC KHÁC | D25: lot | E25: 1 | J25: =J230 -> 0
A28: A | B28: STRUCTURE WORK / CÔNG TÁC KẾT CẤU | J28: =+J29+J38+J47+J52+J57 -> 0
A29: 1 | B29: EARTH WORK / CÔNG TÁC ĐẤT | J29: =SUM(J30:J36) -> 0
A30: 1 | B30: Excavation (by Equipment) Đào đất bằng máy | D30: m3 | E30: 7470.6892 | H30: 0 | I30: =+SUM(F30:H30) -> 0 | J30: =ROUND(E30*I30,0) -> 0
A31: 2 | B31: Excavation (by worker) Đào đất thủ công | D31: m3 | E31: 747.06892 | H31: 0 | I31: =+SUM(F31:H31) -> 0 | J31: =ROUND(E31*I31,0) -> 0
A32: 3 | B32: Backfilling soil for foundation Đắp đất | D32: m3 | E32: 2988.2757 | H32: 0 | I32: =+SUM(F32:H32) -> 0 | J32: =ROUND(E32*I32,0) -> 0
A33: 4 | B33: Remove surplus soil Vận chuyển đất đổ đi | C33: Distance D<=1Km Khoảng cách D<=1Km | D33: m3 | E33: 5229.4824 | H33: 0 | I33: =+SUM(F33:H33) -> 0 | J33: =ROUND(E33*I33,0) -> 0
A34: 5 | B34: Earth compaction, K=0.9 Đầm đất, K=0.9 | D34: m2 | E34: 14352 | H34: 0 | I34: =+SUM(F34:H34) -> 0 | J34: =ROUND(E34*I34,0) -> 0
A35: 6 | B35: Compacting by stone aggregate K=0.95 Đá base đầm chặt K=0.95 | C35: Base type I / CPĐD - I Cấp phối đá dăm loại I | D35: m3 | E35: 3731.52 | H35: 0 | I35: =+SUM(F35:H35) -> 0 | J35: =ROUND(E35*I35,0) -> 0
A36: 7 | B36: 1 layer nylon thk. 0.3mm 1 lớp nylon dày 0.3mm | D36: m2 | E36: 14352 | H36: 0 | I36: =+SUM(F36:H36) -> 0 | J36: =ROUND(E36*I36,0) -> 0
A38: 2 | B38: CONCRETE WORK / CÔNG TÁC BÊ TÔNG | J38: =SUM(J39:J45) -> 0
A39: 1 | B39: Lean concrete for foundation, ground beam Bê tông lót cho móng, dầm | C39: Gr. 150 | D39: m3 | E39: 806.8093 | H39: 0 | I39: =F39+G39+H39 -> 0 | J39: =ROUND(E39*I39,0) -> 0
A40: 2 | B40: Concrete for foundation,beams, ground slab, scolumn Bê tông móng, dầm móng, nền, cổ cột | C40: Gr. 300 | D40: m3 | E40: 3626.9812 | H40: 0 | I40: =F40+G40+H40 -> 0 | J40: =ROUND(E40*I40,0) -> 0
A41: 3 | B41: Concrete for beams slab, column, bracing Bê tông dầm sàn, cột, giằng | C41: Gr. 300 | D41: m3 | E41: 190.51168 | H41: 0 | I41: =F41+G41+H41 -> 0 | J41: =ROUND(E41*I41,0) -> 0
A42: 4 | B42: Pump car Bơm bê tông | D42: m3 | E42: 4624.3022 | I42: =F42+G42+H42 -> 0 | J42: =ROUND(E42*I42,0) -> 0 | K42: đã bao gồm
A43: 5 | B43: Polishing for slab by machine Xoa nền bằng máy | D43: m2 | E43: 15471.808 | H43: 0 | I43: =F43+G43+H43 -> 0 | J43: =ROUND(E43*I43,0) -> 0
A44: 6 | B44: Cutting joint for floor/ Cắt mạch nền | D44: m | E44: 3414 | H44: 0 | I44: =F44+G44+H44 -> 0 | J44: =ROUND(E44*I44,0) -> 0
...

Sheet 3.Nhà Bảo Trì, Rang Đậu, BB
A1: BILL OF QUANTITIES
A2: =+Cover!C7 -> PROJECT NAME / TÊN DỰ ÁN :
A3: 3.NHÀ BẢO TRÌ + NHÀ RANG ĐẬU + BAO BÌ
A4: NO / STT | B4: WORK SCOPE / CÔNG VIỆC | C4: SPECIFICATION / ĐẶC ĐIỂM KỸ THUẬT | D4: UNIT/ ĐƠN VỊ | E4: QUANTITY / KHỐI LƯỢNG | F4: UNIT PRICE / ĐƠN GIÁ (VNĐ) | J4: AMOUNT / THÀNH TIỀN (VNĐ) | K4: REMARK / GHI CHÚ
F5: MATERIAL / VẬT LIỆU | G5: LABOUR / NHÂN CÔNG | H5: EQUIPMENT / THIẾT BỊ | I5: UNIT PRICE / TỔNG ĐƠN GIÁ
A6: 3 | B6: NHÀ BẢO TRÌ + NHÀ RANG ĐẬU + BAO BÌ | J6: =+J7+J14 -> 0
A7: A | B7: =B25 -> STRUCTURE WORK / CÔNG TÁC KẾT CẤU | J7: =SUM(J8:J12) -> 0
A8: 1 | B8: =+B26 -> EARTH WORK / CÔNG TÁC ĐẤT | D8: lot | E8: 1 | J8: =+J26 -> 0
A9: =+A8+1 -> 2 | B9: =+B35 -> CONCRETE WORK / CÔNG TÁC BÊ TÔNG | D9: lot | E9: 1 | J9: =+J35 -> 0
A10: =+A9+1 -> 3 | B10: =+B42 -> FORM WORK / CÔNG TÁC VÁN KHUÔN | D10: lot | E10: 1 | J10: =+J42 -> 0
A11: =+A10+1 -> 4 | B11: =+B45 -> REINFORCEMENT WORK / CÔNG TÁC CỐT THÉP | D11: lot | E11: 1 | J11: =+J45 -> 0
A12: =+A11+1 -> 5 | B12: =+B50 -> STEEL STRUCTURE WORK / CÔNG TÁC KẾT CẤU THÉP TIỀN CHẾ | D12: lot | E12: 1 | J12: =+J50 -> 0
A14: B | B14: =B70 -> FINISING WORK / CÔNG TÁC HOÀN THIỆN | J14: =SUM(J15:J20) -> 0
A15: 1 | B15: =B71 -> FLOOR FINISHING WORK / HOÀN THIỆN SÀN | D15: lot | E15: 1 | J15: =J71 -> 0
A16: 2 | B16: =B74 -> CEILLING WORK / CÔNG TÁC TRẦN | D16: lot | E16: 1
A17: =+A16+1 -> 3 | B17: =B80 -> OUTSIDE & INSIDE WALL PANEL WORK / CÔNG TÁC VÁCH PANEL | D17: lot | E17: 1
A18: =+A17+1 -> 4 | B18: =B104 -> ROOF WORK/ CÔNG TÁC MÁI | D18: lot | E18: 1 | J18: =J104 -> 0
A19: =+A18+1 -> 5 | B19: =B126 -> DOOR AND WINDOW / CỬA ĐI VÀ CỬA SỔ | D19: lot | E19: 1 | J19: =J126 -> 0
A20: =+A19+1 -> 6 | B20: =B137 -> OTHERS WORK / CÔNG VIỆC KHÁC | D20: lot | E20: 1 | J20: =J137 -> 0
A25: A | B25: STRUCTURE WORK / CÔNG TÁC KẾT CẤU | J25: =+J26+J35+J42+J45+J50 -> 0
A26: 1 | B26: EARTH WORK / CÔNG TÁC ĐẤT | J26: =SUM(J27:J33) -> 0
A27: 1 | B27: Excavation (by Equipment) Đào đất bằng máy | D27: m3 | E27: 1310.699 | H27: 0 | I27: =+SUM(F27:H27) -> 0 | J27: =ROUND(E27*I27,0) -> 0
A28: 2 | B28: Excavation (by worker) Đào đất thủ công | D28: m3 | E28: 131.0699 | H28: 0 | I28: =+SUM(F28:H28) -> 0 | J28: =ROUND(E28*I28,0) -> 0
A29: 3 | B29: Backfilling soil for foundation Đắp đất | D29: m3 | E29: 524.2796 | H29: 0 | I29: =+SUM(F29:H29) -> 0 | J29: =ROUND(E29*I29,0) -> 0
A30: 4 | B30: Remove surplus soil Vận chuyển đất đổ đi | C30: Distance D<=1Km Khoảng cách D<=1Km | D30: m3 | E30: 917.4893 | H30: 0 | I30: =+SUM(F30:H30) -> 0 | J30: =ROUND(E30*I30,0) -> 0
A31: 5 | B31: Earth compaction, K=0.9 Đầm đất, K=0.9 | D31: m2 | E31: 2280 | H31: 0 | I31: =+SUM(F31:H31) -> 0 | J31: =ROUND(E31*I31,0) -> 0
A32: 6 | B32: Compacting by stone aggregate K=0.95 Đá base đầm chặt K=0.95 | C32: Base type I / CPĐD - I Cấp phối đá dăm loại I | D32: m3 | E32: 592.8 | H32: 0 | I32: =+SUM(F32:H32) -> 0 | J32: =ROUND(E32*I32,0) -> 0
A33: 7 | B33: 1 layer nylon thk. 0.3mm 1 lớp nylon dày 0.3mm | D33: m2 | E33: 2280 | H33: 0 | I33: =+SUM(F33:H33) -> 0 | J33: =ROUND(E33*I33,0) -> 0
A35: 2 | B35: CONCRETE WORK / CÔNG TÁC BÊ TÔNG | J35: =SUM(J36:J40) -> 0
A36: 1 | B36: Lean concrete for foundation, ground beam Bê tông lót cho móng, dầm | C36: Gr. 150 | D36: m3 | E36: 136.57182 | H36: 0 | I36: =F36+G36+H36 -> 0 | J36: =ROUND(E36*I36,0) -> 0
A37: 2 | B37: Concrete for foundation,beams, ground slab, scolumn Bê tông móng, dầm móng, nền, cổ cột | C37: Gr. 300 | D37: m3 | E37: 471.42375 | H37: 0 | I37: =F37+G37+H37 -> 0 | J37: =ROUND(E37*I37,0) -> 0
A38: 3 | B38: Pump car Bơm bê tông | D38: m3 | E38: 607.99557 | H38: 0 | I38: =F38+G38+H38 -> 0 | J38: =ROUND(E38*I38,0) -> 0 | K38: đã bao gồm
A39: 4 | B39: Polishing for slab by machine Xoa nền bằng máy | D39: m2 | E39: 2280 | H39: 0 | I39: =F39+G39+H39 -> 0 | J39: =ROUND(E39*I39,0) -> 0
A40: 5 | B40: Cutting joint for floor/ Cắt mạch nền | D40: m | E40: 626 | H40: 0 | I40: =F40+G40+H40 -> 0 | J40: =ROUND(E40*I40,0) -> 0
A42: 3 | B42: FORM WORK / CÔNG TÁC VÁN KHUÔN | J42: =+SUM(J43:J44) -> 0
A43: 1 | B43: For lean concrete for foundation & ground beam Ván khuôn bê tông lót móng, dầm | D43: m2 | E43: 60.40125 | H43: 0 | I43: =+SUM(F43:H43) -> 0 | J43: =ROUND(E43*I43,0) -> 0
A44: 2 | B44: For foundation, ground beam, slab, scolumn Ván khuôn móng, dầm, nền, cổ cột | D44: m2 | E44: 495.4572 | H44: 0 | I44: =+SUM(F44:H44) -> 0 | J44: =ROUND(E44*I44,0) -> 0
A45: 4 | B45: REINFORCEMENT WORK / CÔNG TÁC CỐT THÉP | J45: =+SUM(J46:J48) -> 0
A46: 1 | B46: Re-bar for foundation, ground beam, ground slab Cốt thép móng, dầm, cổ cột | D46: ton | E46: 5.03265 | H46: 0 | I46: =+SUM(F46:H46) -> 0 | J46: =ROUND(E46*I46,0) -> 0 | K46: Hoa Phat/ Equivalent
A47: 2 | B47: Re-bar for ground slab Cốt thép cho sàn | D47: ton | E47: 10.626 | H47: 0 | I47: =+SUM(F47:H47) -> 0 | J47: =ROUND(E47*I47,0) -> 0 | K47: =K46 -> Hoa Phat/ Equivalent
...

Sheet 4.Nhà BB Thuỷ Tinh, Carton
A1: ='3.Nhà Bảo Trì, Rang Đậu, BB'!A1:K1 -> BILL OF QUANTITIES
A2: =+Cover!C7 -> PROJECT NAME / TÊN DỰ ÁN :
A3: 4.NHÀ BAO BÌ THỦY TINH + NHÀ CARTON
A4: NO / STT | B4: WORK SCOPE / CÔNG VIỆC | C4: SPECIFICATION / ĐẶC ĐIỂM KỸ THUẬT | D4: UNIT/ ĐƠN VỊ | E4: QUANTITY / KHỐI LƯỢNG | F4: UNIT PRICE / ĐƠN GIÁ (VNĐ) | J4: AMOUNT / THÀNH TIỀN (VNĐ) | K4: REMARK / GHI CHÚ
F5: MATERIAL / VẬT LIỆU | G5: LABOUR / NHÂN CÔNG | H5: EQUIPMENT / THIẾT BỊ | I5: UNIT PRICE / TỔNG ĐƠN GIÁ
A6: 4 | B6: NHÀ BAO BÌ THỦY TINH + NHÀ CARTON | J6: =+J7+J14 -> 0
A7: A | B7: =B25 -> STRUCTURE WORK / CÔNG TÁC KẾT CẤU | J7: =SUM(J8:J12) -> 0
A8: 1 | B8: =+B26 -> EARTH WORK / CÔNG TÁC ĐẤT | D8: lot | E8: 1 | J8: =+J26 -> 0
A9: =+A8+1 -> 2 | B9: =+B35 -> CONCRETE WORK / CÔNG TÁC BÊ TÔNG | D9: lot | E9: 1 | J9: =+J35 -> 0
A10: =+A9+1 -> 3 | B10: =+B42 -> FORM WORK / CÔNG TÁC VÁN KHUÔN | D10: lot | E10: 1 | J10: =+J42 -> 0
A11: =+A10+1 -> 4 | B11: =+B45 -> REINFORCEMENT WORK / CÔNG TÁC CỐT THÉP | D11: lot | E11: 1 | J11: =+J45 -> 0
A12: =+A11+1 -> 5 | B12: =+B50 -> STEEL STRUCTURE WORK / CÔNG TÁC KẾT CẤU THÉP TIỀN CHẾ | D12: lot | E12: 1 | J12: =+J50 -> 0
A14: B | B14: =B70 -> FINISING WORK / CÔNG TÁC HOÀN THIỆN | J14: =SUM(J15:J20) -> 0
A15: 1 | B15: =B71 -> FLOOR FINISHING WORK / HOÀN THIỆN SÀN | D15: lot | E15: 1 | J15: =J71 -> 0
A16: 2 | B16: =B74 -> CEILLING WORK / CÔNG TÁC TRẦN | D16: lot | E16: 1 | J16: =J74 -> 0
A17: =+A16+1 -> 3 | B17: =B80 -> OUTSIDE & INSIDE WALL PANEL WORK / CÔNG TÁC VÁCH PANEL | D17: lot | E17: 1 | J17: =J80 -> 0
A18: =+A17+1 -> 4 | B18: =B99 -> ROOF WORK/ CÔNG TÁC MÁI | D18: lot | E18: 1 | J18: =J99 -> 0
A19: =+A18+1 -> 5 | B19: =B121 -> DOOR AND WINDOW / CỬA ĐI VÀ CỬA SỔ | D19: lot | E19: 1 | J19: =J121 -> 0
A20: =+A19+1 -> 6 | B20: =B130 -> OTHERS WORK / CÔNG VIỆC KHÁC | D20: lot | E20: 1 | J20: =J130 -> 0
A25: A | B25: STRUCTURE WORK / CÔNG TÁC KẾT CẤU | J25: =+J26+J35+J42+J45+J50 -> 0
A26: 1 | B26: EARTH WORK / CÔNG TÁC ĐẤT | J26: =SUM(J27:J33) -> 0
A27: 1 | B27: Excavation (by Equipment) Đào đất bằng máy | D27: m3 | E27: 1131.9321 | H27: 0 | I27: =+SUM(F27:H27) -> 0 | J27: =ROUND(E27*I27,0) -> 0
A28: 2 | B28: Excavation (by worker) Đào đất thủ công | D28: m3 | E28: 113.19321 | H28: 0 | I28: =+SUM(F28:H28) -> 0 | J28: =ROUND(E28*I28,0) -> 0
A29: 3 | B29: Backfilling soil for foundation Đắp đất | D29: m3 | E29: 452.77284 | H29: 0 | I29: =+SUM(F29:H29) -> 0 | J29: =ROUND(E29*I29,0) -> 0
A30: 4 | B30: Remove surplus soil Vận chuyển đất đổ đi | C30: Distance D<=1Km Khoảng cách D<=1Km | D30: m3 | E30: 792.35247 | H30: 0 | I30: =+SUM(F30:H30) -> 0 | J30: =ROUND(E30*I30,0) -> 0
A31: 5 | B31: Earth compaction, K=0.9 Đầm đất, K=0.9 | D31: m2 | E31: 1830 | H31: 0 | I31: =+SUM(F31:H31) -> 0 | J31: =ROUND(E31*I31,0) -> 0
A32: 6 | B32: Compacting by stone aggregate K=0.95 Đá base đầm chặt K=0.95 | C32: Base type I / CPĐD - I Cấp phối đá dăm loại I | D32: m3 | E32: 475.8 | H32: 0 | I32: =+SUM(F32:H32) -> 0 | J32: =ROUND(E32*I32,0) -> 0
A33: 7 | B33: 1 layer nylon thk. 0.3mm 1 lớp nylon dày 0.3mm | D33: m2 | E33: 1830 | H33: 0 | I33: =+SUM(F33:H33) -> 0 | J33: =ROUND(E33*I33,0) -> 0
A35: 2 | B35: CONCRETE WORK / CÔNG TÁC BÊ TÔNG | J35: =SUM(J36:J40) -> 0
A36: 1 | B36: Lean concrete for foundation, ground beam Bê tông lót cho móng, dầm | C36: Gr. 150 | D36: m3 | E36: 111.61389 | H36: 0 | I36: =F36+G36+H36 -> 0 | J36: =ROUND(E36*I36,0) -> 0
A37: 2 | B37: Concrete for foundation,beams, ground slab, scolumn Bê tông móng, dầm móng, nền, cổ cột | C37: Gr. 300 | D37: m3 | E37: 391.15354 | H37: 0 | I37: =F37+G37+H37 -> 0 | J37: =ROUND(E37*I37,0) -> 0
A38: 3 | B38: Pump car Bơm bê tông | D38: m3 | E38: 502.76743 | H38: 0 | I38: =F38+G38+H38 -> 0 | J38: =ROUND(E38*I38,0) -> 0 | K38: đã bao gồm
A39: 4 | B39: Polishing for slab by machine Xoa nền bằng máy | D39: m2 | E39: 1830 | H39: 0 | I39: =F39+G39+H39 -> 0 | J39: =ROUND(E39*I39,0) -> 0
A40: 5 | B40: Cutting joint for floor/ Cắt mạch nền | D40: m | E40: 626 | H40: 0 | I40: =F40+G40+H40 -> 0 | J40: =ROUND(E40*I40,0) -> 0
A42: 3 | B42: FORM WORK / CÔNG TÁC VÁN KHUÔN | J42: =+SUM(J43:J44) -> 0
A43: 1 | B43: For lean concrete for foundation & ground beam Ván khuôn bê tông lót móng, dầm | D43: m2 | E43: 53.74425 | H43: 0 | I43: =+SUM(F43:H43) -> 0 | J43: =ROUND(E43*I43,0) -> 0
A44: 2 | B44: For foundation, ground beam, slab, scolumn Ván khuôn móng, dầm, nền, cổ cột | D44: m2 | E44: 441.9954 | H44: 0 | I44: =+SUM(F44:H44) -> 0 | J44: =ROUND(E44*I44,0) -> 0
A45: 4 | B45: REINFORCEMENT WORK / CÔNG TÁC CỐT THÉP | J45: =+SUM(J46:J48) -> 0
A46: 1 | B46: Re-bar for foundation, ground beam, ground slab Cốt thép móng, dầm, cổ cột | D46: ton | E46: 4.4734667 | H46: 0 | I46: =+SUM(F46:H46) -> 0 | J46: =ROUND(E46*I46,0) -> 0 | K46: Hoa Phat/ Equivalent
A47: 2 | B47: Re-bar for ground slab Cốt thép cho sàn | D47: ton | E47: 8.5287632 | H47: 0 | I47: =+SUM(F47:H47) -> 0 | J47: =ROUND(E47*I47,0) -> 0 | K47: =K46 -> Hoa Phat/ Equivalent
...

Sheet 5.Nhà Lò Hơi & Nén Khí
A1: ='4.Nhà BB Thuỷ Tinh, Carton'!A1:K1 -> BILL OF QUANTITIES
A2: =+Cover!C7 -> PROJECT NAME / TÊN DỰ ÁN :
A3: 5.NHÀ LÒ HƠI + NHÀ NÉN KHÍ
A4: NO / STT | B4: WORK SCOPE / CÔNG VIỆC | C4: SPECIFICATION / ĐẶC ĐIỂM KỸ THUẬT | D4: UNIT/ ĐƠN VỊ | E4: QUANTITY / KHỐI LƯỢNG | F4: UNIT PRICE / ĐƠN GIÁ (VNĐ) | J4: AMOUNT / THÀNH TIỀN (VNĐ) | K4: REMARK / GHI CHÚ
F5: MATERIAL / VẬT LIỆU | G5: LABOUR / NHÂN CÔNG | H5: EQUIPMENT / THIẾT BỊ | I5: UNIT PRICE / TỔNG ĐƠN GIÁ
A6: 5 | B6: NHÀ LÒ HƠI + NÉN KHÍ | J6: =+J7+J14 -> 0
A7: A | B7: =B25 -> STRUCTURE WORK / CÔNG TÁC KẾT CẤU | J7: =SUM(J8:J12) -> 0
A8: 1 | B8: =+B26 -> EARTH WORK / CÔNG TÁC ĐẤT | D8: lot | E8: 1 | J8: =+J26 -> 0
A9: =+A8+1 -> 2 | B9: =+B35 -> CONCRETE WORK / CÔNG TÁC BÊ TÔNG | D9: lot | E9: 1 | J9: =+J35 -> 0
A10: =+A9+1 -> 3 | B10: =+B42 -> FORM WORK / CÔNG TÁC VÁN KHUÔN | D10: lot | E10: 1 | J10: =+J42 -> 0
A11: =+A10+1 -> 4 | B11: =+B45 -> REINFORCEMENT WORK / CÔNG TÁC CỐT THÉP | D11: lot | E11: 1 | J11: =+J45 -> 0
A12: =+A11+1 -> 5 | B12: =+B50 -> STEEL STRUCTURE WORK / CÔNG TÁC KẾT CẤU THÉP TIỀN CHẾ | D12: lot | E12: 1 | J12: =+J50 -> 0
A14: B | B14: =B70 -> FINISING WORK / CÔNG TÁC HOÀN THIỆN | J14: =SUM(J15:J20) -> 0
A15: 1 | B15: =B71 -> FLOOR FINISHING WORK / HOÀN THIỆN SÀN | D15: lot | E15: 1 | J15: =J71 -> 0
A16: 2 | B16: =B74 -> CEILLING WORK / CÔNG TÁC TRẦN | D16: lot | E16: 1 | J16: =J74 -> 0
A17: =+A16+1 -> 3 | B17: =B79 -> OUTSIDE & INSIDE WALL PANEL WORK / CÔNG TÁC VÁCH PANEL | D17: lot | E17: 1 | J17: =J79 -> 0
A18: =+A17+1 -> 4 | B18: =B94 -> ROOF WORK/ CÔNG TÁC MÁI | D18: lot | E18: 1 | J18: =J94 -> 0
A19: =+A18+1 -> 5 | B19: =B116 -> DOOR AND WINDOW / CỬA ĐI VÀ CỬA SỔ | D19: lot | E19: 1 | J19: =J116 -> 0
A20: =+A19+1 -> 6 | B20: =B122 -> OTHERS WORK / CÔNG VIỆC KHÁC | D20: lot | E20: 1 | J20: =J122 -> 0
A25: A | B25: STRUCTURE WORK / CÔNG TÁC KẾT CẤU | J25: =+J26+J35+J42+J45+J50 -> 0
A26: 1 | B26: EARTH WORK / CÔNG TÁC ĐẤT | J26: =SUM(J27:J33) -> 0
A27: 1 | B27: Excavation (by Equipment) Đào đất bằng máy | D27: m3 | E27: 501.0902 | I27: =+SUM(F27:H27) -> 0 | J27: =ROUND(E27*I27,0) -> 0
A28: 2 | B28: Excavation (by worker) Đào đất thủ công | D28: m3 | E28: 50.10902 | I28: =+SUM(F28:H28) -> 0 | J28: =ROUND(E28*I28,0) -> 0
A29: 3 | B29: Backfilling soil for foundation Đắp đất | D29: m3 | E29: 200.43608 | I29: =+SUM(F29:H29) -> 0 | J29: =ROUND(E29*I29,0) -> 0
A30: 4 | B30: Remove surplus soil Vận chuyển đất đổ đi | C30: Distance D<=1Km Khoảng cách D<=1Km | D30: m3 | E30: 350.76314 | I30: =+SUM(F30:H30) -> 0 | J30: =ROUND(E30*I30,0) -> 0
A31: 5 | B31: Earth compaction, K=0.9 Đầm đất, K=0.9 | D31: m2 | E31: 600 | I31: =+SUM(F31:H31) -> 0 | J31: =ROUND(E31*I31,0) -> 0
A32: 6 | B32: Compacting by stone aggregate K=0.95 Đá base đầm chặt K=0.95 | C32: Base type I / CPĐD - I Cấp phối đá dăm loại I | D32: m3 | E32: 156 | I32: =+SUM(F32:H32) -> 0 | J32: =ROUND(E32*I32,0) -> 0
A33: 7 | B33: 1 layer nylon thk. 0.3mm 1 lớp nylon dày 0.3mm | D33: m2 | E33: 600 | I33: =+SUM(F33:H33) -> 0 | J33: =ROUND(E33*I33,0) -> 0
A35: 2 | B35: CONCRETE WORK / CÔNG TÁC BÊ TÔNG | J35: =SUM(J36:J40) -> 0
A36: 1 | B36: Lean concrete for foundation, ground beam Bê tông lót cho móng, dầm | C36: Gr. 150 | D36: m3 | E36: 39.84246 | I36: =F36+G36+H36 -> 0 | J36: =ROUND(E36*I36,0) -> 0
A37: 2 | B37: Concrete for foundation,beams, ground slab, scolumn Bê tông móng, dầm móng, nền, cổ cột | C37: Gr. 300 | D37: m3 | E37: 149.2648 | I37: =F37+G37+H37 -> 0 | J37: =ROUND(E37*I37,0) -> 0
A38: 3 | B38: Pump car Bơm bê tông | D38: m3 | E38: 189.10726 | I38: =F38+G38+H38 -> 0 | J38: =ROUND(E38*I38,0) -> 0 | K38: đã bao gồm
A39: 4 | B39: Polishing for slab by machine Xoa nền bằng máy | D39: m2 | E39: 600 | I39: =F39+G39+H39 -> 0 | J39: =ROUND(E39*I39,0) -> 0
A40: 5 | B40: Cutting joint for floor/ Cắt mạch nền | D40: m | E40: 626 | I40: =F40+G40+H40 -> 0 | J40: =ROUND(E40*I40,0) -> 0
A42: 3 | B42: FORM WORK / CÔNG TÁC VÁN KHUÔN | J42: =+SUM(J43:J44) -> 0
A43: 1 | B43: For lean concrete for foundation & ground beam Ván khuôn bê tông lót móng, dầm | D43: m2 | E43: 29.23725 | I43: =+SUM(F43:H43) -> 0 | J43: =ROUND(E43*I43,0) -> 0
A44: 2 | B44: For foundation, ground beam, slab, scolumn Ván khuôn móng, dầm, nền, cổ cột | D44: m2 | E44: 239.5596 | I44: =+SUM(F44:H44) -> 0 | J44: =ROUND(E44*I44,0) -> 0
A45: 4 | B45: REINFORCEMENT WORK / CÔNG TÁC CỐT THÉP | J45: =+SUM(J46:J48) -> 0
A46: 1 | B46: Re-bar for foundation, ground beam, ground slab Cốt thép móng, dầm, cổ cột | D46: ton | E46: 2.61826 | I46: =+SUM(F46:H46) -> 0 | J46: =ROUND(E46*I46,0) -> 0 | K46: Hoa Phat/ Equivalent
A47: 2 | B47: Re-bar for ground slab Cốt thép cho sàn | D47: ton | E47: 2.7963158 | I47: =+SUM(F47:H47) -> 0 | J47: =ROUND(E47*I47,0) -> 0 | K47: =K46 -> Hoa Phat/ Equivalent
...

Sheet 6.Nhà Để Xe Máy
A1: BILL OF QUANTITIES
A2: =Cover!C7 -> PROJECT NAME / TÊN DỰ ÁN :
A3: 6. BIKE PARKING & PUMP ROOM/ NHÀ XE MÁY & PHÒNG BƠM
A4: NO / STT | B4: WORK SCOPE / CÔNG VIỆC | C4: SPECIFICATION / ĐẶC ĐIỂM KỸ THUẬT | D4: UNIT/ ĐƠN VỊ | E4: QUANTITY / KHỐI LƯỢNG | F4: UNIT PRICE / ĐƠN GIÁ (VNĐ) | J4: AMOUNT / THÀNH TIỀN (VNĐ) | K4: REMARK / GHI CHÚ
F5: MATERIAL / VẬT LIỆU | G5: LABOUR / NHÂN CÔNG | H5: EQUIPMENT / THIẾT BỊ | I5: UNIT PRICE / TỔNG ĐƠN GIÁ
A6: 6 | B6: BIKE PARKING & PUMP ROOM/ NHÀ XE MÁY & PHÒNG BƠM | J6: =+J7+J14 -> 0
A7: A | B7: =B26 -> STRUCTURE WORK / CÔNG TÁC KẾT CẤU | J7: =SUM(J8:J12) -> 0
A8: 1 | B8: =+B27 -> EARTH WORK / CÔNG TÁC ĐẤT | D8: lot | E8: 1 | J8: =+J27 -> 0
A9: =+A8+1 -> 2 | B9: =+B36 -> CONCRETE WORK / CÔNG TÁC BÊ TÔNG | D9: lot | E9: 1 | J9: =+J36 -> 0
A10: =+A9+1 -> 3 | B10: =+B44 -> FORM WORK / CÔNG TÁC VÁN KHUÔN | D10: lot | E10: 1 | J10: =+J44 -> 0
A11: =+A10+1 -> 4 | B11: =+B47 -> REINFORCEMENT WORK / CÔNG TÁC CỐT THÉP | D11: lot | E11: 1 | J11: =+J47 -> 0
A12: =+A11+1 -> 5 | B12: =+B51 -> STEEL STRUCTURE WORK / CÔNG TÁC KẾT CẤU THÉP TIỀN CHẾ | D12: lot | E12: 1 | J12: =+J51 -> 0
A14: B | B14: =B80 -> FINISING WORK / CÔNG TÁC HOÀN THIỆN | J14: =SUM(J15:J21) -> 0
A15: 1 | B15: =B81 -> BRICK WORK / CÔNG TÁC XÂY | D15: lot | E15: 1 | J15: =J81 -> 0
A16: =+A15+1 -> 2 | B16: =B84 -> PLASTERING WORK / CÔNG TÁC TRÁT | D16: lot | E16: 1 | J16: =J84 -> 0
A17: =+A16+1 -> 3 | B17: =B88 -> PAINTING WORK / CÔNG TÁC SƠN | D17: lot | E17: 1 | J17: =J88 -> 0
A18: =+A17+1 -> 4 | B18: =B91 -> TILING & FLOOR FINISHING WORK / ỐP LÁT VÀ HOÀN THIỆN SÀN | D18: lot | E18: 1 | J18: =J91 -> 0
A19: =+A18+1 -> 5 | B19: =B94 -> ROOF WORK/ CÔNG TÁC MÁI | D19: lot | E19: 1 | J19: =J94 -> 0
A20: =+A19+1 -> 6 | B20: =B111 -> DOOR AND WINDOW / CỬA ĐI VÀ CỬA SỔ | D20: lot | E20: 1 | J20: =J111 -> 0
A21: =+A20+1 -> 7 | B21: =B115 -> OTHERS WORK / CÔNG VIỆC KHÁC | D21: lot | E21: 1 | J21: =J115 -> 0
A26: A | B26: STRUCTURE WORK / CÔNG TÁC KẾT CẤU | J26: =+J27+J36+J44+J47+J51 -> 0
A27: 1 | B27: EARTH WORK / CÔNG TÁC ĐẤT | J27: =SUM(J28:J34) -> 0
A28: 1 | B28: Excavation (by Equipment) Đào đất bằng máy | D28: m3 | E28: 579.6336 | I28: =+SUM(F28:H28) -> 0 | J28: =ROUND(E28*I28,0) -> 0
A29: 2 | B29: Excavation (by worker) Đào đất thủ công | D29: m3 | E29: 57.96336 | I29: =+SUM(F29:H29) -> 0 | J29: =ROUND(E29*I29,0) -> 0
A30: 3 | B30: Backfilling soil for foundation Đắp đất | D30: m3 | E30: 231.85344 | I30: =+SUM(F30:H30) -> 0 | J30: =ROUND(E30*I30,0) -> 0
A31: 4 | B31: Remove surplus soil Vận chuyển đất đổ đi | C31: Distance D<=1Km Khoảng cách D<=1Km | D31: m3 | E31: 405.74352 | I31: =+SUM(F31:H31) -> 0 | J31: =ROUND(E31*I31,0) -> 0
A32: 5 | B32: Earth compaction, K=0.9 Đầm đất, K=0.9 | D32: m2 | E32: 370 | I32: =+SUM(F32:H32) -> 0 | J32: =ROUND(E32*I32,0) -> 0
A33: 6 | B33: Compacting by stone aggregate K=0.95 Đá base đầm chặt K=0.95 | C33: Base type I / CPĐD - I Cấp phối đá dăm loại I | D33: m3 | E33: 144.3 | I33: =+SUM(F33:H33) -> 0 | J33: =ROUND(E33*I33,0) -> 0
A34: 7 | B34: 1 layer nylon thk. 0.3mm 1 lớp nylon dày 0.3mm | D34: m2 | E34: 370 | I34: =+SUM(F34:H34) -> 0 | J34: =ROUND(E34*I34,0) -> 0
A36: 3 | B36: CONCRETE WORK / CÔNG TÁC BÊ TÔNG | J36: =SUM(J37:J42) -> 0
A37: 1 | B37: Lean concrete for foundation, ground beam Bê tông lót cho móng, dầm | C37: Gr. 150 | D37: m3 | E37: 6.7568 | I37: =F37+G37+H37 -> 0 | J37: =ROUND(E37*I37,0) -> 0
A38: 2 | B38: Concrete for foundation,beams, ground slab, scolumn Bê tông móng, dầm móng, nền, cổ cột | C38: Gr. 300 | D38: m3 | E38: 89.5688 | I38: =F38+G38+H38 -> 0 | J38: =ROUND(E38*I38,0) -> 0
A39: 3 | B39: Concrete for beams, column Bê tông dầm, cột | C39: Gr. 300 | D39: m3 | E39: 57.9272 | I39: =F39+G39+H39 -> 0 | J39: =ROUND(E39*I39,0) -> 0
A40: 4 | B40: Pump car Bơm bê tông | D40: m3 | E40: 154.2528 | I40: =F40+G40+H40 -> 0 | J40: =ROUND(E40*I40,0) -> 0 | K40: đã bao gồm
A41: 5 | B41: Polishing for slab by machine Xoa nền bằng máy | D41: m2 | E41: 570 | I41: =F41+G41+H41 -> 0 | J41: =ROUND(E41*I41,0) -> 0
A42: 6 | B42: Cutting joint for floor/ Cắt mạch nền | D42: m | E42: 257 | I42: =F42+G42+H42 -> 0 | J42: =ROUND(E42*I42,0) -> 0
A44: 4 | B44: FORM WORK / CÔNG TÁC VÁN KHUÔN | J44: =+SUM(J45:J46) -> 0
A45: 1 | B45: For lean concrete for foundation & ground beam Ván khuôn bê tông lót móng, dầm | D45: m2 | E45: 20.307 | I45: =+SUM(F45:H45) -> 0 | J45: =ROUND(E45*I45,0) -> 0
A46: 2 | B46: For foundation, ground beam, slab, scolumn Ván khuôn móng, dầm, nền, cổ cột | D46: m2 | E46: 397.53 | I46: =+SUM(F46:H46) -> 0 | J46: =ROUND(E46*I46,0) -> 0
A47: 5 | B47: REINFORCEMENT WORK / CÔNG TÁC CỐT THÉP | J47: =+SUM(J48:J49) -> 0
...

Sheet 7.Nhà Nghỉ Giữa Ca
A1: BILL OF QUANTITIES
A2: ='C4.Hệ Thống Điện & Điện Nhẹ '!A2:K2 -> PROJECT NAME / TÊN DỰ ÁN :
A3: 7. DORMITORY HOUSE/ NHÀ NGHỈ GIỮA CA
A4: NO / STT | B4: WORK SCOPE / CÔNG VIỆC | C4: SPECIFICATION / ĐẶC ĐIỂM KỸ THUẬT | D4: UNIT/ ĐƠN VỊ | E4: QUANTITY / KHỐI LƯỢNG | F4: UNIT PRICE / ĐƠN GIÁ (VNĐ) | J4: AMOUNT / THÀNH TIỀN (VNĐ) | K4: REMARK / GHI CHÚ
F5: MATERIAL / VẬT LIỆU | G5: LABOUR / NHÂN CÔNG | H5: EQUIPMENT / THIẾT BỊ | I5: UNIT PRICE / TỔNG ĐƠN GIÁ
A6: 7 | B6: DORMITORY HOUSE/ NHÀ NGHỈ GIỮA CA | J6: =+J7+J12 -> 0
A7: A | B7: =$B$23 -> STRUCTURE WORK / CÔNG TÁC KẾT CẤU | J7: =SUM(J8:J11) -> 0
A8: 1 | B8: =+B24 -> EARTH WORK / CÔNG TÁC ĐẤT | D8: lot | E8: 1 | J8: =+J24 -> 0
A9: 2 | B9: =+B33 -> CONCRETE WORK / CÔNG TÁC BÊ TÔNG | D9: lot | E9: 1 | J9: =+J33 -> 0
A10: =+A9+1 -> 3 | B10: =+B40 -> FORM WORK / CÔNG TÁC VÁN KHUÔN | D10: lot | E10: 1 | J10: =+J40 -> 0
A11: =+A10+1 -> 4 | B11: =+B45 -> REINFORCEMENT WORK / CÔNG TÁC CỐT THÉP | D11: lot | E11: 1 | J11: =+J45 -> 0
A12: B | B12: =B50 -> FINISING WORK / CÔNG TÁC HOÀN THIỆN | J12: =SUM(J13:J19) -> 0
A13: 1 | B13: =+B51 -> BRICK WORK / CÔNG TÁC XÂY | D13: lot | E13: 1 | J13: =+J51 -> 0
A14: =+A13+1 -> 2 | B14: =+B54 -> PLASTERING WORK / CÔNG TÁC TRÁT | D14: lot | E14: 1 | J14: =+J54 -> 0
A15: =+A14+1 -> 3 | B15: =+B40 -> FORM WORK / CÔNG TÁC VÁN KHUÔN | D15: lot | E15: 1 | J15: =+J58 -> 0
A16: =+A15+1 -> 4 | B16: =+B45 -> REINFORCEMENT WORK / CÔNG TÁC CỐT THÉP | D16: lot | E16: 1 | J16: =+J61 -> 0
A17: =+A16+1 -> 5 | B17: =+B71 -> WET FINISHING WORK / CÔNG TÁC HOÀN THIỆN MỀM | D17: lot | E17: 1 | J17: =+J71 -> 0
A18: =+A17+1 -> 6 | B18: =+B75 -> DOOR AND WINDOW / CỬA ĐI VÀ CỬA SỔ | D18: lot | E18: 1 | J18: =+J75 -> 0
A19: =+A18+1 -> 7 | B19: =+B79 -> OTHERS WORK/ CÔNG VIỆC KHÁC | D19: lot | E19: 1 | J19: =+J79 -> 0
A23: A | B23: STRUCTURE WORK / CÔNG TÁC KẾT CẤU | J23: =+J24+J33+J40+J45 -> 0
A24: 1 | B24: EARTH WORK / CÔNG TÁC ĐẤT | J24: =SUM(J25:J31) -> 0
A25: 1 | B25: Excavation (by Equipment) Đào đất bằng máy | D25: m3 | E25: 167.5024 | I25: =+SUM(F25:H25) -> 0 | J25: =ROUND(E25*I25,0) -> 0
A26: 2 | B26: Excavation (by worker) Đào đất thủ công | D26: m3 | E26: 33.50048 | I26: =+SUM(F26:H26) -> 0 | J26: =ROUND(E26*I26,0) -> 0
A27: 3 | B27: Backfilling soil for foundation Đắp đất | D27: m3 | E27: 50.25072 | I27: =+SUM(F27:H27) -> 0 | J27: =ROUND(E27*I27,0) -> 0
A28: 4 | B28: Remove surplus soil Vận chuyển đất đổ đi | C28: Distance D<=1Km Khoảng cách D<=1Km | D28: m3 | E28: 150.75216 | I28: =+SUM(F28:H28) -> 0 | J28: =ROUND(E28*I28,0) -> 0
A29: 5 | B29: Earth compaction, K=0.9 Đầm đất, K=0.9 | D29: m2 | E29: 120 | I29: =+SUM(F29:H29) -> 0 | J29: =ROUND(E29*I29,0) -> 0
A30: 6 | B30: Compacting by stone aggregate K=0.95 Đá base đầm chặt K=0.95 | D30: m3 | E30: 46.8 | I30: =+SUM(F30:H30) -> 0 | J30: =ROUND(E30*I30,0) -> 0
A31: 7 | B31: 1 layer nylon thk. 0.3mm 1 lớp nylon dày 0.3mm | D31: m2 | E31: 120 | I31: =+SUM(F31:H31) -> 0 | J31: =ROUND(E31*I31,0) -> 0
A33: 2 | B33: CONCRETE WORK / CÔNG TÁC BÊ TÔNG | J33: =SUM(J34:J38) -> 0
A34: 1 | B34: Lean concrete for foundation & ground beam Bê tông lót cho móng, dầm | C34: Gr. 100 | D34: m3 | E34: 2.40608 | I34: =+SUM(F34:H34) -> 0 | J34: =ROUND(E34*I34,0) -> 0
A35: 2 | B35: Concrete for foundation,beams, ground slab Bê tông móng, dầm móng, nền | C35: Gr. 300 | D35: m3 | E35: 26.93244 | I35: =+SUM(F35:H35) -> 0 | J35: =ROUND(E35*I35,0) -> 0
A36: 3 | B36: Concrete for column, beams, slab roof Bê tông cột, dầm, sàn tầng mái | C36: Gr.300 | D36: m3 | E36: 27.94184 | I36: =+SUM(F36:H36) -> 0 | J36: =ROUND(E36*I36,0) -> 0
A37: 4 | B37: Pump car Bơm bê tông | D37: m3 | E37: 57.28036 | I37: =+SUM(F37:H37) -> 0 | J37: =ROUND(E37*I37,0) -> 0 | K37: đã bao gồm
A38: 5 | B38: Polishing for slab Xoa nền | D38: m2 | E38: 267 | I38: =+SUM(F38:H38) -> 0 | J38: =ROUND(E38*I38,0) -> 0
A40: 3 | B40: FORM WORK / CÔNG TÁC VÁN KHUÔN | J40: =+SUM(J41:J43) -> 0
A41: 1 | B41: For lean concrete for foundation Ván khuôn bê tông lót móng | D41: m2 | E41: 9.66 | I41: =+SUM(F41:H41) -> 0 | J41: =ROUND(E41*I41,0) -> 0
A42: 2 | B42: For foundation, ground beam, slab Ván khuôn móng, dầm, nền | D42: m2 | E42: 110.565 | I42: =+SUM(F42:H42) -> 0 | J42: =ROUND(E42*I42,0) -> 0
A43: 3 | B43: For column, beams, slab roof Ván khuôn cột, dầm, sàn tầng mái | D43: m2 | E43: 271.614 | I43: =+SUM(F43:H43) -> 0 | J43: =ROUND(E43*I43,0) -> 0
A45: 4 | B45: REINFORCEMENT WORK / CÔNG TÁC CỐT THÉP | J45: =+SUM(J46:J48) -> 0
A46: 1 | B46: Re-bar for foundation, ground beam, slab Cốt thép móng, dầm, nền | D46: ton | E46: 2.967066 | I46: =+SUM(F46:H46) -> 0 | J46: =ROUND(E46*I46,0) -> 0
...

Sheet 8.Nhà Bảo Vệ 1
A1: BILL OF QUANTITIES
A2: ='C4.Hệ Thống Điện & Điện Nhẹ '!A2:K2 -> PROJECT NAME / TÊN DỰ ÁN :
A3: 8. GUARD HOUSE 1/ NHÀ BẢO VỆ 1
A4: NO / STT | B4: WORK SCOPE / CÔNG VIỆC | C4: SPECIFICATION / ĐẶC ĐIỂM KỸ THUẬT | D4: UNIT/ ĐƠN VỊ | E4: QUANTITY / KHỐI LƯỢNG | F4: UNIT PRICE / ĐƠN GIÁ (VNĐ) | J4: AMOUNT / THÀNH TIỀN (VNĐ) | K4: REMARK / GHI CHÚ
F5: MATERIAL / VẬT LIỆU | G5: LABOUR / NHÂN CÔNG | H5: EQUIPMENT / THIẾT BỊ | I5: UNIT PRICE / TỔNG ĐƠN GIÁ
A6: 8 | B6: GUARD HOUSE 1/ NHÀ BẢO VỆ 1 | J6: =+J7+J12 -> 0
A7: A | B7: =$B$23 -> STRUCTURE WORK / CÔNG TÁC KẾT CẤU | J7: =SUM(J8:J11) -> 0
A8: 1 | B8: =+B24 -> EARTH WORK / CÔNG TÁC ĐẤT | D8: lot | E8: 1 | J8: =+J24 -> 0
A9: 2 | B9: =+B33 -> CONCRETE WORK / CÔNG TÁC BÊ TÔNG | D9: lot | E9: 1 | J9: =+J33 -> 0
A10: =+A9+1 -> 3 | B10: =+B40 -> FORM WORK / CÔNG TÁC VÁN KHUÔN | D10: lot | E10: 1 | J10: =+J40 -> 0
A11: =+A10+1 -> 4 | B11: =+B45 -> REINFORCEMENT WORK / CÔNG TÁC CỐT THÉP | D11: lot | E11: 1 | J11: =+J45 -> 0
A12: B | B12: =B50 -> FINISING WORK / CÔNG TÁC HOÀN THIỆN | J12: =SUM(J13:J19) -> 0
A13: 1 | B13: =+B51 -> BRICK WORK / CÔNG TÁC XÂY | D13: lot | E13: 1 | J13: =+J51 -> 0
A14: =+A13+1 -> 2 | B14: =+B54 -> PLASTERING WORK / CÔNG TÁC TRÁT | D14: lot | E14: 1 | J14: =+J54 -> 0
A15: =+A14+1 -> 3 | B15: =+B40 -> FORM WORK / CÔNG TÁC VÁN KHUÔN | D15: lot | E15: 1 | J15: =+J58 -> 0
A16: =+A15+1 -> 4 | B16: =+B45 -> REINFORCEMENT WORK / CÔNG TÁC CỐT THÉP | D16: lot | E16: 1 | J16: =+J61 -> 0
A17: =+A16+1 -> 5 | B17: =+B71 -> WET FINISHING WORK / CÔNG TÁC HOÀN THIỆN MỀM | D17: lot | E17: 1 | J17: =+J71 -> 0
A18: =+A17+1 -> 6 | B18: =+B75 -> DOOR AND WINDOW / CỬA ĐI VÀ CỬA SỔ | D18: lot | E18: 1 | J18: =+J75 -> 0
A19: =+A18+1 -> 7 | B19: =+B79 -> OTHERS WORK/ CÔNG VIỆC KHÁC | D19: lot | E19: 1 | J19: =+J79 -> 0
A23: A | B23: STRUCTURE WORK / CÔNG TÁC KẾT CẤU | J23: =+J24+J33+J40+J45 -> 0
A24: 1 | B24: EARTH WORK / CÔNG TÁC ĐẤT | J24: =SUM(J25:J31) -> 0
A25: 1 | B25: Excavation (by Equipment) Đào đất bằng máy | D25: m3 | E25: 50.4088 | I25: =+SUM(F25:H25) -> 0 | J25: =ROUND(E25*I25,0) -> 0
A26: 2 | B26: Excavation (by worker) Đào đất thủ công | D26: m3 | E26: 10.08176 | I26: =+SUM(F26:H26) -> 0 | J26: =ROUND(E26*I26,0) -> 0
A27: 3 | B27: Backfilling soil for foundation Đắp đất | D27: m3 | E27: 15.12264 | I27: =+SUM(F27:H27) -> 0 | J27: =ROUND(E27*I27,0) -> 0
A28: 4 | B28: Remove surplus soil Vận chuyển đất đổ đi | C28: Distance D<=1Km Khoảng cách D<=1Km | D28: m3 | E28: 45.36792 | I28: =+SUM(F28:H28) -> 0 | J28: =ROUND(E28*I28,0) -> 0
A29: 5 | B29: Earth compaction, K=0.9 Đầm đất, K=0.9 | D29: m2 | E29: 15 | I29: =+SUM(F29:H29) -> 0 | J29: =ROUND(E29*I29,0) -> 0
A30: 6 | B30: Compacting by stone aggregate K=0.95 Đá base đầm chặt K=0.95 | D30: m3 | E30: 5.85 | I30: =+SUM(F30:H30) -> 0 | J30: =ROUND(E30*I30,0) -> 0
A31: 7 | B31: 1 layer nylon thk. 0.3mm 1 lớp nylon dày 0.3mm | D31: m2 | E31: 15 | I31: =+SUM(F31:H31) -> 0 | J31: =ROUND(E31*I31,0) -> 0
A33: 2 | B33: CONCRETE WORK / CÔNG TÁC BÊ TÔNG | J33: =SUM(J34:J38) -> 0
A34: 1 | B34: Lean concrete for foundation & ground beam Bê tông lót cho móng, dầm | C34: Gr. 100 | D34: m3 | E34: 0.8446 | I34: =+SUM(F34:H34) -> 0 | J34: =ROUND(E34*I34,0) -> 0
A35: 2 | B35: Concrete for foundation,beams, ground slab Bê tông móng, dầm móng, nền | C35: Gr. 300 | D35: m3 | E35: 6.30978 | I35: =+SUM(F35:H35) -> 0 | J35: =ROUND(E35*I35,0) -> 0
A36: 3 | B36: Concrete for column, beams, slab roof Bê tông cột, dầm, sàn tầng mái | C36: Gr.300 | D36: m3 | E36: 5.0264 | I36: =+SUM(F36:H36) -> 0 | J36: =ROUND(E36*I36,0) -> 0
A37: 4 | B37: Pump car Bơm bê tông | D37: m3 | E37: 12.18078 | I37: =+SUM(F37:H37) -> 0 | J37: =ROUND(E37*I37,0) -> 0 | K37: đã bao gồm
A38: 5 | B38: Polishing for slab Xoa nền | D38: m2 | E38: 39 | I38: =+SUM(F38:H38) -> 0 | J38: =ROUND(E38*I38,0) -> 0
A40: 3 | B40: FORM WORK / CÔNG TÁC VÁN KHUÔN | J40: =+SUM(J41:J43) -> 0
A41: 1 | B41: For lean concrete for foundation Ván khuôn bê tông lót móng | D41: m2 | E41: 3.465 | I41: =+SUM(F41:H41) -> 0 | J41: =ROUND(E41*I41,0) -> 0
A42: 2 | B42: For foundation, ground beam, slab Ván khuôn móng, dầm, nền | D42: m2 | E42: 37.926 | I42: =+SUM(F42:H42) -> 0 | J42: =ROUND(E42*I42,0) -> 0
A43: 3 | B43: For column, beams, slab roof Ván khuôn cột, dầm, sàn tầng mái | D43: m2 | E43: 51.576 | I43: =+SUM(F43:H43) -> 0 | J43: =ROUND(E43*I43,0) -> 0
A45: 4 | B45: REINFORCEMENT WORK / CÔNG TÁC CỐT THÉP | J45: =+SUM(J46:J48) -> 0
A46: 1 | B46: Re-bar for foundation, ground beam, slab Cốt thép móng, dầm, nền | D46: ton | E46: 0.630978 | I46: =+SUM(F46:H46) -> 0 | J46: =ROUND(E46*I46,0) -> 0
...

Sheet 9.Nhà Bảo Vệ 2
A1: BILL OF QUANTITIES
A2: ='C4.Hệ Thống Điện & Điện Nhẹ '!A2:K2 -> PROJECT NAME / TÊN DỰ ÁN :
A3: 9. GUARD HOUSE 2/ NHÀ BẢO VỆ 2
A4: NO / STT | B4: WORK SCOPE / CÔNG VIỆC | C4: SPECIFICATION / ĐẶC ĐIỂM KỸ THUẬT | D4: UNIT/ ĐƠN VỊ | E4: QUANTITY / KHỐI LƯỢNG | F4: UNIT PRICE / ĐƠN GIÁ (VNĐ) | J4: AMOUNT / THÀNH TIỀN (VNĐ) | K4: REMARK / GHI CHÚ
F5: MATERIAL / VẬT LIỆU | G5: LABOUR / NHÂN CÔNG | H5: EQUIPMENT / THIẾT BỊ | I5: UNIT PRICE / TỔNG ĐƠN GIÁ
A6: 9 | B6: GUARD HOUSE 2/ NHÀ BẢO VỆ 2 | J6: =+J7+J12 -> 0
A7: A | B7: =$B$23 -> STRUCTURE WORK / CÔNG TÁC KẾT CẤU | J7: =SUM(J8:J11) -> 0
A8: 1 | B8: =+B24 -> EARTH WORK / CÔNG TÁC ĐẤT | D8: lot | E8: 1 | J8: =+J24 -> 0
A9: 2 | B9: =+B33 -> CONCRETE WORK / CÔNG TÁC BÊ TÔNG | D9: lot | E9: 1 | J9: =+J33 -> 0
A10: =+A9+1 -> 3 | B10: =+B40 -> FORM WORK / CÔNG TÁC VÁN KHUÔN | D10: lot | E10: 1 | J10: =+J40 -> 0
A11: =+A10+1 -> 4 | B11: =+B45 -> REINFORCEMENT WORK / CÔNG TÁC CỐT THÉP | D11: lot | E11: 1 | J11: =+J45 -> 0
A12: B | B12: =B50 -> FINISING WORK / CÔNG TÁC HOÀN THIỆN | J12: =SUM(J13:J19) -> 0
A13: 1 | B13: =+B51 -> BRICK WORK / CÔNG TÁC XÂY | D13: lot | E13: 1 | J13: =+J51 -> 0
A14: =+A13+1 -> 2 | B14: =+B54 -> PLASTERING WORK / CÔNG TÁC TRÁT | D14: lot | E14: 1 | J14: =+J54 -> 0
A15: =+A14+1 -> 3 | B15: =+B40 -> FORM WORK / CÔNG TÁC VÁN KHUÔN | D15: lot | E15: 1 | J15: =+J58 -> 0
A16: =+A15+1 -> 4 | B16: =+B45 -> REINFORCEMENT WORK / CÔNG TÁC CỐT THÉP | D16: lot | E16: 1 | J16: =+J61 -> 0
A17: =+A16+1 -> 5 | B17: =+B71 -> WET FINISHING WORK / CÔNG TÁC HOÀN THIỆN MỀM | D17: lot | E17: 1 | J17: =+J71 -> 0
A18: =+A17+1 -> 6 | B18: =+B75 -> DOOR AND WINDOW / CỬA ĐI VÀ CỬA SỔ | D18: lot | E18: 1 | J18: =+J75 -> 0
A19: =+A18+1 -> 7 | B19: =+B79 -> OTHERS WORK/ CÔNG VIỆC KHÁC | D19: lot | E19: 1 | J19: =+J79 -> 0
A23: A | B23: STRUCTURE WORK / CÔNG TÁC KẾT CẤU | J23: =+J24+J33+J40+J45 -> 0
A24: 1 | B24: EARTH WORK / CÔNG TÁC ĐẤT | J24: =SUM(J25:J31) -> 0
A25: 1 | B25: Excavation (by Equipment) Đào đất bằng máy | D25: m3 | E25: 50.4088 | I25: =+SUM(F25:H25) -> 0 | J25: =ROUND(E25*I25,0) -> 0
A26: 2 | B26: Excavation (by worker) Đào đất thủ công | D26: m3 | E26: 10.08176 | I26: =+SUM(F26:H26) -> 0 | J26: =ROUND(E26*I26,0) -> 0
A27: 3 | B27: Backfilling soil for foundation Đắp đất | D27: m3 | E27: 15.12264 | I27: =+SUM(F27:H27) -> 0 | J27: =ROUND(E27*I27,0) -> 0
A28: 4 | B28: Remove surplus soil Vận chuyển đất đổ đi | C28: Distance D<=1Km Khoảng cách D<=1Km | D28: m3 | E28: 45.36792 | I28: =+SUM(F28:H28) -> 0 | J28: =ROUND(E28*I28,0) -> 0
A29: 5 | B29: Earth compaction, K=0.9 Đầm đất, K=0.9 | D29: m2 | E29: 15 | I29: =+SUM(F29:H29) -> 0 | J29: =ROUND(E29*I29,0) -> 0
A30: 6 | B30: Compacting by stone aggregate K=0.95 Đá base đầm chặt K=0.95 | D30: m3 | E30: 5.85 | I30: =+SUM(F30:H30) -> 0 | J30: =ROUND(E30*I30,0) -> 0
A31: 7 | B31: 1 layer nylon thk. 0.3mm 1 lớp nylon dày 0.3mm | D31: m2 | E31: 15 | I31: =+SUM(F31:H31) -> 0 | J31: =ROUND(E31*I31,0) -> 0
A33: 2 | B33: CONCRETE WORK / CÔNG TÁC BÊ TÔNG | J33: =SUM(J34:J38) -> 0
A34: 1 | B34: Lean concrete for foundation & ground beam Bê tông lót cho móng, dầm | C34: Gr. 100 | D34: m3 | E34: 0.8446 | I34: =+SUM(F34:H34) -> 0 | J34: =ROUND(E34*I34,0) -> 0
A35: 2 | B35: Concrete for foundation,beams, ground slab Bê tông móng, dầm móng, nền | C35: Gr. 300 | D35: m3 | E35: 6.30978 | I35: =+SUM(F35:H35) -> 0 | J35: =ROUND(E35*I35,0) -> 0
A36: 3 | B36: Concrete for column, beams, slab roof Bê tông cột, dầm, sàn tầng mái | C36: Gr.300 | D36: m3 | E36: 5.0264 | I36: =+SUM(F36:H36) -> 0 | J36: =ROUND(E36*I36,0) -> 0
A37: 4 | B37: Pump car Bơm bê tông | D37: m3 | E37: 12.18078 | I37: =+SUM(F37:H37) -> 0 | J37: =ROUND(E37*I37,0) -> 0 | K37: đã bao gồm
A38: 5 | B38: Polishing for slab Xoa nền | D38: m2 | E38: 39 | I38: =+SUM(F38:H38) -> 0 | J38: =ROUND(E38*I38,0) -> 0
A40: 3 | B40: FORM WORK / CÔNG TÁC VÁN KHUÔN | J40: =+SUM(J41:J43) -> 0
A41: 1 | B41: For lean concrete for foundation Ván khuôn bê tông lót móng | D41: m2 | E41: 3.465 | I41: =+SUM(F41:H41) -> 0 | J41: =ROUND(E41*I41,0) -> 0
A42: 2 | B42: For foundation, ground beam, slab Ván khuôn móng, dầm, nền | D42: m2 | E42: 37.926 | I42: =+SUM(F42:H42) -> 0 | J42: =ROUND(E42*I42,0) -> 0
A43: 3 | B43: For column, beams, slab roof Ván khuôn cột, dầm, sàn tầng mái | D43: m2 | E43: 51.576 | I43: =+SUM(F43:H43) -> 0 | J43: =ROUND(E43*I43,0) -> 0
A45: 4 | B45: REINFORCEMENT WORK / CÔNG TÁC CỐT THÉP | J45: =+SUM(J46:J48) -> 0
A46: 1 | B46: Re-bar for foundation, ground beam, slab Cốt thép móng, dầm, nền | D46: ton | E46: 0.630978 | I46: =+SUM(F46:H46) -> 0 | J46: =ROUND(E46*I46,0) -> 0
...

Sheet 10.Nhà Rác, Phòng Điện
A1: BILL OF QUANTITIES
A2: ='C4.Hệ Thống Điện & Điện Nhẹ '!A2:K2 -> PROJECT NAME / TÊN DỰ ÁN :
A3: 10. GARBAGE, TRANSFORMER HOUSE/ NHÀ RÁC, PHÒNG ĐIỆN
A4: NO / STT | B4: WORK SCOPE / CÔNG VIỆC | C4: SPECIFICATION / ĐẶC ĐIỂM KỸ THUẬT | D4: UNIT/ ĐƠN VỊ | E4: QUANTITY / KHỐI LƯỢNG | F4: UNIT PRICE / ĐƠN GIÁ (VNĐ) | J4: AMOUNT / THÀNH TIỀN (VNĐ) | K4: REMARK / GHI CHÚ
F5: MATERIAL / VẬT LIỆU | G5: LABOUR / NHÂN CÔNG | H5: EQUIPMENT / THIẾT BỊ | I5: UNIT PRICE / TỔNG ĐƠN GIÁ
A6: 10 | B6: GARBAGE, TRANSFORMER HOUSE/ NHÀ RÁC, PHÒNG ĐIỆN | J6: =+J7+J12 -> 0
A7: A | B7: =$B$23 -> STRUCTURE WORK / CÔNG TÁC KẾT CẤU | J7: =SUM(J8:J11) -> 0
A8: 1 | B8: =+B24 -> EARTH WORK / CÔNG TÁC ĐẤT | D8: lot | E8: 1 | J8: =+J24 -> 0
A9: 2 | B9: =+B33 -> CONCRETE WORK / CÔNG TÁC BÊ TÔNG | D9: lot | E9: 1 | J9: =+J33 -> 0
A10: =+A9+1 -> 3 | B10: =+B40 -> FORM WORK / CÔNG TÁC VÁN KHUÔN | D10: lot | E10: 1 | J10: =+J40 -> 0
A11: =+A10+1 -> 4 | B11: =+B45 -> REINFORCEMENT WORK / CÔNG TÁC CỐT THÉP | D11: lot | E11: 1 | J11: =+J45 -> 0
A12: B | B12: =B50 -> FINISING WORK / CÔNG TÁC HOÀN THIỆN | J12: =SUM(J13:J19) -> 0
A13: 1 | B13: =+B51 -> BRICK WORK / CÔNG TÁC XÂY | D13: lot | E13: 1 | J13: =+J51 -> 0
A14: =+A13+1 -> 2 | B14: =+B54 -> PLASTERING WORK / CÔNG TÁC TRÁT | D14: lot | E14: 1 | J14: =+J54 -> 0
A15: =+A14+1 -> 3 | B15: =+B40 -> FORM WORK / CÔNG TÁC VÁN KHUÔN | D15: lot | E15: 1 | J15: =+J58 -> 0
A16: =+A15+1 -> 4 | B16: =+B45 -> REINFORCEMENT WORK / CÔNG TÁC CỐT THÉP | D16: lot | E16: 1 | J16: =+J61 -> 0
A17: =+A16+1 -> 5 | B17: =+B65 -> WET FINISHING WORK / CÔNG TÁC HOÀN THIỆN MỀM | D17: lot | E17: 1 | J17: =+J65 -> 0
A18: =+A17+1 -> 6 | B18: =+B68 -> DOOR AND WINDOW / CỬA ĐI VÀ CỬA SỔ | D18: lot | E18: 1 | J18: =+J68 -> 0
A19: =+A18+1 -> 7 | B19: =+B72 -> OTHERS WORK/ CÔNG VIỆC KHÁC | D19: lot | E19: 1 | J19: =+J72 -> 0
A23: A | B23: STRUCTURE WORK / CÔNG TÁC KẾT CẤU | J23: =+J24+J33+J40+J45 -> 0
A24: 1 | B24: EARTH WORK / CÔNG TÁC ĐẤT | J24: =SUM(J25:J31) -> 0
A25: 1 | B25: Excavation (by Equipment) Đào đất bằng máy | D25: m3 | E25: 203.2784 | I25: =+SUM(F25:H25) -> 0 | J25: =ROUND(E25*I25,0) -> 0
A26: 2 | B26: Excavation (by worker) Đào đất thủ công | D26: m3 | E26: 40.65568 | I26: =+SUM(F26:H26) -> 0 | J26: =ROUND(E26*I26,0) -> 0
A27: 3 | B27: Backfilling soil for foundation Đắp đất | D27: m3 | E27: 60.98352 | I27: =+SUM(F27:H27) -> 0 | J27: =ROUND(E27*I27,0) -> 0
A28: 4 | B28: Remove surplus soil Vận chuyển đất đổ đi | C28: Distance D<=1Km Khoảng cách D<=1Km | D28: m3 | E28: 182.95056 | I28: =+SUM(F28:H28) -> 0 | J28: =ROUND(E28*I28,0) -> 0
A29: 5 | B29: Earth compaction, K=0.9 Đầm đất, K=0.9 | D29: m2 | E29: 180 | I29: =+SUM(F29:H29) -> 0 | J29: =ROUND(E29*I29,0) -> 0
A30: 6 | B30: Compacting by stone aggregate K=0.95 Đá base đầm chặt K=0.95 | D30: m3 | E30: 70.2 | I30: =+SUM(F30:H30) -> 0 | J30: =ROUND(E30*I30,0) -> 0
A31: 7 | B31: 1 layer nylon thk. 0.3mm 1 lớp nylon dày 0.3mm | D31: m2 | E31: 180 | I31: =+SUM(F31:H31) -> 0 | J31: =ROUND(E31*I31,0) -> 0
A33: 2 | B33: CONCRETE WORK / CÔNG TÁC BÊ TÔNG | J33: =SUM(J34:J38) -> 0
A34: 1 | B34: Lean concrete for foundation & ground beam Bê tông lót cho móng, dầm | C34: Gr. 100 | D34: m3 | E34: 2.8634 | I34: =+SUM(F34:H34) -> 0 | J34: =ROUND(E34*I34,0) -> 0
A35: 2 | B35: Concrete for foundation,beams, ground slab Bê tông móng, dầm móng, nền | C35: Gr. 300 | D35: m3 | E35: 36.81426 | I35: =+SUM(F35:H35) -> 0 | J35: =ROUND(E35*I35,0) -> 0
A36: 3 | B36: Concrete for column, beams, slab roof Bê tông cột, dầm, sàn tầng mái | C36: Gr.300 | D36: m3 | E36: 48.14014 | I36: =+SUM(F36:H36) -> 0 | J36: =ROUND(E36*I36,0) -> 0
A37: 4 | B37: Pump car Bơm bê tông | D37: m3 | E37: 87.8178 | I37: =+SUM(F37:H37) -> 0 | J37: =ROUND(E37*I37,0) -> 0 | K37: đã bao gồm
A38: 5 | B38: Polishing for slab Xoa nền | D38: m2 | E38: 397 | I38: =+SUM(F38:H38) -> 0 | J38: =ROUND(E38*I38,0) -> 0
A40: 3 | B40: FORM WORK / CÔNG TÁC VÁN KHUÔN | J40: =+SUM(J41:J43) -> 0
A41: 1 | B41: For lean concrete for foundation Ván khuôn bê tông lót móng | D41: m2 | E41: 9.597 | I41: =+SUM(F41:H41) -> 0 | J41: =ROUND(E41*I41,0) -> 0
A42: 2 | B42: For foundation, ground beam, slab Ván khuôn móng, dầm, nền | D42: m2 | E42: 107.94 | I42: =+SUM(F42:H42) -> 0 | J42: =ROUND(E42*I42,0) -> 0
A43: 3 | B43: For column, beams, slab roof Ván khuôn cột, dầm, sàn tầng mái | D43: m2 | E43: 462.819 | I43: =+SUM(F43:H43) -> 0 | J43: =ROUND(E43*I43,0) -> 0
A45: 4 | B45: REINFORCEMENT WORK / CÔNG TÁC CỐT THÉP | J45: =+SUM(J46:J48) -> 0
A46: 1 | B46: Re-bar for foundation, ground beam, slab Cốt thép móng, dầm, nền | D46: ton | E46: 3.912939 | I46: =+SUM(F46:H46) -> 0 | J46: =ROUND(E46*I46,0) -> 0
...

Sheet 11.Bể Nước Ngầm PCCC
A1: BILL OF QUANTITIES
A2: ='C4.Hệ Thống Điện & Điện Nhẹ '!A2:K2 -> PROJECT NAME / TÊN DỰ ÁN :
A3: 11. WATER TANK FF/ BỂ NƯỚC NGẦM PCCC
A4: NO / STT | B4: WORK SCOPE / CÔNG VIỆC | C4: SPECIFICATION / ĐẶC ĐIỂM KỸ THUẬT | D4: UNIT/ ĐƠN VỊ | E4: QUANTITY / KHỐI LƯỢNG | F4: UNIT PRICE / ĐƠN GIÁ (VNĐ) | J4: AMOUNT / THÀNH TIỀN (VNĐ) | K4: REMARK / GHI CHÚ
F5: MATERIAL / VẬT LIỆU | G5: LABOUR / NHÂN CÔNG | H5: EQUIPMENT / THIẾT BỊ | I5: UNIT PRICE / TỔNG ĐƠN GIÁ
A6: 11 | B6: WATER TANK FF/ BỂ NƯỚC NGẦM PCCC | J6: =+J7+J13 -> 0
A7: A | B7: =$B$20 -> STRUCTURE WORK / CÔNG TÁC KẾT CẤU | J7: =+SUM(J8:J11) -> 0
A8: 1 | B8: =+B21 -> EARTH WORK / CÔNG TÁC ĐẤT | D8: lot | E8: 1 | J8: =+J21 -> 0
A9: =+A8+1 -> 2 | B9: =+B30 -> CONCRETE WORK / CÔNG TÁC BÊ TÔNG | D9: lot | E9: 1 | J9: =+J30 -> 0
A10: =+A9+1 -> 3 | B10: =+B38 -> FORM WORK / CÔNG TÁC VÁN KHUÔN | D10: lot | E10: 1 | J10: =+J38 -> 0
A11: =+A10+1 -> 4 | B11: =+B44 -> REINFORCEMENT WORK / CÔNG TÁC CỐT THÉP | D11: lot | E11: 1 | J11: =+J44 -> 0
A13: B | B13: =B49 -> FINISING WORK / CÔNG TÁC HOÀN THIỆN | J13: =+SUM(J14:J15) -> 0
A14: 1 | B14: WET FINISHING WORK | D14: lot | E14: 1 | J14: =+J50 -> 0
A15: 2 | B15: =$B$55 -> OTHERS WORK/ CÔNG VIỆC KHÁC | D15: lot | E15: 1 | J15: =+J55 -> 0
A20: A | B20: STRUCTURE WORK / CÔNG TÁC KẾT CẤU | J20: =+J21+J30+J38+J44 -> 0
A21: 1 | B21: EARTH WORK / CÔNG TÁC ĐẤT | J21: =+SUM(J22:J28) -> 0
A22: 1 | B22: Sheet pile cover for tank area Thi công cừ chắn cho khu vực bể | C22: Sheet pile 6m including transport & install | D22: lot | E22: 1 | I22: =+SUM(F22:H22) -> 0 | J22: =ROUND(E22*I22,0) -> 0
A23: 2 | B23: Excavation (by Equipment) Đào đất bằng máy | D23: m3 | E23: 942.5 | I23: =+SUM(F23:H23) -> 0 | J23: =ROUND(E23*I23,0) -> 0
A24: 3 | B24: Excavation (by worker) Đào đất thủ công | D24: m3 | E24: 141.375 | I24: =+SUM(F24:H24) -> 0 | J24: =ROUND(E24*I24,0) -> 0
A25: 4 | B25: Backfilling soil for foundation Đắp đất | D25: m3 | E25: 282.75 | I25: =+SUM(F25:H25) -> 0 | J25: =ROUND(E25*I25,0) -> 0
A26: 5 | B26: Remove surplus soil Vận chuyển đất đổ | C26: Distance D<=1Km Khoảng cách D<=1Km | D26: m3 | E26: 801.125 | I26: =+SUM(F26:H26) -> 0 | J26: =ROUND(E26*I26,0) -> 0
A27: =+A26+1 -> 6 | B27: Earth compaction, K=0.9 Đầm đất, K=0.9 | D27: m2 | E27: 290 | I27: =+SUM(F27:H27) -> 0 | J27: =ROUND(E27*I27,0) -> 0
A28: =+A27+1 -> 7 | B28: 1 layer nylon thk. 0.3mm 1 lớp nylon dày 0.3mm | D28: m2 | E28: 290 | I28: =+SUM(F28:H28) -> 0 | J28: =ROUND(E28*I28,0) -> 0
A30: 2 | B30: CONCRETE WORK / CÔNG TÁC BÊ TÔNG | J30: =+SUM(J31:J36) -> 0
A31: 1 | B31: Lean concrete for tank Bê tông lót | C31: Gr. 100 | D31: m3 | E31: 8.37184 | I31: =+SUM(F31:H31) -> 0 | J31: =ROUND(E31*I31,0) -> 0
A32: 2 | B32: Concrete for bottom Bê tông đáy bể | C32: Gr. 300 | D32: m3 | E32: 56.32452 | I32: =+SUM(F32:H32) -> 0 | J32: =ROUND(E32*I32,0) -> 0
A33: 3 | B33: Concrete for wall & column Bê tông thành bể và cột | C33: Gr. 300 | D33: m3 | E33: 45.3715 | I33: =+SUM(F33:H33) -> 0 | J33: =ROUND(E33*I33,0) -> 0
A34: 4 | B34: Concrete for cover slab Bê tông nắp bể | C34: Gr. 300 | D34: m3 | E34: 36.3075 | I34: =+SUM(F34:H34) -> 0 | J34: =ROUND(E34*I34,0) -> 0
A35: 6 | B35: Pump car Bơm bê tông | D35: m3 | E35: 146.37536 | I35: =+SUM(F35:H35) -> 0 | J35: =ROUND(E35*I35,0) -> 0 | K35: đã bao gồm
A36: 7 | B36: Polishing for bottom, cover slab Đánh bóng đáy bể, mặt bể | D36: m2 | E36: 770.24 | I36: =+SUM(F36:H36) -> 0 | J36: =ROUND(E36*I36,0) -> 0
A38: 4 | B38: FORM WORK / CÔNG TÁC VÁN KHUÔN | J38: =+SUM(J39:J42) -> 0
A39: 1 | B39: For lean concrete Ván khuôn bê tông lót | D39: m2 | E39: 3.339 | I39: =+SUM(F39:H39) -> 0 | J39: =ROUND(E39*I39,0) -> 0
A40: 2 | B40: Formwork for bottom Ván khuôn đáy bể | D40: m2 | E40: 23.079 | I40: =+SUM(F40:H40) -> 0 | J40: =ROUND(E40*I40,0) -> 0
A41: 3 | B41: Formwork for wall, colum Ván khuôn thành bể, cột | C41: (including scaffolding, bracing, supports, etc.) | D41: m2 | E41: 380.1 | I41: =+SUM(F41:H41) -> 0 | J41: =ROUND(E41*I41,0) -> 0
A42: 4 | B42: Formwork for cover slab Ván khuôn nắp bể | C42: (including scaffolding, bracing, supports, etc.) | D42: m2 | E42: 268.8 | I42: =+SUM(F42:H42) -> 0 | J42: =ROUND(E42*I42,0) -> 0
A44: 5 | B44: REINFORCEMENT WORK / CÔNG TÁC CỐT THÉP | J44: =+SUM(J45:J47) -> 0
A45: 1 | B45: Re-bar for bottom Cốt thép đáy bể | D45: ton | E45: 5.2934112 | I45: =+SUM(F45:H45) -> 0 | J45: =ROUND(E45*I45,0) -> 0 | K45: ='[79]14.Bể XLNT'!K43 -> Hoa Phat/ Equivalent
A46: 2 | B46: Re-bar for wall, colum Cốt thép thành bể, cột | D46: ton | E46: 4.61008 | I46: =+SUM(F46:H46) -> 0 | J46: =ROUND(E46*I46,0) -> 0 | K46: =K45 -> Hoa Phat/ Equivalent
A47: 3 | B47: Re-bar for cover slab Cốt thép thành nắp bể | D47: ton | E47: 2.772 | I47: =+SUM(F47:H47) -> 0 | J47: =ROUND(E47*I47,0) -> 0 | K47: =K46 -> Hoa Phat/ Equivalent
A49: B | B49: FINISING WORK / CÔNG TÁC HOÀN THIỆN | J49: =+J50+J55 -> 0
...

Sheet 12.Bể Nước Ngầm Xả Nguội
A1: BILL OF QUANTITIES
A2: ='C4.Hệ Thống Điện & Điện Nhẹ '!A2:K2 -> PROJECT NAME / TÊN DỰ ÁN :
A3: 12. COLD WATER TANK/ BỂ NƯỚC XẢ NGUỘI
A4: NO / STT | B4: WORK SCOPE / CÔNG VIỆC | C4: SPECIFICATION / ĐẶC ĐIỂM KỸ THUẬT | D4: UNIT/ ĐƠN VỊ | E4: QUANTITY / KHỐI LƯỢNG | F4: UNIT PRICE / ĐƠN GIÁ (VNĐ) | J4: AMOUNT / THÀNH TIỀN (VNĐ) | K4: REMARK / GHI CHÚ
F5: MATERIAL / VẬT LIỆU | G5: LABOUR / NHÂN CÔNG | H5: EQUIPMENT / THIẾT BỊ | I5: UNIT PRICE / TỔNG ĐƠN GIÁ
A6: 12 | B6: COLD WATER TANK/ BỂ NƯỚC XẢ NGUỘI | J6: =+J7+J13 -> 0
A7: A | B7: =$B$20 -> STRUCTURE WORK / CÔNG TÁC KẾT CẤU | J7: =+SUM(J8:J11) -> 0
A8: 1 | B8: =+B21 -> EARTH WORK / CÔNG TÁC ĐẤT | D8: lot | E8: 1 | J8: =+J21 -> 0
A9: =+A8+1 -> 2 | B9: =+B30 -> CONCRETE WORK / CÔNG TÁC BÊ TÔNG | D9: lot | E9: 1 | J9: =+J30 -> 0
A10: =+A9+1 -> 3 | B10: =+B38 -> FORM WORK / CÔNG TÁC VÁN KHUÔN | D10: lot | E10: 1 | J10: =+J38 -> 0
A11: =+A10+1 -> 4 | B11: =+B44 -> REINFORCEMENT WORK / CÔNG TÁC CỐT THÉP | D11: lot | E11: 1 | J11: =+J44 -> 0
A13: B | B13: =B49 -> FINISING WORK / CÔNG TÁC HOÀN THIỆN | J13: =+SUM(J14:J15) -> 0
A14: 1 | B14: WET FINISHING WORK | D14: lot | E14: 1 | J14: =+J50 -> 0
A15: 2 | B15: =$B$55 -> OTHERS WORK/ CÔNG VIỆC KHÁC | D15: lot | E15: 1 | J15: =+J55 -> 0
A20: A | B20: STRUCTURE WORK / CÔNG TÁC KẾT CẤU | J20: =+J21+J30+J38+J44 -> 0
A21: 1 | B21: EARTH WORK / CÔNG TÁC ĐẤT | J21: =+SUM(J22:J28) -> 0
A22: 1 | B22: Sheet pile cover for tank area Thi công cừ chắn cho khu vực bể | C22: Sheet pile 6m including transport & install | D22: lot | E22: 1 | I22: =+SUM(F22:H22) -> 0 | J22: =ROUND(E22*I22,0) -> 0
A23: 2 | B23: Excavation (by Equipment) Đào đất bằng máy | D23: m3 | E23: 617.5 | I23: =+SUM(F23:H23) -> 0 | J23: =ROUND(E23*I23,0) -> 0
A24: 3 | B24: Excavation (by worker) Đào đất thủ công | D24: m3 | E24: 92.625 | I24: =+SUM(F24:H24) -> 0 | J24: =ROUND(E24*I24,0) -> 0
A25: 4 | B25: Backfilling soil for foundation Đắp đất | D25: m3 | E25: 185.25 | I25: =+SUM(F25:H25) -> 0 | J25: =ROUND(E25*I25,0) -> 0
A26: 5 | B26: Remove surplus soil Vận chuyển đất đổ | C26: Distance D<=1Km Khoảng cách D<=1Km | D26: m3 | E26: 524.875 | I26: =+SUM(F26:H26) -> 0 | J26: =ROUND(E26*I26,0) -> 0
A27: =+A26+1 -> 6 | B27: Earth compaction, K=0.9 Đầm đất, K=0.9 | D27: m2 | E27: 190 | I27: =+SUM(F27:H27) -> 0 | J27: =ROUND(E27*I27,0) -> 0
A28: =+A27+1 -> 7 | B28: 1 layer nylon thk. 0.3mm 1 lớp nylon dày 0.3mm | D28: m2 | E28: 190 | I28: =+SUM(F28:H28) -> 0 | J28: =ROUND(E28*I28,0) -> 0
A30: 2 | B30: CONCRETE WORK / CÔNG TÁC BÊ TÔNG | J30: =+SUM(J31:J36) -> 0
A31: 1 | B31: Lean concrete for tank Bê tông lót | C31: Gr. 100 | D31: m3 | E31: 5.07584 | I31: =+SUM(F31:H31) -> 0 | J31: =ROUND(E31*I31,0) -> 0
A32: 2 | B32: Concrete for bottom Bê tông đáy bể | C32: Gr. 300 | D32: m3 | E32: 33.97352 | I32: =+SUM(F32:H32) -> 0 | J32: =ROUND(E32*I32,0) -> 0
A33: 3 | B33: Concrete for wall & column Bê tông thành bể và cột | C33: Gr. 300 | D33: m3 | E33: 34.32475 | I33: =+SUM(F33:H33) -> 0 | J33: =ROUND(E33*I33,0) -> 0
