Workbook
Name \0: #REF!
Name \d: #N/A
Name \z: #REF!
Name _: #N/A
Name _?: #REF!
Name _??: #N/A
Name _??????: #REF!
Name _??_1: NA()
Name _??_1_1: NA()
Name _??_1_2: NA()
Name _??_1_3: NA()
Name _??_1_4: NA()
Name _??_1_5: NA()
Name _??_6: NA()
Name _??_7: NA()
Name _??_9: NA()
Name _?1: #N/A
Name _?1_1: NA()
Name _?1_1_1: NA()
Name _?1_1_2: NA()
Name _?1_1_3: NA()
Name _?1_1_4: NA()
Name _?1_1_5: NA()
Name _?1_6: NA()
Name _?1_7: NA()
Name _?1_9: NA()
Name _?271: #N/A
Name _?271_1: NA()
Name _?271_1_1: NA()
Name _?271_1_2: NA()
Name _?271_1_3: NA()
Name _?271_1_4: NA()
Name _?271_1_5: NA()
Name _?271_6: NA()
Name _?271_7: NA()
Name _?271_9: NA()
Name __: #REF!
Name __??: #N/A
Name __?1: #N/A
Name __?271: #N/A
Name ___??: #N/A
Name ___?1: #N/A
Name ___?271: #N/A
Name ________________________kr2: [0]!__
Name ________________________kr2: [0]!__
Name ________________________kr2: [0]!__
Name ________________________kr2: [0]!__
Name ________________________kr2: [0]!__
Name ________________________kr2: [0]!__
Name ________________________kr2: [0]!__
Name ________________________kr2: [0]!__
Name ________________________kr2: [0]!__
Name ________________________kr2: [0]!__
Name ________________________kr2: [0]!__
Name ________________________kr2: [0]!__
Name ________________________kr2: [0]!__
Name _______________________kr2: [0]!__
Name _______________________kr2: [0]!__
Name _______________________kr2: [0]!__
Name _______________________kr2: [0]!__

Sheet Cover 
A11: THIẾT KẾ & XIN PHÉP XÂY DỰNG, TỔNG THẦU THI CÔNG DESIGN & CONSTRUCTION PERMIT APPLICATION, GENERAL CONTRACTOR FOR CONSTRUCTION
B16: Công trình : Project:
B17: Địa chỉ: Address: | D17: KCN HỰU THẠNH, XÃ HỰU THẠNH, HUYỆN ĐỨC HÒA, TỈNH LONG AN, VIỆT NAM HUU THANH INDUSTRIAL PARK, HUU THANH COMMUNE, DUC HOA DISTRICT, LONG AN PROVINCE, VIETNAM
B18: Gói thầu: Tender Package: | D18: THIẾT KẾ & XIN PHÉP XÂY DỰNG, TỔNG THẦU THI CÔNG DESIGN & CONSTRUCTION PERMIT APPLICATION, GENERAL CONTRACTOR FOR CONSTRUCTION
B19: Nhà Thầu Chính : Main Contractor: | D19: CÔNG TY CỔ PHẦN TƯ VÂN ĐẦU TƯ XÂY DỰNG MỚI (NICON) NEW INVESTMENT CONSTRUCTION CONSULTANT JOINT STOCK COMPANY
A28: 45839

Sheet Total 
A1: DỰ ÁN: NHÀ MÁY SẢN XUẤT BAO BÌ
A2: ĐỊA ĐIỂM: KCN HỰUTHẠNH , XÃ HỰU THẠNH, HUYỆN ĐỨC HÒA,TỈNH LONG AN
A3: CHỦ ĐẦU TƯ : CÔNG TY …
A4: TỔNG HỢP DỰ TOÁN/ BOQ SUMMARY
A6: MỤC ITEM | B6: MÔ TẢ DESCRIPTION | C6: THÀNH TIỀN TRƯỚC THUẾ AMOUNT BEFORE VAT (VND) | D6: NOTED/ GHI CHÚ
A8: 1 | B8: Tổng giá trị phần Thi công | C8: ='Summary '!C28 -> 0 | D8: Chi tiết trang sau
A9: 2 | B9: Tổng giá trị thiết kế và xin phép | C9: ='Design and permit'!H35 -> 0 | D9: Chi tiết trang sau
B12: TỔNG CỘNG ( Chưa bao gồm thuế VAT ) TOTAL (Excluding VAT) | C12: =SUM(C8:C11) -> 0
A13: CÔNG TY TNHH BẢO MINH ÂN VIỆT NAM | C13: CÔNG TY CỔ PHẦN TƯ VẤN ĐẦU TƯ XÂY DỰNG MỚI (NICON)
A14: General Director | C14: General Director

Sheet Summary 
A1: DỰ ÁN: NHÀ MÁY SẢN XUẤT BAO BÌ
A2: ĐỊA ĐIỂM: KCN HỰU THẠNH , XÃ HỰU THẠNH, HUYỆN ĐỨC HÒA,TỈNH LONG AN
A3: ='Total '!A3 -> CHỦ ĐẦU TƯ : CÔNG TY …
A4: TỔNG HỢP DỰ TOÁN THI CÔNG
A6: MỤC ITEM | B6: MÔ TẢ DESCRIPTION | C6: THÀNH TIỀN TRƯỚC THUẾ AMOUNT BEFORE VAT (VND) | E6: đợt trước | H6: NOTED/ GHI CHÚ
A7: A | B7: HẠNG MỤC THEO HÌNH THỨC KHỐI LƯỢNG THỰC TẾ | C7: =SUM(C8:C9) -> 0
A8: 1 | B8: ='1. San lấp'!B8 -> HẠNG MỤC SAN LẤP NÂNG NỀN | F8: =C8-E8 -> 0 | H8: Chi tiết trang sau
A9: 2 | B9: ='Cọc BTCT D300'!B8 -> CỌC BTCT DUL D300 | H9: =H8 -> Chi tiết trang sau
A10: B | B10: HẠNG MỤC THEO HÌNH THỨC TRỌN GÓI | C10: =C11+C22 -> 0
A11: I | B11: THI CÔNG XÂY DỰNG | C11: =SUBTOTAL(9,C12:C21) -> 0 | D11: =C11/14897 -> 0 | E11: =SUM(E12:E21) -> 6.8737491e+10
A12: 1 | B12: CÔNG TÁC TẠM PHỤC VỤ THI CÔNG | E12: 544065570 | F12: =C12-E12 -> -544065570 | H12: Chi tiết trang sau
A13: 2 | B13: ='01 Nhà Xưởng 01+02'!B8 -> HẠNG MỤC NHÀ XƯỞNG 1 & 2 | D13: 12363 | E13: 4.828291e+10 | F13: =C13-E13 -> -4.828291e+10 | G13: =C13/D13 -> 0 | H13: Chi tiết trang sau
A14: 3 | B14: =' 02 Văn Phòng 01+02'!B8 -> HẠNG MỤC NHÀ VĂN PHÒNG 1&2 | D14: =1196+400 -> 1596 | E14: 1.1395223e+10 | F14: =C14-E14 -> -1.1395223e+10 | G14: =C14/D14 -> 0 | H14: Chi tiết trang sau
A15: 4 | B15: ='03 NHÀ BẢO VỆ 01 &02'!B8 -> HẠNG MỤC NHÀ BẢO VỆ 01 &02 | E15: 198000000 | F15: =C15-E15 -> -198000000 | H15: Chi tiết trang sau
A16: 5 | B16: ='04 NHÀ XE'!B18 -> HẠNG MỤC NHÀ XE 1 TẦNG | E16: 9.1844245e+08 | F16: =C16-E16 -> -9.1844245e+08 | H16: Chi tiết trang sau
A17: 6 | B17: ='05 BỂ PCCC & NHÀ BƠM'!B8 -> HẠNG MỤC BỂ NƯỚC PCCC, NHÀ BƠM | D17: 560 | E17: 1.9764115e+09 | F17: =C17-E17 -> -1.9764115e+09 | G17: =C17/D17 -> 0 | H17: Chi tiết trang sau | J17: =J15-J16 -> 0
A18: 7 | B18: ='07 BẢNG HIỆU+ CỔNG '!B8 -> BẢNG HIỆU +CỔNG 1,2,3+ 2 NHÀ TRẠM ĐIỆN | E18: 6.9084354e+08 | F18: =C18-E18 -> -6.9084354e+08 | H18: Chi tiết trang sau
A19: 8 | B19: ='08 GIAOTHONG'!B12 -> HẠNG MỤC HẠ TẦNG GIAO THÔNG | E19: 2.6498115e+09 | F19: =C19-E19 -> -2.6498115e+09 | H19: Chi tiết trang sau
A20: 9 | B20: ='09 Hàng Rào '!B17 -> HẠNG MỤC HÀNG RÀO | D20: 482 | E20: 1.271855e+09 | F20: =C20-E20 -> -1.271855e+09 | G20: =C20/D20 -> 0 | H20: Chi tiết trang sau
A21: 10 | B21: ='10 THOÁT NƯỚC MƯA'!B13 -> HẠNG MỤC THOÁT NƯỚC MƯA TỔNG THỂ | E21: 8.0992848e+08 | F21: =C21-E21 -> -8.0992848e+08 | H21: Chi tiết trang sau
A22: B | B22: HỆ THỐNG MEP | C22: =SUBTOTAL(9,C23:C27) -> 0 | E22: =SUM(E23:E27) -> 1.9151634e+10
A23: 1 | B23: HẠNG MỤC ĐIỆN XƯỞNG 1 | E23: 4.4352577e+09 | F23: =C23-E23 -> -4.4352577e+09 | H23: =H21 -> Chi tiết trang sau
A24: 2 | B24: HẠNG MỤC ĐIỆN XƯỞNG 2 | E24: 3.382905e+09 | F24: =C24-E24 -> -3.382905e+09 | G24: =1630*1.7 -> 2771 | H24: =H23 -> Chi tiết trang sau
A25: 3 | B25: HẠNG MỤC CẤP THOÁT NƯỚC | E25: 1.7270742e+09 | F25: =C25-E25 -> -1.7270742e+09 | G25: =7818-3900 -> 3918 | H25: =H23 -> Chi tiết trang sau
A26: 4 | B26: HẠNG MỤC MÁY LẠNH | E26: 1337622144 | F26: =C26-E26 -> -1337622144 | G26: =G25/14052 -> 0.27882152 | H26: =H24 -> Chi tiết trang sau
A27: 5 | B27: HẠNG MỤC PCCC | E27: 8268774660 | F27: =C27-E27 -> -8268774660 | H27: =H25 -> Chi tiết trang sau
B28: TỔNG CỘNG ( Chưa bao gồm thuế VAT ) TOTAL (Excluding VAT) | C28: =C10+C7 -> 0 | E28: =E22+E11 -> 8.7889125e+10 | F28: =SUM(F13:F27) -> -8.7345059e+10
B30: Ghi chú:
B31: 1. Không bao gồm thang máy nâng hàng 5t
B32: 2. Không bao gồm Máy phát điện
B33: 3. Không bao gồm Hệ thống máy lạnh cho nhà văn phòng 2, thiết bị máy lạnh văn phòng 1
B34: 4. Không bao gồm Hệ thống điện nhẹ: camera, internet, điện thoại
B35: 5. Hạng mục nâng nền cát sẽ được tính theo khối lượng thực tế sau khi xác định chiều cao nâng nền
B36: 6. Hạng mục cọc sẽ tính theo khối lượng thực tế
B37: 7. Không bao gồm hạng mục nhôm kính, cửa cuốn, vách trần panel
B38: 8. Không bao gồm tủ MSB xưởng 2, cáp điện hạ thế, thang máng cáp xưởng 2
B39: 9. Tải trọng nền xưởng 2 là 1T/m2
A41: CÔNG TY TNHH BẢO MINH ÂN VIỆT NAM | C41: CÔNG TY CỔ PHẦN TƯ VẤN ĐẦU TƯ XÂY DỰNG MỚI (NICON)
A42: General Director | C42: General Director
J45: Vo Tri Nguyen

Sheet Design and permit
A1: Công trình : Project:
A2: Địa chỉ: Address: | B2: =[4]Cover!D17 -> KCN HỰU THẠNH, XÃ HỰU THẠNH, HUYỆN ĐỨC HÒA, TỈNH LONG AN, VIỆT NAM HUU THANH INDUSTRIAL PARK, HUU THANH COMMUNE, DUC HOA DISTRICT, LONG AN PROVINCE, VIETNAM
A3: Gói thầu: Tender Package: | B3: =[4]Cover!D18 -> THIẾT KẾ & XIN PHÉP XÂY DỰNG, TỔNG THẦU THI CÔNG DESIGN & CONSTRUCTION PERMIT APPLICATION, GENERAL CONTRACTOR FOR CONSTRUCTION
A4: Nhà thầu Chính: Main Contractor: | B4: =[5]Cover!D19 -> CÔNG TY CỔ PHẦN TƯ VÂN ĐẦU TƯ XÂY DỰNG MỚI (NICON) NEW INVESTMENT CONSTRUCTION CONSULTANT JOINT STOCK COMPANY
A6: BẢNG DỰ TOÁN CHI PHÍ COST ESTIMATE
A7: =+'[5]1. Summary'!A7:A8 -> STT No. | B7: =+'[5]1. Summary'!B7:B8 -> Diễn Giải Interpretation | C7: Scope | E7: =+'[5]1. Summary'!C7:C8 -> Đơn Vị Unit | F7: =+'[5]1. Summary'!D7:D8 -> Khối Lượng Quantity | G7: Đơn Giá Price (VND) | H7: =+'[5]1. Summary'!F7:F8 -> Thành tiền Total amount (VND) | I7: =+'[5]1. Summary'!G7:G8 -> Ghi chú Notes
C8: NICON | D8: BMA
A9: A. | B9: CÔNG TÁC DỮ LIỆU PHỤC VỤ THIẾT KẾ VÀ XIN PHÉP DESIGN DATA SERVER AND ASK FOR PERMISSION | H9: =SUBTOTAL(9,H10:H12) -> 0
A10: 1 | B10: Công tác khảo sát, đo cao độ hiện trạng Survey and measurement of current elevation
A11: =A10+1 -> 2 | B11: Công tác khảo sát địa chất Geological survey work | H11: =SUBTOTAL(9,H12:H12) -> 0 | I11: Xác định khả năng chịu tải của nền đất, tính toán móng công trình 6 – 8 hố khoan (mỗi hố 30m sâu)
A12: 2.1 | B12: Khoan, thí nghiệm, lập báo cáo Drilling, testing, report | C12: x | E12: Lot | F12: 1 | H12: =G12*F12 -> 0
A13: B. | B13: CÔNG TÁC THIẾT KẾ ( PHỤC VỤ XIN PHÉP XÂY DỰNG) DESIGN WORK (FOR CONSTRUCTION PERMIT APPLICATION | H13: =SUBTOTAL(9,H14:H23) -> 0
A14: 1 | B14: LẬP BẢN VẼ THIẾT KẾ DESIGN DRAWING | H14: =SUBTOTAL(9,H15:H20) -> 0
A15: =+A14+0.1 -> 1.1 | B15: Thiết Kế Kiến trúc ( Bản vẽ + thuyết minh) Architectural Design ( drawing + explanation document) | C15: x | E15: Lot | F15: 1 | H15: =G15*F15 -> 0
A16: =+A15+0.1 -> 1.2 | B16: Thiết kế Kết cấu ( Bản vẽ + thuyết minh) Structural Design ( drawing + explanation document) | C16: x
A17: =+A16+0.1 -> 1.3 | B17: Thiết kế Hạ tầng kỹ thuật Infrastructure Design ( drawing + explanation document) | C17: x
A18: =+A17+0.1 -> 1.4 | B18: Thiết kế MEP ( Bản vẽ + thuyết minh) MEP Design ( drawing + explanation document) | C18: x
A19: =+A18+0.1 -> 1.5 | B19: Thiết kế PCCC ( drawing + explanation document) Fire Protection Design ( drawing + explanation document) | C19: x
B20: Đơn vị thiết kế cung cấp hồ sơ năng lực: Design unit provides capacity profile:
A21: 1 | B21: Chứng chỉ năng lực hoạt động xây dựng cho chức năng thiết kế Certificate of construction operation capacity for design function | C21: x | E21: Lot | F21: 1 | H21: =G21*F21 -> 0 | I21: Free
A22: 2 | B22: Chính chỉ hành nghề cá nhân tham gia thiết kế kiến trúc, kết cấu, cấp thoát nước, cơ điện, hạ tầng kỹ thuật Personal practice certificate participating in architectural, structural, water supply and drainage, mechanical and electrical design, technical infrastructure | C22: x | E22: Lot | F22: 1 | H22: =G22*F22 -> 0 | I22: Free
A23: 3 | B23: Chứng chỉ năng lực có chức năng thiết kế PCCC Certificate of capacity with fire protection design function | C23: x | E23: Lot | F23: 1 | H23: =G23*F23 -> 0 | I23: Free
A24: C. | B24: CÔNG TÁC XIN PHÉP XÂY DỰNG CONSTRUCTION PERMIT WORK | H24: =SUBTOTAL(9,H25:H34) -> 0
A25: 1 | B25: Xin phép quy hoạch 1/500 (Quy hoạch chi tiết rút gọn) Request for planning permission 1/500 (Shorten detailed planning) | C25: x | E25: Lot | F25: 1 | H25: =F25*G25 -> 0
A26: 2 | B26: Xin phép thi công công tác tạm (khảo sát, ép cọc thử…) Apply permission for temporary construction work (survey, test pile driving...) | C26: x
A27: =+A26+1 -> 3 | B27: Thỏa thuận đấu nối hạ tầng Infrastructure connection agreement | C27: x
A28: =+A27+1 -> 4 | B28: Xin phép môi trường Apply for environmental permit | C28: x | E28: Lot | F28: 1 | H28: =F28*G28 -> 0 | I28: Xin phép ở xã Hựu Thạnh
A29: =+A28+1 -> 5 | B29: Xin Phép PCCC Apply for fire protection permit | C29: x | E29: Lot | F29: 1 | H29: =F29*G29 -> 0
A30: =+A29+1 -> 6 | B30: Lập báo cáo thẩm tra thiết kế (phục vụ xin phép xây dựng) Prepare design review report (for construction permit application) | C30: x | E30: Lot | F30: 1 | H30: =F30*G30 -> 0
A31: =+A30+1 -> 7 | B31: Thẩm định báo cáo nghiên cứu khả thi đầu tư xây dựng Appraise investment feasibility study report | C31: x | E31: Lot
A32: =+A31+1 -> 8 | B32: Lập hồ sơ thẩm định thiết kế xây dựng triển khai sau thiết kế cơ sở ( Thiết kế kỹ thuật) Prepare construction design review file to be implemented after basic design ( technical design) | C32: x | E32: Lot
A33: =+A32+1 -> 9 | B33: Xin phép xây dựng Apply for construction permit | C33: x | E33: Lot
A34: =+A33+1 -> 10 | B34: Chi phí in hồ sơ và Scan tài liệu Cost of printing file and scanning documents | C34: x | E34: Lot | F34: 1 | G34: free | H34: 0
B35: TỔNG CỘNG GIÁ TRỊ : TOTAL VALUE: | H35: =SUBTOTAL(9,H9:H34) -> 0

Sheet Prelim
A1: Dự án / Project : Nhà máy BMA
A2: Hạng mục / Item : Common temporary works/Công tác chung, tạm thời
A5: STT/ No | B5: Diễn Giải / Description | E5: Đơn vị/ Unit | F5: Khối lượng/ Qty | G5: Đơn Giá / Unit Price (VND) | H5: Thành Tiền / Amount (VND)
A6: A | B6: Common temporary works/Công tác chung, tạm thời
A7: 1 | B7: Preparation work for working area, road/Công tác chuẩn bị đường tạm | E7: L/s | F7: 1 | H7: =G7*F7 -> 0
A8: 2 | B8: Temporary fence, gate door & sign for project/Hàng rào, cổng, bảng hiệu tạm | E8: L/s | F8: 1 | H8: =G8*F8 -> 0
A9: 3 | B9: Temporary site office/Văn phòng tạm | E9: L/s | F9: 1 | H9: =G9*F9 -> 0
A10: 5 | B10: Toilet for worker/Toilet tạm | E10: L/s | F10: 1 | H10: =G10*F10 -> 0
A11: 6 | B11: Security/An ninh | E11: L/s | F11: 1 | H11: =G11*F11 -> 0
A12: 7 | B12: Arranging & Cleaning/Vệ sinh | E12: L/s | F12: 1 | H12: =G12*F12 -> 0
A13: 8 | B13: Site records/ Camera công trình | E13: L/s | F13: 1 | H13: =G13*F13 -> 0
A14: 10 | B14: Transportation for common temporary work/Vận chuyển công tác tạm | E14: L/s | F14: 1 | H14: =G14*F14 -> 0
A15: 12 | B15: Insurances/Bảo hiểm | E15: L/s | F15: 1 | H15: =G15*F15 -> 0
A16: 13 | B16: Safety and environmental protection works/ Công tác an toàn và bảo vệ môi trường | E16: L/s | F16: 1 | H16: =G16*F16 -> 0
A17: 15 | B17: Fee of test Lab marterial, equipment/ Phí thí nghiệm vật liệu, thiết bị | E17: L/s | F17: 1 | H17: =G17*F17 -> 0
A18: 16 | B18: Fee shopdrawing, as built drawing/ Phí shopdrawing và bản vẽ hoàn công | E18: L/s | F18: 1 | H18: =G18*F18 -> 0
B19: Tổng cộng/ Total (I) | H19: =SUM(H7:H18) -> 0
A23: B | B23: Giai đoạn 2/ Stage 2
A24: III | B24: Phần xây dựng/ Construction
A25: 1 | B25: Nhà xưởng/ Factory | E25: set | F25: 1 | G25: =#REF! -> #REF! | H25: =G25*F25 -> #REF!
A26: 2 | B26: Giao thông/ Road | E26: L/s | F26: 1 | G26: =#REF! -> #REF! | H26: =G26*F26 -> #REF!
A27: 3 | B27: Hệ thống thoát nước mưa và bể tự hoại/ Storm drainage system and septic tank | E27: L/s | F27: 1 | G27: =#REF! -> #REF! | H27: =G27*F27 -> #REF!
B28: Tổng cộng/ Total (III) | H28: =SUM(H25:H27) -> #REF!
A29: IV | B29: Phần MEP
A30: 1 | B30: =#REF! -> #REF! | E30: =E26 -> L/s | F30: 1 | G30: =#REF! -> #REF! | H30: =_11B_19 -> #REF!
A31: =A30+1 -> 2 | B31: =#REF! -> #REF! | E31: =E27 -> L/s | F31: 1 | G31: =#REF! -> #REF! | H31: =_11B_19 -> #REF!
A32: =A31+1 -> 3 | B32: =#REF! -> #REF! | E32: =E31 -> L/s | F32: 1 | G32: =#REF! -> #REF! | H32: =_11B_19 -> #REF!
A33: =A32+1 -> 4 | B33: Hệ thống PCCC/ Fire fighting system | E33: L/s | F33: 1 | G33: =#REF! -> #REF! | H33: =_11B_19 -> #REF!
A34: =A33+1 -> 5 | B34: Hệ thống báo cháy/ Alarm fire fighting system | E34: L/s | F34: 1 | G34: =#REF! -> #REF! | H34: =_11B_19 -> #REF!
A35: =A34+1 -> 6 | B35: Hệ thống ĐHKK/ AC System | E35: =E32 -> L/s | F35: 1 | G35: =#REF! -> #REF! | H35: =_11B_19 -> #REF!
B36: Tổng cộng/ Total (IV) | H36: =SUM(H30:H35) -> #REF!
B37: Tổng cộng giai đoạn 2/ Total stage 2 (III)+(IV) | H37: =H28+H36 -> #REF!
C38: Total before VAT | H38: =#REF!+H37 -> #REF!
C39: VAT (10%) | H39: =H38*0.1 -> #REF!
C40: Total after VAT | H40: =SUM(H38:H39) -> #REF!

Sheet 1. San lấp
A1: BẢNG DỰ TOÁN BÁO GIÁ CÔNG TRÌNH / ESTIMATE TABLE
A3: ="HẠNG MỤC / ITEM : "&B8 -> HẠNG MỤC / ITEM : HẠNG MỤC SAN LẤP NÂNG NỀN
A6: STT NO. | B6: TÊN CÔNG VIỆC VÀ DIỄN GIẢI DESCRIPTION | C6: ĐẶC TÍNH KỸ THUẬT STANDARD | D6: NHÃN HIỆU & XUẤT XỨ BRAND NAME & ORIGIN | E6: Đvt Unit | F6: KL TỔNG Q'TY | G6: ĐƠN GIÁ / RATE | J6: TỔNG CỘNG (VNĐ) TOTAL COST(VND) | L6: REMARK GHI CHÚ
G7: VẬT TƯ RATE MATERIALS | H7: NHÂN CÔNG RATE LABOUR | I7: MMTB RATE EQUIPMENT | J7: ĐƠN GIÁ TỔNG TOTAL PRICE | K7: THÀNH TIỀN AMOUNT TOTAL
B8: HẠNG MỤC SAN LẤP NÂNG NỀN | K8: =K9 -> 0
A9: 1 | B9: Nâng nền toàn bộ bằng cát lấp lên cao 400mm, ban ủi nền cát, khối lượng sẽ tính thực tế hiện trường, đơn giá đã bao gồm hệ số đầm nén nền cát | C9: Cát Campuchia | E9: m3 | J9: =H9+G9 -> 0 | K9: =J9*F9 -> 0
A17: =IF(ISBLANK(E17),"",COUNTA($E$17:E17)) | G17: 0 | H17: 0 | J17: =+G17+H17 -> 0 | K17: =J17*$F17 -> 0
A18: =IF(ISBLANK(E18),"",COUNTA($E$17:E18)) | G18: 0 | H18: 0 | J18: =+G18+H18 -> 0 | K18: =J18*$F18 -> 0

Sheet Cọc BTCT D300
A1: BẢNG DỰ TOÁN BÁO GIÁ CÔNG TRÌNH / ESTIMATE TABLE
A6: STT NO. | B6: TÊN CÔNG VIỆC VÀ DIỄN GIẢI DESCRIPTION | C6: ĐẶC TÍNH KỸ THUẬT STANDARD | D6: NHÃN HIỆU & XUẤT XỨ BRAND NAME & ORIGIN | E6: Đvt Unit | F6: SL | G6: DÀI | H6: RỘNG | I6: CAO | J6: KL | K6: KL TỔNG Q'TY | L6: ĐƠN GIÁ / RATE | O6: TỔNG CỘNG (VNĐ) TOTAL COST(VND) | Q6: REMARK GHI CHÚ
L7: VẬT TƯ RATE MATERIALS | M7: NHÂN CÔNG RATE LABOUR | N7: MMTB RATE EQUIPMENT | O7: ĐƠN GIÁ TỔNG TOTAL PRICE | P7: THÀNH TIỀN AMOUNT TOTAL | R7: VẬT TƯ RATE MATERIALS | S7: NHÂN CÔNG RATE LABOUR
B8: CỌC BTCT DUL D300 | P8: =SUBTOTAL(9,P9:P14) -> 0 | Q8: Quyết toán theo khối lượng thực tế
A9: 1 | B9: NHÀ XƯỞNG 1 & NHÀ XƯỞNG 2 | P9: =P15 -> 0
A10: 2 | B10: NHÀ VĂN PHÒNG 1 & 2 | P10: =P33 -> 0
A11: 3 | B11: =B39 -> NHÀ XE 1 TẦNG | P11: =P39 -> 0
A12: 4 | B12: =B45 -> HẠNG MỤC BỂ NƯỚC PCCC, NHÀ BƠM | P12: =P45 -> 0
A13: 5 | B13: HÀNG RÀO | P13: =P51 -> 0
P14: =P148 -> 0
B15: =B9 -> NHÀ XƯỞNG 1 & NHÀ XƯỞNG 2 | P15: =SUM(P16:P32) -> 0
A16: 1 | B16: Cung cấp và thi công, kiểm tra cọc thử, PHC-A D300 Supply and construction of test piles, PHC-A D300 | C16: Cọc PHC A , D300, L=33m, Pmax =120 tấn PHC A pile, D300, L=33m, Pmax =120 tons | D16: Kiến Hoa, Phan Vũ, BT Thủ Đức, Việt Thái An Kien Hoa, Phan Vu, BT Thu Duc, VTA | E16: tim | K16: =SUM(J17:J20) -> 132 | O16: =+L16+M16+N16 -> 0 | P16: =O16*$K16 -> 0
B17: Nhà xưởng 01 | F17: 2 | G17: 33 | J17: =F17*G17 -> 66 | O17: =+L17+M17+N17 -> 0 | P17: =O17*$K17 -> 0
B20: Nhà xưởng 2 | F20: 2 | G20: 33 | J20: =F20*G20 -> 66 | O20: =+L20+M20+N20 -> 0 | P20: =O20*$K20 -> 0
A21: 3 | B21: Tập kết giàn ép tới công trình | E21: lot | K21: 2 | O21: =+L21+M21+N21 -> 0 | P21: =O21*$K21 -> 0
A22: 4 | B22: Cung cấp và thi công cọc đại trà, PHC-A D300 Supply and construction of mass piles, PHC-A D300 | C22: Cọc PHC A , D300, Pmax =120 tấn PHC A pile, D300, Pmax =120 tons | D22: Kiến Hoa, Phan Vũ, BT Thủ Đức, Việt Thái An Kien Hoa, Phan Vu, BT Thu Duc, VTA | E22: md | K22: =SUM(J23:J28) -> 18595 | O22: =+L22+M22+N22 -> 0 | P22: =O22*$K22 -> 0 | Q22: Cọc móng chính dự kiến ép 30md, cọc cho nền dự kiến ép 25md
B23: Nhà xưởng 02 | F23: 309 | J23: =F23*G23 -> 0 | O23: =+L23+M23+N23 -> 0 | P23: =O23*$K23 -> 0
B24: Cọc chính móng | F24: 106 | G24: 30 | J24: =PRODUCT(F24:H24) -> 3180
B25: Cọc nền | F25: =F23-F24 -> 203 | G25: 25 | J25: =PRODUCT(F25:H25) -> 5075
B26: Nhà xưởng 01 | F26: 396 | O26: =+L26+M26+N26 -> 0 | P26: =O26*$K26 -> 0
B27: Cọc chính móng | F27: 88 | G27: 30 | J27: =PRODUCT(F27:H27) -> 2640
B28: Cọc nền | F28: =F26-F27 -> 308 | G28: 25 | J28: =PRODUCT(F28:H28) -> 7700
A29: 6 | B29: Trắc đạt định vị cọc | E29: lot | J29: 1 | K29: 1 | O29: =+L29+M29+N29 -> 0 | P29: =O29*$K29 -> 0
A30: 7 | B30: Test cọc D300, thử tĩnh tải | E30: tim | J30: 4 | K30: 4 | O30: =+L30+M30+N30 -> 0 | P30: =O30*$K30 -> 0
A31: 8 | B31: Máy phát điện thi công cọc Pile construction generator | E31: md | J31: =K22 -> 18595 | K31: =J31 -> 18595 | O31: =+L31+M31+N31 -> 0 | P31: =O31*$K31 -> 0
A32: 9 | B32: Cắt đầu cọc Cutting pile heads | E32: cái | J32: =F23+F26 -> 705 | K32: =J32 -> 705 | O32: =+L32+M32+N32 -> 0 | P32: =O32*$K32 -> 0
B33: =B10 -> NHÀ VĂN PHÒNG 1 & 2 | P33: =SUM(P34:P38) -> 0
A34: 1 | B34: Cung cấp và thi công cọc đại trà, PHC-A D300 Supply and construction of mass piles, PHC-A D300 | C34: Cọc PHC A , D300, Pmax =120 tấn PHC A pile, D300, Pmax =120 tons | D34: Kiến Hoa, Phan Vũ, BT Thủ Đức, Việt Thái An Kien Hoa, Phan Vu, BT Thu Duc, VTA | E34: md | K34: =J35+J36 -> 2695 | O34: =+L34+M34+N34 -> 0 | P34: =O34*$K34 -> 0 | Q34: Dự kiến Cọc Vp1 dài 28m, cọc vp2 dài 25
B35: Nhà Văn Phòng 01 | F35: 65 | G35: 28 | J35: =F35*G35 -> 1820
B36: Nhà Văn Phòng 02 | F36: 35 | G36: 25 | J36: =F36*G36 -> 875
A37: 2 | B37: Máy phát điện thi công cọc Pile construction generator | E37: md | J37: =J35+J36 -> 2695 | K37: =J37 -> 2695 | O37: =+L37+M37+N37 -> 0 | P37: =O37*$K37 -> 0
A38: 3 | B38: Cắt đầu cọc Cutting pile heads | E38: cái | J38: =F35+F36 -> 100 | K38: =J38 -> 100 | O38: =+L38+M38+N38 -> 0 | P38: =O38*$K38 -> 0
B39: NHÀ XE 1 TẦNG | P39: =SUM(P40:P43) -> 0
A40: 1 | B40: Cung cấp và thi công cọc đại trà, PHC-A D300 Supply and construction of mass piles, PHC-A D300 | C40: Cọc PHC A , D300, L=27m, Pmax =120 tấn PHC A pile, D300, L=27m, Pmax =120 tons | D40: Kiến Hoa, Phan Vũ, BT Thủ Đức, Việt Thái An Kien Hoa, Phan Vu, BT Thu Duc, VTA | E40: md | K40: =J41 -> 351 | O40: =+L40+M40+N40 -> 0 | P40: =O40*$K40 -> 0 | Q40: Dự kiến ép cọc 27md
B41: Nhà xe | F41: 13 | G41: 27 | J41: =F41*G41 -> 351
A42: 2 | B42: Máy phát điện thi công cọc Pile construction generator | E42: md | J42: =J41 -> 351 | K42: =J42 -> 351 | O42: =+L42+M42+N42 -> 0 | P42: =O42*$K42 -> 0
A43: 3 | B43: Cắt đầu cọc Cutting pile heads | E43: cái | J43: =14 -> 14 | K43: =J43 -> 14 | O43: =+L43+M43+N43 -> 0 | P43: =O43*$K43 -> 0
O44: =+L44+M44+N44 -> 0 | P44: =O44*$K44 -> 0
B45: ='Summary '!B17 -> HẠNG MỤC BỂ NƯỚC PCCC, NHÀ BƠM | O45: =+L45+M45+N45 -> 0 | P45: =SUM(P47:P50) -> 0
O46: =+L46+M46+N46 -> 0 | P46: =O46*$K46 -> 0
...

Sheet 01 Nhà Xưởng 01+02
A1: BẢNG DỰ TOÁN BÁO GIÁ CÔNG TRÌNH / ESTIMATE TABLE
A3: ="HẠNG MỤC / ITEM : "&B8 -> HẠNG MỤC / ITEM : HẠNG MỤC NHÀ XƯỞNG 1 & 2
A6: STT NO. | B6: TÊN CÔNG VIỆC VÀ DIỄN GIẢI DESCRIPTION | C6: ĐẶC TÍNH KỸ THUẬT STANDARD | D6: NHÃN HIỆU & XUẤT XỨ BRAND NAME & ORIGIN | E6: Đvt Unit | F6: SL | G6: DÀI | H6: RỘNG | I6: CAO | J6: KL | K6: KL TỔNG Q'TY | L6: ĐƠN GIÁ / RATE | O6: TỔNG CỘNG (VNĐ) TOTAL COST(VND) | Q6: REMARK GHI CHÚ
L7: VẬT TƯ RATE MATERIALS | M7: NHÂN CÔNG RATE LABOUR | N7: MMTB RATE EQUIPMENT | O7: ĐƠN GIÁ TỔNG TOTAL PRICE | P7: THÀNH TIỀN AMOUNT TOTAL
B8: HẠNG MỤC NHÀ XƯỞNG 1 & 2 | K8: =SUM(K9:K22) -> 4.7237774e+10 | L8: =P8-K8 -> -4.7237774e+10 | P8: =SUBTOTAL(9,P9:P21) -> 0
A9: 1 | B9: =B23 -> CÔNG TÁC XỬ LÝ ĐẦU CỌC PILING WORKS | K9: 8.6873522e+09 | P9: =P23 -> 0
A10: 2 | B10: =B45 -> CÔNG TÁC ĐẤT EARTHWORKS | K10: 3.8678304e+08 | P10: =P45 -> 0
A11: 3 | B11: =B77 -> CÔNG TÁC BÊ TÔNG CONCRETE WORKS | K11: 5.4866826e+09 | P11: =P77 -> 0
A12: 4 | B12: =B126 -> CÔNG TÁC VÁN KHUÔN FORMWORK WORKS | K12: 675827296 | P12: =P126 -> 0
A13: 5 | B13: =B173 -> CÔNG TÁC CỐT THÉP REINFORCEMENT WORKS | K13: 3.2147143e+09 | P13: =P173 -> 0
A14: 6 | B14: =B182 -> CÔNG TÁC XÂY BRICK WALL | K14: 1.5126728e+09 | P14: =P182 -> 0 | R14: =2.5+3.2+1.7+0.8+1.7+0.8 -> 10.7
A15: 7 | B15: =B207 -> CÔNG TÁC TÔ TRÁT PLASTERING WORKS | K15: 670270440 | P15: =P207 -> 0
A16: 8 | B16: =B219 -> CÔNG TÁC SƠN PAINTING WORK | K16: 5.0721212e+08 | P16: =P219 -> 0
A17: 9 | B17: =B223 -> CÔNG TÁC HOÀN THIỆN NỀN SÀN FLOOR FINISHING WORK | K17: 992452188 | P17: =P223 -> 0
A18: 10 | B18: =B230 -> CÔNG TÁC TRẦN VÁCH CEILING & PARTITION WORKS | K18: 3253569200 | P18: =P230 -> 0
A19: 11 | B19: =B233 -> CÔNG TÁC CỬA DOOR WORKS | K19: 1.0316923e+09 | P19: =P233 -> 0
A20: 13 | B20: =B242 -> CÔNG TÁC KẾT CẤU THÉP VÀ MÁI STEEL STRUCTURE AND ROOF WORK | K20: 2.0653497e+10 | P20: =P242 -> 0
A21: 14 | B21: =B323 -> CÔNG TÁC HOÀN THIỆN KHÁC OTHER WORKS | K21: 165047700 | P21: =P323 -> 0
A23: 1 | B23: CÔNG TÁC XỬ LÝ ĐẦU CỌC PILING WORKS | P23: =SUBTOTAL(9,P24:P43) -> 0
A24: 1 | B24: Cung cấp và thi công, kiểm tra cọc thử, PHC-A D300 Supply and construction of test piles, PHC-A D300 | C24: Cọc PHC A , D300, L=33m, Pmax =120 tấn PHC A pile, D300, L=33m, Pmax =120 tons | D24: Kiến Hoa, Phan Vũ, BT Thủ Đức, Việt Thái An Kien Hoa, Phan Vu, BT Thu Duc, VTA | E24: tim | K24: =SUM(J25:J28) -> 132 | O24: =+L24+M24+N24 -> 0 | P24: =O24*$K24 -> 0
B25: Nhà xưởng 01 | F25: 2 | G25: 33 | J25: =F25*G25 -> 66 | O25: =+L25+M25+N25 -> 0 | P25: =O25*$K25 -> 0
B28: Nhà xưởng 2 | F28: 2 | G28: 33 | J28: =F28*G28 -> 66 | O28: =+L28+M28+N28 -> 0 | P28: =O28*$K28 -> 0
A29: 3 | B29: Tập kết giàn ép tới công trình | E29: lot | K29: 2 | O29: =+L29+M29+N29 -> 0 | P29: =O29*$K29 -> 0
A30: 4 | B30: Cung cấp và thi công cọc đại trà, PHC-A D300 Supply and construction of mass piles, PHC-A D300 | C30: Cọc PHC A , D300, Pmax =120 tấn PHC A pile, D300, Pmax =120 tons | D30: Kiến Hoa, Phan Vũ, BT Thủ Đức, Việt Thái An Kien Hoa, Phan Vu, BT Thu Duc, VTA | E30: md | K30: =SUM(J31:J36) -> 18595 | O30: =+L30+M30+N30 -> 0 | P30: =O30*$K30 -> 0
B31: Nhà xưởng 02 | F31: 309 | J31: =F31*G31 -> 0 | O31: =+L31+M31+N31 -> 0 | P31: =O31*$K31 -> 0
B32: Cọc chính móng | F32: 106 | G32: 30 | J32: =PRODUCT(F32:H32) -> 3180
B33: Cọc nền | F33: =F31-F32 -> 203 | G33: 25 | J33: =PRODUCT(F33:H33) -> 5075
B34: Nhà xưởng 01 | F34: 396 | O34: =+L34+M34+N34 -> 0 | P34: =O34*$K34 -> 0
B35: Cọc chính móng | F35: 88 | G35: 30 | J35: =PRODUCT(F35:H35) -> 2640
B36: Cọc nền | F36: =F34-F35 -> 308 | G36: 25 | J36: =PRODUCT(F36:H36) -> 7700
A37: 6 | B37: Trắc đạt định vị cọc | E37: lot | J37: 1 | K37: 1 | O37: =+L37+M37+N37 -> 0 | P37: =O37*$K37 -> 0
A38: 7 | B38: Test cọc D300, thử tĩnh tải | E38: tim | J38: 4 | K38: 4 | O38: =+L38+M38+N38 -> 0 | P38: =O38*$K38 -> 0
A39: 8 | B39: Máy phát điện thi công cọc Pile construction generator | E39: md | J39: =K30 -> 18595 | K39: =J39 -> 18595 | O39: =+L39+M39+N39 -> 0 | P39: =O39*$K39 -> 0
A40: 9 | B40: Cắt đầu cọc Cutting pile heads | E40: cái | J40: =F31+F34 -> 705 | K40: =J40 -> 705 | O40: =+L40+M40+N40 -> 0 | P40: =O40*$K40 -> 0
A41: 10 | B41: SXLD bản mã đầu cọc Anchor plate for pile heads | C41: Tấm dày 5mm, thép SS400 5mm thick plate, SS400 steel | D41: SS400 | E41: Kg | J41: =0.25*0.25*0.002*7850*739 -> 725.14375 | K41: =J41 -> 725.14375 | O41: =+L41+M41+N41 -> 0 | P41: =O41*$K41 -> 0
A42: 11 | B42: Cốt thép đầu cọc Anchor steel for pile heads | C42: 6D14, L=1500mm; D6a150 6D14, L=1500mm; D6a150 | E42: Kg | J42: =J40*11 -> 7755 | K42: =J42 -> 7755 | O42: =+L42+M42+N42 -> 0 | P42: =O42*$K42 -> 0
A43: 12 | B43: Bê tông đầu cọc Pile head concrete | C43: Độ sụt 10±2cm, Mác M300 Slump 10±2cm, Grade M300 | E43: m3 | J43: =0.2*0.2*1*739 -> 29.56 | K43: =J43 -> 29.56 | O43: =+L43+M43+N43 -> 0 | P43: =O43*$K43 -> 0
A45: 2 | B45: CÔNG TÁC ĐẤT EARTHWORKS | P45: =SUBTOTAL(9,P46:P76) -> 0
A46: =IF(ISBLANK(E46),"",COUNTA($E$22:E46)) -> 11 | B46: Đào đất móng, đà kiềng Excavation of foundation, tie beam | E46: m3 | K46: =SUM(J47:J53) -> 1152.104 | O46: =+L46+M46+N46 -> 0 | P46: =O46*$K46 -> 0
B47: Nhà xưởng 02
...

Sheet  02 Văn Phòng 01+02
A1: BẢNG DỰ TOÁN BÁO GIÁ CÔNG TRÌNH / ESTIMATE TABLE
A3: ="HẠNG MỤC / ITEM : "&B8 -> HẠNG MỤC / ITEM : HẠNG MỤC NHÀ VĂN PHÒNG 1&2
A6: STT NO. | B6: TÊN CÔNG VIỆC VÀ DIỄN GIẢI DESCRIPTION | C6: ĐẶC TÍNH KỸ THUẬT STANDARD | D6: NHÃN HIỆU & XUẤT XỨ BRAND NAME & ORIGIN | E6: Đvt Unit | F6: SL | G6: DÀI | H6: RỘNG | I6: CAO | J6: KL | K6: KL TỔNG Q'TY | L6: ĐƠN GIÁ / RATE | O6: TỔNG CỘNG (VNĐ) TOTAL COST(VND) | Q6: REMARK GHI CHÚ
L7: VẬT TƯ RATE MATERIALS | M7: NHÂN CÔNG RATE LABOUR | N7: MMTB RATE EQUIPMENT | O7: ĐƠN GIÁ TỔNG TOTAL PRICE | P7: THÀNH TIỀN AMOUNT TOTAL
B8: HẠNG MỤC NHÀ VĂN PHÒNG 1&2 | K8: 1.1475749e+10 | P8: =SUBTOTAL(9,P9:P22) -> 0 | Q8: =P8/1596 -> 0
A9: A | B9: =B24 -> CÔNG TÁC XỬ LÝ ĐẦU CỌC PILING WORKS | K9: 1.2778588e+09 | P9: =P24 -> 0
A10: =A38 -> B | B10: =B38 -> CÔNG TÁC ĐẤT EARTHWORKS | K10: 32116252 | P10: =P38 -> 0
A11: =A83 -> C | B11: =B83 -> CÔNG TÁC BÊ TÔNG CONCRETE WORKS | K11: 1.1469311e+09 | P11: =P83 -> 0
A12: D | B12: =B200 -> CÔNG TÁC VÁN KHUÔN FORMWORK WORKS | K12: 9.5994736e+08 | P12: =P200 -> 0
A13: =A315 -> E | B13: =B315 -> CÔNG TÁC CỐT THÉP REINFORCEMENT WORKS | K13: 1.8461051e+09 | P13: =P315 -> 0
A14: =A323 -> F | B14: =B323 -> CÔNG TÁC XÂY BRICK WALL | K14: 1.1897028e+09 | P14: =P323 -> 0
A15: =A347 -> G | B15: =B347 -> CÔNG TÁC TÔ TRÁT PLASTERING WORKS | K15: 5.2699803e+08 | P15: =P347 -> 0
A16: =A373 -> H | B16: =B373 -> CÔNG TÁC SƠN PAINTING WORK | K16: 5.6652711e+08 | P16: =P373 -> 0
A17: =A378 -> I | B17: =B378 -> CÔNG TÁC CHỐNG THẤM WATERPROFING WORKS | K17: 1.9793814e+08 | P17: =P378 -> 0
A18: =A394 -> K | B18: =B394 -> CÔNG TÁC ỐP LÁT TILING WORK | K18: 1.3485196e+09 | P18: =P394 -> 0
A19: =A411 -> L | B19: =B411 -> CÔNG TÁC TRẦN VÁCH CEILING & PARTITION WORKS | K19: 486901085 | P19: =P411 -> 0
A20: =A428 -> M | B20: =B428 -> CÔNG TÁC CỬA DOOR WORKS | K20: 1868143276 | P20: =P428 -> 0
A21: =A440 -> P | B21: =B440 -> CÔNG TÁC HOÀN THIỆN KHÁC OTHER WORKS | K21: 28060000 | P21: =P440 -> 0
A24: A | B24: CÔNG TÁC XỬ LÝ ĐẦU CỌC PILING WORKS | P24: =SUBTOTAL(9,P25:P37) -> 0
A25: 1 | B25: Cung cấp và thi công cọc thử, PHC-A D300 Supply and construction of test piles, PHC-A D300
B26: Nhà Văn Phòng 01
B27: Nhà Văn Phòng 02
A28: 3 | B28: Thí nghiệm Cọc thử Test Pile Experiment
A29: 4 | B29: Cung cấp và thi công cọc đại trà, PHC-A D300 Supply and construction of mass piles, PHC-A D300 | C29: Cọc PHC A , D300, Pmax =120 tấn PHC A pile, D300, Pmax =120 tons | D29: Kiến Hoa, Phan Vũ, BT Thủ Đức, Việt Thái An Kien Hoa, Phan Vu, BT Thu Duc, VTA | E29: md | K29: =J30+J31 -> 2695 | O29: =+L29+M29+N29 -> 0 | P29: =O29*$K29 -> 0
B30: Nhà Văn Phòng 01 | F30: 65 | G30: 28 | J30: =F30*G30 -> 1820
B31: Nhà Văn Phòng 02 | F31: 35 | G31: 25 | J31: =F31*G31 -> 875
A32: 8 | B32: Máy phát điện thi công cọc Pile construction generator | E32: md | J32: =J30+J31 -> 2695 | K32: =J32 -> 2695 | O32: =+L32+M32+N32 -> 0 | P32: =O32*$K32 -> 0
A33: 9 | B33: Cắt đầu cọc Cutting pile heads | E33: cái | J33: =F30+F31 -> 100 | K33: =J33 -> 100 | O33: =+L33+M33+N33 -> 0 | P33: =O33*$K33 -> 0
A34: 10 | B34: SXLD bản mã đầu cọc Anchor plate for pile heads | D34: SS400 | E34: Kg | J34: =0.3*0.3*0.005*7850*108 -> 381.51 | K34: =J34 -> 381.51 | O34: =+L34+M34+N34 -> 0 | P34: =O34*$K34 -> 0
A35: 11 | B35: Cốt thép đầu cọc Anchor steel for pile heads | C35: 6D14, L=1500mm; D6a150 6D14, L=1500mm; D6a150 | E35: Kg | J35: =F35*(G35+0.6)*(H35+0.6)*I35 -> 0 | K35: =K33*11 -> 1100 | O35: =+L35+M35+N35 -> 0 | P35: =O35*$K35 -> 0
A36: 12 | B36: Bê tông đầu cọc Pile head concrete | C36: Độ sụt 10±2cm, Mác M300 Slump 10±2cm, Grade M300 | E36: m3 | J36: =F36*(G36+0.6)*(H36+0.6)*I36 -> 0 | K36: =0.2*0.2*1*108 -> 4.32 | O36: =+L36+M36+N36 -> 0 | P36: =O36*$K36 -> 0
A38: B | B38: CÔNG TÁC ĐẤT EARTHWORKS | P38: =SUBTOTAL(9,P39:P82) -> 0
A39: =IF(ISBLANK(E39),"",COUNTA($E$23:E39)) -> 7 | B39: Đào đất móng, đà kiềng Excavation of foundation, tie beam | E39: m3 | K39: =SUM(J40:J49) -> 178.465 | O39: =+L39+M39+N39 -> 0 | P39: =O39*$K39 -> 0
B40: Nhà Văn Phòng 01
B41: Mv1 | F41: 3 | G41: 1.7 | H41: 0.8 | I41: 1 | J41: =F41*(G41+0.6)*(H41+0.6)*I41 -> 9.66
B42: Mv2 | F42: 14 | G42: 1.7 | H42: 0.8 | I42: 1 | J42: =F42*(G42+0.6)*(H42+0.6)*I42 -> 45.08
B43: Mv3 | F43: 5 | G43: 1.7 | H43: 1.6 | I43: 1 | J43: =F43*(G43+0.6)*(H43+0.6)*I43 -> 25.3
B44: Mv4 | F44: 4 | G44: 1.7 | H44: 1.7 | I44: 1 | J44: =F44*(G44+0.6)*(H44+0.6)*I44 -> 21.16
B45: Mv5 | F45: 1 | G45: 2.6 | H45: 2.75 | I45: 1 | J45: =F45*(G45+0.6)*(H45+0.6)*I45 -> 10.72
B46: Mv6 | F46: 1 | G46: 2.1 | H46: 2.75 | I46: 1 | J46: =F46*(G46+0.6)*(H46+0.6)*I46 -> 9.045
...

Sheet 02 Nhà Bảo Vệ_& P. Y TẾ
A1: BẢNG DỰ TOÁN BÁO GIÁ CÔNG TRÌNH / ESTIMATE TABLE
A2: ="DỰ ÁN / PROJECT : "&#REF! -> #REF!
A3: ="HẠNG MỤC / ITEM : "&B8 -> HẠNG MỤC / ITEM : NHÀ BẢO VỆ & PHÒNG Y TẾ GUARD HOUSE & MEDICAL ROOM
A4: ="CHỦ ĐẦU TƯ / : "&#REF! -> #REF!
A6: STT NO. | B6: TÊN CÔNG VIỆC VÀ DIỄN GIẢI DESCRIPTION | C6: ĐẶC TÍNH KỸ THUẬT STANDARD | D6: NHÃN HIỆU & XUẤT XỨ BRAND NAME & ORIGIN | E6: Đvt Unit | F6: SL | G6: DÀI | H6: RỘNG | I6: CAO | J6: KL | K6: KL TỔNG Q'TY | L6: ĐƠN GIÁ / RATE | O6: TỔNG CỘNG (VNĐ) TOTAL COST(VND) | Q6: REMARK GHI CHÚ
L7: VẬT TƯ RATE MATERIALS | M7: NHÂN CÔNG RATE LABOUR | N7: MMTB RATE EQUIPMENT | O7: ĐƠN GIÁ TỔNG TOTAL PRICE | P7: THÀNH TIỀN AMOUNT TOTAL | R7: VẬT TƯ RATE MATERIALS | S7: NHÂN CÔNG RATE LABOUR
A8: =A21 -> *** | B8: =B21 -> NHÀ BẢO VỆ & PHÒNG Y TẾ GUARD HOUSE & MEDICAL ROOM | P8: =SUBTOTAL(9,P9:P20) -> #REF!
A9: A | B9: =B22 -> CÔNG TÁC ĐẤT EARTHWORK | P9: =P22 -> #REF!
A10: =A47 -> C | B10: =B47 -> CÔNG TÁC BÊ TÔNG CONCRETE WORK | P10: =P47 -> #REF!
A11: =A82 -> D | B11: =B82 -> CÔNG TÁC VÁN KHUÔN FORMWORK | P11: =P82 -> #REF!
A12: =A116 -> E | B12: =B116 -> CÔNG TÁC CỐT THÉP REBAR WORK | P12: =P116 -> #REF!
A13: =A123 -> F | B13: =B123 -> CÔNG TÁC XÂY BRICK WALL | P13: =P123 -> #REF!
A14: =A133 -> G | B14: =B133 -> CÔNG TÁC TÔ TRÁT PLASTERING WORK | P14: =P133 -> #REF!
A15: =A146 -> H | B15: =B146 -> CÔNG TÁC SƠN PAINTING WORK | P15: =P146 -> #REF!
A16: =A150 -> I | B16: =B150 -> CÔNG TÁC CHỐNG THẤM WATERPROOFING WORK | P16: =P150 -> #REF!
A17: =A158 -> J | B17: =B158 -> CÔNG TÁC TRẦN VÁCH CEILING & PARTITION WORKS | P17: =P158 -> #REF!
A18: =A162 -> K | B18: =B162 -> CÔNG TÁC CỬA DOOR WORK | P18: =P162 -> 60121000
A19: =A170 -> L | B19: =B170 -> CÔNG TÁC KHÁC OTHER WORKS | P19: =P170 -> 590000
A21: *** | B21: NHÀ BẢO VỆ & PHÒNG Y TẾ GUARD HOUSE & MEDICAL ROOM | P21: =SUBTOTAL(9,P178:P418) -> 0 | R21: Profit | T21: 1.18
A22: B | B22: CÔNG TÁC ĐẤT EARTHWORK | P22: =SUBTOTAL(9,P23:P46) -> #REF!
A23: =IF(ISBLANK(E23),"",COUNTA($E$21:E23)) -> 1 | B23: Đào đất hố móng, đường ống, khuôn đường Excavation of foundation pits, pipes, road molds | E23: m3 | K23: =SUM(J24:J26) -> 27.216 | L23: =R23*$T$21 -> #REF! | M23: =S23*$T$21 -> #REF! | O23: =+L23+M23+N23 -> #REF! | P23: =O23*$K23 -> #REF! | R23: ='01 Nhà Xưởng 01+02'!#REF! -> #REF! | S23: ='01 Nhà Xưởng 01+02'!#REF! -> #REF!
B24: M1 | F24: 3 | G24: 1.2 | H24: 1.2 | I24: 1.4 | J24: =F24*(G24+0.6)*(H24+0.6)*I24 -> 13.608
B25: M2 | F25: 2 | G25: 1.2 | H25: 1.2 | I25: 1.4 | J25: =F25*(G25+0.6)*(H25+0.6)*I25 -> 9.072
B26: M3 | F26: 1 | G26: 1.2 | H26: 1.2 | I26: 1.4 | J26: =F26*(G26+0.6)*(H26+0.6)*I26 -> 4.536
A27: =IF(ISBLANK(E27),"",COUNTA($E$21:E27)) -> 2 | B27: Đào đất đà kiềng, nền nhà Digging up the land and the foundation of the house | E27: m3 | K27: =SUM(J28:J31) -> 12.21 | L27: =R27*$T$21 -> 0 | M27: =S27*$T$21 -> 50740 | O27: =+L27+M27+N27 -> 50740 | P27: =O27*$K27 -> 619535.4 | S27: 43000
B28: DK1 | F28: 2 | G28: 9 | H28: 0.2 | I28: 0.4 | J28: =F28*(G28+0.6)*(H28+0.6)*I28 -> 6.144 | M28: =S28*$T$21 -> 0 | S28: =S24 -> 0
F29: 3 | G29: 4 | H29: 0.2 | I29: 0.4 | J29: =F29*(G29+0.6)*(H29+0.6)*I29 -> 4.416 | M29: =S29*$T$21 -> 0 | S29: =S25 -> 0
B30: DK2 | F30: 1 | G30: 4 | H30: 0.2 | I30: 0.3 | J30: =F30*(G30+0.6)*(H30+0.6)*I30 -> 1.104 | M30: =S30*$T$21 -> 0 | S30: =S26 -> 0
B31: DK3 | F31: 1 | G31: 2 | H31: 0.1 | I31: 0.3 | J31: =F31*(G31+0.6)*(H31+0.6)*I31 -> 0.546 | M31: =S31*$T$21 -> 50740 | S31: =S27 -> 43000
A32: 3 | B32: Đắp đất nền Backfilling for floor | E32: m3 | K32: =9*4*0.5*1.3 -> 23.4 | M32: =S32*$T$21 -> 50740 | O32: =+L32+M32+N32 -> 50740 | P32: =O32*$K32 -> 1187316 | S32: 43000
A33: =IF(ISBLANK(E33),"",COUNTA($E$21:E33)) -> 4 | B33: Đắp đất móng đầm chặt Compacting the foundation | E33: m3 | K33: =K23-K52-K57 -> 23.887 | L33: =R33*$T$21 -> 0 | M33: =S33*$T$21 -> 50740 | O33: =+L33+M33+N33 -> 50740 | P33: =O33*$K33 -> 1212026.4 | S33: 43000
A34: =IF(ISBLANK(E34),"",COUNTA($E$21:E34)) -> 5 | B34: Vận chuyển đất ra ngoài phạm vi công trình Transporting land outside the scope of the project | E34: m3 | K34: =K23-K33 -> 3.329 | L34: =R34*$T$21 -> 0 | M34: =S34*$T$21 -> #REF! | O34: =+L34+M34+N34 -> #REF! | P34: =O34*$K34 -> #REF! | S34: ='01 Nhà Xưởng 01+02'!#REF! -> #REF!
A35: =IF(ISBLANK(E35),"",COUNTA($E$21:E35)) -> 6 | B35: Đầm chặt và xử lý đất đáy đà kiềng và nền K≥0.92 Compaction and treatment of soil at the bottom of Da Kieng and the foundation K≥0.92 | E35: m2 | K35: =SUM(J36:J43) -> 65.14 | L35: =R35*$T$21 -> 0 | M35: =S35*$T$21 -> 21240 | O35: =+L35+M35+N35 -> 21240 | P35: =O35*$K35 -> 1383573.6 | S35: 18000
B36: M1 | F36: 3 | G36: 1.2 | H36: 1.2 | J36: =F36*(G36+0.2)*(H36+0.2) -> 5.88 | L36: =R36*$T$21 -> 0
B37: M2 | F37: 2 | G37: 1.2 | H37: 1.2 | J37: =F37*(G37+0.2)*(H37+0.2) -> 3.92 | L37: =R37*$T$21 -> 0
B38: M3 | F38: 1 | G38: 1.2 | H38: 1.2 | J38: =F38*(G38+0.2)*(H38+0.2) -> 1.96 | L38: =R38*$T$21 -> 0
B39: DK1 | F39: 2 | G39: 9 | H39: 0.2 | J39: =F39*(G39+0.2)*(H39+0.2) -> 7.36 | L39: =R39*$T$21 -> 0
F40: 3 | G40: 4 | H40: 0.2 | J40: =F40*(G40+0.2)*(H40+0.2) -> 5.04 | L40: =R40*$T$21 -> 0
B41: DK2 | F41: 1 | G41: 4 | H41: 0.2 | J41: =F41*(G41+0.2)*(H41+0.2) -> 1.68 | L41: =R41*$T$21 -> 0
B42: DK3 | F42: 1 | G42: 2 | H42: 0.1 | J42: =F42*(G42+0.2)*(H42+0.2) -> 0.66 | L42: =R42*$T$21 -> 0
...

Sheet 03 NHÀ BẢO VỆ 01 &02
A1: BẢNG DỰ TOÁN BÁO GIÁ CÔNG TRÌNH / ESTIMATE TABLE
A3: ="HẠNG MỤC / ITEM : "&B8 -> HẠNG MỤC / ITEM : HẠNG MỤC NHÀ BẢO VỆ 01 &02
A6: STT NO. | B6: TÊN CÔNG VIỆC VÀ DIỄN GIẢI DESCRIPTION | C6: ĐẶC TÍNH KỸ THUẬT STANDARD | D6: NHÃN HIỆU & XUẤT XỨ BRAND NAME & ORIGIN | E6: Đvt Unit | F6: SL | G6: DÀI | H6: RỘNG | I6: CAO | J6: KL | K6: KL TỔNG Q'TY | L6: ĐƠN GIÁ / RATE | O6: TỔNG CỘNG (VNĐ) TOTAL COST(VND) | Q6: REMARK GHI CHÚ
L7: VẬT TƯ RATE MATERIALS | M7: NHÂN CÔNG RATE LABOUR | N7: MMTB RATE EQUIPMENT | O7: ĐƠN GIÁ TỔNG TOTAL PRICE | P7: THÀNH TIỀN AMOUNT TOTAL | R7: VẬT TƯ RATE MATERIALS | S7: NHÂN CÔNG RATE LABOUR
B8: HẠNG MỤC NHÀ BẢO VỆ 01 &02 | E8: m2 | K8: 33.6 | P8: =O8*K8 -> 0
A9: A | B9: CÔNG TÁC ĐẤT EARTHWORK
A10: B | B10: CÔNG TÁC BÊ TÔNG CONCRETE WORK
A11: C | B11: CÔNG TÁC VÁN KHUÔN FORMWORK
A12: D | B12: CÔNG TÁC CỐT THÉP REBAR WORK
A13: E | B13: CÔNG TÁC XÂY BRICK WALL
A14: F | B14: CÔNG TÁC TÔ TRÁT PLASTERING WORK
A15: G | B15: CÔNG TÁC SƠN PAINTING WORK
A16: H | B16: CÔNG TÁC CHỐNG THẤM WATERPROOFING WORK
A17: I | B17: CÔNG TÁC TRẦN VÁCH CEILING & PARTITION WORKS
A18: J | B18: CÔNG TÁC CỬA DOOR WORK
A19: L
A21: =IF(ISBLANK(E21),"",MAX(#REF!)+1) | O21: =+L21+M21 -> 0 | P21: =O21*$K21 -> 0
A22: =IF(ISBLANK(E22),"",MAX($A$20:A21)+1) | O22: =+L22+M22+N22 -> 0 | P22: =O22*$K22 -> 0
A23: =IF(ISBLANK(E23),"",MAX($A$20:A22)+1) | O23: =+L23+M23+N23 -> 0 | P23: =O23*$K23 -> 0
A24: =IF(ISBLANK(E24),"",MAX($A$20:A23)+1) | O24: =+L24+M24+N24 -> 0 | P24: =O24*$K24 -> 0

Sheet 04 NHÀ XE
A1: BẢNG DỰ TOÁN BÁO GIÁ CÔNG TRÌNH / ESTIMATE TABLE
A2: ='03 NHÀ BẢO VỆ 01 &02'!A2 -> 0
A3: ="HẠNG MỤC / ITEM : "&B8 -> HẠNG MỤC / ITEM : HẠNG MỤC NHÀ XE 1 TẦNG
A4: ='03 NHÀ BẢO VỆ 01 &02'!A4 -> 0
A6: STT NO. | B6: TÊN CÔNG VIỆC VÀ DIỄN GIẢI DESCRIPTION | C6: ĐẶC TÍNH KỸ THUẬT STANDARD | D6: NHÃN HIỆU & XUẤT XỨ BRAND NAME & ORIGIN | E6: Đvt Unit | F6: SL | G6: DÀI | H6: RỘNG | I6: CAO | J6: KL | K6: KL TỔNG Q'TY | L6: ĐƠN GIÁ / RATE | O6: TỔNG CỘNG (VNĐ) TOTAL COST(VND) | Q6: REMARK GHI CHÚ
L7: VẬT TƯ RATE MATERIALS | M7: NHÂN CÔNG RATE LABOUR | N7: MMTB RATE EQUIPMENT | O7: ĐƠN GIÁ TỔNG TOTAL PRICE | P7: THÀNH TIỀN AMOUNT TOTAL
A8: =A18 -> *** | B8: =B18 -> HẠNG MỤC NHÀ XE 1 TẦNG | P8: =SUBTOTAL(9,P9:P17) -> 0
A9: A | B9: =B19 -> CÔNG TÁC XỬ LÝ ĐẦU CỌC PILING WORKS | P9: =P19 -> 0
A10: =A44 -> 0 | B10: =B30 -> CÔNG TÁC ĐẤT EARTHWORK | P10: =P30 -> 0
A11: =A92 -> 0 | B11: =B40 -> CÔNG TÁC BÊ TÔNG CONCRETE WORK | P11: =P40 -> 0
A12: D | B12: =B54 -> CÔNG TÁC VÁN KHUÔN FORMWORK | P12: =P54 -> 0
A13: =A334 -> 0 | B13: =B67 -> CÔNG TÁC CỐT THÉP REBAR WORK | P13: =P67 -> 0
A14: =A341 -> 0 | B14: =B75 -> CÔNG TÁC HOÀN THIỆN NỀN SÀN FINISHING THE FLOOR | P14: =P75 -> 0
A15: =A366 -> 0 | B15: =B80 -> CÔNG TÁC KẾT CẤU THÉP STEEL STRUCTURE AND WORK | P15: =P81 -> 0
A18: *** | B18: HẠNG MỤC NHÀ XE 1 TẦNG
A19: A | B19: CÔNG TÁC XỬ LÝ ĐẦU CỌC PILING WORKS | P19: =SUBTOTAL(9,P20:P29) -> 0
A22: 4 | B22: Cung cấp và thi công cọc đại trà, PHC-A D300 Supply and construction of mass piles, PHC-A D300 | C22: Cọc PHC A , D300, L=27m, Pmax =120 tấn PHC A pile, D300, L=27m, Pmax =120 tons | D22: Kiến Hoa, Phan Vũ, BT Thủ Đức, Việt Thái An Kien Hoa, Phan Vu, BT Thu Duc, VTA | E22: md | K22: =J23 -> 351 | O22: =+L22+M22+N22 -> 0 | P22: =O22*$K22 -> 0 | Q22: ='05 BỂ PCCC & NHÀ BƠM'!L23 -> Dự kiến ép cọc 27md
B23: Nhà xe | F23: 13 | G23: 27 | J23: =F23*G23 -> 351
A24: 6 | B24: Ép âm cọc Embedded pressing | E24: md | J24: =F24*(G24+0.6)*(H24+0.6)*I24 -> 0
A25: 8 | B25: Máy phát điện thi công cọc Pile construction generator | E25: md | J25: =J23 -> 351 | K25: =J25 -> 351 | O25: =+L25+M25+N25 -> 0 | P25: =O25*$K25 -> 0
A26: 9 | B26: Cắt đầu cọc Cutting pile heads | E26: cái | J26: =14 -> 14 | K26: =J26 -> 14 | O26: =+L26+M26+N26 -> 0 | P26: =O26*$K26 -> 0
A27: 10 | B27: SXLD bản mã đầu cọc Anchor plate for pile heads | C27: Tấm dày 5mm, thép SS400 5mm thick plate, SS400 steel | D27: SS400 | E27: Kg | J27: =0.3*0.3*0.005*7850*14 -> 49.455 | K27: =J27 -> 49.455 | O27: =+L27+M27+N27 -> 0 | P27: =O27*$K27 -> 0
A28: 11 | B28: Cốt thép đầu cọc Anchor steel for pile heads | C28: 6D14, L=1500mm; D6a150 6D14, L=1500mm; D6a150 | E28: Kg | J28: =F28*(G28+0.6)*(H28+0.6)*I28 -> 0 | K28: =K26*11 -> 154 | O28: =+L28+M28+N28 -> 0 | P28: =O28*$K28 -> 0
A29: 12 | B29: Bê tông đầu cọc Pile head concrete | C29: Độ sụt 10±2cm, Mác M300 Slump 10±2cm, Grade M300 | E29: m3 | J29: =F29*(G29+0.6)*(H29+0.6)*I29 -> 0 | K29: =0.2*0.2*1*14 -> 0.56 | O29: =+L29+M29+N29 -> 0 | P29: =O29*$K29 -> 0
A30: II | B30: CÔNG TÁC ĐẤT EARTHWORK | P30: =SUBTOTAL(9,P31:P39) -> 0
A31: =IF(ISBLANK(E31),"",COUNTA($E$18:E31)) -> 8 | B31: Đào đất hố móng, đường ống, khuôn đường Excavation of foundation pits, pipes, road molds | E31: m3 | K31: =J32 -> 41.16 | O31: =+L31+M31+N31 -> 0 | P31: =O31*$K31 -> 0
B32: M1 | F32: 14 | G32: 0.8 | H32: 0.8 | I32: 1.5 | J32: =F32*(G32+0.6)*(H32+0.6)*I32 -> 41.16
A33: =IF(ISBLANK(E33),"",COUNTA($E$18:E33)) -> 9 | B33: Đào đất đà kiềng Digging up the land | E33: m3 | K33: =J34+J35 -> 30.861 | O33: =+L33+M33+N33 -> 0 | P33: =O33*$K33 -> 0
B34: 20x35 | F34: 1 | G34: =24*2 -> 48 | H34: 0.2 | I34: 0.35 | J34: =F34*(G34+0.6)*(H34+0.6)*I34 -> 13.608
B35: 30x45 | F35: 1 | G35: =6*7 -> 42 | H35: 0.3 | I35: 0.45 | J35: =F35*(G35+0.6)*(H35+0.6)*I35 -> 17.253
A36: =IF(ISBLANK(E36),"",COUNTA($E$18:E36)) -> 10 | B36: Đắp đất móng đầm chặt Compacting the foundation | E36: m3 | K36: =(K31+K33)-K41-K43-K46-K48 -> 60.244 | O36: =+L36+M36+N36 -> 0 | P36: =O36*$K36 -> 0
A37: =IF(ISBLANK(E37),"",COUNTA($E$18:E37)) -> 11 | B37: Vận chuyển đất bên trong phạm vi công trình Transporting land inside the scope of the project | E37: m3 | K37: =(K31+K33)-K36 -> 11.777 | O37: =+L37+M37+N37 -> 0 | P37: =O37*$K37 -> 0
A38: =IF(ISBLANK(E38),"",COUNTA($E$18:E38)) -> 12 | B38: Đầm chặt đất nền, K>=92 Compacting the soil, K>=92 | E38: m2 | K38: 212 | O38: =+L38+M38+N38 -> 0 | P38: =O38*$K38 -> 0
A39: =IF(ISBLANK(E39),"",COUNTA($E$18:E39)) -> 13 | B39: Lớp PVC, dày 0.3mm PVC layer, 0.3mm thick | E39: m2 | K39: =K38 -> 212 | O39: =+L39+M39+N39 -> 0 | P39: =O39*$K39 -> 0
A40: III | B40: CÔNG TÁC BÊ TÔNG CONCRETE WORK | P40: =SUBTOTAL(9,P41:P53) -> 0
A41: =IF(ISBLANK(E41),"",COUNTA($E$18:E41)) -> 14 | B41: Bê tông lót móng đá 1x2 M150 Concrete lining stone foundation 1x2 M150 | E41: m3 | K41: =J42 -> 0.7 | O41: =+L41+M41+N41 -> 0 | P41: =O41*$K41 -> 0
B42: M1 | F42: 14 | G42: 0.8 | H42: 0.8 | I42: 0.05 | J42: =F42*(G42+0.2)*(H42+0.2)*I42 -> 0.7
A43: =IF(ISBLANK(E43),"",COUNTA($E$18:E43)) -> 15 | B43: Bê tông lót đá đà kiềng 1x2 M150 Concrete lined with stone 1x2 M150 | E43: m3 | K43: =SUM(J44:J45) -> 2.019 | O43: =+L43+M43+N43 -> 0 | P43: =O43*$K43 -> 0
B44: 20x35 | F44: 1 | G44: =24*2 -> 48 | H44: 0.2 | I44: 0.05 | J44: =F44*(G44+0.2)*(H44+0.2)*I44 -> 0.964
B45: 30x45 | F45: 1 | G45: =6*7 -> 42 | H45: 0.3 | I45: 0.05 | J45: =F45*(G45+0.2)*(H45+0.2)*I45 -> 1.055
...

Sheet  TRẠM BƠM
A1: BẢNG DỰ TOÁN BÁO GIÁ CÔNG TRÌNH / ESTIMATE TABLE
A2: ="DỰ ÁN / PROJECT : "&[6]COVER!K10 -> DỰ ÁN / PROJECT : AN KHANG FOODS JSC
A3: ="HẠNG MỤC / ITEM : "&B8 -> HẠNG MỤC / ITEM : TRẠM BƠM PUMP STATION
A4: ="CHỦ ĐẦU TƯ / : "&[6]COVER!K19 -> CHỦ ĐẦU TƯ / : AN KHANG FOODS JSC
A6: STT NO. | B6: TÊN CÔNG VIỆC VÀ DIỄN GIẢI DESCRIPTION | C6: ĐẶC TÍNH KỸ THUẬT STANDARD | D6: NHÃN HIỆU & XUẤT XỨ BRAND NAME & ORIGIN | E6: Đvt Unit | F6: KL TỔNG Q'TY | G6: ĐƠN GIÁ / RATE | J6: TỔNG CỘNG (VNĐ) TOTAL COST(VND) | L6: REMARK GHI CHÚ
G7: VẬT TƯ RATE MATERIALS | H7: NHÂN CÔNG RATE LABOUR | I7: MMTB RATE EQUIPMENT | J7: ĐƠN GIÁ TỔNG TOTAL PRICE | K7: THÀNH TIỀN AMOUNT TOTAL
A8: =A21 -> *** | B8: =B21 -> TRẠM BƠM PUMP STATION | K8: =SUBTOTAL(9,K9:K20) -> #REF!
A9: =A22 -> II | B9: =B22 -> CÔNG TÁC ĐẤT EARTHWORK | K9: =K22 -> #REF!
A10: =A30 -> III | B10: =B30 -> CÔNG TÁC BÊ TÔNG CONCRETE WORK | K10: =K30 -> #REF!
A11: =A40 -> III | B11: =B40 -> CÔNG TÁC VÁN KHUÔN FORMWORK | K11: =K40 -> #REF!
A12: =A48 -> III | B12: =B48 -> CÔNG TÁC CỐT THÉP REBAR WORK | K12: =K48 -> #REF!
A13: =A55 -> VI | B13: =B55 -> CÔNG TÁC XÂY BRICK WALL | K13: =K55 -> #REF!
A14: =A61 -> VI | B14: =B61 -> CÔNG TÁC TÔ TRÁT PLASTERING WORK | K14: =K61 -> #REF!
A15: =A66 -> VII | B15: =B66 -> CÔNG TÁC SƠN PAINTING WORK | K15: =K66 -> #REF!
A16: =A69 -> VII | B16: =B69 -> CÔNG TÁC HOÀN THIỆN NỀN SÀN FINISHING THE FLOOR | K16: =K69 -> 0
A17: =A73 -> VII | B17: =B73 -> CÔNG TÁC CỬA DOOR WORK | K17: =K73 -> 17558400
A18: =A78 -> VII | B18: =B78 -> CÔNG TÁC KẾT CẤU THÉP STEEL STRUCTURE AND WORK | K18: =K78 -> #REF!
A21: *** | B21: TRẠM BƠM PUMP STATION | M21: Profit | O21: 1.18
A22: II | B22: CÔNG TÁC ĐẤT EARTHWORK | K22: =SUBTOTAL(9,K23:K29) -> #REF! | M22: VẬT TƯ RATE MATERIALS | N22: NHÂN CÔNG RATE LABOUR
A23: =IF(ISBLANK(E23),"",COUNTA($E$21:E23)) -> 1 | B23: Đào đất hố móng, đường ống, khuôn đường Excavation of foundation pits, pipes, road molds | E23: m3 | G23: =M23*$O$21 -> #REF! | H23: =N23*$O$21 -> #REF! | J23: =+G23+H23+I23 -> #REF! | K23: =J23*$F23 -> #REF! | M23: ='02 Nhà Bảo Vệ_& P. Y TẾ'!R23 -> #REF! | N23: ='02 Nhà Bảo Vệ_& P. Y TẾ'!S23 -> #REF!
A24: =IF(ISBLANK(E24),"",COUNTA($E$21:E24)) -> 2 | B24: Đào đất đà kiềng Digging up the land | E24: m3 | G24: =M24*$O$21 -> 0 | H24: =N24*$O$21 -> 50740 | J24: =+G24+H24+I24 -> 50740 | K24: =J24*$F24 -> 0 | M24: ='02 Nhà Bảo Vệ_& P. Y TẾ'!R27 -> 0 | N24: ='02 Nhà Bảo Vệ_& P. Y TẾ'!S27 -> 43000
A25: =IF(ISBLANK(E25),"",COUNTA($E$21:E25)) -> 3 | B25: Đắp đất móng đầm chặt Compacting the foundation | E25: m3 | G25: =M25*$O$21 -> 0 | H25: =N25*$O$21 -> 50740 | J25: =+G25+H25+I25 -> 50740 | K25: =J25*$F25 -> 0 | M25: ='02 Nhà Bảo Vệ_& P. Y TẾ'!R33 -> 0 | N25: ='02 Nhà Bảo Vệ_& P. Y TẾ'!S33 -> 43000
A26: =IF(ISBLANK(E26),"",COUNTA($E$21:E26)) -> 4 | B26: Vận chuyển đất bên trong phạm vi công trình Transporting land inside the scope of the project | E26: m3 | G26: =M26*$O$21 -> 0 | H26: =N26*$O$21 -> #REF! | J26: =+G26+H26+I26 -> #REF! | K26: =J26*$F26 -> #REF! | M26: ='02 Nhà Bảo Vệ_& P. Y TẾ'!R34 -> 0 | N26: ='02 Nhà Bảo Vệ_& P. Y TẾ'!S34 -> #REF!
A27: =IF(ISBLANK(E27),"",COUNTA($E$21:E27)) -> 5 | B27: Đầm chặt đất nền, K>=92 Compacting the soil, K>=92 | E27: m2 | G27: =M27*$O$21 -> 0 | H27: =N27*$O$21 -> 21240 | J27: =+G27+H27+I27 -> 21240 | K27: =J27*$F27 -> 0 | M27: ='02 Nhà Bảo Vệ_& P. Y TẾ'!R35 -> 0 | N27: ='02 Nhà Bảo Vệ_& P. Y TẾ'!S35 -> 18000
A28: =IF(ISBLANK(E28),"",COUNTA($E$21:E28)) -> 6 | B28: Đầm chặt và xử lý đất đáy đà kiềng, bó vỉa Compacting and treating the soil at the bottom of the dam, bundling the pavement | E28: m2 | G28: =M28*$O$21 -> 0 | H28: =N28*$O$21 -> 21240 | J28: =+G28+H28+I28 -> 21240 | K28: =J28*$F28 -> 0 | N28: =N27 -> 18000
A29: =IF(ISBLANK(E29),"",COUNTA($E$21:E29)) -> 7 | B29: Lớp PVC, dày 0.3mm PVC layer, 0.3mm thick | E29: m2 | G29: =M29*$O$21 -> #REF! | H29: =N29*$O$21 -> #REF! | J29: =+G29+H29+I29 -> #REF! | K29: =J29*$F29 -> #REF! | M29: ='02 Nhà Bảo Vệ_& P. Y TẾ'!R44 -> #REF! | N29: ='02 Nhà Bảo Vệ_& P. Y TẾ'!S44 -> #REF!
A30: III | B30: CÔNG TÁC BÊ TÔNG CONCRETE WORK | K30: =SUBTOTAL(9,K31:K39) -> #REF!
A31: =IF(ISBLANK(E31),"",COUNTA($E$21:E31)) -> 8 | B31: Bê tông lót móng đá 1x2 M150 Concrete lining stone foundation 1x2 M150 | E31: m3 | G31: =M31*$O$21 -> #REF! | H31: =N31*$O$21 -> #REF! | J31: =+G31+H31+I31 -> #REF! | K31: =J31*$F31 -> #REF! | M31: ='02 Nhà Bảo Vệ_& P. Y TẾ'!R48 -> #REF! | N31: ='02 Nhà Bảo Vệ_& P. Y TẾ'!S48 -> #REF!
A32: =IF(ISBLANK(E32),"",COUNTA($E$21:E32)) -> 9 | B32: Bê tông lót đá đà kiềng 1x2 M150 Concrete lined with stone 1x2 M150 | E32: m3 | G32: =M32*$O$21 -> #REF! | H32: =N32*$O$21 -> #REF! | J32: =+G32+H32+I32 -> #REF! | K32: =J32*$F32 -> #REF! | M32: ='02 Nhà Bảo Vệ_& P. Y TẾ'!R52 -> #REF! | N32: ='02 Nhà Bảo Vệ_& P. Y TẾ'!S52 -> #REF!
A33: =IF(ISBLANK(E33),"",COUNTA($E$21:E33)) -> 10 | B33: Bê tông móng đá 1x2 M250 Stone foundation concrete 1x2 M250 | C33: Độ sụt 10±2cm | D33: Kiến Hoa, Phan Vũ, BT Thủ Đức Kien Hoa, Phan Vu, BT Thu Duc | E33: m3 | G33: =M33*$O$21 -> 1392400 | H33: =N33*$O$21 -> 212400 | J33: =+G33+H33+I33 -> 1604800 | K33: =J33*$F33 -> 0 | M33: ='02 Nhà Bảo Vệ_& P. Y TẾ'!R57 -> 1180000 | N33: ='02 Nhà Bảo Vệ_& P. Y TẾ'!S57 -> 180000
A34: =IF(ISBLANK(E34),"",COUNTA($E$21:E34)) -> 11 | B34: Bê tông cổ móng đá 1x2 M250 Stone foundation neck concrete 1x2 M250 | C34: Độ sụt 10±2cm | D34: Kiến Hoa, Phan Vũ, BT Thủ Đức Kien Hoa, Phan Vu, BT Thu Duc | E34: m3 | G34: =M34*$O$21 -> 1392400 | H34: =N34*$O$21 -> 212400 | J34: =+G34+H34+I34 -> 1604800 | K34: =J34*$F34 -> 0 | M34: =M33 -> 1180000 | N34: =N33 -> 180000
A35: =IF(ISBLANK(E35),"",COUNTA($E$21:E35)) -> 12 | B35: Bê tông đà kiềng đá 1x2 M250 1x2 M250 Stone Concrete | C35: Độ sụt 10±2cm | D35: Kiến Hoa, Phan Vũ, BT Thủ Đức Kien Hoa, Phan Vu, BT Thu Duc | E35: m3 | G35: =M35*$O$21 -> 1392400 | H35: =N35*$O$21 -> 212400 | J35: =+G35+H35+I35 -> 1604800 | K35: =J35*$F35 -> 0 | M35: =M34 -> 1180000 | N35: =N34 -> 180000
A36: =IF(ISBLANK(E36),"",COUNTA($E$21:E36)) -> 13 | B36: Bê tông nền đá 1x2 M250 Stone foundation concrete 1x2 M250 | C36: Độ sụt 10±2cm | D36: Kiến Hoa, Phan Vũ, BT Thủ Đức Kien Hoa, Phan Vu, BT Thu Duc | E36: m3 | G36: =M36*$O$21 -> 1392400 | H36: =N36*$O$21 -> 212400 | J36: =+G36+H36+I36 -> 1604800 | K36: =J36*$F36 -> 0 | M36: =M35 -> 1180000 | N36: =N35 -> 180000
A37: =IF(ISBLANK(E37),"",COUNTA($E$21:E37)) -> 14 | B37: Bê tông cột đá 1x2 M250 1x2 M250 column Concrete | C37: Độ sụt 10±2cm | D37: Kiến Hoa, Phan Vũ, BT Thủ Đức Kien Hoa, Phan Vu, BT Thu Duc | E37: m3 | G37: =M37*$O$21 -> 1392400 | H37: =N37*$O$21 -> 212400 | J37: =+G37+H37+I37 -> 1604800 | K37: =J37*$F37 -> 0 | M37: =M36 -> 1180000 | N37: =N36 -> 180000
A38: =IF(ISBLANK(E38),"",COUNTA($E$21:E38)) -> 15 | B38: Bê tông sàn đá 1x2 M250 Concrete stone floor 1x2 M250 | C38: Độ sụt 10±2cm | D38: Kiến Hoa, Phan Vũ, BT Thủ Đức Kien Hoa, Phan Vu, BT Thu Duc | E38: m3 | G38: =M38*$O$21 -> 1392400 | H38: =N38*$O$21 -> 212400 | J38: =+G38+H38+I38 -> 1604800 | K38: =J38*$F38 -> 0 | M38: =M37 -> 1180000 | N38: =N37 -> 180000
A39: 21 | B39: Bê tông ram dốc 1x2 M250 Concrete Ramps 1x2 M250 | C39: Độ sụt 10±2cm | D39: Kiến Hoa, Phan Vũ, BT Thủ Đức Kien Hoa, Phan Vu, BT Thu Duc | E39: m3 | G39: =M39*$O$21 -> 1392400 | H39: =N39*$O$21 -> 212400 | J39: =+G39+H39+I39 -> 1604800 | K39: =J39*$F39 -> 0 | M39: =M38 -> 1180000 | N39: =N38 -> 180000
A40: III | B40: CÔNG TÁC VÁN KHUÔN FORMWORK | K40: =SUBTOTAL(9,K41:K47) -> #REF!
A41: =IF(ISBLANK(E41),"",COUNTA($E$21:E41)) -> 17 | B41: Ván khuôn bê tông lót móng Formwork for foundation lean concrete | E41: m2 | G41: =M41*$O$21 -> #REF! | H41: =N41*$O$21 -> #REF! | J41: =+G41+H41+I41 -> #REF! | K41: =J41*$F41 -> #REF! | M41: ='02 Nhà Bảo Vệ_& P. Y TẾ'!R83 -> #REF! | N41: ='02 Nhà Bảo Vệ_& P. Y TẾ'!S83 -> #REF!
A42: =IF(ISBLANK(E42),"",COUNTA($E$21:E42)) -> 18 | B42: Ván khuôn bê tông lót đà kiềng Formwork for tie beam lean concrete | E42: m2 | G42: =M42*$O$21 -> #REF! | H42: =N42*$O$21 -> #REF! | J42: =+G42+H42+I42 -> #REF! | K42: =J42*$F42 -> #REF! | M42: =M41 -> #REF! | N42: =N41 -> #REF!
A43: =IF(ISBLANK(E43),"",COUNTA($E$21:E43)) -> 19 | B43: Ván khuôn bê tông móng Formwork for foundation concrete | E43: m2 | G43: =M43*$O$21 -> #REF! | H43: =N43*$O$21 -> #REF! | J43: =+G43+H43+I43 -> #REF! | K43: =J43*$F43 -> #REF! | M43: =M42 -> #REF! | N43: =N42 -> #REF!
...

Sheet 05 BỂ PCCC & NHÀ BƠM
A1: BẢNG DỰ TOÁN BÁO GIÁ CÔNG TRÌNH / ESTIMATE TABLE
A2: ='04 NHÀ XE'!A2 -> 0
A3: ="HẠNG MỤC / ITEM : "&B8 -> HẠNG MỤC / ITEM : HẠNG MỤC BỂ NƯỚC PCCC, NHÀ BƠM
A4: ='04 NHÀ XE'!A4 -> 0
A6: STT NO. | B6: TÊN CÔNG VIỆC VÀ DIỄN GIẢI DESCRIPTION | C6: ĐẶC TÍNH KỸ THUẬT STANDARD | D6: NHÃN HIỆU & XUẤT XỨ BRAND NAME & ORIGIN | E6: Đvt Unit | F6: KL TỔNG Q'TY | G6: ĐƠN GIÁ / RATE | J6: TỔNG CỘNG (VNĐ) TOTAL COST(VND) | L6: REMARK GHI CHÚ
G7: VẬT TƯ RATE MATERIALS | H7: NHÂN CÔNG RATE LABOUR | I7: MMTB RATE EQUIPMENT | J7: ĐƠN GIÁ TỔNG TOTAL PRICE | K7: THÀNH TIỀN AMOUNT TOTAL
A8: =A18 -> *** | B8: =B18 -> HẠNG MỤC BỂ NƯỚC PCCC, NHÀ BƠM | C8: BỂ NƯỚC 560M3 | K8: =SUBTOTAL(9,K9:K17) -> 0
A9: A | B9: =B19 -> CÔNG TÁC XỬ LÝ ĐẦU CỌC PILING WORKS | K9: =K19 -> 0
A10: B | B10: =B31 -> CÔNG TÁC ĐẤT EARTHWORK | K10: =K31 -> 0
A11: C | B11: =B36 -> CÔNG TÁC BÊ TÔNG CONCRETE WORK | K11: =K36 -> 0
A12: D | B12: =B42 -> CÔNG TÁC VÁN KHUÔN FORMWORK | K12: =K42 -> 0
A13: H | B13: =B54 -> CÔNG TÁC CỐT THÉP REBAR WORK | K13: =K54 -> 0
A14: K | B14: =B70 -> CÔNG TÁC CHỐNG THẤM WATERPROOFING WORK | K14: =K70 -> 0
A15: L | B15: =B78 -> CÔNG TÁC KHÁC OTHER WORKS | K15: =K78 -> 0
A18: *** | B18: HẠNG MỤC BỂ NƯỚC PCCC, NHÀ BƠM | K18: =SUBTOTAL(9,K89:K314) -> 0
A19: A | B19: CÔNG TÁC XỬ LÝ ĐẦU CỌC PILING WORKS | K19: =SUBTOTAL(9,K20:K30) -> 0
A23: 4 | B23: Cung cấp và thi công cọc đại trà, PHC-A D300 Supply and construction of mass piles, PHC-A D300 | C23: Cọc PHC A , D300, L=27m, Pmax =120 tấn PHC A pile, D300, L=27m, Pmax =120 tons, | D23: Kiến Hoa, Phan Vũ, BT Thủ Đức, Việt Thái An Kien Hoa, Phan Vu, BT Thu Duc, VTA | E23: md | F23: =19*27 -> 513 | J23: =+G23+H23+I23 -> 0 | K23: =J23*F23 -> 0 | L23: Dự kiến ép cọc 27md
B24: Bể PCCC
A25: 6 | B25: Ép âm cọc Embedded pressing | E25: md
A26: 8 | B26: Máy phát điện thi công cọc Pile construction generator | E26: md | F26: =20*33 -> 660 | J26: =+G26+H26+I26 -> 0 | K26: =J26*F26 -> 0
A27: 9 | B27: Cắt đầu cọc Cutting pile heads | E27: cái | F27: 19 | J27: =+G27+H27+I27 -> 0 | K27: =J27*F27 -> 0
A28: 10 | B28: SXLD bản mã đầu cọc Anchor plate for pile heads | C28: Tấm dày 5mm, thép SS400 5mm thick plate, SS400 steel | D28: SS400 | E28: Kg | F28: =0.3*0.3*0.005*7850*20 -> 70.65 | J28: =+G28+H28+I28 -> 0 | K28: =J28*F28 -> 0
A29: 11 | B29: Cốt thép đầu cọc Anchor steel for pile heads | C29: 6D14, L=1500mm; D6a150 6D14, L=1500mm; D6a150 | E29: Kg | F29: =F27*11 -> 209 | J29: =+G29+H29+I29 -> 0 | K29: =J29*F29 -> 0
A30: 12 | B30: Bê tông đầu cọc Pile head concrete | C30: Độ sụt 10±2cm, Mác M300 Slump 10±2cm, Grade M300 | E30: m3 | F30: =0.2*0.2*1*20 -> 0.8 | J30: =+G30+H30+I30 -> 0 | K30: =J30*F30 -> 0
A31: B | B31: CÔNG TÁC ĐẤT EARTHWORK | K31: =SUBTOTAL(9,K32:K35) -> 0
A32: =IF(ISBLANK(E32),"",COUNTA($E$18:E32)) -> 8 | B32: Đào đất bể nước Excavation of water tank | C32: Lấy đất đắp nền nhà xưởng, ko chuyển đi | E32: m3 | F32: =(20*(1*1*0.65)+65.6*0.25*0.25+5*30*5)*65% -> 498.615 | J32: =+G32+H32+I32 -> 0 | K32: =J32*$F32 -> 0
A33: =IF(ISBLANK(E33),"",COUNTA($E$18:E33)) -> 9 | B33: Đắp đất BỂ đầm chặt Compacting the water tank | E33: m3 | F33: =(F32-F37-30*5*4.9)*1.2 -> -300.9516 | J33: =+G33+H33+I33 -> 0 | K33: =J33*$F33 -> 0
A34: =IF(ISBLANK(E34),"",COUNTA($E$18:E34)) -> 10 | B34: Vận chuyển đất ra ngoài phạm vi công trình Transporting land outside the scope of the project | C34: Không vận chuyển ra ngoài | E34: m3 | F34: =F32-F33 -> 799.5666 | J34: =+G34+H34+I34 -> 0 | K34: =J34*$F34 -> 0
A35: =IF(ISBLANK(E35),"",COUNTA($E$18:E35)) -> 11 | B35: Đầm chặt đất nền Compacting the ground | E35: m2 | F35: =30.2*5.2 -> 157.04 | J35: =+G35+H35+I35 -> 0 | K35: =J35*$F35 -> 0
A36: B | B36: CÔNG TÁC BÊ TÔNG CONCRETE WORK | K36: =SUBTOTAL(9,K37:K41) -> 0
A37: =IF(ISBLANK(E37),"",COUNTA($E$18:E37)) -> 12 | B37: Bê tông lót đá đáy bể 1x2 M150 Concrete lining stone bottom tank 1x2 M100 | E37: m3 | F37: =20*1*0.05+65.6*0.35*0.05+(29.2*4.5-20*0.8*0.55)*0.1 -> 14.408 | J37: =+G37+H37+I37 -> 0 | K37: =J37*$F37 -> 0
A38: =IF(ISBLANK(E38),"",COUNTA($E$18:E38)) -> 13 | B38: Bê tông đáy bể đá 1x2, M250, phụ gia chống thấm B8 1x2 rock tank bottom concrete, M250, B8 waterproofing additive | E38: m3 | F38: =20*0.8*0.55+(60+3.4*2-20*0.8)*0.25*0.25+6.8*0.2*0.25+30*5*0.25 -> 49.815 | J38: =+G38+H38+I38 -> 0 | K38: =J38*$F38 -> 0
A39: =IF(ISBLANK(E39),"",COUNTA($E$18:E39)) -> 14 | B39: Bê tông thành bể đá 1x2, M250, phụ gia chống thấm B8 Concrete into stone tank 1x2, M250, waterproofing additive B8 | E39: m3 | F39: =(30*2+4.5*2)*4.5*0.25+4.5*2*4.5*0.2 -> 85.725 | J39: =+G39+H39+I39 -> 0 | K39: =J39*$F39 -> 0
A40: =IF(ISBLANK(E40),"",COUNTA($E$18:E40)) -> 15 | B40: Bê tông nắp bể đá 1x2, M300, phụ gia chống thấm 1x2 Stone Tank Cover Concrete, M250, Waterproofing Additive | E40: m3 | F40: =30*5*0.15-0.6*0.6*0.15*6 -> 22.176 | J40: =+G40+H40+I40 -> 0 | K40: =J40*$F40 -> 0
A41: =IF(ISBLANK(E41),"",COUNTA($E$18:E41))
A42: C | B42: CÔNG TÁC VÁN KHUÔN FORMWORK | K42: =SUBTOTAL(9,K43:K53) -> 0
A43: =IF(ISBLANK(E43),"",COUNTA($E$18:E43)) -> 16 | B43: Ván khuôn lót đáy bể Tank bottom lining formwork | E43: m2 | F43: =20*1*4*0.05+(60+3.4*2-20*0.8)*0.45*0.05+6.8*0.4*0.05 -> 5.279 | J43: =+G43+H43+I43 -> 0 | K43: =J43*$F43 -> 0
A44: =IF(ISBLANK(E44),"",COUNTA($E$18:E44)) -> 17 | B44: Ván khuôn đáy bể Tank bottom formwork | E44: m2 | F44: =20*0.8*4*0.55+(60+3.4*2-20*0.8)*0.25+6.8*0.25*2+(30+5)*2*0.5 -> 86.3 | J44: =+G44+H44+I44 -> 0 | K44: =J44*$F44 -> 0
A45: =IF(ISBLANK(E45),"",COUNTA($E$18:E45)) -> 18 | B45: Ván khuôn thành bể Tank Formwork | E45: m2 | F45: =(70*4.5+27.81*3*4.5)*80% -> 552.348 | J45: =+G45+H45+I45 -> 0 | K45: =J45*$F45 -> 0
A46: =IF(ISBLANK(E46),"",COUNTA($E$18:E46)) -> 19 | B46: Ván khuôn đà nắp bể Formwork Beams | E46: m2 | J46: =+G46+H46+I46 -> 0 | K46: =J46*$F46 -> 0
...

Sheet PHÒNG MÁY PHÁT ĐIỆN
A1: BẢNG DỰ TOÁN BÁO GIÁ CÔNG TRÌNH / ESTIMATE TABLE
A2: ="DỰ ÁN / PROJECT : "&[6]COVER!K10 -> DỰ ÁN / PROJECT : AN KHANG FOODS JSC
A3: ="HẠNG MỤC / ITEM : "&B8 -> HẠNG MỤC / ITEM : MÁY PHÁT GENERATOR
A4: ="CHỦ ĐẦU TƯ / : "&[6]COVER!K19 -> CHỦ ĐẦU TƯ / : AN KHANG FOODS JSC
A6: STT NO. | B6: TÊN CÔNG VIỆC VÀ DIỄN GIẢI DESCRIPTION | C6: ĐẶC TÍNH KỸ THUẬT STANDARD | D6: NHÃN HIỆU & XUẤT XỨ BRAND NAME & ORIGIN | E6: Đvt Unit | F6: KL TỔNG Q'TY | G6: ĐƠN GIÁ / RATE | J6: TỔNG CỘNG (VNĐ) TOTAL COST(VND) | L6: REMARK GHI CHÚ
G7: VẬT TƯ RATE MATERIALS | H7: NHÂN CÔNG RATE LABOUR | I7: MMTB RATE EQUIPMENT | J7: ĐƠN GIÁ TỔNG TOTAL PRICE | K7: THÀNH TIỀN AMOUNT TOTAL
A8: =A21 -> *** | B8: =B21 -> MÁY PHÁT GENERATOR | K8: =SUBTOTAL(9,K9:K20) -> #REF!
A9: =A22 -> II | B9: =B22 -> CÔNG TÁC ĐẤT EARTHWORK | K9: =K22 -> #REF!
A10: =A30 -> III | B10: =B30 -> CÔNG TÁC BÊ TÔNG CONCRETE WORK | K10: =K30 -> #REF!
A11: =A40 -> III | B11: =B40 -> CÔNG TÁC VÁN KHUÔN FORMWORK | K11: =K40 -> #REF!
A12: =A48 -> III | B12: =B48 -> CÔNG TÁC CỐT THÉP REBAR WORK | K12: =K48 -> #REF!
A13: =A55 -> VI | B13: =B55 -> CÔNG TÁC XÂY BRICK WALL | K13: =K55 -> #REF!
A14: =A61 -> VI | B14: =B61 -> CÔNG TÁC TÔ TRÁT PLASTERING WORK | K14: =K61 -> #REF!
A15: =A66 -> VII | B15: =B66 -> CÔNG TÁC SƠN PAINTING WORK | K15: =K66 -> #REF!
A16: =A69 -> VII | B16: =B69 -> CÔNG TÁC HOÀN THIỆN NỀN SÀN FINISHING THE FLOOR | K16: =K69 -> 0
A17: =A73 -> VII | B17: =B73 -> CÔNG TÁC CỬA DOOR WORK | K17: =K73 -> 16992000
A18: =A78 -> VII | B18: =B78 -> CÔNG TÁC KẾT CẤU THÉP STEEL STRUCTURE AND WORK | K18: =K78 -> #REF!
A21: *** | B21: MÁY PHÁT GENERATOR | M21: Profit | O21: 1.18
A22: II | B22: CÔNG TÁC ĐẤT EARTHWORK | K22: =SUBTOTAL(9,K23:K29) -> #REF! | M22: VẬT TƯ RATE MATERIALS | N22: NHÂN CÔNG RATE LABOUR
A23: =IF(ISBLANK(E23),"",COUNTA($E$21:E23)) -> 1 | B23: Đào đất hố móng, đường ống, khuôn đường Excavation of foundation pits, pipes, road molds | E23: m3 | G23: =M23*$O$21 -> #REF! | H23: =N23*$O$21 -> #REF! | J23: =+G23+H23+I23 -> #REF! | K23: =J23*$F23 -> #REF! | M23: ='02 Nhà Bảo Vệ_& P. Y TẾ'!R23 -> #REF! | N23: ='02 Nhà Bảo Vệ_& P. Y TẾ'!S23 -> #REF!
A24: =IF(ISBLANK(E24),"",COUNTA($E$21:E24)) -> 2 | B24: Đào đất đà kiềng Digging up the land | E24: m3 | G24: =M24*$O$21 -> 0 | H24: =N24*$O$21 -> 50740 | J24: =+G24+H24+I24 -> 50740 | K24: =J24*$F24 -> 0 | M24: ='02 Nhà Bảo Vệ_& P. Y TẾ'!R27 -> 0 | N24: ='02 Nhà Bảo Vệ_& P. Y TẾ'!S27 -> 43000
